Workbook

Sheet SD_SE_CALC_INDICATORS
A1: Inputs D–E: pumping, energy and farm-level adaptive capacity
A3: Year | B3: Pumped volume | C3: Hydrant-supplied volume | D3: Source withdrawals | E3: Irrigated area | F3: Consumed energy | G3: Energy cost | H3: Renewable energy | I3: Installed pumping capacity | J3: Required pumping capacity | K3: Total area | L3: Irrigated area | M3: GIR50%ISW_EF_H | N3: GIR50%ISW_EF_L | O3: GIR90%ISW_EF_H | P3: GIR90%ISW_EF_L | Q3: PD50%ISW_EF_H | R3: PD50%ISW_EF_L | S3: PD90%ISW_EF_H | T3: PD90%ISW_EF_L | U3: Hypothetical coincident peak | V3: TC Sprinkler | W3: TC Drip | X3: Area permanent crop | Y3: TAW_CIS | Z3: D1 | AA3: D2 | AB3: D3 | AC3: D4 | AD3: D5 | AE3: D6 | AF3: D7 | AG3: D8 | AH3: Notes | AJ3: Year | AK3: E1 main | AL3: E1 sc1 | AM3: E1 sc2 | AN3: E1 sc3 | AO3: E1 sc4 | AP3: E2 main | AQ3: E2 sc1 | AR3: E2 sc2 | AS3: E2 sc3 | AT3: E2 sc4 | AU3: E3 main | AV3: E3 sc1 | AW3: E3 sc2 | AX3: E3 sc3 | AY3: E3 sc4 | AZ3: E4 main | BA3: E4 low eff | BB3: E4 high eff | BC3: E5 OFTC | BD3: E6 WDST | BE3: E7 Permanent share | BF3: E8 SWBC | BG3: E9 ALAS | BH3: E10 CRI | BI3: Notes
A4: =[1]CONTROL_YEARS!A14 -> 2016 | B4: 6110817.9 | C4: 5745391 | D4: 6110817.9 | E4: 1334.2037 | G4: 144011.24 | H4: 0 | I4: 2600 | J4: 1382 | K4: 1563 | L4: 1334.2037 | M4: 535885.67 | N4: 648575.19 | O4: 497605.93 | P4: 602129.53 | Q4: 184241.55 | R4: 223073.49 | S4: 180553.7 | T4: 218595.39 | U4: 2480119.9 | V4: 0.37069983 | W4: 0.18385804 | X4: =CRI!N10 -> 287.99554 | Y4: =SWBC!AF4 -> 103804.37 | Z4: =IFERROR(F4/E4,"") -> 0 | AA4: =IFERROR(F4/C4,"") -> 0 | AB4: =IFERROR(F4/D4,"") -> 0 | AC4: =IFERROR(G4/E4,"") -> 107.93797 | AD4: =IFERROR(G4/C4,"") -> 0.025065525 | AE4: =IFERROR(G4/D4,"") -> 0.023566606 | AF4: =IFERROR(H4/F4,"") | AG4: =IFERROR((I4-J4)/J4,"") -> 0.8813314 | AJ4: =[1]CONTROL_YEARS!A14 -> 2016 | AK4: =IFERROR(AVERAGE(AL4:AO4),"") -> 406.89192 | AL4: =M4/L4 -> 401.65207 | AM4: 451.30255 | AN4: 401.65207 | AO4: 372.96099 | AP4: =IFERROR(AVERAGE(AQ4:AT4),"") -> 0.35340835 | AQ4: =Q4/M4 -> 0.34380756 | AR4: =R4/N4 -> 0.34394391 | AS4: =S4/O4 -> 0.36284476 | AT4: =T4/P4 -> 0.36303715 | AU4: =IFERROR(AVERAGE(AV4:AY4),"") -> 0.81292855 | AV4: =Q4*10/$U4 -> 0.74287354 | AW4: =R4*10/$U4 -> 0.89944637 | AX4: =S4*10/$U4 -> 0.72800391 | AY4: =T4*10/$U4 -> 0.88139039 | AZ4: =IFERROR(AVERAGE(BA4:BB4),"") -> 0.9998195 | BA4: =ISF!X4 -> 1.0898319 | BB4: =ISF!Y4 -> 0.90980714 | BC4: =IFERROR(SUM(V4:W4),"") -> 0.55455787 | BD4: 0.56121245 | BE4: =X4/K4 -> 0.18425818 | BF4: =Y4/L4 -> 77.802488 | BG4: =ALAS!G7 -> 0.41686881 | BH4: 0.90774403
A5: =[1]CONTROL_YEARS!A15 -> 2017 | B5: 7059537.3 | C5: 6637377 | D5: 7059537.3 | E5: 1268.2827 | G5: 171448.05 | H5: 0 | I5: 2600 | J5: 1496 | K5: 1563 | L5: 1268.2827 | M5: 583140.12 | N5: 705810.27 | O5: 524626.61 | P5: 634826.16 | Q5: 188890.03 | R5: 228635.66 | S5: 183925.77 | T5: 222612.54 | U5: 2707543.2 | V5: 0.36955416 | W5: 0.18560773 | X5: =CRI!N11 -> 292.51975 | Y5: =SWBC!AF5 -> 104376.24 | Z5: =IFERROR(F5/E5,"") -> 0 | AA5: =IFERROR(F5/C5,"") -> 0 | AB5: =IFERROR(F5/D5,"") -> 0 | AC5: =IFERROR(G5/E5,"") -> 135.18126 | AD5: =IFERROR(G5/C5,"") -> 0.025830693 | AE5: =IFERROR(G5/D5,"") -> 0.024286018 | AF5: =IFERROR(H5/F5,"") | AG5: =IFERROR((I5-J5)/J5,"") -> 0.73796791 | AJ5: =[1]CONTROL_YEARS!A15 -> 2017 | AK5: =IFERROR(AVERAGE(AL5:AO5),"") -> 482.62173 | AL5: 556.50863 | AM5: 500.53995 | AN5: 459.78718 | AO5: 413.65117 | AP5: =IFERROR(AVERAGE(AQ5:AT5),"") -> 0.33727586 | AQ5: =Q5/M5 -> 0.32391877 | AR5: =R5/N5 -> 0.3239336 | AS5: =S5/O5 -> 0.35058415 | AT5: =T5/P5 -> 0.35066693 | AU5: =IFERROR(AVERAGE(AV5:AY5),"") -> 0.76089645 | AV5: =Q5*10/$U5 -> 0.69764364 | AW5: =R5*10/$U5 -> 0.84443957 | AX5: =S5*10/$U5 -> 0.67930873 | AY5: =T5*10/$U5 -> 0.82219385 | AZ5: =IFERROR(AVERAGE(BA5:BB5),"") -> 0.99818254 | BA5: =ISF!X5 -> 1.0880142 | BB5: =ISF!Y5 -> 0.90835083 | BC5: =IFERROR(SUM(V5:W5),"") -> 0.55516189 | BD5: 0.55299896 | BE5: =X5/K5 -> 0.18715275 | BF5: =Y5/L5 -> 82.2973 | BG5: =BG4 -> 0.41686881 | BH5: 0.9916382
A6: =[1]CONTROL_YEARS!A16 -> 2018 | B6: 5630773.2 | C6: 5294053 | D6: 5630773.2 | E6: 1308.1205 | F6: 1247571.8 | G6: 144161.73 | H6: 0 | I6: 2600 | J6: 1400 | K6: 1563 | L6: 1308.1205 | M6: 493345.78 | N6: 596941.67 | O6: 455815.14 | P6: 551461.64 | Q6: 186783.84 | R6: 226159.36 | S6: 180174.59 | T6: 218135.75 | U6: 2623079 | V6: 0.36955416 | W6: 0.18560773 | X6: =CRI!N12 -> 292.51975 | Y6: =SWBC!AF6 -> 104246.78 | Z6: =IFERROR(F6/E6,"") -> 953.71314 | AA6: =IFERROR(F6/C6,"") -> 0.23565532 | AB6: =IFERROR(F6/D6,"") -> 0.22156313 | AC6: =IFERROR(G6/E6,"") -> 110.20523 | AD6: =IFERROR(G6/C6,"") -> 0.027230882 | AE6: =IFERROR(G6/D6,"") -> 0.025602475 | AF6: =IFERROR(H6/F6,"") -> 0 | AG6: =IFERROR((I6-J6)/J6,"") -> 0.85714286 | AJ6: =[1]CONTROL_YEARS!A16 -> 2018 | AK6: =IFERROR(AVERAGE(AL6:AO6),"") -> 400.87365 | AL6: 456.33537 | AM6: 421.56791 | AN6: 377.14092 | AO6: 348.45041 | AP6: =IFERROR(AVERAGE(AQ6:AT6),"") -> 0.38707723 | AQ6: =Q6/M6 -> 0.37860634 | AR6: =R6/N6 -> 0.37886341 | AS6: =S6/O6 -> 0.39527995 | AT6: =T6/P6 -> 0.39555924 | AU6: =IFERROR(AVERAGE(AV6:AY6),"") -> 0.77318822 | AV6: =Q6*10/$U6 -> 0.71207858 | AW6: =R6*10/$U6 -> 0.86219039 | AX6: =S6*10/$U6 -> 0.68688203 | AY6: =T6*10/$U6 -> 0.83160188 | AZ6: =IFERROR(AVERAGE(BA6:BB6),"") -> 1.003259 | BA6: =ISF!X6 -> 1.0937246 | BB6: =ISF!Y6 -> 0.91279334 | BC6: =IFERROR(SUM(V6:W6),"") -> 0.55516189 | BD6: 0.55748011 | BE6: =X6/K6 -> 0.18715275 | BF6: =Y6/L6 -> 79.692025 | BG6: =BG5 -> 0.41686881 | BH6: 1
A7: =[1]CONTROL_YEARS!A17 -> 2019 | B7: 6644251.2 | C7: 6246925 | D7: 6644251.2 | E7: 1300.2075 | F7: 1522770 | G7: 195057.4 | H7: 0 | I7: 2600 | J7: 1410 | K7: 1563 | L7: 1300.2075 | M7: 571298.63 | N7: 690816.7 | O7: 523147.99 | P7: 632557.97 | Q7: 182394.94 | R7: 220586.08 | S7: 176054.39 | T7: 212896.55 | U7: 2717956.9 | V7: 0.36955416 | W7: 0.18560773 | X7: =CRI!N13 -> 316.69939 | Y7: =SWBC!AF7 -> 104816.36 | Z7: =IFERROR(F7/E7,"") -> 1171.1746 | AA7: =IFERROR(F7/C7,"") -> 0.24376313 | AB7: =IFERROR(F7/D7,"") -> 0.2291861 | AC7: =IFERROR(G7/E7,"") -> 150.02021 | AD7: =IFERROR(G7/C7,"") -> 0.031224546 | AE7: =IFERROR(G7/D7,"") -> 0.029357319 | AF7: =IFERROR(H7/F7,"") -> 0 | AG7: =IFERROR((I7-J7)/J7,"") -> 0.84397163 | AJ7: =[1]CONTROL_YEARS!A17 -> 2019 | AK7: =IFERROR(AVERAGE(AL7:AO7),"") -> 464.89144 | AL7: 531.31266 | AM7: 486.50541 | AN7: 439.39036 | AO7: 402.35731 | AP7: =IFERROR(AVERAGE(AQ7:AT7),"") -> 0.32791728 | AQ7: =Q7/M7 -> 0.31926375 | AR7: =R7/N7 -> 0.31931203 | AS7: =S7/O7 -> 0.33652884 | AT7: =T7/P7 -> 0.33656449 | AU7: =IFERROR(AVERAGE(AV7:AY7),"") -> 0.7284258 | AV7: =Q7*10/$U7 -> 0.67107371 | AW7: =R7*10/$U7 -> 0.81158786 | AX7: =S7*10/$U7 -> 0.64774533 | AY7: =T7*10/$U7 -> 0.78329628 | AZ7: =IFERROR(AVERAGE(BA7:BB7),"") -> 0.99871949 | BA7: =ISF!X7 -> 1.0887075 | BB7: =ISF!Y7 -> 0.90873147 | BC7: =IFERROR(SUM(V7:W7),"") -> 0.55516189 | BD7: 0.55765976 | BE7: =X7/K7 -> 0.20262277 | BF7: =Y7/L7 -> 80.615102 | BG7: =BG6 -> 0.41686881 | BH7: 1
A8: =[1]CONTROL_YEARS!A18 -> 2020 | B8: 6331532.7 | C8: 5952907 | D8: 6331532.7 | E8: 1281.3704 | F8: 1501399 | G8: 171821.71 | H8: 0 | I8: 2600 | J8: 1406 | K8: 1563 | L8: 1281.3704 | M8: 517466.69 | N8: 625434.91 | O8: 483609.47 | P8: 584458.51 | Q8: 185606.6 | R8: 224336.03 | S8: 177116.82 | T8: 214052.64 | U8: 2701452.8 | V8: 0.36048643 | W8: 0.1994562 | X8: =CRI!N14 -> 292.51975 | Y8: =SWBC!AF8 -> 107220.47 | Z8: =IFERROR(F8/E8,"") -> 1171.7135 | AA8: =IFERROR(F8/C8,"") -> 0.25221274 | AB8: =IFERROR(F8/D8,"") -> 0.23713042 | AC8: =IFERROR(G8/E8,"") -> 134.09215 | AD8: =IFERROR(G8/C8,"") -> 0.028863496 | AE8: =IFERROR(G8/D8,"") -> 0.027137459 | AF8: =IFERROR(H8/F8,"") -> 0 | AG8: =IFERROR((I8-J8)/J8,"") -> 0.84921764 | AJ8: =[1]CONTROL_YEARS!A18 -> 2020 | AK8: =IFERROR(AVERAGE(AL8:AO8),"") -> 431.36818 | AL8: 488.09847 | AM8: 456.11989 | AN8: 403.83851 | AO8: 377.41584 | AP8: =IFERROR(AVERAGE(AQ8:AT8),"") -> 0.36246289 | AQ8: =Q8/M8 -> 0.35868318 | AR8: =R8/N8 -> 0.35868805 | AS8: =S8/O8 -> 0.36623936 | AT8: =T8/P8 -> 0.36624096 | AU8: =IFERROR(AVERAGE(AV8:AY8),"") -> 0.74137156 | AV8: =Q8*10/$U8 -> 0.68706217 | AW8: =R8*10/$U8 -> 0.83042737 | AX8: =S8*10/$U8 -> 0.65563546 | AY8: =T8*10/$U8 -> 0.79236123 | AZ8: =IFERROR(AVERAGE(BA8:BB8),"") -> 1.0122147 | BA8: =ISF!X8 -> 1.1037543 | BB8: =ISF!Y8 -> 0.92067513 | BC8: =IFERROR(SUM(V8:W8),"") -> 0.55994263 | BD8: 0.54353886 | BE8: =X8/K8 -> 0.18715275 | BF8: =Y8/L8 -> 83.676408 | BG8: =BG7 -> 0.41686881 | BH8: 0.94883684
A9: =[1]CONTROL_YEARS!A19 -> 2021 | B9: 6070613.7 | C9: 5707591 | D9: 6070613.7 | E9: 1267.9013 | F9: 1370300.8 | G9: 160490.29 | H9: 0 | I9: 2600 | J9: 1521 | K9: 1563 | L9: 1267.9013 | M9: 581074.76 | N9: 702431.36 | O9: 523703.72 | P9: 632995.01 | Q9: 192882.95 | R9: 233285.01 | S9: 188686.54 | T9: 228206.11 | U9: 2955003 | V9: 0.37808622 | W9: 0.17257736 | X9: =CRI!N15 -> 189.18405 | Y9: =SWBC!AF9 -> 100568.81 | Z9: =IFERROR(F9/E9,"") -> 1080.7629 | AA9: =IFERROR(F9/C9,"") -> 0.24008391 | AB9: =IFERROR(F9/D9,"") -> 0.22572689 | AC9: =IFERROR(G9/E9,"") -> 126.57948 | AD9: =IFERROR(G9/C9,"") -> 0.028118744 | AE9: =IFERROR(G9/D9,"") -> 0.026437243 | AF9: =IFERROR(H9/F9,"") -> 0 | AG9: =IFERROR((I9-J9)/J9,"") -> 0.70940171 | AJ9: =[1]CONTROL_YEARS!A19 -> 2021 | AK9: =IFERROR(AVERAGE(AL9:AO9),"") -> 481.15039 | AL9: 554.01107 | AM9: 499.24627 | AN9: 458.29652 | AO9: 413.0477 | AP9: =IFERROR(AVERAGE(AQ9:AT9),"") -> 0.34621576 | AQ9: =Q9/M9 -> 0.33194171 | AR9: =R9/N9 -> 0.33211075 | AS9: =S9/O9 -> 0.36029253 | AT9: =T9/P9 -> 0.36051803 | AU9: =IFERROR(AVERAGE(AV9:AY9),"") -> 0.71324852 | AV9: =Q9*10/$U9 -> 0.6527335 | AW9: =R9*10/$U9 -> 0.78945777 | AX9: =S9*10/$U9 -> 0.63853248 | AY9: =T9*10/$U9 -> 0.77227033 | AZ9: =IFERROR(AVERAGE(BA9:BB9),"") -> 1.0469067 | BA9: =ISF!X9 -> 1.1420468 | BB9: =ISF!Y9 -> 0.95176659 | BC9: =IFERROR(SUM(V9:W9),"") -> 0.55066358 | BD9: 0.55486945 | BE9: =X9/K9 -> 0.12103906 | BF9: =Y9/L9 -> 79.319116 | BG9: =BG8 -> 0.41686881 | BH9: 0.98958161
A10: =[1]CONTROL_YEARS!A20 -> 2022 | B10: 7065031.9 | C10: 6642543 | D10: 7065031.9 | E10: 1495.4465 | F10: 1589106.5 | G10: 115521.7 | H10: 0 | I10: 2600 | J10: 1680 | K10: 1978.8 | L10: 1495.4465 | M10: 672842.37 | N10: 810847.22 | O10: 629299.93 | P10: 758260.44 | Q10: 230617.82 | R10: 278024.38 | S10: 223308.58 | T10: 269204.38 | U10: 3512919.9 | V10: 0.33556878 | W10: 0.23286218 | X10: =CRI!N16 -> 355.71493 | Y10: =SWBC!AF10 -> 113675.69 | Z10: =IFERROR(F10/E10,"") -> 1062.6301 | AA10: =IFERROR(F10/C10,"") -> 0.23923165 | AB10: =IFERROR(F10/D10,"") -> 0.22492559 | AC10: =IFERROR(G10/E10,"") -> 77.248967 | AD10: =IFERROR(G10/C10,"") -> 0.017391186 | AE10: =IFERROR(G10/D10,"") -> 0.016351193 | AF10: =IFERROR(H10/F10,"") -> 0 | AG10: =IFERROR((I10-J10)/J10,"") -> 0.54761905 | AJ10: =[1]CONTROL_YEARS!A20 -> 2022 | AK10: =IFERROR(AVERAGE(AL10:AO10),"") -> 479.99877 | AL10: 542.21077 | AM10: 507.04617 | AN10: 449.9274 | AO10: 420.81072 | AP10: =IFERROR(AVERAGE(AQ10:AT10),"") -> 0.34887857 | AQ10: =Q10/M10 -> 0.34275164 | AR10: =R10/N10 -> 0.34288134 | AS10: =S10/O10 -> 0.35485238 | AT10: =T10/P10 -> 0.35502892 | AU10: =IFERROR(AVERAGE(AV10:AY10),"") -> 0.71248078 | AV10: =Q10*10/$U10 -> 0.65648473 | AW10: =R10*10/$U10 -> 0.79143388 | AX10: =S10*10/$U10 -> 0.63567798 | AY10: =T10*10/$U10 -> 0.76632656 | AZ10: =IFERROR(AVERAGE(BA10:BB10),"") -> 1.0277026 | BA10: =ISF!X10 -> 1.1212708 | BB10: =ISF!Y10 -> 0.93413451 | BC10: =IFERROR(SUM(V10:W10),"") -> 0.56843096 | BD10: 0.54461099 | BE10: =X10/K10 -> 0.17976295 | BF10: =Y10/L10 -> 76.014548 | BG10: =BG9 -> 0.41686881 | BH10: 1
A11: =[1]CONTROL_YEARS!A21 -> 2023 | B11: 8105353.1 | C11: 7620653 | D11: 8105353.1 | E11: 1552.837 | F11: 1787288.2 | G11: 212833.77 | H11: 0 | I11: 2600 | J11: 1480 | K11: 1978.8 | L11: 1552.837 | M11: 757045.93 | N11: 912016.36 | O11: 669408.27 | P11: 805896.11 | Q11: 229048.6 | R11: 276006.02 | S11: 220383.38 | T11: 265545.18 | U11: 3060818.5 | V11: 0.30038011 | W11: 0.28333861 | X11: =CRI!N17 -> 480.35597 | Y11: =SWBC!AF11 -> 119317.91 | Z11: =IFERROR(F11/E11,"") -> 1150.9825 | AA11: =IFERROR(F11/C11,"") -> 0.23453217 | AB11: =IFERROR(F11/D11,"") -> 0.22050714 | AC11: =IFERROR(G11/E11,"") -> 137.06125 | AD11: =IFERROR(G11/C11,"") -> 0.027928548 | AE11: =IFERROR(G11/D11,"") -> 0.02625842 | AF11: =IFERROR(H11/F11,"") -> 0 | AG11: =IFERROR((I11-J11)/J11,"") -> 0.75675676 | AJ11: =[1]CONTROL_YEARS!A21 -> 2023 | AK11: =IFERROR(AVERAGE(AL11:AO11),"") -> 506.22936 | AL11: 587.32267 | AM11: 518.98308 | AN11: 487.52441 | AO11: 431.08729 | AP11: =IFERROR(AVERAGE(AQ11:AT11),"") -> 0.31597817 | AQ11: =Q11/M11 -> 0.30255576 | AR11: =R11/N11 -> 0.30263275 | AS11: =S11/O11 -> 0.32922118 | AT11: =T11/P11 -> 0.329503 | AU11: =IFERROR(AVERAGE(AV11:AY11),"") -> 0.80941028 | AV11: =Q11*10/$U11 -> 0.74832468 | AW11: =R11*10/$U11 -> 0.90173925 | AX11: =S11*10/$U11 -> 0.72001454 | AY11: =T11*10/$U11 -> 0.86756266 | AZ11: =IFERROR(AVERAGE(BA11:BB11),"") -> 0.98955181 | BA11: =ISF!X11 -> 1.0789505 | BB11: =ISF!Y11 -> 0.9001531 | BC11: =IFERROR(SUM(V11:W11),"") -> 0.58371872 | BD11: 0.53718611 | BE11: =X11/K11 -> 0.24275115 | BF11: =Y11/L11 -> 76.838659 | BG11: =BG10 -> 0.41686881 | BH11: 0.99184776
A12: =[1]CONTROL_YEARS!A22 -> 2024 | B12: 7165430.8 | C12: 6736938 | D12: 7165430.8 | E12: 1560.0147 | F12: 1521350.2 | G12: 236077.79 | H12: 0 | I12: 2600 | J12: 1335 | K12: 1978.8 | L12: 1560.0147 | M12: 593376.17 | N12: 713753.09 | O12: 553546.86 | P12: 665697.93 | Q12: 206241.46 | R12: 248459.3 | S12: 200125.25 | T12: 241071.84 | U12: 2864548.9 | V12: 0.28948531 | W12: 0.29912147 | X12: =CRI!N18 -> 477.41639 | Y12: =SWBC!AF12 -> 120519.97 | Z12: =IFERROR(F12/E12,"") -> 975.21535 | AA12: =IFERROR(F12/C12,"") -> 0.22582221 | AB12: =IFERROR(F12/D12,"") -> 0.21231804 | AC12: =IFERROR(G12/E12,"") -> 151.33049 | AD12: =IFERROR(G12/C12,"") -> 0.035042298 | AE12: =IFERROR(G12/D12,"") -> 0.032946769 | AF12: =IFERROR(H12/F12,"") -> 0 | AG12: =IFERROR((I12-J12)/J12,"") -> 0.94756554 | AJ12: =[1]CONTROL_YEARS!A22 -> 2024 | AK12: =IFERROR(AVERAGE(AL12:AO12),"") -> 404.86383 | AL12: 457.52973 | AM12: 426.72543 | AN12: 380.36576 | AO12: 354.8344 | AP12: =IFERROR(AVERAGE(AQ12:AT12),"") -> 0.35483551 | AQ12: =Q12/M12 -> 0.34757287 | AR12: =R12/N12 -> 0.34810259 | AS12: =S12/O12 -> 0.36153263 | AT12: =T12/P12 -> 0.36213397 | AU12: =IFERROR(AVERAGE(AV12:AY12),"") -> 0.78188388 | AV12: =Q12*10/$U12 -> 0.71997884 | AW12: =R12*10/$U12 -> 0.86735925 | AX12: =S12*10/$U12 -> 0.69862746 | AY12: =T12*10/$U12 -> 0.84156999 | AZ12: =IFERROR(AVERAGE(BA12:BB12),"") -> 0.99877193 | BA12: =ISF!X12 -> 1.0892735 | BB12: =ISF!Y12 -> 0.90827041 | BC12: =IFERROR(SUM(V12:W12),"") -> 0.58860678 | BD12: 0.5339345 | BE12: =X12/K12 -> 0.24126561 | BF12: =Y12/L12 -> 77.255667 | BG12: =BG11 -> 0.41686881 | BH12: 0.91166331
A13: =[1]CONTROL_YEARS!A23 -> 2025 | B13: 7321800.7 | C13: 6883957 | D13: 7321800.7 | E13: 1483.9115 | F13: 1139604 | G13: 178991.02 | H13: 105508 | I13: 2600 | J13: 1347 | K13: 1978.8 | L13: 1483.9115 | M13: 649854.09 | N13: 782806.31 | O13: 612408.7 | P13: 737512.97 | Q13: 212111.84 | R13: 255862.11 | S13: 206367.57 | T13: 248904.72 | U13: 2890713.9 | V13: 0.29513881 | W13: 0.2963449 | X13: =CRI!N19 -> 477.41639 | Y13: =SWBC!AF13 -> 121535.66 | Z13: =IFERROR(F13/E13,"") -> 767.97303 | AA13: =IFERROR(F13/C13,"") -> 0.1655449 | AB13: =IFERROR(F13/D13,"") -> 0.15564532 | AC13: =IFERROR(G13/E13,"") -> 120.62109 | AD13: =IFERROR(G13/C13,"") -> 0.026001182 | AE13: =IFERROR(G13/D13,"") -> 0.024446311 | AF13: =IFERROR(H13/F13,"") -> 0.092583038 | AG13: =IFERROR((I13-J13)/J13,"") -> 0.93021529 | AJ13: =[1]CONTROL_YEARS!A23 -> 2025 | AK13: =IFERROR(AVERAGE(AL13:AO13),"") -> 468.79179 | AL13: 527.52898 | AM13: 497.00604 | AN13: 437.93319 | AO13: 412.69894 | AP13: =IFERROR(AVERAGE(AQ13:AT13),"") -> 0.33193011 | AQ13: =Q13/M13 -> 0.32639918 | AR13: =R13/N13 -> 0.32685239 | AS13: =S13/O13 -> 0.33697688 | AT13: =T13/P13 -> 0.33749199 | AU13: =IFERROR(AVERAGE(AV13:AY13),"") -> 0.79845869 | AV13: =Q13*10/$U13 -> 0.73376977 | AW13: =R13*10/$U13 -> 0.8851174 | AX13: =S13*10/$U13 -> 0.7138983 | AY13: =T13*10/$U13 -> 0.86104931 | AZ13: =IFERROR(AVERAGE(BA13:BB13),"") -> 0.99662189 | BA13: =ISF!X13 -> 1.0867613 | BB13: =ISF!Y13 -> 0.90648245 | BC13: =IFERROR(SUM(V13:W13),"") -> 0.5914837 | BD13: 0.5449357 | BE13: =X13/K13 -> 0.24126561 | BF13: =Y13/L13 -> 81.902228 | BG13: =BG12 -> 0.41686881 | BH13: 0.94033577
A14: =[1]CONTROL_YEARS!A24 | Z14: =IFERROR(F14/E14,"") | AA14: =IFERROR(F14/C14,"") | AB14: =IFERROR(F14/D14,"") | AC14: =IFERROR(G14/E14,"") | AD14: =IFERROR(G14/C14,"") | AE14: =IFERROR(G14/D14,"") | AF14: =IFERROR(H14/F14,"") | AG14: =IFERROR((I14-J14)/J14,"") | AJ14: =[1]CONTROL_YEARS!A24 | AK14: =IFERROR(AVERAGE(AL14:AO14),"") | AP14: =IFERROR(AVERAGE(AQ14:AT14),"") | AU14: =IFERROR(AVERAGE(AV14:AY14),"") | AZ14: =IFERROR(AVERAGE(BA14:BB14),"")
A15: =[1]CONTROL_YEARS!A25 | Z15: =IFERROR(F15/E15,"") | AA15: =IFERROR(F15/C15,"") | AB15: =IFERROR(F15/D15,"") | AC15: =IFERROR(G15/E15,"") | AD15: =IFERROR(G15/C15,"") | AE15: =IFERROR(G15/D15,"") | AF15: =IFERROR(H15/F15,"") | AG15: =IFERROR((I15-J15)/J15,"") | AJ15: =[1]CONTROL_YEARS!A25 | AK15: =IFERROR(AVERAGE(AL15:AO15),"") | AP15: =IFERROR(AVERAGE(AQ15:AT15),"") | AU15: =IFERROR(AVERAGE(AV15:AY15),"") | AZ15: =IFERROR(AVERAGE(BA15:BB15),"")
A16: =[1]CONTROL_YEARS!A26 | Z16: =IFERROR(F16/E16,"") | AA16: =IFERROR(F16/C16,"") | AB16: =IFERROR(F16/D16,"") | AC16: =IFERROR(G16/E16,"") | AD16: =IFERROR(G16/C16,"") | AE16: =IFERROR(G16/D16,"") | AF16: =IFERROR(H16/F16,"") | AG16: =IFERROR((I16-J16)/J16,"") | AJ16: =[1]CONTROL_YEARS!A26 | AK16: =IFERROR(AVERAGE(AL16:AO16),"") | AP16: =IFERROR(AVERAGE(AQ16:AT16),"") | AU16: =IFERROR(AVERAGE(AV16:AY16),"") | AZ16: =IFERROR(AVERAGE(BA16:BB16),"")
A17: =[1]CONTROL_YEARS!A27 | Z17: =IFERROR(F17/E17,"") | AA17: =IFERROR(F17/C17,"") | AB17: =IFERROR(F17/D17,"") | AC17: =IFERROR(G17/E17,"") | AD17: =IFERROR(G17/C17,"") | AE17: =IFERROR(G17/D17,"") | AF17: =IFERROR(H17/F17,"") | AG17: =IFERROR((I17-J17)/J17,"") | AJ17: =[1]CONTROL_YEARS!A27 | AK17: =IFERROR(AVERAGE(AL17:AO17),"") | AP17: =IFERROR(AVERAGE(AQ17:AT17),"") | AU17: =IFERROR(AVERAGE(AV17:AY17),"") | AZ17: =IFERROR(AVERAGE(BA17:BB17),"")
A18: =[1]CONTROL_YEARS!A28 | Z18: =IFERROR(F18/E18,"") | AA18: =IFERROR(F18/C18,"") | AB18: =IFERROR(F18/D18,"") | AC18: =IFERROR(G18/E18,"") | AD18: =IFERROR(G18/C18,"") | AE18: =IFERROR(G18/D18,"") | AF18: =IFERROR(H18/F18,"") | AG18: =IFERROR((I18-J18)/J18,"") | AJ18: =[1]CONTROL_YEARS!A28 | AK18: =IFERROR(AVERAGE(AL18:AO18),"") | AP18: =IFERROR(AVERAGE(AQ18:AT18),"") | AU18: =IFERROR(AVERAGE(AV18:AY18),"") | AZ18: =IFERROR(AVERAGE(BA18:BB18),"")
A19: =[1]CONTROL_YEARS!A29 | Z19: =IFERROR(F19/E19,"") | AA19: =IFERROR(F19/C19,"") | AB19: =IFERROR(F19/D19,"") | AC19: =IFERROR(G19/E19,"") | AD19: =IFERROR(G19/C19,"") | AE19: =IFERROR(G19/D19,"") | AF19: =IFERROR(H19/F19,"") | AG19: =IFERROR((I19-J19)/J19,"") | AJ19: =[1]CONTROL_YEARS!A29 | AK19: =IFERROR(AVERAGE(AL19:AO19),"") | AP19: =IFERROR(AVERAGE(AQ19:AT19),"") | AU19: =IFERROR(AVERAGE(AV19:AY19),"") | AZ19: =IFERROR(AVERAGE(BA19:BB19),"")
A20: =[1]CONTROL_YEARS!A30 | Z20: =IFERROR(F20/E20,"") | AA20: =IFERROR(F20/C20,"") | AB20: =IFERROR(F20/D20,"") | AC20: =IFERROR(G20/E20,"") | AD20: =IFERROR(G20/C20,"") | AE20: =IFERROR(G20/D20,"") | AF20: =IFERROR(H20/F20,"") | AG20: =IFERROR((I20-J20)/J20,"") | AJ20: =[1]CONTROL_YEARS!A30 | AK20: =IFERROR(AVERAGE(AL20:AO20),"") | AP20: =IFERROR(AVERAGE(AQ20:AT20),"") | AU20: =IFERROR(AVERAGE(AV20:AY20),"") | AZ20: =IFERROR(AVERAGE(BA20:BB20),"")
A21: =[1]CONTROL_YEARS!A31 | Z21: =IFERROR(F21/E21,"") | AA21: =IFERROR(F21/C21,"") | AB21: =IFERROR(F21/D21,"") | AC21: =IFERROR(G21/E21,"") | AD21: =IFERROR(G21/C21,"") | AE21: =IFERROR(G21/D21,"") | AF21: =IFERROR(H21/F21,"") | AG21: =IFERROR((I21-J21)/J21,"") | AJ21: =[1]CONTROL_YEARS!A31 | AK21: =IFERROR(AVERAGE(AL21:AO21),"") | AP21: =IFERROR(AVERAGE(AQ21:AT21),"") | AU21: =IFERROR(AVERAGE(AV21:AY21),"") | AZ21: =IFERROR(AVERAGE(BA21:BB21),"")
A22: =[1]CONTROL_YEARS!A32 | Z22: =IFERROR(F22/E22,"") | AA22: =IFERROR(F22/C22,"") | AB22: =IFERROR(F22/D22,"") | AC22: =IFERROR(G22/E22,"") | AD22: =IFERROR(G22/C22,"") | AE22: =IFERROR(G22/D22,"") | AF22: =IFERROR(H22/F22,"") | AG22: =IFERROR((I22-J22)/J22,"") | AJ22: =[1]CONTROL_YEARS!A32 | AK22: =IFERROR(AVERAGE(AL22:AO22),"") | AP22: =IFERROR(AVERAGE(AQ22:AT22),"") | AU22: =IFERROR(AVERAGE(AV22:AY22),"") | AZ22: =IFERROR(AVERAGE(BA22:BB22),"")
A23: =[1]CONTROL_YEARS!A33 | Z23: =IFERROR(F23/E23,"") | AA23: =IFERROR(F23/C23,"") | AB23: =IFERROR(F23/D23,"") | AC23: =IFERROR(G23/E23,"") | AD23: =IFERROR(G23/C23,"") | AE23: =IFERROR(G23/D23,"") | AF23: =IFERROR(H23/F23,"") | AG23: =IFERROR((I23-J23)/J23,"") | AJ23: =[1]CONTROL_YEARS!A33 | AK23: =IFERROR(AVERAGE(AL23:AO23),"") | AP23: =IFERROR(AVERAGE(AQ23:AT23),"") | AU23: =IFERROR(AVERAGE(AV23:AY23),"") | AZ23: =IFERROR(AVERAGE(BA23:BB23),"")
A24: =[1]CONTROL_YEARS!A34 | Z24: =IFERROR(F24/E24,"") | AA24: =IFERROR(F24/C24,"") | AB24: =IFERROR(F24/D24,"") | AC24: =IFERROR(G24/E24,"") | AD24: =IFERROR(G24/C24,"") | AE24: =IFERROR(G24/D24,"") | AF24: =IFERROR(H24/F24,"") | AG24: =IFERROR((I24-J24)/J24,"") | AJ24: =[1]CONTROL_YEARS!A34 | AK24: =IFERROR(AVERAGE(AL24:AO24),"") | AP24: =IFERROR(AVERAGE(AQ24:AT24),"") | AU24: =IFERROR(AVERAGE(AV24:AY24),"") | AZ24: =IFERROR(AVERAGE(BA24:BB24),"")
A25: =[1]CONTROL_YEARS!A35 | Z25: =IFERROR(F25/E25,"") | AA25: =IFERROR(F25/C25,"") | AB25: =IFERROR(F25/D25,"") | AC25: =IFERROR(G25/E25,"") | AD25: =IFERROR(G25/C25,"") | AE25: =IFERROR(G25/D25,"") | AF25: =IFERROR(H25/F25,"") | AG25: =IFERROR((I25-J25)/J25,"") | AJ25: =[1]CONTROL_YEARS!A35 | AK25: =IFERROR(AVERAGE(AL25:AO25),"") | AP25: =IFERROR(AVERAGE(AQ25:AT25),"") | AU25: =IFERROR(AVERAGE(AV25:AY25),"") | AZ25: =IFERROR(AVERAGE(BA25:BB25),"")
... A33: =[1]CONTROL_YEARS!A43 | Z33: =IFERROR(F33/E33,"") | AA33: =IFERROR(F33/C33,"") | AB33: =IFERROR(F33/D33,"") | AC33: =IFERROR(G33/E33,"") | AD33: =IFERROR(G33/C33,"") | AE33: =IFERROR(G33/D33,"") | AF33: =IFERROR(H33/F33,"") | AG33: =IFERROR((I33-J33)/J33,"") | AJ33: =[1]CONTROL_YEARS!A43 | AK33: =IFERROR(AVERAGE(AL33:AO33),"") | AP33: =IFERROR(AVERAGE(AQ33:AT33),"") | AU33: =IFERROR(AVERAGE(AV33:AY33),"") | AZ33: =IFERROR(AVERAGE(BA33:BB33),"")

Sheet GIR
B1: Year | C1: 2016 | D1: 2017 | E1: 2018 | F1: 2019 | G1: 2020 | H1: 2021 | I1: 2022 | J1: 2023 | K1: 2024 | L1: 2025
B2: Area | C2: 1334.2037 | D2: 1268.2827 | E2: 1308.1205 | F2: 1300.2075 | G2: 1281.3704 | H2: 1267.9013 | I2: 1495.4465 | J2: 1552.837 | K2: 1560.0147 | L2: 1483.9115
B3: GIR50%ISW_EF_H | C3: 535885.67 | D3: 583140.12 | E3: 493345.78 | F3: 571298.63 | G3: 517466.69 | H3: 581074.76 | I3: 672842.37 | J3: 757045.93 | K3: 593376.17 | L3: 649854.09
B4: GIR50%ISW_EF_L | C4: 648575.19 | D4: 705810.27 | E4: 596941.67 | F4: 690816.7 | G4: 625434.91 | H4: 702431.36 | I4: 810847.22 | J4: 912016.36 | K4: 713753.09 | L4: 782806.31
B5: GIR90%ISW_EF_H | C5: 497605.93 | D5: 524626.61 | E5: 455815.14 | F5: 523147.99 | G5: 483609.47 | H5: 523703.72 | I5: 629299.93 | J5: 669408.27 | K5: 553546.86 | L5: 612408.7
B6: GIR90%ISW_EF_L | C6: 602129.53 | D6: 634826.16 | E6: 551461.64 | F6: 632557.97 | G6: 584458.51 | H6: 632995.01 | I6: 758260.44 | J6: 805896.11 | K6: 665697.93 | L6: 737512.97
B7: GIR50%ISW_EF_H | C7: =C3/$C$2 -> 401.65207 | D7: =D3/$D$2 -> 459.78718 | E7: =E3/$E$2 -> 377.14092 | F7: =F3/$F$2 -> 439.39036 | G7: =G3/$G$2 -> 403.83851 | H7: =H3/$H$2 -> 458.29652 | I7: =I3/$I$2 -> 449.9274 | J7: =J3/$J$2 -> 487.52441 | K7: =K3/$K$2 -> 380.36576 | L7: =L3/$L$2 -> 437.93319
B8: GIR50%ISW_EF_L | C8: =C4/$C$2 -> 486.11408 | D8: =D4/$D$2 -> 556.50863 | E8: =E4/$E$2 -> 456.33537 | F8: =F4/$F$2 -> 531.31266 | G8: =G4/$G$2 -> 488.09847 | H8: =H4/$H$2 -> 554.01107 | I8: =I4/$I$2 -> 542.21077 | J8: =J4/$J$2 -> 587.32267 | K8: =K4/$K$2 -> 457.52973 | L8: =L4/$L$2 -> 527.52898
B9: GIR90%ISW_EF_H | C9: =C5/$C$2 -> 372.96099 | D9: =D5/$D$2 -> 413.65117 | E9: =E5/$E$2 -> 348.45041 | F9: =F5/$F$2 -> 402.35731 | G9: =G5/$G$2 -> 377.41584 | H9: =H5/$H$2 -> 413.0477 | I9: =I5/$I$2 -> 420.81072 | J9: =J5/$J$2 -> 431.08729 | K9: =K5/$K$2 -> 354.8344 | L9: =L5/$L$2 -> 412.69894
B10: GIR90%ISW_EF_L | C10: =C6/$C$2 -> 451.30255 | D10: =D6/$D$2 -> 500.53995 | E10: =E6/$E$2 -> 421.56791 | F10: =F6/$F$2 -> 486.50541 | G10: =G6/$G$2 -> 456.11989 | H10: =H6/$H$2 -> 499.24627 | I10: =I6/$I$2 -> 507.04617 | J10: =J6/$J$2 -> 518.98308 | K10: =K6/$K$2 -> 426.72543 | L10: =L6/$L$2 -> 497.00604
B11: Mean | C11: =AVERAGE(C7:C10) -> 428.00742 | D11: =AVERAGE(D7:D10) -> 482.62173 | E11: =AVERAGE(E7:E10) -> 400.87365 | F11: =AVERAGE(F7:F10) -> 464.89144 | G11: =AVERAGE(G7:G10) -> 431.36818 | H11: =AVERAGE(H7:H10) -> 481.15039 | I11: =AVERAGE(I7:I10) -> 479.99877 | J11: =AVERAGE(J7:J10) -> 506.22936 | ... L11: =AVERAGE(L7:L10) -> 468.79179
B12: GIR_year_mm | C12: 444.78921 | D12: 506.982 | E12: 419.20137 | F12: 493.04019 | G12: 446.05694 | H12: 522.65268 | I12: 545.44884 | J12: 533.12336 | K12: 442.46739 | L12: 466.8483
B14: Year | C14: 2016 | D14: 2017 | E14: 2018 | F14: 2019 | G14: 2020 | H14: 2021 | I14: 2022 | J14: 2023 | K14: 2024 | L14: 2025
B15: GIR50%ISW_EF_L | C15: 486.11408 | D15: 556.50863 | E15: 456.33537 | F15: 531.31266 | G15: 488.09847 | H15: 554.01107 | I15: 542.21077 | J15: 587.32267 | K15: 457.52973 | L15: 527.52898
B16: GIR90%ISW_EF_L | C16: 451.30255 | D16: 500.53995 | E16: 421.56791 | F16: 486.50541 | G16: 456.11989 | H16: 499.24627 | I16: 507.04617 | J16: 518.98308 | K16: 426.72543 | L16: 497.00604
B17: Mean | C17: 428.00742 | D17: 482.62173 | E17: 400.87365 | F17: 464.89144 | G17: 431.36818 | H17: 481.15039 | I17: 479.99877 | J17: 506.22936 | K17: 404.86383 | L17: 468.79179
B18: GIR50%ISW_EF_H | C18: 401.65207 | D18: 459.78718 | E18: 377.14092 | F18: 439.39036 | G18: 403.83851 | H18: 458.29652 | I18: 449.9274 | J18: 487.52441 | K18: 380.36576 | L18: 437.93319
B19: GIR90%ISW_EF_H | C19: 372.96099 | D19: 413.65117 | E19: 348.45041 | F19: 402.35731 | G19: 377.41584 | H19: 413.0477 | I19: 420.81072 | J19: 431.08729 | K19: 354.8344 | L19: 412.69894
C20: 2016 | D20: 2017 | E20: 2018 | F20: 2019 | G20: 2020 | H20: 2021 | I20: 2022 | J20: 2023 | K20: 2024 | L20: 2025
B21: Mean | C21: 428.00742 | D21: 482.62173 | E21: 400.87365 | F21: 464.89144 | G21: 431.36818 | H21: 481.15039 | I21: 479.99877 | J21: 506.22936 | K21: 404.86383 | L21: 468.79179
B22: min | C22: =MIN(C15:C19) -> 372.96099 | D22: =MIN(D15:D19) -> 413.65117 | E22: =MIN(E15:E19) -> 348.45041 | F22: =MIN(F15:F19) -> 402.35731 | G22: =MIN(G15:G19) -> 377.41584 | H22: =MIN(H15:H19) -> 413.0477 | I22: =MIN(I15:I19) -> 420.81072 | J22: =MIN(J15:J19) -> 431.08729 | ... L22: =MIN(L15:L19) -> 412.69894
B23: Max | C23: =MAX(C15:C19) -> 486.11408 | D23: =MAX(D15:D19) -> 556.50863 | E23: =MAX(E15:E19) -> 456.33537 | F23: =MAX(F15:F19) -> 531.31266 | G23: =MAX(G15:G19) -> 488.09847 | H23: =MAX(H15:H19) -> 554.01107 | I23: =MAX(I15:I19) -> 542.21077 | J23: =MAX(J15:J19) -> 587.32267 | ... L23: =MAX(L15:L19) -> 527.52898
B24: Mean -min | C24: =C21-C22 -> 55.046432 | D24: =D21-D22 -> 68.970567 | E24: =E21-E22 -> 52.423241 | F24: =F21-F22 -> 62.534122 | G24: =G21-G22 -> 53.952339 | H24: =H21-H22 -> 68.10269 | I24: =I21-I22 -> 59.188046 | J24: =J21-J22 -> 75.142075 | ... L24: =L21-L22 -> 56.092846
B25: Max- mean | C25: =C23-C21 -> 58.106653 | D25: =D23-D21 -> 73.8869 | E25: =E23-E21 -> 55.461717 | F25: =F23-F21 -> 66.421226 | G25: =G23-G21 -> 56.730292 | H25: =H23-H21 -> 72.860679 | I25: =I23-I21 -> 62.212007 | J25: =J23-J21 -> 81.093312 | ... L25: =L23-L21 -> 58.737193

Sheet DPF
B3: Sum of GIR50%ISW_EF_H | N3: Sum of GIR50%ISW_EF_L | Z3: Sum of GIR90%ISW_EF_H | AL3: Sum of GIR90%ISW_EF_L
B4: Year | C4: 2016 | D4: 2017 | E4: 2018 | F4: 2019 | G4: 2020 | H4: 2021 | I4: 2022 | J4: 2023 | K4: 2024 | L4: 2025 | N4: Year | O4: 2016 | P4: 2017 | Q4: 2018 | R4: 2019 | S4: 2020 | T4: 2021 | U4: 2022 | V4: 2023 | W4: 2024 | X4: 2025 | Z4: Year | AA4: 2016 | AB4: 2017 | AC4: 2018 | AD4: 2019 | AE4: 2020 | AF4: 2021 | AG4: 2022 | AH4: 2023 | AI4: 2024 | AJ4: 2025 | AL4: Year | AM4: 2016 | AN4: 2017 | AO4: 2018 | AP4: 2019 | AQ4: 2020 | AR4: 2021 | AS4: 2022 | AT4: 2023 | AU4: 2024 | AV4: 2025
B5: Jun | C5: 87409.924 | D5: 107327.03 | E5: 39818.249 | F5: 101863.26 | G5: 88217.304 | H5: 92682.353 | I5: 102157.86 | J5: 106664.5 | K5: 56076.724 | L5: 117384.56 | N5: Jun | O5: 105718.48 | P5: 129847.97 | Q5: 48035.851 | R5: 122962.28 | S5: 106602.83 | T5: 111859.63 | U5: 122877.21 | V5: 128128.52 | W5: 67098.791 | X5: 141071.35 | Z5: Jun | AA5: 71446.308 | AB5: 96129.24 | AC5: 25438.759 | AD5: 92842.387 | AE5: 73674.024 | AF5: 79147.124 | AG5: 92304.519 | AH5: 93821.262 | AI5: 44671.27 | AJ5: 104736.4 | AL5: Jun | AM5: 86334.088 | AN5: 116282.5 | AO5: 30606.484 | AP5: 112049.8 | AQ5: 88970.99 | AR5: 95502.185 | AS5: 110979.99 | AT5: 112619.79 | AU5: 53320.691 | AV5: 125754.1
B6: Jul | C6: 153395.39 | D6: 188890.03 | E6: 126988.13 | F6: 182394.94 | G6: 185606.6 | H6: 176979.76 | I6: 230617.82 | J6: 229048.6 | K6: 173512.07 | L6: 173866.61 | N6: Jul | O6: 185570.66 | P6: 228635.66 | Q6: 153508.3 | R6: 220586.08 | S6: 224336.03 | T6: 213912.32 | U6: 278024.38 | V6: 276006.02 | W6: 208716.57 | X6: 209308.59 | Z6: Jul | AA6: 144769.21 | AB6: 183925.77 | AC6: 115762.77 | AD6: 176054.39 | AE6: 177116.82 | AF6: 168512.26 | AG6: 223308.58 | AH6: 220383.38 | AI6: 162533.61 | AJ6: 165026.41 | AL6: Jul | AM6: 175097.1 | AN6: 222612.54 | AO6: 139891.33 | AP6: 212896.55 | AQ6: 214052.64 | AR6: 203665.83 | AS6: 269204.38 | AT6: 265545.18 | AU6: 195452.86 | AV6: 198608.03
B7: Apr | C7: 2540.9381 | D7: 37154.768 | E7: 1086.706 | F7: 11724.413 | G7: 899.10261 | H7: 18892.295 | I7: 10574.215 | J7: 75412.042 | K7: 2191.5439 | L7: 638.74742 | N7: Apr | O7: 3040.5272 | P7: 45060.151 | Q7: 1290.888 | R7: 14189.096 | S7: 1067.9157 | T7: 22930.687 | U7: 12795.434 | V7: 90973.624 | W7: 2641.6517 | X7: 758.74574 | Z7: Apr | AA7: 1296.0953 | AB7: 4918.4679 | AC7: 15.398795 | AD7: 1814.2933 | AE7: 6.8813997 | AF7: 2780.3399 | AG7: 2986.622 | AH7: 26835.452 | AI7: 280.9962 | AJ7: 38.782663 | AL7: Apr | AM7: 1562.2764 | AN7: 5939.3549 | AO7: 18.626412 | AP7: 2201.8047 | AQ7: 8.3559854 | AR7: 3375.4676 | AS7: 3617.7117 | AT7: 32040.425 | AU7: 340.71261 | AV7: 46.287595
B8: Aug | C8: 184241.55 | D8: 123501.05 | E8: 186783.84 | F8: 142241.82 | G8: 159676.17 | H8: 192882.95 | I8: 190465.13 | J8: 212703.24 | K8: 206241.46 | L8: 212111.84 | N8: Aug | O8: 223073.49 | P8: 149372.46 | Q8: 226159.36 | R8: 172231.88 | S8: 193054.54 | T8: 233285.01 | U8: 229600.11 | V8: 256518.04 | W8: 248459.3 | X8: 255862.11 | Z8: Aug | AA8: 180553.7 | AB8: 121443.56 | AC8: 180174.59 | AD8: 139497.07 | AE8: 155954.41 | AF8: 188686.54 | AG8: 186744.32 | AH8: 208856.13 | AI8: 200125.25 | AJ8: 206367.57 | AL8: Aug | AM8: 218595.39 | AN8: 146873.44 | AO8: 218135.75 | AP8: 168904.76 | AQ8: 188554.31 | AR8: 228206.11 | AS8: 225111.56 | AT8: 251851.57 | AU8: 241071.84 | AV8: 248904.72
B9: May | C9: 8998.0679 | D9: 21546.318 | E9: 6803.8033 | F9: 56802.593 | G9: 17710.435 | H9: 37409.401 | I9: 79079.174 | J9: 63490.295 | K9: 43934.46 | L9: 31774.48 | N9: May | O9: 10880.968 | P9: 26035.328 | Q9: 8190.7721 | R9: 68575.932 | S9: 21390.2 | T9: 45137.571 | U9: 95251.266 | V9: 76325.92 | W9: 52598.173 | X9: 38128.075 | Z9: May | AA9: 2544.9449 | AB9: 15387.367 | AC9: 5447.0658 | AD9: 37503.768 | AE9: 12728.081 | AF9: 24028.219 | AG9: 64859.532 | AH9: 49637.786 | AI9: 36846.694 | AJ9: 23794.577 | AL9: May | AM9: 3047.489 | AN9: 18564.508 | AO9: 6559.6347 | AP9: 45251.953 | AQ9: 15379.386 | AR9: 28978.207 | AS9: 78082.381 | AT9: 59599.657 | AU9: 44096.604 | AV9: 28505.467
B10: Oct | C10: 24259.288 | D10: 31214.37 | E10: 31488.93 | F10: 9320.8667 | G10: 9483.4433 | H10: 17537.65 | I10: 17136.734 | J10: 11583.517 | K10: 12571.908 | L10: 28490.611 | N10: Oct | O10: 29416.664 | P10: 37827.032 | Q10: 38189.592 | R10: 11270.139 | S10: 11515.293 | T10: 21290.767 | U10: 20752.682 | V10: 13883.027 | W10: 15219.383 | X10: 34432.667 | Z10: Oct | AA10: 24259.288 | AB10: 30887.133 | AC10: 30805.812 | AD10: 9305.9144 | AE10: 9325.1683 | AF10: 17537.65 | AG10: 16895.791 | AH10: 11896.06 | AI10: 12644.783 | AJ10: 28770.24 | AL10: Oct | AM10: 29416.664 | AN10: 37429.672 | AO10: 37360.091 | AP10: 11252.383 | AQ10: 11323.102 | AR10: 21290.767 | AS10: 20460.108 | AT10: 14261.643 | AU10: 15307.875 | AV10: 34772.216
B11: Sep | C11: 75040.515 | D11: 73506.548 | E11: 100376.12 | F11: 66950.742 | G11: 55873.633 | H11: 44690.354 | I11: 42811.44 | J11: 58143.723 | K11: 98848.014 | L11: 85587.24 | N11: Sep | O11: 90874.4 | P11: 89031.665 | Q11: 121566.92 | R11: 81001.288 | S11: 67468.095 | T11: 54015.38 | U11: 51546.145 | V11: 70181.208 | W11: 119019.23 | X11: 103244.77 | Z11: Sep | AA11: 72736.377 | AB11: 71935.074 | AC11: 98170.746 | AD11: 66130.167 | AE11: 54804.075 | AF11: 43011.592 | AG11: 42200.566 | AH11: 57978.196 | AI11: 96444.26 | AJ11: 83674.716 | AL11: Sep | AM11: 88076.519 | AN11: 87124.146 | AO11: 118889.73 | AP11: 80000.726 | AQ11: 66169.721 | AR11: 51976.433 | AS11: 50804.305 | AT11: 69977.833 | AU11: 116107.35 | AV11: 100922.15
B12: Grand Total | C12: 535885.67 | D12: 583140.12 | E12: 493345.78 | F12: 571298.63 | G12: 517466.69 | H12: 581074.76 | I12: 672842.37 | J12: 757045.93 | K12: 593376.17 | L12: 649854.09 | N12: Grand Total | O12: 648575.19 | P12: 705810.27 | Q12: 596941.67 | R12: 690816.7 | S12: 625434.91 | T12: 702431.36 | U12: 810847.22 | V12: 912016.36 | W12: 713753.09 | X12: 782806.31 | Z12: Grand Total | AA12: 497605.93 | AB12: 524626.61 | AC12: 455815.14 | AD12: 523147.99 | AE12: 483609.47 | AF12: 523703.72 | AG12: 629299.93 | AH12: 669408.27 | AI12: 553546.86 | AJ12: 612408.7 | AL12: Grand Total | AM12: 602129.53 | AN12: 634826.16 | AO12: 551461.64 | AP12: 632557.97 | AQ12: 584458.51 | AR12: 632995.01 | AS12: 758260.44 | AT12: 805896.11 | AU12: 665697.93 | AV12: 737512.97
B14: Year | C14: 2016 | D14: 2017 | E14: 2018 | F14: 2019 | G14: 2020 | H14: 2021 | I14: 2022 | J14: 2023 | K14: 2024 | L14: 2025 | N14: Year | O14: 2016 | P14: 2017 | Q14: 2018 | R14: 2019 | S14: 2020 | T14: 2021 | U14: 2022 | V14: 2023 | W14: 2024 | X14: 2025 | Z14: Year | AA14: 2016 | AB14: 2017 | AC14: 2018 | AD14: 2019 | AE14: 2020 | AF14: 2021 | AG14: 2022 | AH14: 2023 | AI14: 2024 | AJ14: 2025 | AL14: Year | AM14: 2016 | AN14: 2017 | AO14: 2018 | AP14: 2019 | AQ14: 2020 | AR14: 2021 | AS14: 2022 | AT14: 2023 | AU14: 2024 | AV14: 2025
B15: Jun | C15: =C5/C$12 -> 0.16311301 | D15: =D5/D$12 -> 0.18405016 | E15: =E5/E$12 -> 0.08071063 | F15: =F5/F$12 -> 0.17830125 | G15: =G5/G$12 -> 0.17047919 | H15: =H5/H$12 -> 0.1595016 | I15: =I5/I$12 -> 0.1518303 | J15: =J5/J$12 -> 0.14089569 | ... L15: =L5/L$12 -> 0.18063217 | N15: Jun | O15: =O5/O$12 -> 0.16300112 | P15: =P5/P$12 -> 0.18397007 | Q15: =Q5/Q$12 -> 0.080469923 | R15: =R5/R$12 -> 0.17799553 | S15: =S5/S$12 -> 0.17044593 | T15: =T5/T$12 -> 0.15924635 | U15: =U5/U$12 -> 0.15154175 | V15: =V5/V$12 -> 0.14048928 | ... X15: =X5/X$12 -> 0.18021234 | Z15: Jun | AA15: =AA5/AA$12 -> 0.1435801 | AB15: =AB5/AB$12 -> 0.18323363 | AC15: =AC5/AC$12 -> 0.055809377 | AD15: =AD5/AD$12 -> 0.17746869 | AE15: =AE5/AE$12 -> 0.15234198 | AF15: =AF5/AF$12 -> 0.15112958 | AG15: =AG5/AG$12 -> 0.1466781 | AH15: =AH5/AH$12 -> 0.14015552 | ... AJ15: =AJ5/AJ$12 -> 0.1710237 | AL15: Jun | AM15: =AM5/AM$12 -> 0.14338126 | AN15: =AN5/AN$12 -> 0.18317219 | AO15: =AO5/AO$12 -> 0.055500658 | AP15: =AP5/AP$12 -> 0.17713759 | AQ15: =AQ5/AQ$12 -> 0.15222807 | AR15: =AR5/AR$12 -> 0.15087352 | AS15: =AS5/AS$12 -> 0.14636131 | AT15: =AT5/AT$12 -> 0.1397448 | ... AV15: =AV5/AV$12 -> 0.17051104
B16: Jul | C16: =C6/C$12 -> 0.28624649 | D16: =D6/D$12 -> 0.32391877 | E16: =E6/E$12 -> 0.25740187 | F16: =F6/F$12 -> 0.31926375 | G16: =G6/G$12 -> 0.35868318 | H16: =H6/H$12 -> 0.30457313 | I16: =I6/I$12 -> 0.34275164 | J16: =J6/J$12 -> 0.30255576 | ... L16: =L6/L$12 -> 0.26754715 | N16: Jul | O16: =O6/O$12 -> 0.28612051 | P16: =P6/P$12 -> 0.3239336 | Q16: =Q6/Q$12 -> 0.25715795 | R16: =R6/R$12 -> 0.31931203 | S16: =S6/S$12 -> 0.35868805 | T16: =T6/T$12 -> 0.30453127 | U16: =U6/U$12 -> 0.34288134 | V16: =V6/V$12 -> 0.30263275 | ... X16: =X6/X$12 -> 0.26738235 | Z16: Jul | AA16: =AA6/AA$12 -> 0.29093145 | AB16: =AB6/AB$12 -> 0.35058415 | AC16: =AC6/AC$12 -> 0.25396869 | AD16: =AD6/AD$12 -> 0.33652884 | AE16: =AE6/AE$12 -> 0.36623936 | AF16: =AF6/AF$12 -> 0.32177021 | AG16: =AG6/AG$12 -> 0.35485238 | AH16: =AH6/AH$12 -> 0.32922118 | ... AJ16: =AJ6/AJ$12 -> 0.26947104 | AL16: Jul | AM16: =AM6/AM$12 -> 0.29079641 | AN16: =AN6/AN$12 -> 0.35066693 | AO16: =AO6/AO$12 -> 0.25367373 | AP16: =AP6/AP$12 -> 0.33656449 | AQ16: =AQ6/AQ$12 -> 0.36624096 | AR16: =AR6/AR$12 -> 0.32174951 | AS16: =AS6/AS$12 -> 0.35502892 | AT16: =AT6/AT$12 -> 0.329503 | ... AV16: =AV6/AV$12 -> 0.26929429
B17: Apr | C17: =C7/C$12 -> 0.0047415675 | D17: =D7/D$12 -> 0.063714991 | E17: =E7/E$12 -> 0.0022027268 | F17: =F7/F$12 -> 0.020522389 | G17: =G7/G$12 -> 0.0017375082 | H17: =H7/H$12 -> 0.032512676 | I17: =I7/I$12 -> 0.015715739 | J17: =J7/J$12 -> 0.099613563 | ... L17: =L7/L$12 -> 0.00098290897 | N17: Apr | O17: =O7/O$12 -> 0.0046880103 | P17: =P7/P$12 -> 0.063841734 | Q17: =Q7/Q$12 -> 0.0021625028 | R17: =R7/R$12 -> 0.020539596 | S17: =S7/S$12 -> 0.001707477 | T17: =T7/T$12 -> 0.032644737 | U17: =U7/U$12 -> 0.015780326 | V17: =V7/V$12 -> 0.099749991 | ... X17: =X7/X$12 -> 0.0009692637 | Z17: Apr | AA17: =AA7/AA$12 -> 0.0026046621 | AB17: =AB7/AB$12 -> 0.0093751781 | AC17: =AC7/AC$12 -> 3.3782982e-05 | AD17: =AD7/AD$12 -> 0.0034680307 | AE17: =AE7/AE$12 -> 1.4229249e-05 | AF17: =AF7/AF$12 -> 0.005308994 | AG17: =AG7/AG$12 -> 0.0047459437 | AH17: =AH7/AH$12 -> 0.040088318 | ... AJ17: =AJ7/AJ$12 -> 6.3328073e-05 | AL17: Apr | AM17: =AM7/AM$12 -> 0.0025945853 | AN17: =AN7/AN$12 -> 0.009355876 | AO17: =AO7/AO$12 -> 3.3776442e-05 | AP17: =AP7/AP$12 -> 0.0034807951 | AQ17: =AQ7/AQ$12 -> 1.4296969e-05 | AR17: =AR7/AR$12 -> 0.0053325343 | AS17: =AS7/AS$12 -> 0.0047710674 | AT17: =AT7/AT$12 -> 0.039757513 | ... AV17: =AV7/AV$12 -> 6.2761737e-05
B18: Aug | C18: =C8/C$12 -> 0.34380756 | D18: =D8/D$12 -> 0.21178623 | E18: =E8/E$12 -> 0.37860634 | F18: =F8/F$12 -> 0.24897979 | G18: =G8/G$12 -> 0.30857286 | H18: =H8/H$12 -> 0.33194171 | I18: =I8/I$12 -> 0.28307541 | J18: =J8/J$12 -> 0.28096478 | ... L18: =L8/L$12 -> 0.32639918 | N18: Aug | O18: =O8/O$12 -> 0.34394391 | P18: =P8/P$12 -> 0.2116326 | Q18: =Q8/Q$12 -> 0.37886341 | R18: =R8/R$12 -> 0.24931632 | S18: =S8/S$12 -> 0.30867248 | T18: =T8/T$12 -> 0.33211075 | U18: =U8/U$12 -> 0.28316075 | V18: =V8/V$12 -> 0.28126473 | ... X18: =X8/X$12 -> 0.32685239 | Z18: Aug | AA18: =AA8/AA$12 -> 0.36284476 | AB18: =AB8/AB$12 -> 0.2314857 | AC18: =AC8/AC$12 -> 0.39527995 | AD18: =AD8/AD$12 -> 0.26664935 | AE18: =AE8/AE$12 -> 0.32248007 | AF18: =AF8/AF$12 -> 0.36029253 | AG18: =AG8/AG$12 -> 0.29674931 | AH18: =AH8/AH$12 -> 0.31200112 | ... AJ18: =AJ8/AJ$12 -> 0.33697688 | AL18: Aug | AM18: =AM8/AM$12 -> 0.36303715 | AN18: =AN8/AN$12 -> 0.23136009 | AO18: =AO8/AO$12 -> 0.39555924 | AP18: =AP8/AP$12 -> 0.26701862 | AQ18: =AQ8/AQ$12 -> 0.32261368 | AR18: =AR8/AR$12 -> 0.36051803 | AS18: =AS8/AS$12 -> 0.29687895 | AT18: =AT8/AT$12 -> 0.31251122 | ... AV18: =AV8/AV$12 -> 0.33749199
B19: May | C19: =C9/C$12 -> 0.016791022 | D19: =D9/D$12 -> 0.036948784 | E19: =E9/E$12 -> 0.013791145 | F19: =F9/F$12 -> 0.099427147 | G19: =G9/G$12 -> 0.034225266 | H19: =H9/H$12 -> 0.06437967 | I19: =I9/I$12 -> 0.11753001 | J19: =J9/J$12 -> 0.083865843 | ... L19: =L9/L$12 -> 0.048894791 | N19: May | O19: =O9/O$12 -> 0.016776726 | P19: =P9/P$12 -> 0.036887149 | Q19: =Q9/Q$12 -> 0.013721227 | R19: =R9/R$12 -> 0.099267913 | S19: =S9/S$12 -> 0.034200522 | T19: =T9/T$12 -> 0.064259048 | U19: =U9/U$12 -> 0.11747129 | V19: =V9/V$12 -> 0.0836892 | ... X19: =X9/X$12 -> 0.048706907 | Z19: May | AA19: =AA9/AA$12 -> 0.0051143782 | AB19: =AB9/AB$12 -> 0.02933013 | AC19: =AC9/AC$12 -> 0.011950164 | AD19: =AD9/AD$12 -> 0.071688641 | AE19: =AE9/AE$12 -> 0.026318924 | AF19: =AF9/AF$12 -> 0.045881322 | AG19: =AG9/AG$12 -> 0.10306617 | AH19: =AH9/AH$12 -> 0.074151737 | ... AJ19: =AJ9/AJ$12 -> 0.03885408 | AL19: May | AM19: =AM9/AM$12 -> 0.005061185 | AN19: =AN9/AN$12 -> 0.029243452 | AO19: =AO9/AO$12 -> 0.011894997 | AP19: =AP9/AP$12 -> 0.071538033 | AQ19: =AQ9/AQ$12 -> 0.026313906 | AR19: =AR9/AR$12 -> 0.04577952 | AS19: =AS9/AS$12 -> 0.10297568 | AT19: =AT9/AT$12 -> 0.073954517 | ... AV19: =AV9/AV$12 -> 0.038650801
B20: Oct | C20: =C10/C$12 -> 0.045269522 | D20: =D10/D$12 -> 0.053528079 | E20: =E10/E$12 -> 0.063827302 | F20: =F10/F$12 -> 0.016315227 | G20: =G10/G$12 -> 0.018326674 | H20: =H10/H$12 -> 0.030181401 | I20: =I10/I$12 -> 0.025469166 | J20: =J10/J$12 -> 0.015300944 | ... L20: =L10/L$12 -> 0.043841551 | N20: Oct | O20: =O10/O$12 -> 0.045355826 | P20: =P10/P$12 -> 0.053593768 | Q20: =Q10/Q$12 -> 0.063975416 | R20: =R10/R$12 -> 0.016314224 | S20: =S10/S$12 -> 0.018411657 | T20: =T10/T$12 -> 0.030310103 | U20: =U10/U$12 -> 0.025593825 | V20: =V10/V$12 -> 0.015222344 | ... X20: =X10/X$12 -> 0.04398619 | Z20: Oct | AA20: =AA10/AA$12 -> 0.048752008 | AB20: =AB10/AB$12 -> 0.058874507 | AC20: =AC10/AC$12 -> 0.067584002 | AD20: =AD10/AD$12 -> 0.017788302 | AE20: =AE10/AE$12 -> 0.019282435 | AF20: =AF10/AF$12 -> 0.033487732 | AG20: =AG10/AG$12 -> 0.02684855 | AH20: =AH10/AH$12 -> 0.017771009 | ... AJ20: =AJ10/AJ$12 -> 0.046978823 | AL20: Oct | AM20: =AM10/AM$12 -> 0.048854378 | AN20: =AN10/AN$12 -> 0.058960507 | AO20: =AO10/AO$12 -> 0.067747397 | AP20: =AP10/AP$12 -> 0.017788698 | AQ20: =AQ10/AQ$12 -> 0.019373662 | AR20: =AR10/AR$12 -> 0.033634968 | AS20: =AS10/AS$12 -> 0.026982956 | AT20: =AT10/AT$12 -> 0.017696627 | ... AV20: =AV10/AV$12 -> 0.047147939
B21: Sep | C21: =C11/C$12 -> 0.14003083 | D21: =D11/D$12 -> 0.12605298 | E21: =E11/E$12 -> 0.20345998 | F21: =F11/F$12 -> 0.11719045 | G21: =G11/G$12 -> 0.10797532 | H21: =H11/H$12 -> 0.076909819 | I21: =I11/I$12 -> 0.06362774 | J21: =J11/J$12 -> 0.076803429 | ... L21: =L11/L$12 -> 0.13170224 | N21: Sep | O21: =O11/O$12 -> 0.1401139 | P21: =P11/P$12 -> 0.12614107 | Q21: =Q11/Q$12 -> 0.20364957 | R21: =R11/R$12 -> 0.11725439 | S21: =S11/S$12 -> 0.10787389 | T21: =T11/T$12 -> 0.076897733 | U21: =U11/U$12 -> 0.063570725 | V21: =V11/V$12 -> 0.076951698 | ... X21: =X11/X$12 -> 0.13189057 | Z21: Sep | AA21: =AA11/AA$12 -> 0.14617265 | AB21: =AB11/AB$12 -> 0.13711671 | AC21: =AC11/AC$12 -> 0.21537404 | AD21: =AD11/AD$12 -> 0.12640815 | AE21: =AE11/AE$12 -> 0.113323 | AF21: =AF11/AF$12 -> 0.082129629 | AG21: =AG11/AG$12 -> 0.067059543 | AH21: =AH11/AH$12 -> 0.086611114 | ... AJ21: =AJ11/AJ$12 -> 0.13663215 | AL21: Sep | AM21: =AM11/AM$12 -> 0.14627504 | AN21: =AN11/AN$12 -> 0.13724095 | AO21: =AO11/AO$12 -> 0.2155902 | AP21: =AP11/AP$12 -> 0.12647177 | AQ21: =AQ11/AQ$12 -> 0.11321543 | AR21: =AR11/AR$12 -> 0.082111916 | AS21: =AS11/AS$12 -> 0.067001128 | AT21: =AT11/AT$12 -> 0.086832325 | ... AV21: =AV11/AV$12 -> 0.13684118
B22: Max | C22: =MAX(C15:C21) -> 0.34380756 | D22: =MAX(D15:D21) -> 0.32391877 | E22: =MAX(E15:E21) -> 0.37860634 | F22: =MAX(F15:F21) -> 0.31926375 | G22: =MAX(G15:G21) -> 0.35868318 | H22: =MAX(H15:H21) -> 0.33194171 | I22: =MAX(I15:I21) -> 0.34275164 | J22: =MAX(J15:J21) -> 0.30255576 | ... L22: =MAX(L15:L21) -> 0.32639918 | N22: Max | O22: =MAX(O15:O21) -> 0.34394391 | P22: =MAX(P15:P21) -> 0.3239336 | Q22: =MAX(Q15:Q21) -> 0.37886341 | R22: =MAX(R15:R21) -> 0.31931203 | S22: =MAX(S15:S21) -> 0.35868805 | T22: =MAX(T15:T21) -> 0.33211075 | U22: =MAX(U15:U21) -> 0.34288134 | V22: =MAX(V15:V21) -> 0.30263275 | ... X22: =MAX(X15:X21) -> 0.32685239 | Z22: Max | AA22: =MAX(AA15:AA21) -> 0.36284476 | AB22: =MAX(AB15:AB21) -> 0.35058415 | AC22: =MAX(AC15:AC21) -> 0.39527995 | AD22: =MAX(AD15:AD21) -> 0.33652884 | AE22: =MAX(AE15:AE21) -> 0.36623936 | AF22: =MAX(AF15:AF21) -> 0.36029253 | AG22: =MAX(AG15:AG21) -> 0.35485238 | AH22: =MAX(AH15:AH21) -> 0.32922118 | ... AJ22: =MAX(AJ15:AJ21) -> 0.33697688 | AL22: Max | AM22: =MAX(AM15:AM21) -> 0.36303715 | AN22: =MAX(AN15:AN21) -> 0.35066693 | AO22: =MAX(AO15:AO21) -> 0.39555924 | AP22: =MAX(AP15:AP21) -> 0.33656449 | AQ22: =MAX(AQ15:AQ21) -> 0.36624096 | AR22: =MAX(AR15:AR21) -> 0.36051803 | AS22: =MAX(AS15:AS21) -> 0.35502892 | AT22: =MAX(AT15:AT21) -> 0.329503 | ... AV22: =MAX(AV15:AV21) -> 0.33749199
B25: Year | C25: GIR50%ISW_EF_H | D25: GIR50%ISW_EF_L | E25: GIR90%ISW_EF_H | F25: GIR90%ISW_EF_L | G25: Mean | H25: obs | K25: GIR_year_mm | L25: Peak_demand_CIS_mm | M25: Peak_demand_CIS_July_mm | N25: Ensemble_peak_month | P25: CIS | Q25: July | R25: min | S25: max | T25: STD- | U25: STD+ | V25: Year | W25: DPF | X25: PDS | Y25: STD- | Z25: STD+
B26: 2016 | C26: 0.34380756 | D26: 0.34394391 | E26: 0.36284476 | F26: 0.36303715 | G26: =MEDIAN(C26:F26) -> 0.35339433 | H26: 0.29510514 | K26: 444.78921 | L26: 152.976 | M26: 126.20715 | N26: Aug | O26: 2016 | P26: =L26/K26 -> 0.3439292 | Q26: =M26/K26 -> 0.28374598 | R26: =MIN(C26:F26) -> 0.34380756 | S26: =MAX(C26:F26) -> 0.36303715 | T26: =G26-R26 -> 0.00958677 | U26: =S26-G26 -> 0.0096428181 | V26: 2016 | W26: 0.3439292 | X26: 0.046709293 | Y26: 0.0084119197 | Z26: 0.0080394819
B27: 2017 | C27: 0.32391877 | D27: 0.3239336 | E27: 0.35058415 | F27: 0.35066693 | G27: =MEDIAN(C27:F27) -> 0.33725888 | H27: 0.25192054 | K27: 506.982 | L27: 165.6319 | M27: 165.6319 | N27: Jul | O27: 2017 | P27: =L27/K27 -> 0.32670173 | Q27: =M27/K27 -> 0.32670173 | R27: =MIN(C27:F27) -> 0.32391877 | S27: =MAX(C27:F27) -> 0.35066693 | T27: =G27-R27 -> 0.013340103 | U27: =S27-G27 -> 0.01340805 | V27: 2017 | W27: 0.32670173 | X27: 0.051771968 | Y27: 0.0083543122 | Z27: 0.008158772
B28: 2018 | C28: 0.37860634 | D28: 0.37886341 | E28: 0.39527995 | F28: 0.39555924 | G28: =MEDIAN(C28:F28) -> 0.38707168 | H28: 0.35035734 | K28: 419.20137 | L28: 155.00951 | M28: 106.86964 | N28: Aug | O28: 2018 | P28: =L28/K28 -> 0.3697734 | Q28: =M28/K28 -> 0.25493628 | R28: =MIN(C28:F28) -> 0.37860634 | S28: =MAX(C28:F28) -> 0.39555924 | T28: =G28-R28 -> 0.0084653366 | U28: =S28-G28 -> 0.008487558 | V28: 2018 | W28: 0.3697734 | X28: 0.088749877 | Y28: 0.0074228273 | Z28: 0.0069669493
B29: 2019 | C29: 0.31926375 | D29: 0.31931203 | E29: 0.33652884 | F29: 0.33656449 | G29: =MEDIAN(C29:F29) -> 0.32792044 | H29: 0.27763909 | K29: 493.04019 | L29: 156.09505 | M29: 156.09505 | N29: Jul | O29: 2019 | P29: =L29/K29 -> 0.31659701 | Q29: =M29/K29 -> 0.31659701 | R29: =MIN(C29:F29) -> 0.31926375 | S29: =MAX(C29:F29) -> 0.33656449 | T29: =G29-R29 -> 0.0086566911 | U29: =S29-G29 -> 0.0086440527 | V29: 2019 | W29: 0.31659701 | X29: 0.11440084 | Y29: 0.0083162068 | Z29: 0.0080680466
B30: 2020 | C30: 0.35868318 | D30: 0.35868805 | E30: 0.36623936 | F30: 0.36624096 | G30: =MEDIAN(C30:F30) -> 0.36246371 | H30: 0.30936653 | K30: 446.05694 | L30: 155.67964 | M30: 155.67964 | N30: Jul | O30: 2020 | P30: =L30/K30 -> 0.34901292 | Q30: =M30/K30 -> 0.34901292 | R30: =MIN(C30:F30) -> 0.35868318 | S30: =MAX(C30:F30) -> 0.36624096 | T30: =G30-R30 -> 0.0037805272 | U30: =S30-G30 -> 0.0037772474 | V30: 2020 | W30: 0.34901292 | X30: 0.090141394 | Y30: 0.0089055809 | Z30: 0.0085736093
B31: 2021 | C31: 0.33194171 | D31: 0.33211075 | E31: 0.36029253 | F31: 0.36051803 | G31: =MEDIAN(C31:F31) -> 0.34620164 | H31: 0.28234448 | K31: 522.65268 | L31: 168.36689 | M31: 153.43243 | N31: Aug | O31: 2021 | P31: =L31/K31 -> 0.32213915 | Q31: =M31/K31 -> 0.29356481 | R31: =MIN(C31:F31) -> 0.33194171 | S31: =MAX(C31:F31) -> 0.36051803 | T31: =G31-R31 -> 0.014259938 | U31: =S31-G31 -> 0.01431639 | V31: 2021 | W31: 0.32213915 | X31: 0.13938616 | Y31: 0.0078324038 | Z31: 0.0075313915
B32: 2022 | C32: 0.34275164 | D32: 0.34288134 | E32: 0.35485238 | F32: 0.35502892 | G32: =MEDIAN(C32:F32) -> 0.34886686 | H32: 0.32035125 | K32: 545.44884 | L32: 186.00531 | M32: 186.00531 | N32: Jul | O32: 2022 | P32: =L32/K32 -> 0.34101331 | Q32: =M32/K32 -> 0.34101331 | R32: =MIN(C32:F32) -> 0.34275164 | S32: =MAX(C32:F32) -> 0.35502892 | T32: =G32-R32 -> 0.0061152244 | U32: =S32-G32 -> 0.006162055 | V32: 2022 | W32: 0.34101331 | X32: 0.11240621 | Y32: 0.0078953094 | Z32: 0.0076802809
B33: 2023 | C33: 0.30255576 | D33: 0.30263275 | E33: 0.32922118 | F33: 0.329503 | G33: =MEDIAN(C33:F33) -> 0.31592697 | H33: 0.28456419 | K33: 533.12336 | L33: 163.77619 | M33: 163.77619 | N33: Jul | O33: 2023 | P33: =L33/K33 -> 0.30720131 | Q33: =M33/K33 -> 0.30720131 | R33: =MIN(C33:F33) -> 0.30255576 | S33: =MAX(C33:F33) -> 0.329503 | T33: =G33-R33 -> 0.013371209 | U33: =S33-G33 -> 0.013576032 | V33: 2023 | W33: 0.30720131 | X33: 0.072423809 | Y33: 0.009232897 | Z33: 0.0089395741
B34: 2024 | C34: 0.34757287 | D34: 0.34810259 | E34: 0.36153263 | F34: 0.36213397 | G34: =MEDIAN(C34:F34) -> 0.35481761 | H34: 0.29565243 | K34: 442.46739 | L34: 147.7207 | M34: 123.74956 | N34: Aug | O34: 2024 | P34: =L34/K34 -> 0.33385669 | Q34: =M34/K34 -> 0.27968063 | R34: =MIN(C34:F34) -> 0.34757287 | S34: =MAX(C34:F34) -> 0.36213397 | T34: =G34-R34 -> 0.0072447389 | U34: =S34-G34 -> 0.0073163646 | V34: 2024 | W34: 0.33385669 | X34: 0.098162464 | Y34: 0.0082605649 | Z34: 0.00786168
B35: 2025 | C35: 0.32639918 | D35: 0.32685239 | E35: 0.33697688 | F35: 0.33749199 | G35: =MEDIAN(C35:F35) -> 0.33191463 | K35: 466.8483 | L35: 149.05609 | M35: 122.39151 | N35: Aug | O35: 2025 | P35: =L35/K35 -> 0.31928163 | Q35: =M35/K35 -> 0.26216549 | R35: =MIN(C35:F35) -> 0.32639918 | S35: =MAX(C35:F35) -> 0.33749199 | T35: =G35-R35 -> 0.0055154514 | U35: =S35-G35 -> 0.0055773538 | V35: 2025 | W35: 0.31928163 | X35: 0.092001146 | Y35: 0.0078202749 | Z35: 0.0074984934

Sheet PDS
A1: Year | B1: Crop | C1: Area_ha | D1: GIR_year_m3 | E1: GIR_year_mm | F1: Peak_demand_crop_m3 | G1: Peak_demand_crop_mm | H1: Peak_demand_crop_July_m3 | I1: Peak_demand_crop_July_mm | J1: Ensemble_peak_month
A2: 2016 | B2: Complex syst. | C2: 86.162063 | D2: 538561.41 | E2: 625.05631 | F2: 172201.99 | G2: 199.85825 | H2: 162696.47 | I2: 188.82611 | J2: Aug
A3: 2016 | B3: Fodder crops | C3: 84.586986 | D3: 147270.07 | E3: 174.10488 | F3: 59531.765 | G3: 70.379344 | H3: 0 | I3: 0 | J3: Oct
A4: 2016 | B4: Olive grove | C4: 144.61537 | D4: 247210.79 | E4: 170.94365 | F4: 79086.529 | G4: 54.6875 | H4: 68765.002 | I4: 47.550273 | J4: Aug | M4: Peak_demand_CIS_m3 | N4: Peak_demand_crop_m3 | O4: PDS
A5: 2016 | B5: P. tomate | C5: 69.467999 | D5: 349123.41 | E5: 502.56725 | F5: 135697.74 | G5: 195.33849 | H5: 135697.74 | I5: 195.33849 | J5: Jul | M5: Real | N5: hipotetical
A6: 2016 | B6: Pastures | C6: 308.72395 | D6: 1283063.6 | E6: 415.60222 | F6: 421478.46 | G6: 136.52276 | H6: 293365 | I6: 95.025022 | J6: Aug | L6: 2016 | M6: 2364275.3 | N6: 2480119.9 | O6: =1-(M6/N6) -> 0.046709293
A7: 2016 | B7: Silage | C7: 708.58388 | D7: 4094962.3 | E7: 577.90791 | F7: 1533594.8 | G7: 216.43094 | H7: 1218973.1 | I7: 172.02947 | J7: Aug | L7: 2017 | M7: 2567368.4 | N7: 2707543.2 | O7: =1-(M7/N7) -> 0.051771968
A8: 2016 | B8: Vineyard | C8: 143.3802 | D8: 214116.62 | E8: 149.33486 | F8: 78528.677 | G8: 54.769541 | H8: 71060.038 | I8: 49.560565 | J8: Aug | L8: 2018 | M8: 2390281.1 | N8: 2623079 | O8: =1-(M8/N8) -> 0.088749877
A9: 2017 | B9: Complex syst. | C9: 86.162063 | D9: 563898.2 | E9: 654.46228 | F9: 189380.49 | G9: 219.79568 | H9: 189380.49 | I9: 219.79568 | J9: Jul | L9: 2019 | M9: 2407020.3 | N9: 2717956.9 | O9: =1-(M9/N9) -> 0.11440084
A10: 2017 | B10: Fodder crops | C10: 106.51539 | D10: 289061.04 | E10: 271.37961 | F10: 140174.84 | G10: 131.60056 | H10: 0 | I10: 0 | J10: May | L10: 2020 | M10: 2457940 | N10: 2701452.8 | O10: =1-(M10/N10) -> 0.090141394
A11: 2017 | B11: Olive grove | C11: 144.61537 | D11: 325762.49 | E11: 225.26132 | F11: 85223.198 | G11: 58.930941 | H11: 85223.198 | I11: 58.930941 | J11: Jul | L11: 2021 | M11: 2543116.5 | N11: 2955003 | O11: =1-(M11/N11) -> 0.13938616
A12: 2017 | B12: P. tomate | C12: 81.964214 | D12: 504119.65 | E12: 615.04847 | F12: 187397.99 | G12: 228.63392 | H12: 187397.99 | I12: 228.63392 | J12: Jul | L12: 2022 | M12: 3118045.9 | N12: 3512919.9 | O12: =1-(M12/N12) -> 0.11240621
A13: 2017 | B13: Pastures | C13: 271.31285 | D13: 1368106 | E13: 504.25403 | F13: 370208.61 | G13: 136.45082 | H13: 370208.61 | I13: 136.45082 | J13: Jul | L13: 2023 | M13: 2839142.4 | N13: 3060818.5 | O13: =1-(M13/N13) -> 0.072423809
A14: 2017 | B14: Silage | C14: 711.57037 | D14: 4547492.6 | E14: 639.07841 | F14: 1641460.2 | G14: 230.68135 | H14: 1641460.2 | I14: 230.68135 | J14: Jul | L14: 2024 | M14: 2583357.7 | N14: 2864548.9 | O14: =1-(M14/N14) -> 0.098162464
A15: 2017 | B15: Vineyard | C15: 147.90442 | D15: 260007.52 | E15: 175.79429 | F15: 93697.935 | G15: 63.35033 | H15: 93697.935 | I15: 63.35033 | J15: Jul | L15: 2025 | M15: 2624764.9 | N15: 2890713.9 | O15: =1-(M15/N15) -> 0.092001146
A16: 2018 | B16: Complex syst. | C16: 86.162063 | D16: 516313.73 | E16: 599.23557 | F16: 181819.63 | G16: 211.02051 | H16: 157811.77 | I16: 183.15691 | J16: Aug | N16: MEAN | O16: =AVERAGE(O6:O15)*100 -> 9.0615316
A17: 2018 | B17: Fodder crops | C17: 145.93257 | D17: 260839.66 | E17: 178.73985 | F17: 156024.19 | G17: 106.91526 | H17: 0 | I17: 0 | J17: Oct | N17: STD | O17: =_xlfn.STDEV.S(O6:O15)*100 -> 2.8380841
A18: 2018 | B18: Olive grove | C18: 144.61537 | D18: 255521.35 | E18: 176.69032 | F18: 83428.607 | G18: 57.690001 | H18: 70447.072 | I18: 48.713407 | J18: Aug
A19: 2018 | B19: P. tomate | C19: 69.467999 | D19: 313844.08 | E19: 451.78224 | F19: 132410.84 | G19: 190.60696 | H19: 132410.84 | I19: 190.60696 | J19: Jul
A20: 2018 | B20: Pastures | C20: 263.29036 | D20: 1138305.5 | E20: 432.33848 | F20: 359600.95 | G20: 136.57961 | H20: 295015.4 | I20: 112.04945 | J20: Aug
A21: 2018 | B21: Silage | C21: 684.6494 | D21: 3760731.8 | E21: 549.29309 | F21: 1624121.7 | G21: 237.21947 | H21: 920709.79 | I21: 134.47902 | J21: Aug
A22: 2018 | B22: Vineyard | C22: 147.90442 | D22: 218621.84 | E22: 147.81292 | F22: 85673.112 | G22: 57.924648 | H22: 71558.652 | I22: 48.381688 | J22: Aug
A23: 2019 | B23: Complex syst. | C23: 95.634456 | D23: 640311.05 | E23: 669.54012 | F23: 194310.79 | G23: 203.18074 | H23: 194310.79 | I23: 203.18074 | J23: Jul
A24: 2019 | B24: Fodder crops | C24: 153.09053 | D24: 372881.39 | E24: 243.5692 | F24: 310936.56 | G24: 203.10633 | H24: 0 | I24: 0 | J24: May
A25: 2019 | B25: Olive grove | C25: 144.61537 | D25: 314725.18 | E25: 217.62914 | F25: 79573.042 | G25: 55.023919 | H25: 79573.042 | I25: 55.023919 | J25: Jul
A26: 2019 | B26: P. tomate | C26: 69.467999 | D26: 342502.95 | E26: 493.03701 | F26: 140911.23 | G26: 202.84336 | H26: 140911.23 | I26: 202.84336 | J26: Jul
A27: 2019 | B27: Pastures | C27: 246.66001 | D27: 1181989.1 | E27: 479.19771 | F27: 336777.88 | G27: 136.53526 | H27: 336777.88 | I27: 136.53526 | J27: Jul
A28: 2019 | B28: Silage | C28: 660.46977 | D28: 4427513.8 | E28: 670.35828 | F28: 1554237.4 | G28: 235.32302 | H28: 1554237.4 | I28: 235.32302 | J28: Jul
A29: 2019 | B29: Vineyard | C29: 172.08405 | D29: 322865.6 | E29: 187.62087 | F29: 101209.98 | G29: 58.814272 | H29: 101209.98 | I29: 58.814272 | J29: Jul
... A75: 2025 | B75: Vineyard | C75: 147.90442 | D75: 297631.51 | E75: 201.23234 | F75: 96763.824 | G75: 65.423215 | H75: 96763.824 | I75: 65.423215 | J75: Jul

Sheet ISF
J2: IS | K2: Year | L2: Crop | M2: Area_ha | N2: Area_total_ha | O2: Area_share_pct | P2: I j,low | Q2: I j,high | R2: ISF_low_ef | S2: ISF_high_ef
J3: drip | K3: 2016 | L3: Complex syst. | M3: 86.162063 | N3: 1545.5205 | O3: 5.5749546 | P3: {=IFERROR(_xlfn.XLOOKUP(1,($D$11:$D$19=J3)*($B$11:$B$19=L3),$G$11:$G$19),"")} -> 1.25 | Q3: 1.0526316 | R3: =(P3*M3)/N3 -> 0.069686932 | S3: =(Q3*M3)/N3 -> 0.058683733 | U3: Row Labels | V3: Sum of WAFAE_low_ef | W3: Sum of WAFAE_high_ef | X3: Sum of WAFAE_low_ef | Y3: Sum of WAFAE_high_ef
J4: Sprinkler | K4: 2016 | L4: Fodder crops | M4: 84.586986 | N4: 1545.5205 | O4: 5.4730421 | P4: {=IFERROR(_xlfn.XLOOKUP(1,($D$11:$D$19=J4)*($B$11:$B$19=L4),$G$11:$G$19),"")} -> 1.4285714 | Q4: 1.1764706 | R4: =(P4*M4)/N4 -> 0.078186316 | S4: =(Q4*M4)/N4 -> 0.064388731 | U4: 2016 | V4: 1.0898319 | W4: 0.90980714 | X4: 1.0898319 | Y4: 0.90980714
J5: drip | K5: 2016 | L5: Olive grove | M5: 144.61537 | N5: 1545.5205 | O5: 9.3570659 | P5: {=IFERROR(_xlfn.XLOOKUP(1,($D$11:$D$19=J5)*($B$11:$B$19=L5),$G$11:$G$19),"")} -> 0.6875 | Q5: 0.57894737 | R5: =(P5*M5)/N5 -> 0.064329828 | S5: =(Q5*M5)/N5 -> 0.054172487 | U5: 2017 | V5: 1.0880142 | W5: 0.90835083 | X5: 1.0880142 | Y5: 0.90835083
J6: drip | K6: 2016 | L6: P. tomate | M6: 69.467999 | N6: 1545.5205 | O6: 4.4947965 | P6: {=IFERROR(_xlfn.XLOOKUP(1,($D$11:$D$19=J6)*($B$11:$B$19=L6),$G$11:$G$19),"")} -> 1 | Q6: 1.1764706 | R6: =(P6*M6)/N6 -> 0.044947965 | S6: =(Q6*M6)/N6 -> 0.052879959 | U6: 2018 | V6: 1.0937246 | W6: 0.91279334 | X6: 1.0937246 | Y6: 0.91279334
J7: Sprinkler | K7: 2016 | L7: Pastures | M7: 308.72395 | N7: 1545.5205 | O7: 19.975404 | P7: {=IFERROR(_xlfn.XLOOKUP(1,($D$11:$D$19=J7)*($B$11:$B$19=L7),$G$11:$G$19),"")} -> 1.4285714 | Q7: 1.1764706 | R7: =(P7*M7)/N7 -> 0.28536291 | S7: =(Q7*M7)/N7 -> 0.23500475 | U7: 2019 | V7: 1.0887075 | W7: 0.90873147 | X7: 1.0887075 | Y7: 0.90873147
J8: Sprinkler | K8: 2016 | L8: Silage | M8: 708.58388 | N8: 1545.5205 | O8: 45.84759 | P8: {=IFERROR(_xlfn.XLOOKUP(1,($D$11:$D$19=J8)*($B$11:$B$19=L8),$G$11:$G$19),"")} -> 1.4285714 | Q8: 0.84210526 | R8: =(P8*M8)/N8 -> 0.65496558 | S8: =(Q8*M8)/N8 -> 0.38608497 | U8: 2020 | V8: 1.1037543 | W8: 0.92067513 | X8: 1.1037543 | Y8: 0.92067513
E9: EF (%) | H9: I j,high | J9: drip | K9: 2016 | L9: Vineyard | M9: 143.3802 | N9: 1545.5205 | O9: 9.2771467 | P9: {=IFERROR(_xlfn.XLOOKUP(1,($D$11:$D$19=J9)*($B$11:$B$19=L9),$G$11:$G$19),"")} -> 0.75 | Q9: 0.63157895 | R9: =(P9*M9)/N9 -> 0.0695786 | S9: =(Q9*M9)/N9 -> 0.058592505 | U9: 2021 | V9: 1.1420468 | W9: 0.95176659 | X9: 1.1420468 | Y9: 0.95176659
B10: Crop | C10: SWF | D10: IS | E10: low | F10: high | G10: I j,low | J10: =J3 -> drip | K10: 2017 | L10: Complex syst. | M10: 86.162063 | N10: 1550.0447 | O10: 5.5586826 | P10: {=IFERROR(_xlfn.XLOOKUP(1,($D$11:$D$19=J10)*($B$11:$B$19=L10),$G$11:$G$19),"")} -> 1.25 | Q10: 1.0526316 | R10: =(P10*M10)/N10 -> 0.069483533 | S10: =(Q10*M10)/N10 -> 0.058512448 | U10: 2022 | V10: 1.1212708 | W10: 0.93413451 | X10: 1.1212708 | Y10: 0.93413451
B11: Almond orchard | C11: 0.6 | D11: drip | E11: 0.8 | F11: 0.95 | G11: =1*C11/E11 -> 0.75 | H11: =C11/F11 -> 0.63157895 | J11: =J4 -> Sprinkler | K11: 2017 | L11: Fodder crops | M11: 106.51539 | N11: 1550.0447 | O11: 6.8717624 | P11: {=IFERROR(_xlfn.XLOOKUP(1,($D$11:$D$19=J11)*($B$11:$B$19=L11),$G$11:$G$19),"")} -> 1.4285714 | Q11: 1.1764706 | R11: =(P11*M11)/N11 -> 0.098168034 | S11: =(Q11*M11)/N11 -> 0.080844263 | U11: 2023 | V11: 1.0789505 | W11: 0.9001531 | X11: 1.0789505 | Y11: 0.9001531
B12: Complex syst. | C12: 1 | D12: drip | E12: 0.8 | F12: 0.95 | G12: =C12/E12 -> 1.25 | H12: =C12/F12 -> 1.0526316 | J12: =J5 -> drip | K12: 2017 | L12: Olive grove | M12: 144.61537 | N12: 1550.0447 | O12: 9.3297549 | P12: {=IFERROR(_xlfn.XLOOKUP(1,($D$11:$D$19=J12)*($B$11:$B$19=L12),$G$11:$G$19),"")} -> 0.6875 | Q12: 0.57894737 | R12: =(P12*M12)/N12 -> 0.064142065 | S12: =(Q12*M12)/N12 -> 0.05401437 | U12: 2024 | V12: 1.0892735 | W12: 0.90827041 | X12: 1.0892735 | Y12: 0.90827041
B13: Fodder crops | C13: 1 | D13: Sprinkler | E13: 0.7 | F13: 0.85 | G13: =C13/E13 -> 1.4285714 | H13: =C13/F13 -> 1.1764706 | J13: =J6 -> drip | K13: 2017 | L13: P. tomate | M13: 81.964214 | N13: 1550.0447 | O13: 5.2878614 | P13: {=IFERROR(_xlfn.XLOOKUP(1,($D$11:$D$19=J13)*($B$11:$B$19=L13),$G$11:$G$19),"")} -> 1 | Q13: 1.1764706 | R13: =(P13*M13)/N13 -> 0.052878614 | S13: =(Q13*M13)/N13 -> 0.062210135 | U13: 2025 | V13: 1.0867613 | W13: 0.90648245 | X13: 1.0867613 | Y13: 0.90648245
