Workbook

Sheet README
A1: Subsystem B — Reservoir and service performance calculation tool
A3: Purpose | B3: Calculate Subsystem B indicators directly from monthly reservoir simulation outputs.
A4: Populated period | B4: 2016–2025.
A5: Future extension | B5: The layout and formula ranges are prepared for 30-year horizons; paste additional monthly simulations and copy formulas down if needed.
A6: Scenario handling | B6: All reservoir simulation scenarios are retained. The dashboard highlights the ensemble-mean scenario and reports scenario ranges.
A7: Calendar-year handling | B7: Calendar years were derived from the chronological month sequence to avoid blank/intermittent year labels in the source sheets.
A8: Colour code | B8: Yellow = input/simulation data; grey = calculations; blue = outputs; purple = dashboard score; green/orange/red = quality checks.
A9: Paste period/scenario results | B9: Sheet EXPORT_CIS, yellow cells B6:I12.
A10: Paste annual results | B10: Sheet ANNUAL_DATA, yellow cells A4:Q203.
A11: Do not paste formulas | B11: Paste values only, unless you intentionally want to retain formulas from the original workbook.
A12: Four GIR variants | B12: Keep the four complete GIR variants as separate rows. Do not combine minima and maxima from different variants.
A13: Central estimate | B13: The ensemble mean is calculated automatically from the four GIR variants.
A14: Transition year | B14: 2021 should remain identifiable and excluded later from pre-/post-expansion means.
A15: Colour convention | B15: Dark blue = headings; yellow = editable/paste cells; grey = formulas or reference cells; white = outputs.

Sheet CONTROL_PANEL
A1: Control panel
A2: Parameter | B2: Value | C2: Unit/option | D2: Notes
A3: Case study | B3: Minutos Collective Irrigation System
A4: Subsystem | B4: B — Reservoir and service performance
A5: Basin area | B5: 94900
A6: Assessment start year | B6: 2016 | C6: year | D6: Editable
A7: Assessment end year | B7: 2025 | C7: year | D7: Editable
A8: Maximum prepared period | B8: 30 | C8: years | D8: The tool is structured for 30-year horizons.
A9: Main scenario for reporting | B9: Ensemble mean | D9: Dashboard highlights this scenario.
A10: Full storage capcity | B10: 264 | C10: m
A11: Net reservoir capacity | B11: 50000000 | C11: m³ | D11: Used for storage ratio.
A12: Minimum operating level | B12: 235 | C12: m
A13: Minimum operating level storage | B13: 2100000 | C13: m³ | D13: Diagnostic only.
A14: Environmental flow setting | B14: 0.07 | C14: fraction of inflow | D14: Current simulations include 7% environmental flow.
A15: Use scenario mean in dashboard | B15: Yes | D15: Scenario uncertainty is retained separately.

Sheet B_METHOD
A1: Subsystem B methodology
A3: ID | B3: Indicator | C3: Equation implemented in the workbook | D3: Unit | E3: Orientation | F3: Interpretation | G3: References
A4: B1 | B4: Time-based supply reliability | C4: 1 - (number of failure months / number of assessed months) | D4: - | E4: Positive | F4: Frequency with which demand at the source is fully satisfied. | G4: Hashimoto et al. (1982); Palop-Donat et al. (2020)
A5: B2 | B5: Volumetric supply reliability | C5: Σ supplied volume / Σ demand at source | D5: - | E5: Positive | F5: Proportion of total irrigation demand effectively supplied.
A6: B3 | B6: Mean relative deficit performance | C6: 1 - mean(service deficit / demand) during failure months | D6: - | E6: Positive | F6: Severity-adjusted service performance during failure months. | G6: Granados et al. (2021)
A7: B4 | B7: Recovery after failure | C7: Transitions from failure to satisfactory service / failure months with a following month | D7: - | E7: Positive | F7: Capacity to return to satisfactory service after failure. | G7: McMahon et al. (2006); Palop-Donat et al. (2020)
A8: B5 | B8: Spill–shortage coexistence | C8: 1 if annual spill > 0 and annual service deficit > 0; 0 otherwise | D8: - | E8: Negative | F8: Identifies years in which spill and irrigation shortage occur in the same year. | G8: Di Baldassarre et al. (2018); McMahon et al. (2007)

Sheet DATA_DICTIONARY
A1: Data dictionary
A3: Sheet | B3: Variable | C3: Description | D3: Unit | E3: Source | F3: Notes
A4: B_INPUT_RESERVOIR | B4: Demand at source | C4: Monthly irrigation demand at source/reservoir control point | D4: m³ | E4: SB_CAL_IND.xlsx BE sheets | F4: Used as D_t.
A5: B_INPUT_RESERVOIR | B5: Service deficit source | C5: Unmet irrigation demand from reservoir simulation | D5: m³ | E5: SB_CAL_IND.xlsx BE sheets | F5: Used as SD_t.
A6: B_INPUT_RESERVOIR | B6: Supplied volume | C6: Demand at source minus service deficit | D6: m³ | E6: Calculated | F6: Used as Sup_t.
A7: B_INPUT_RESERVOIR | B7: Failure state | C7: 1 if service deficit > 0; otherwise 0 | D7: - | E7: Calculated | F7: Used for B1 and B4.
A8: B_INPUT_RESERVOIR | B8: Spill | C8: Monthly spilled/discharged volume | D8: m³ | E8: SB_CAL_IND.xlsx BE sheets | F8: Used for B5.
A9: B_CALC_ANNUAL | B9: B1 Rt | C9: Annual time-based supply reliability | D9: - | E9: Calculated | F9: Higher is better.
A10: B_CALC_ANNUAL | B10: B2 Rv | C10: Annual volumetric supply reliability | D10: - | E10: Calculated | F10: Higher is better.
A11: B_CALC_ANNUAL | B11: B3 | C11: One minus mean relative deficit during failure months | D11: - | E11: Calculated | F11: Higher is better.
A12: B_CALC_ANNUAL | B12: B4 | C12: Recovery after failure | D12: - | E12: Calculated | F12: Higher is better.
A13: B_CALC_ANNUAL | B13: B5 SSC flag | C13: Annual spill–shortage coexistence | D13: - | E13: Calculated | F13: Lower is better.

Sheet DATA_INPUT
A1: Monthly reservoir simulation input data
K3: Irrigation ensemble
A4: Hydrological Year | B4: Month | C4: P | D4: ETo | E4: Ke | F4: Kpan | G4: Er | H4: ED | I4: Inflow (mm) | K4: GIR50%ISW_EF_H | L4: GIR50%ISW_EF_L | M4: EnsMean_Source_m3 | N4: GIR90%ISW_EF_H | O4: GIR90%ISW_EF_L
A5: 2015 | B5: 10 | C5: 69 | D5: 69.845625 | E5: 1.1629439 | F5: 0.7 | G5: =D5*E5 -> 81.226542 | H5: =F5*D5*E5 -> 56.85858 | I5: 0 | K5: 0 | L5: 0 | M5: 0 | N5: 0 | O5: 0
A6: 2015 | B6: 11 | C6: 17 | D6: 49.99075 | E6: 1.0906947 | F6: 0.7 | G6: =D6*E6 -> 54.524646 | H6: =F6*D6*E6 -> 38.167252 | I6: 0 | K6: 0 | L6: 0 | M6: 0 | N6: 0 | O6: 0
A7: 2015 | B7: 12 | C7: 31.405769 | D7: 37.998625 | E7: 0.92428785 | F7: 0.6 | G7: =D7*E7 -> 35.121668 | H7: =F7*D7*E7 -> 21.073001 | I7: 0.68814698 | K7: 0 | L7: 0 | M7: 0 | N7: 0 | O7: 0
A8: 2016 | B8: 1 | C8: 103 | D8: 35.454218 | E8: 0.82346133 | F8: 0.6 | G8: =D8*E8 -> 29.195178 | H8: =F8*D8*E8 -> 17.517107 | I8: 1.6752078 | K8: 0 | L8: 0 | M8: 0 | N8: 0 | O8: 0
A9: 2016 | B9: 2 | C9: 72 | D9: 45.375886 | E9: 0.83040998 | F9: 0.6 | G9: =D9*E9 -> 37.680589 | H9: =F9*D9*E9 -> 22.608353 | I9: 0.78460202 | K9: 0 | L9: 0 | M9: 0 | N9: 0 | O9: 0
A10: 2016 | B10: 3 | C10: 29 | D10: 74.441098 | E10: 0.86832081 | F10: 0.6 | G10: =D10*E10 -> 64.638754 | H10: =F10*D10*E10 -> 38.783253 | I10: 5.8924163 | K10: 0 | L10: 0 | M10: 0 | N10: 0 | O10: 0
A11: 2016 | B11: 4 | C11: 110 | D11: 100.07134 | E11: 0.97263527 | F11: 0.7 | G11: =D11*E11 -> 97.332911 | H11: =F11*D11*E11 -> 68.133038 | I11: 8.0845783 | K11: 25674.231 | L11: 32339.153 | M11: 21896.076 | N11: 13785.315 | O11: 15785.605
A12: 2016 | B12: 5 | C12: 110 | D12: 124.57491 | E12: 0.95871846 | F12: 0.7 | G12: =D12*E12 -> 119.43227 | H12: =F12*D12*E12 -> 83.602588 | I12: 2.7629512 | K12: 90918.576 | L12: 115730.36 | M12: 66127.399 | N12: 27068.123 | O12: 30792.539
A13: 2016 | B13: 6 | C13: 0.22064 | D13: 171.37315 | E13: 1.2091047 | F13: 0.8 | G13: =D13*E13 -> 207.20808 | H13: =F13*D13*E13 -> 165.76647 | I13: 0.41207547 | K13: 883210.26 | L13: 1124425.4 | M13: 909970.22 | N13: 759905.43 | O13: 872339.75
A14: 2016 | B14: 7 | C14: 6.2333333 | D14: 197.24617 | E14: 1.3003334 | F14: 0.8 | G14: =D14*E14 -> 256.48578 | H14: =F14*D14*E14 -> 205.18863 | I14: 0.057050426 | K14: 1549942.8 | L14: 1973736 | M14: 1708167.8 | N14: 1539770.4 | O14: 1769222
A15: 2016 | B15: 8 | C15: 0 | D15: 185.0881 | E15: 1.3823064 | F15: 0.8 | G15: =D15*E15 -> 255.84847 | H15: =F15*D15*E15 -> 204.67878 | I15: 0.0078148416 | K15: 1861619.5 | L15: 2372617.4 | M15: 2090837.8 | N15: 1920375.5 | O15: 2208738.8
A16: 2016 | B16: 9 | C16: 13.359717 | D16: 132.4592 | E16: 1.3453601 | F16: 0.8 | G16: =D16*E16 -> 178.20532 | H16: =F16*D16*E16 -> 142.56426 | I16: 0.0011655307 | K16: 758226.86 | L16: 966543.29 | M16: 847085.62 | N16: 773626.65 | O16: 889945.68
A17: 2016 | B17: 10 | C17: 54.578554 | D17: 80.354556 | E17: =E5 -> 1.1629439 | F17: =F5 -> 0.7 | G17: =D17*E17 -> 93.447839 | H17: =F17*D17*E17 -> 65.413487 | I17: 0.00015965592 | K17: 245121.5 | L17: 312876.66 | M17: 278313.41 | N17: 258022.63 | O17: 297232.83
A18: 2016 | B18: 11 | C18: 83.318394 | D18: 42.190475 | E18: =E6 -> 1.0906947 | F18: =F6 -> 0.7 | G18: =D18*E18 -> 46.016928 | H18: =F18*D18*E18 -> 32.21185 | I18: 2.3811599e-05 | K18: 0 | L18: 0 | M18: 0 | N18: 0 | O18: 0
A19: 2016 | B19: 12 | C19: 64.09792 | D19: 37.081212 | E19: =E7 -> 0.92428785 | F19: =F7 -> 0.6 | G19: =D19*E19 -> 34.273713 | H19: =F19*D19*E19 -> 20.564228 | I19: 3.2966337e-06 | K19: 0 | L19: 0 | M19: 0 | N19: 0 | O19: 0
A20: 2017 | B20: 1 | C20: 45.218339 | D20: 37.930146 | E20: =E8 -> 0.82346133 | F20: =F8 -> 0.6 | G20: =D20*E20 -> 31.234008 | H20: =F20*D20*E20 -> 18.740405 | I20: 0.086231951 | K20: 0 | L20: 0 | M20: 0 | N20: 0 | O20: 0
A21: 2017 | B21: 2 | C21: 57.644633 | D21: 48.392921 | E21: =E9 -> 0.83040998 | F21: =F9 -> 0.6 | G21: =D21*E21 -> 40.185964 | H21: =F21*D21*E21 -> 24.111579 | I21: 3.7172527 | K21: 0 | L21: 0 | M21: 0 | N21: 0 | O21: 0
A22: 2017 | B22: 3 | C22: 78.925723 | D22: 83.353616 | E22: =E10 -> 0.86832081 | F22: =F10 -> 0.6 | G22: =D22*E22 -> 72.377679 | H22: =F22*D22*E22 -> 43.426608 | I22: 1.7023756 | K22: 0 | L22: 0 | M22: 0 | N22: 0 | O22: 0
A23: 2017 | B23: 4 | C23: 1.9115987 | D23: 130.60478 | E23: =E11 -> 0.97263527 | F23: =F11 -> 0.7 | G23: =D23*E23 -> 127.03082 | H23: =F23*D23*E23 -> 88.921573 | I23: 0.25389779 | K23: 375420.44 | L23: 479261.34 | M23: 241751.85 | N23: 52312.997 | O23: 60012.626
A24: 2017 | B24: 5 | C24: 49.441998 | D24: 163.28744 | E24: =E12 -> 0.95871846 | F24: =F12 -> 0.7 | G24: =D24*E24 -> 156.54668 | H24: =F24*D24*E24 -> 109.58268 | I24: 0.03477925 | K24: 217709.02 | L24: 276912.66 | M24: 211465.59 | N24: 163660.57 | O24: 187580.12
A25: 2017 | B25: 6 | C25: 9.4666667 | D25: 193.06562 | E25: =E13 -> 1.2091047 | F25: =F13 -> 0.8 | G25: =D25*E25 -> 233.43655 | H25: =F25*D25*E25 -> 186.74924 | I25: 0.0051870898 | K25: 1084457.4 | L25: 1381067.5 | M25: 1165726.1 | N25: 1022433.9 | O25: 1174945.5
A26: 2017 | B26: 7 | C26: 0 | D26: 199.55806 | E26: =E14 -> 1.3003334 | F26: =F14 -> 0.8 | G26: =D26*E26 -> 259.49202 | H26: =F26*D26*E26 -> 207.59361 | I26: 0.00071813467 | K26: 1908588.9 | L26: 2431776.9 | M26: 2136483.9 | N26: 1956241 | O26: 2249329
A27: 2017 | B27: 8 | C27: 14.699363 | D27: 181.81743 | E27: =E15 -> 1.3823064 | F27: =F15 -> 0.8 | G27: =D27*E27 -> 251.3274 | H27: =F27*D27*E27 -> 201.06192 | I27: 9.8371023e-05 | K27: 1247883.4 | L27: 1588730.7 | M27: 1403083.9 | N27: 1291677.9 | O27: 1484043.5
A28: 2017 | B28: 9 | C28: 0 | D28: 129.46044 | E28: =E16 -> 1.3453601 | F28: =F16 -> 0.8 | G28: =D28*E28 -> 174.17091 | H28: =F28*D28*E28 -> 139.33673 | I28: 1.4671372e-05 | K28: 742727.3 | L28: 946943.9 | M28: 833774.46 | N28: 765103.95 | O28: 880322.68
... A53: 2019 | B53: 10 | C53: 32.989572 | D53: 80.60755 | E53: =E41 -> 1.1629439 | F53: =F41 -> 0.7 | G53: =D53*E53 -> 93.742056 | H53: =F53*D53*E53 -> 65.61944 | I53: 1.4462547 | K53: 94180.21 | L53: 119869.59 | M53: 106681.13 | N53: 98978.03 | O53: 113696.7
A54: 2019 | B54: 11 | C54: 111.27085 | D54: 37.197868 | E54: =E42 -> 1.0906947 | F54: =F42 -> 0.7 | G54: =D54*E54 -> 40.571518 | H54: =F54*D54 -> 26.038508 | I54: 17.431581 | K54: 0 | L54: 0 | M54: 0 | N54: 0 | O54: 0
A55: 2019 | B55: 12 | C55: 113.75735 | D55: 32.633332 | E55: =E43 -> 0.92428785 | F55: =F43 -> 0.6 | G55: =D55*E55 -> 30.162592 | H55: =F55*D55 -> 19.579999 | I55: 13.102925 | K55: 0 | L55: 0 | M55: 0 | N55: 0 | O55: 0
A56: 2020 | B56: 1 | C56: 56.391435 | D56: 36.664914 | E56: =E44 -> 0.82346133 | F56: =F44 -> 0.6 | G56: =D56*E56 -> 30.192139 | H56: =F56*D56 -> 21.998948 | I56: 3.7777247 | K56: 0 | L56: 0 | M56: 0 | N56: 0 | O56: 0
A57: 2020 | B57: 2 | C57: 2.8041327 | D57: 57.800346 | E57: =E45 -> 0.83040998 | F57: =F45 -> 0.6 | G57: =D57*E57 -> 47.997984 | H57: =F57*D57 -> 34.680208 | I57: 0.62649629 | K57: 0 | L57: 0 | M57: 0 | N57: 0 | O57: 0
A58: 2020 | B58: 3 | C58: 51.564639 | D58: 80.051129 | E58: =E46 -> 0.86832081 | F58: =F46 -> 0.6 | G58: =D58*E58 -> 69.510061 | H58: =F58*D58 -> 48.030677 | I58: 5.6344814 | K58: 0 | L58: 0 | M58: 0 | N58: 0 | O58: 0
A59: 2020 | B59: 4 | C59: 105.49801 | D59: 96.231877 | E59: =E47 -> 0.97263527 | F59: =F47 -> 0.7 | G59: =D59*E59 -> 93.598518 | H59: =F59*D59 -> 67.362314 | I59: 2.6204538 | K59: 9084.7424 | L59: 11358.389 | M59: 5150.1882 | N59: 73.190807 | O59: 84.430824
A60: 2020 | B60: 5 | C60: 55.473412 | D60: 158.10995 | E60: =E48 -> 0.95871846 | F60: =F48 -> 0.7 | G60: =D60*E60 -> 151.58293 | H60: =F60*D60 -> 110.67697 | I60: 0.35895317 | K60: 178950.36 | L60: 227506.92 | M60: 174307.62 | N60: 135376.31 | O60: 155396.9
A61: 2020 | B61: 6 | C61: 2.4507 | D61: 170.28422 | E61: =E49 -> 1.2091047 | F61: =F49 -> 0.8 | G61: =D61*E61 -> 205.89145 | H61: =F61*D61 -> 136.22737 | I61: 0.053535436 | K61: 891368.21 | L61: 1133831.4 | M61: 926945.69 | N61: 783599.49 | O61: 898983.63
A62: 2020 | B62: 7 | C62: 9.2666667 | D62: 223.7691 | E62: =E50 -> 1.3003334 | F62: =F50 -> 0.8 | G62: =D62*E62 -> 290.97444 | H62: =F62*D62 -> 179.01528 | I62: 0.0074117963 | K62: 1875412.3 | L62: 2386045.8 | M62: 2077029.2 | N62: 1883820.7 | O62: 2162837.8
A63: 2020 | B63: 8 | C63: 0.51595467 | D63: 173.33281 | E63: =E51 -> 1.3823064 | F63: =F51 -> 0.8 | G63: =D63*E63 -> 239.59906 | H63: =F63*D63 -> 138.66625 | I63: 0.0010152775 | K63: 1613405.3 | L63: 2053334.8 | M63: 1807668.4 | N63: 1658736.6 | O63: 1905196.7
A64: 2020 | B64: 9 | C64: 43.032966 | D64: 125.37145 | E64: =E52 -> 1.3453601 | F64: =F52 -> 0.8 | G64: =D64*E64 -> 168.66975 | H64: =F64*D64 -> 100.29716 | I64: 1.6258181 | K64: 564560.21 | L64: 717593.02 | M64: 633411.39 | N64: 582898.06 | O64: 668594.29
A65: 2020 | B65: 10 | C65: 114.86223 | D65: 76.453899 | E65: =E53 -> 1.1629439 | F65: =F53 -> 0.7 | G65: =D65*E65 -> 88.911594 | H65: =F65*D65 -> 53.517729 | I65: 6.5272909 | K65: 95822.922 | L65: 122477.06 | M65: 107973.51 | N65: 99182.816 | O65: 114411.26
...

Sheet STORAGE_BALANCE_ENSEMBLE
A1: Monthly reservoir Balance
N3: =DATA_INPUT!K4 -> GIR50%ISW_EF_H | AG3: =DATA_INPUT!L4 -> GIR50%ISW_EF_L | AZ3: =DATA_INPUT!M4 -> EnsMean_Source_m3 | BS3: =DATA_INPUT!N4 -> GIR90%ISW_EF_H | CL3: =DATA_INPUT!O4 -> GIR90%ISW_EF_L
A4: Hydrological Year | B4: Month | C4: Day | D4: Initial level (m) | E4: Initial volume vt (m3) | F4: Area (m2) | G4: Observed monthly runoff (mm) | H4: Monthly runoff volume (m3) | I4: Monthly precipitation (mm) | J4: Rainfall Volume (m3) | K4: Monthly Evaporation (mm) | L4: Evaporation volume (m3) | M4: Ecological flow volume (m3) | N4: Irrigation (m3) | O4: Final volume (Vt+1 (m3) | P4: Spill (m3) | Q4: Service deficit source (m³) | R4: Data flag | T4: Hydrological Year | U4: Month | V4: Day | W4: Initial level (m) | X4: Initial volume vt (m3) | Y4: Area (m2) | Z4: Observed monthly runoff (mm) | AA4: Monthly runoff volume (m3) | AB4: Monthly precipitation (mm) | AC4: Rainfall Volume (m3) | AD4: Monthly Evaporation (mm) | AE4: Evaporation volume (m3) | AF4: Ecological flow volume (m3) | AG4: Irrigation (m3) | AH4: Final volume (Vt+1 (m3) | AI4: Spill (m3) | AJ4: Service deficit source (m³) | AK4: Data flag | AM4: Hydrological Year | AN4: Month | AO4: Day | AP4: Initial level (m) | AQ4: Initial volume vt (m3) | AR4: Area (m2) | AS4: Observed monthly runoff (mm) | AT4: Monthly runoff volume (m3) | AU4: Monthly precipitation (mm) | AV4: Rainfall Volume (m3) | AW4: Monthly Evaporation (mm) | AX4: Evaporation volume (m3) | AY4: Ecological flow volume (m3) | AZ4: Irrigation (m3) | BA4: Final volume (Vt+1 (m3) | BB4: Spill (m3) | BC4: Service deficit source (m³) | BD4: Data flag | BF4: Hydrological Year | BG4: Month | BH4: Day | BI4: Initial level (m) | BJ4: Initial volume vt (m3) | BK4: Area (m2) | BL4: Observed monthly runoff (mm) | BM4: Monthly runoff volume (m3) | BN4: Monthly precipitation (mm) | BO4: Rainfall Volume (m3) | BP4: Monthly Evaporation (mm) | BQ4: Evaporation volume (m3) | BR4: Ecological flow volume (m3) | BS4: Irrigation (m3) | BT4: Final volume (Vt+1 (m3) | BU4: Spill (m3) | BV4: Service deficit source (m³) | BW4: Data flag | BY4: Hydrological Year | BZ4: Month | CA4: Day | CB4: Initial level (m) | CC4: Initial volume vt (m3) | CD4: Area (m2) | CE4: Observed monthly runoff (mm) | CF4: Monthly runoff volume (m3) | CG4: Monthly precipitation (mm) | CH4: Rainfall Volume (m3) | CI4: Monthly Evaporation (mm) | CJ4: Evaporation volume (m3) | CK4: Ecological flow volume (m3) | CL4: Irrigation (m3) | CM4: Final volume (Vt+1 (m3) | CN4: Spill (m3) | CO4: Service deficit source (m³) | CP4: Data flag
A5: 2015 | B5: 10 | C5: =IF(R5<>1,"",DAY(DATE(A5,B5+1,))) -> 31 | D5: 261.35 | E5: =0.2*(D5-CONTROL_PANEL!$B$12)^3.02*10000 -> 39064967 | F5: =IF(R5<>1,"",0.6*(D5-235)^2.02*10000) -> 4447624.4 | G5: =IF(R5<>1,"",DATA_INPUT!$I5) -> 0 | H5: =IF(R5<>1,"",G5*CONTROL_PANEL!$B$5) -> 0 | I5: =IF(R5<>1,"",DATA_INPUT!$C5) -> 69 | J5: =IF(R5<>1,"",(I5*F5)/1000) -> 306886.08 | K5: =IF(R5<>1,"",DATA_INPUT!$H5) -> 56.85858 | L5: =IF(R5<>1,"",((K5*F5)/1000)) -> 252885.6 | M5: =IF(R5<>1,"",H5*CONTROL_PANEL!$B$14) -> 0 | N5: =IF(R5<>1,"",DATA_INPUT!$K5) -> 0 | O5: =IF(R5<>1,"",(E5+H5+J5)-(L5+N5+M5)) -> 39118968 | P5: =IF(R5<>1,"",IF(O5-CONTROL_PANEL!$B$11<0,0,O5-CONTROL_PANEL!$B$11)) -> 0 | Q5: =IF(R5<>1,"",IF(N5<=0,0,MIN(N5,MAX(0,CONTROL_PANEL!$B$13-O5)))) -> 0 | R5: 1 | T5: 2015 | U5: 10 | V5: =IF(AK5<>1,"",DAY(DATE(T5,U5+1,))) -> 31 | W5: 261.35 | X5: =0.2*(W5-CONTROL_PANEL!$B$12)^3.02*10000 -> 39064967 | Y5: =IF(AK5<>1,"",0.6*(W5-235)^2.02*10000) -> 4447624.4 | Z5: =IF(AK5<>1,"",DATA_INPUT!I5) -> 0 | AA5: =IF(AK5<>1,"",Z5*CONTROL_PANEL!$B$5) -> 0 | AB5: =IF(AK5<>1,"",DATA_INPUT!$C5) -> 69 | AC5: =IF(AK5<>1,"",(AB5*Y5)/1000) -> 306886.08 | AD5: =IF(AK5<>1,"",DATA_INPUT!$H5) -> 56.85858 | AE5: =IF(AK5<>1,"",((AD5*Y5)/1000)) -> 252885.6 | AF5: =IF(AK5<>1,"",AA5*CONTROL_PANEL!$B$14) -> 0 | AG5: =IF(AK5<>1,"",DATA_INPUT!$L5) -> 0 | AH5: =IF(AK5<>1,"",(X5+AA5+AC5)-(AE5+AG5+AF5)) -> 39118968 | AI5: =IF(AK5<>1,"",IF(AH5-CONTROL_PANEL!$B$11<0,0,AH5-CONTROL_PANEL!$B$11)) -> 0 | AJ5: =IF(AK5<>1,"",IF(AG5<=0,0,MIN(AG5,MAX(0,CONTROL_PANEL!$B$13-AH5)))) -> 0 | AK5: 1 | AM5: 2015 | AN5: 10 | AO5: =IF(BD5<>1,"",DAY(DATE(AM5,AN5+1,))) -> 31 | AP5: 261.35 | AQ5: =0.2*(AP5-CONTROL_PANEL!$B$12)^3.02*10000 -> 39064967 | AR5: =IF(BD5<>1,"",0.6*(AP5-235)^2.02*10000) -> 4447624.4 | AS5: =IF(BD5<>1,"",DATA_INPUT!$I5) -> 0 | AT5: =IF(BD5<>1,"",AS5*CONTROL_PANEL!$B$5) -> 0 | AU5: =IF(BD5<>1,"",DATA_INPUT!$C5) -> 69 | AV5: =IF(BD5<>1,"",(AU5*AR5)/1000) -> 306886.08 | AW5: =IF(BD5<>1,"",DATA_INPUT!$H5) -> 56.85858 | AX5: =IF(BD5<>1,"",((AW5*AR5)/1000)) -> 252885.6 | AY5: =IF(BD5<>1,"",AT5*CONTROL_PANEL!$B$14) -> 0 | AZ5: =IF(BD5<>1,"",DATA_INPUT!$M5) -> 0 | BA5: =IF(BD5<>1,"",(AQ5+AT5+AV5)-(AX5+AZ5+AY5)) -> 39118968 | BB5: =IF(BD5<>1,"",IF(BA5-CONTROL_PANEL!$B$11<0,0,BA5-CONTROL_PANEL!$B$11)) -> 0 | BC5: =IF(BD5<>1,"",IF(AZ5<=0,0,MIN(AZ5,MAX(0,CONTROL_PANEL!$B$13-BA5)))) -> 0 | BD5: 1 | BF5: 2015 | BG5: 10 | BH5: =IF(BW5<>1,"",DAY(DATE(BF5,BG5+1,))) -> 31 | BI5: 261.35 | BJ5: =0.2*(BI5-CONTROL_PANEL!$B$12)^3.02*10000 -> 39064967 | BK5: =IF(BW5<>1,"",0.6*(BI5-235)^2.02*10000) -> 4447624.4 | BL5: =IF(BW5<>1,"",DATA_INPUT!$I5) -> 0 | BM5: =IF(BW5<>1,"",BL5*CONTROL_PANEL!$B$5) -> 0 | BN5: =IF(BW5<>1,"",DATA_INPUT!$C5) -> 69 | BO5: =IF(BW5<>1,"",(BN5*BK5)/1000) -> 306886.08 | BP5: =IF(BW5<>1,"",DATA_INPUT!$H5) -> 56.85858 | BQ5: =IF(BW5<>1,"",((BP5*BK5)/1000)) -> 252885.6 | BR5: =IF(BW5<>1,"",BM5*CONTROL_PANEL!$B$14) -> 0 | BS5: =IF(BW5<>1,"",DATA_INPUT!$N5) -> 0 | BT5: =IF(BW5<>1,"",(BJ5+BM5+BO5)-(BQ5+BS5+BR5)) -> 39118968 | BU5: =IF(BW5<>1,"",IF(BT5-CONTROL_PANEL!$B$11<0,0,BT5-CONTROL_PANEL!$B$11)) -> 0 | BV5: =IF(BW5<>1,"",IF(BS5<=0,0,MIN(BS5,MAX(0,CONTROL_PANEL!$B$13-BT5)))) -> 0 | BW5: 1 | BY5: 2015 | BZ5: 10 | CA5: =IF(CP5<>1,"",DAY(DATE(BY5,BZ5+1,))) -> 31 | CB5: 261.35 | CC5: =0.2*(CB5-CONTROL_PANEL!$B$12)^3.02*10000 -> 39064967 | CD5: =IF(CP5<>1,"",0.6*(CB5-235)^2.02*10000) -> 4447624.4 | CE5: =IF(CP5<>1,"",DATA_INPUT!$I5) -> 0 | CF5: =IF(CP5<>1,"",CE5*CONTROL_PANEL!$B$5) -> 0 | CG5: =IF(CP5<>1,"",DATA_INPUT!$C5) -> 69 | CH5: =IF(CP5<>1,"",(CG5*CD5)/1000) -> 306886.08 | CI5: =IF(CP5<>1,"",DATA_INPUT!$H5) -> 56.85858 | CJ5: =IF(CP5<>1,"",((CI5*CD5)/1000)) -> 252885.6 | CK5: =IF(CP5<>1,"",CF5*CONTROL_PANEL!$B$14) -> 0 | CL5: =IF(CP5<>1,"",DATA_INPUT!$O5) -> 0 | CM5: =IF(CP5<>1,"",(CC5+CF5+CH5)-(CJ5+CL5+CK5)) -> 39118968 | CN5: =IF(CP5<>1,"",IF(CM5-CONTROL_PANEL!$B$11<0,0,CM5-CONTROL_PANEL!$B$11)) -> 0 | CO5: =IF(CP5<>1,"",IF(CL5<=0,0,MIN(CL5,MAX(0,CONTROL_PANEL!$B$13-CM5)))) -> 0 | CP5: 1
A6: 2015 | B6: 11 | C6: =IF(R6<>1,"",DAY(DATE(A6,B6+1,))) -> 30 | D6: =IF(R5<>1,"",235+((E6/1000/2)^(1/3.02))) -> 261.36206 | E6: =IF(R5<>1,"",IF(O5>0,IF(O5>CONTROL_PANEL!$B$11,CONTROL_PANEL!$B$11,O5),0)) -> 39118968 | F6: =IF(R6<>1,"",0.6*(D6-235)^2.02*10000) -> 4451735.7 | G6: =IF(R6<>1,"",DATA_INPUT!I6) -> 0 | H6: =IF(R6<>1,"",G6*CONTROL_PANEL!$B$5) -> 0 | I6: =IF(R6<>1,"",DATA_INPUT!C6) -> 17 | J6: =IF(R6<>1,"",(I6*F6)/1000) -> 75679.507 | K6: =IF(R6<>1,"",DATA_INPUT!H6) -> 38.167252 | L6: =IF(R6<>1,"",((K6*F6)/1000)) -> 169910.52 | M6: =IF(R6<>1,"",H6*CONTROL_PANEL!$B$14) -> 0 | N6: =IF(R6<>1,"",DATA_INPUT!K6) -> 0 | O6: =IF(R6<>1,"",(E6+H6+J6)-(L6+N6+M6)) -> 39024737 | P6: =IF(R6<>1,"",IF(O6-CONTROL_PANEL!$B$11<0,0,O6-CONTROL_PANEL!$B$11)) -> 0 | Q6: =IF(R6<>1,"",IF(N6<=0,0,MIN(N6,MAX(0,CONTROL_PANEL!$B$13-O6)))) -> 0 | R6: 1 | T6: 2015 | U6: 11 | V6: =IF(AK6<>1,"",DAY(DATE(T6,U6+1,))) -> 30 | W6: =IF(AK5<>1,"",235+((X6/1000/2)^(1/3.02))) -> 261.36206 | X6: =IF(AK5<>1,"",IF(AH5>0,IF(AH5>CONTROL_PANEL!$B$11,CONTROL_PANEL!$B$11,AH5),0)) -> 39118968 | Y6: =IF(AK6<>1,"",0.6*(W6-235)^2.02*10000) -> 4451735.7 | Z6: =IF(AK6<>1,"",DATA_INPUT!I6) -> 0 | AA6: =IF(AK6<>1,"",Z6*CONTROL_PANEL!$B$5) -> 0 | AB6: =IF(AK6<>1,"",DATA_INPUT!$C6) -> 17 | AC6: =IF(AK6<>1,"",(AB6*Y6)/1000) -> 75679.507 | AD6: =IF(AK6<>1,"",DATA_INPUT!$H6) -> 38.167252 | AE6: =IF(AK6<>1,"",((AD6*Y6)/1000)) -> 169910.52 | AF6: =IF(AK6<>1,"",AA6*CONTROL_PANEL!$B$14) -> 0 | AG6: =IF(AK6<>1,"",DATA_INPUT!$L6) -> 0 | AH6: =IF(AK6<>1,"",(X6+AA6+AC6)-(AE6+AG6+AF6)) -> 39024737 | AI6: =IF(AK6<>1,"",IF(AH6-CONTROL_PANEL!$B$11<0,0,AH6-CONTROL_PANEL!$B$11)) -> 0 | AJ6: =IF(AK6<>1,"",IF(AG6<=0,0,MIN(AG6,MAX(0,CONTROL_PANEL!$B$13-AH6)))) -> 0 | AK6: 1 | AM6: 2015 | AN6: 11 | AO6: =IF(BD6<>1,"",DAY(DATE(AM6,AN6+1,))) -> 30 | AP6: =IF(BD5<>1,"",235+((AQ6/1000/2)^(1/3.02))) -> 261.36206 | AQ6: =IF(BD5<>1,"",IF(BA5>0,IF(BA5>CONTROL_PANEL!$B$11,CONTROL_PANEL!$B$11,BA5),0)) -> 39118968 | AR6: =IF(BD6<>1,"",0.6*(AP6-235)^2.02*10000) -> 4451735.7 | AS6: =IF(BD6<>1,"",DATA_INPUT!$I6) -> 0 | AT6: =IF(BD6<>1,"",AS6*CONTROL_PANEL!$B$5) -> 0 | AU6: =IF(BD6<>1,"",DATA_INPUT!$C6) -> 17 | AV6: =IF(BD6<>1,"",(AU6*AR6)/1000) -> 75679.507 | AW6: =IF(BD6<>1,"",DATA_INPUT!$H6) -> 38.167252 | AX6: =IF(BD6<>1,"",((AW6*AR6)/1000)) -> 169910.52 | AY6: =IF(BD6<>1,"",AT6*CONTROL_PANEL!$B$14) -> 0 | AZ6: =IF(BD6<>1,"",DATA_INPUT!$M6) -> 0 | BA6: =IF(BD6<>1,"",(AQ6+AT6+AV6)-(AX6+AZ6+AY6)) -> 39024737 | BB6: =IF(BD6<>1,"",IF(BA6-CONTROL_PANEL!$B$11<0,0,BA6-CONTROL_PANEL!$B$11)) -> 0 | BC6: =IF(BD6<>1,"",IF(AZ6<=0,0,MIN(AZ6,MAX(0,CONTROL_PANEL!$B$13-BA6)))) -> 0 | BD6: 1 | BF6: 2015 | BG6: 11 | BH6: =IF(BW6<>1,"",DAY(DATE(BF6,BG6+1,))) -> 30 | BI6: =IF(BW5<>1,"",235+((BJ6/1000/2)^(1/3.02))) -> 261.36206 | BJ6: =IF(BW5<>1,"",IF(BT5>0,IF(BT5>CONTROL_PANEL!$B$11,CONTROL_PANEL!$B$11,BT5),0)) -> 39118968 | BK6: =IF(BW6<>1,"",0.6*(BI6-235)^2.02*10000) -> 4451735.7 | BL6: =IF(BW6<>1,"",DATA_INPUT!$I6) -> 0 | BM6: =IF(BW6<>1,"",BL6*CONTROL_PANEL!$B$5) -> 0 | BN6: =IF(BW6<>1,"",DATA_INPUT!$C6) -> 17 | BO6: =IF(BW6<>1,"",(BN6*BK6)/1000) -> 75679.507 | BP6: =IF(BW6<>1,"",DATA_INPUT!$H6) -> 38.167252 | BQ6: =IF(BW6<>1,"",((BP6*BK6)/1000)) -> 169910.52 | BR6: =IF(BW6<>1,"",BM6*CONTROL_PANEL!$B$14) -> 0 | BS6: =IF(BW6<>1,"",DATA_INPUT!$N6) -> 0 | BT6: =IF(BW6<>1,"",(BJ6+BM6+BO6)-(BQ6+BS6+BR6)) -> 39024737 | BU6: =IF(BW6<>1,"",IF(BT6-CONTROL_PANEL!$B$11<0,0,BT6-CONTROL_PANEL!$B$11)) -> 0 | BV6: =IF(BW6<>1,"",IF(BS6<=0,0,MIN(BS6,MAX(0,CONTROL_PANEL!$B$13-BT6)))) -> 0 | BW6: 1 | BY6: 2015 | BZ6: 11 | CA6: =IF(CP6<>1,"",DAY(DATE(BY6,BZ6+1,))) -> 30 | CB6: =IF(CP5<>1,"",235+((CC6/1000/2)^(1/3.02))) -> 261.36206 | CC6: =IF(CP5<>1,"",IF(CM5>0,IF(CM5>CONTROL_PANEL!$B$11,CONTROL_PANEL!$B$11,CM5),0)) -> 39118968 | CD6: =IF(CP6<>1,"",0.6*(CB6-235)^2.02*10000) -> 4451735.7 | CE6: =IF(CP6<>1,"",DATA_INPUT!$I6) -> 0 | CF6: =IF(CP6<>1,"",CE6*CONTROL_PANEL!$B$5) -> 0 | CG6: =IF(CP6<>1,"",DATA_INPUT!$C6) -> 17 | CH6: =IF(CP6<>1,"",(CG6*CD6)/1000) -> 75679.507 | CI6: =IF(CP6<>1,"",DATA_INPUT!$H6) -> 38.167252 | CJ6: =IF(CP6<>1,"",((CI6*CD6)/1000)) -> 169910.52 | CK6: =IF(CP6<>1,"",CF6*CONTROL_PANEL!$B$14) -> 0 | CL6: =IF(CP6<>1,"",DATA_INPUT!$O6) -> 0 | CM6: =IF(CP6<>1,"",(CC6+CF6+CH6)-(CJ6+CL6+CK6)) -> 39024737 | CN6: =IF(CP6<>1,"",IF(CM6-CONTROL_PANEL!$B$11<0,0,CM6-CONTROL_PANEL!$B$11)) -> 0 | CO6: =IF(CP6<>1,"",IF(CL6<=0,0,MIN(CL6,MAX(0,CONTROL_PANEL!$B$13-CM6)))) -> 0 | CP6: 1
A7: 2015 | B7: 12 | C7: =IF(R7<>1,"",DAY(DATE(A7,B7+1,))) -> 31 | D7: =IF(R6<>1,"",235+((E7/1000/2)^(1/3.02))) -> 261.34101 | E7: =IF(R6<>1,"",IF(O6>0,IF(O6>CONTROL_PANEL!$B$11,CONTROL_PANEL!$B$11,O6),0)) -> 39024737 | F7: =IF(R7<>1,"",0.6*(D7-235)^2.02*10000) -> 4444560.2 | G7: =IF(R7<>1,"",DATA_INPUT!I7) -> 0.68814698 | H7: =IF(R7<>1,"",G7*CONTROL_PANEL!$B$5) -> 65305.148 | I7: =IF(R7<>1,"",DATA_INPUT!C7) -> 31.405769 | J7: =IF(R7<>1,"",(I7*F7)/1000) -> 139584.83 | K7: =IF(R7<>1,"",DATA_INPUT!H7) -> 21.073001 | L7: =IF(R7<>1,"",((K7*F7)/1000)) -> 93660.22 | M7: =IF(R7<>1,"",H7*CONTROL_PANEL!$B$14) -> 4571.3604 | N7: =IF(R7<>1,"",DATA_INPUT!K7) -> 0 | O7: =IF(R7<>1,"",(E7+H7+J7)-(L7+N7+M7)) -> 39131395 | P7: =IF(R7<>1,"",IF(O7-CONTROL_PANEL!$B$11<0,0,O7-CONTROL_PANEL!$B$11)) -> 0 | Q7: =IF(R7<>1,"",IF(N7<=0,0,MIN(N7,MAX(0,CONTROL_PANEL!$B$13-O7)))) -> 0 | R7: 1 | T7: 2015 | U7: 12 | V7: =IF(AK7<>1,"",DAY(DATE(T7,U7+1,))) -> 31 | W7: =IF(AK6<>1,"",235+((X7/1000/2)^(1/3.02))) -> 261.34101 | X7: =IF(AK6<>1,"",IF(AH6>0,IF(AH6>CONTROL_PANEL!$B$11,CONTROL_PANEL!$B$11,AH6),0)) -> 39024737 | Y7: =IF(AK7<>1,"",0.6*(W7-235)^2.02*10000) -> 4444560.2 | Z7: =IF(AK7<>1,"",DATA_INPUT!I7) -> 0.68814698 | AA7: =IF(AK7<>1,"",Z7*CONTROL_PANEL!$B$5) -> 65305.148 | AB7: =IF(AK7<>1,"",DATA_INPUT!$C7) -> 31.405769 | AC7: =IF(AK7<>1,"",(AB7*Y7)/1000) -> 139584.83 | AD7: =IF(AK7<>1,"",DATA_INPUT!$H7) -> 21.073001 | AE7: =IF(AK7<>1,"",((AD7*Y7)/1000)) -> 93660.22 | AF7: =IF(AK7<>1,"",AA7*CONTROL_PANEL!$B$14) -> 4571.3604 | AG7: =IF(AK7<>1,"",DATA_INPUT!$L7) -> 0 | AH7: =IF(AK7<>1,"",(X7+AA7+AC7)-(AE7+AG7+AF7)) -> 39131395 | AI7: =IF(AK7<>1,"",IF(AH7-CONTROL_PANEL!$B$11<0,0,AH7-CONTROL_PANEL!$B$11)) -> 0 | AJ7: =IF(AK7<>1,"",IF(AG7<=0,0,MIN(AG7,MAX(0,CONTROL_PANEL!$B$13-AH7)))) -> 0 | AK7: 1 | AM7: 2015 | AN7: 12 | AO7: =IF(BD7<>1,"",DAY(DATE(AM7,AN7+1,))) -> 31 | AP7: =IF(BD6<>1,"",235+((AQ7/1000/2)^(1/3.02))) -> 261.34101 | AQ7: =IF(BD6<>1,"",IF(BA6>0,IF(BA6>CONTROL_PANEL!$B$11,CONTROL_PANEL!$B$11,BA6),0)) -> 39024737 | AR7: =IF(BD7<>1,"",0.6*(AP7-235)^2.02*10000) -> 4444560.2 | AS7: =IF(BD7<>1,"",DATA_INPUT!$I7) -> 0.68814698 | AT7: =IF(BD7<>1,"",AS7*CONTROL_PANEL!$B$5) -> 65305.148 | AU7: =IF(BD7<>1,"",DATA_INPUT!$C7) -> 31.405769 | AV7: =IF(BD7<>1,"",(AU7*AR7)/1000) -> 139584.83 | AW7: =IF(BD7<>1,"",DATA_INPUT!$H7) -> 21.073001 | AX7: =IF(BD7<>1,"",((AW7*AR7)/1000)) -> 93660.22 | AY7: =IF(BD7<>1,"",AT7*CONTROL_PANEL!$B$14) -> 4571.3604 | AZ7: =IF(BD7<>1,"",DATA_INPUT!$M7) -> 0 | BA7: =IF(BD7<>1,"",(AQ7+AT7+AV7)-(AX7+AZ7+AY7)) -> 39131395 | BB7: =IF(BD7<>1,"",IF(BA7-CONTROL_PANEL!$B$11<0,0,BA7-CONTROL_PANEL!$B$11)) -> 0 | BC7: =IF(BD7<>1,"",IF(AZ7<=0,0,MIN(AZ7,MAX(0,CONTROL_PANEL!$B$13-BA7)))) -> 0 | BD7: 1 | BF7: 2015 | BG7: 12 | BH7: =IF(BW7<>1,"",DAY(DATE(BF7,BG7+1,))) -> 31 | BI7: =IF(BW6<>1,"",235+((BJ7/1000/2)^(1/3.02))) -> 261.34101 | BJ7: =IF(BW6<>1,"",IF(BT6>0,IF(BT6>CONTROL_PANEL!$B$11,CONTROL_PANEL!$B$11,BT6),0)) -> 39024737 | BK7: =IF(BW7<>1,"",0.6*(BI7-235)^2.02*10000) -> 4444560.2 | BL7: =IF(BW7<>1,"",DATA_INPUT!$I7) -> 0.68814698 | BM7: =IF(BW7<>1,"",BL7*CONTROL_PANEL!$B$5) -> 65305.148 | BN7: =IF(BW7<>1,"",DATA_INPUT!$C7) -> 31.405769 | BO7: =IF(BW7<>1,"",(BN7*BK7)/1000) -> 139584.83 | BP7: =IF(BW7<>1,"",DATA_INPUT!$H7) -> 21.073001 | BQ7: =IF(BW7<>1,"",((BP7*BK7)/1000)) -> 93660.22 | BR7: =IF(BW7<>1,"",BM7*CONTROL_PANEL!$B$14) -> 4571.3604 | BS7: =IF(BW7<>1,"",DATA_INPUT!$N7) -> 0 | BT7: =IF(BW7<>1,"",(BJ7+BM7+BO7)-(BQ7+BS7+BR7)) -> 39131395 | BU7: =IF(BW7<>1,"",IF(BT7-CONTROL_PANEL!$B$11<0,0,BT7-CONTROL_PANEL!$B$11)) -> 0 | BV7: =IF(BW7<>1,"",IF(BS7<=0,0,MIN(BS7,MAX(0,CONTROL_PANEL!$B$13-BT7)))) -> 0 | BW7: 1 | BY7: 2015 | BZ7: 12 | CA7: =IF(CP7<>1,"",DAY(DATE(BY7,BZ7+1,))) -> 31 | CB7: =IF(CP6<>1,"",235+((CC7/1000/2)^(1/3.02))) -> 261.34101 | CC7: =IF(CP6<>1,"",IF(CM6>0,IF(CM6>CONTROL_PANEL!$B$11,CONTROL_PANEL!$B$11,CM6),0)) -> 39024737 | CD7: =IF(CP7<>1,"",0.6*(CB7-235)^2.02*10000) -> 4444560.2 | CE7: =IF(CP7<>1,"",DATA_INPUT!$I7) -> 0.68814698 | CF7: =IF(CP7<>1,"",CE7*CONTROL_PANEL!$B$5) -> 65305.148 | CG7: =IF(CP7<>1,"",DATA_INPUT!$C7) -> 31.405769 | CH7: =IF(CP7<>1,"",(CG7*CD7)/1000) -> 139584.83 | CI7: =IF(CP7<>1,"",DATA_INPUT!$H7) -> 21.073001 | CJ7: =IF(CP7<>1,"",((CI7*CD7)/1000)) -> 93660.22 | CK7: =IF(CP7<>1,"",CF7*CONTROL_PANEL!$B$14) -> 4571.3604 | CL7: =IF(CP7<>1,"",DATA_INPUT!$O7) -> 0 | CM7: =IF(CP7<>1,"",(CC7+CF7+CH7)-(CJ7+CL7+CK7)) -> 39131395 | CN7: =IF(CP7<>1,"",IF(CM7-CONTROL_PANEL!$B$11<0,0,CM7-CONTROL_PANEL!$B$11)) -> 0 | CO7: =IF(CP7<>1,"",IF(CL7<=0,0,MIN(CL7,MAX(0,CONTROL_PANEL!$B$13-CM7)))) -> 0 | CP7: 1
A8: 2016 | B8: 1 | C8: =IF(R8<>1,"",DAY(DATE(A8,B8+1,))) -> 31 | D8: =IF(R7<>1,"",235+((E8/1000/2)^(1/3.02))) -> 261.36483 | E8: =IF(R7<>1,"",IF(O7>0,IF(O7>CONTROL_PANEL!$B$11,CONTROL_PANEL!$B$11,O7),0)) -> 39131395 | F8: =IF(R8<>1,"",0.6*(D8-235)^2.02*10000) -> 4452681.6 | G8: =IF(R8<>1,"",DATA_INPUT!I8) -> 1.6752078 | H8: =IF(R8<>1,"",G8*CONTROL_PANEL!$B$5) -> 158977.22 | I8: =IF(R8<>1,"",DATA_INPUT!C8) -> 103 | J8: =IF(R8<>1,"",(I8*F8)/1000) -> 458626.21 | K8: =IF(R8<>1,"",DATA_INPUT!H8) -> 17.517107 | L8: =IF(R8<>1,"",((K8*F8)/1000)) -> 77998.099 | M8: =IF(R8<>1,"",H8*CONTROL_PANEL!$B$14) -> 11128.405 | N8: =IF(R8<>1,"",DATA_INPUT!K8) -> 0 | O8: =IF(R8<>1,"",(E8+H8+J8)-(L8+N8+M8)) -> 39659872 | P8: =IF(R8<>1,"",IF(O8-CONTROL_PANEL!$B$11<0,0,O8-CONTROL_PANEL!$B$11)) -> 0 | Q8: =IF(R8<>1,"",IF(N8<=0,0,MIN(N8,MAX(0,CONTROL_PANEL!$B$13-O8)))) -> 0 | R8: 1 | T8: 2016 | U8: 1 | V8: =IF(AK8<>1,"",DAY(DATE(T8,U8+1,))) -> 31 | W8: =IF(AK7<>1,"",235+((X8/1000/2)^(1/3.02))) -> 261.36483 | X8: =IF(AK7<>1,"",IF(AH7>0,IF(AH7>CONTROL_PANEL!$B$11,CONTROL_PANEL!$B$11,AH7),0)) -> 39131395 | Y8: =IF(AK8<>1,"",0.6*(W8-235)^2.02*10000) -> 4452681.6 | Z8: =IF(AK8<>1,"",DATA_INPUT!I8) -> 1.6752078 | AA8: =IF(AK8<>1,"",Z8*CONTROL_PANEL!$B$5) -> 158977.22 | AB8: =IF(AK8<>1,"",DATA_INPUT!$C8) -> 103 | AC8: =IF(AK8<>1,"",(AB8*Y8)/1000) -> 458626.21 | AD8: =IF(AK8<>1,"",DATA_INPUT!$H8) -> 17.517107 | AE8: =IF(AK8<>1,"",((AD8*Y8)/1000)) -> 77998.099 | AF8: =IF(AK8<>1,"",AA8*CONTROL_PANEL!$B$14) -> 11128.405 | AG8: =IF(AK8<>1,"",DATA_INPUT!$L8) -> 0 | AH8: =IF(AK8<>1,"",(X8+AA8+AC8)-(AE8+AG8+AF8)) -> 39659872 | AI8: =IF(AK8<>1,"",IF(AH8-CONTROL_PANEL!$B$11<0,0,AH8-CONTROL_PANEL!$B$11)) -> 0 | AJ8: =IF(AK8<>1,"",IF(AG8<=0,0,MIN(AG8,MAX(0,CONTROL_PANEL!$B$13-AH8)))) -> 0 | AK8: 1 | AM8: 2016 | AN8: 1 | AO8: =IF(BD8<>1,"",DAY(DATE(AM8,AN8+1,))) -> 31 | AP8: =IF(BD7<>1,"",235+((AQ8/1000/2)^(1/3.02))) -> 261.36483 | AQ8: =IF(BD7<>1,"",IF(BA7>0,IF(BA7>CONTROL_PANEL!$B$11,CONTROL_PANEL!$B$11,BA7),0)) -> 39131395 | AR8: =IF(BD8<>1,"",0.6*(AP8-235)^2.02*10000) -> 4452681.6 | AS8: =IF(BD8<>1,"",DATA_INPUT!$I8) -> 1.6752078 | AT8: =IF(BD8<>1,"",AS8*CONTROL_PANEL!$B$5) -> 158977.22 | AU8: =IF(BD8<>1,"",DATA_INPUT!$C8) -> 103 | AV8: =IF(BD8<>1,"",(AU8*AR8)/1000) -> 458626.21 | AW8: =IF(BD8<>1,"",DATA_INPUT!$H8) -> 17.517107 | AX8: =IF(BD8<>1,"",((AW8*AR8)/1000)) -> 77998.099 | AY8: =IF(BD8<>1,"",AT8*CONTROL_PANEL!$B$14) -> 11128.405 | AZ8: =IF(BD8<>1,"",DATA_INPUT!$M8) -> 0 | BA8: =IF(BD8<>1,"",(AQ8+AT8+AV8)-(AX8+AZ8+AY8)) -> 39659872 | BB8: =IF(BD8<>1,"",IF(BA8-CONTROL_PANEL!$B$11<0,0,BA8-CONTROL_PANEL!$B$11)) -> 0 | BC8: =IF(BD8<>1,"",IF(AZ8<=0,0,MIN(AZ8,MAX(0,CONTROL_PANEL!$B$13-BA8)))) -> 0 | BD8: 1 | BF8: 2016 | BG8: 1 | BH8: =IF(BW8<>1,"",DAY(DATE(BF8,BG8+1,))) -> 31 | BI8: =IF(BW7<>1,"",235+((BJ8/1000/2)^(1/3.02))) -> 261.36483 | BJ8: =IF(BW7<>1,"",IF(BT7>0,IF(BT7>CONTROL_PANEL!$B$11,CONTROL_PANEL!$B$11,BT7),0)) -> 39131395 | BK8: =IF(BW8<>1,"",0.6*(BI8-235)^2.02*10000) -> 4452681.6 | BL8: =IF(BW8<>1,"",DATA_INPUT!$I8) -> 1.6752078 | BM8: =IF(BW8<>1,"",BL8*CONTROL_PANEL!$B$5) -> 158977.22 | BN8: =IF(BW8<>1,"",DATA_INPUT!$C8) -> 103 | BO8: =IF(BW8<>1,"",(BN8*BK8)/1000) -> 458626.21 | BP8: =IF(BW8<>1,"",DATA_INPUT!$H8) -> 17.517107 | BQ8: =IF(BW8<>1,"",((BP8*BK8)/1000)) -> 77998.099 | BR8: =IF(BW8<>1,"",BM8*CONTROL_PANEL!$B$14) -> 11128.405 | BS8: =IF(BW8<>1,"",DATA_INPUT!$N8) -> 0 | BT8: =IF(BW8<>1,"",(BJ8+BM8+BO8)-(BQ8+BS8+BR8)) -> 39659872 | BU8: =IF(BW8<>1,"",IF(BT8-CONTROL_PANEL!$B$11<0,0,BT8-CONTROL_PANEL!$B$11)) -> 0 | BV8: =IF(BW8<>1,"",IF(BS8<=0,0,MIN(BS8,MAX(0,CONTROL_PANEL!$B$13-BT8)))) -> 0 | BW8: 1 | BY8: 2016 | BZ8: 1 | CA8: =IF(CP8<>1,"",DAY(DATE(BY8,BZ8+1,))) -> 31 | CB8: =IF(CP7<>1,"",235+((CC8/1000/2)^(1/3.02))) -> 261.36483 | CC8: =IF(CP7<>1,"",IF(CM7>0,IF(CM7>CONTROL_PANEL!$B$11,CONTROL_PANEL!$B$11,CM7),0)) -> 39131395 | CD8: =IF(CP8<>1,"",0.6*(CB8-235)^2.02*10000) -> 4452681.6 | CE8: =IF(CP8<>1,"",DATA_INPUT!$I8) -> 1.6752078 | CF8: =IF(CP8<>1,"",CE8*CONTROL_PANEL!$B$5) -> 158977.22 | CG8: =IF(CP8<>1,"",DATA_INPUT!$C8) -> 103 | CH8: =IF(CP8<>1,"",(CG8*CD8)/1000) -> 458626.21 | CI8: =IF(CP8<>1,"",DATA_INPUT!$H8) -> 17.517107 | CJ8: =IF(CP8<>1,"",((CI8*CD8)/1000)) -> 77998.099 | CK8: =IF(CP8<>1,"",CF8*CONTROL_PANEL!$B$14) -> 11128.405 | CL8: =IF(CP8<>1,"",DATA_INPUT!$O8) -> 0 | CM8: =IF(CP8<>1,"",(CC8+CF8+CH8)-(CJ8+CL8+CK8)) -> 39659872 | CN8: =IF(CP8<>1,"",IF(CM8-CONTROL_PANEL!$B$11<0,0,CM8-CONTROL_PANEL!$B$11)) -> 0 | CO8: =IF(CP8<>1,"",IF(CL8<=0,0,MIN(CL8,MAX(0,CONTROL_PANEL!$B$13-CM8)))) -> 0 | CP8: 1
A9: 2016 | B9: 2 | C9: =IF(R9<>1,"",DAY(DATE(A9,B9+1,))) -> 29 | D9: =IF(R8<>1,"",235+((E9/1000/2)^(1/3.02))) -> 261.4822 | E9: =IF(R8<>1,"",IF(O8>0,IF(O8>CONTROL_PANEL!$B$11,CONTROL_PANEL!$B$11,O8),0)) -> 39659872 | F9: =IF(R9<>1,"",0.6*(D9-235)^2.02*10000) -> 4492814.5 | G9: =IF(R9<>1,"",DATA_INPUT!I9) -> 0.78460202 | H9: =IF(R9<>1,"",G9*CONTROL_PANEL!$B$5) -> 74458.732 | I9: =IF(R9<>1,"",DATA_INPUT!C9) -> 72 | J9: =IF(R9<>1,"",(I9*F9)/1000) -> 323482.64 | K9: =IF(R9<>1,"",DATA_INPUT!H9) -> 22.608353 | L9: =IF(R9<>1,"",((K9*F9)/1000)) -> 101575.14 | M9: =IF(R9<>1,"",H9*CONTROL_PANEL!$B$14) -> 5212.1112 | N9: =IF(R9<>1,"",DATA_INPUT!K9) -> 0 | O9: =IF(R9<>1,"",(E9+H9+J9)-(L9+N9+M9)) -> 39951026 | P9: =IF(R9<>1,"",IF(O9-CONTROL_PANEL!$B$11<0,0,O9-CONTROL_PANEL!$B$11)) -> 0 | Q9: =IF(R9<>1,"",IF(N9<=0,0,MIN(N9,MAX(0,CONTROL_PANEL!$B$13-O9)))) -> 0 | R9: 1 | T9: 2016 | U9: 2 | V9: =IF(AK9<>1,"",DAY(DATE(T9,U9+1,))) -> 29 | W9: =IF(AK8<>1,"",235+((X9/1000/2)^(1/3.02))) -> 261.4822 | X9: =IF(AK8<>1,"",IF(AH8>0,IF(AH8>CONTROL_PANEL!$B$11,CONTROL_PANEL!$B$11,AH8),0)) -> 39659872 | Y9: =IF(AK9<>1,"",0.6*(W9-235)^2.02*10000) -> 4492814.5 | Z9: =IF(AK9<>1,"",DATA_INPUT!I9) -> 0.78460202 | AA9: =IF(AK9<>1,"",Z9*CONTROL_PANEL!$B$5) -> 74458.732 | AB9: =IF(AK9<>1,"",DATA_INPUT!$C9) -> 72 | AC9: =IF(AK9<>1,"",(AB9*Y9)/1000) -> 323482.64 | AD9: =IF(AK9<>1,"",DATA_INPUT!$H9) -> 22.608353 | AE9: =IF(AK9<>1,"",((AD9*Y9)/1000)) -> 101575.14 | AF9: =IF(AK9<>1,"",AA9*CONTROL_PANEL!$B$14) -> 5212.1112 | AG9: =IF(AK9<>1,"",DATA_INPUT!$L9) -> 0 | AH9: =IF(AK9<>1,"",(X9+AA9+AC9)-(AE9+AG9+AF9)) -> 39951026 | AI9: =IF(AK9<>1,"",IF(AH9-CONTROL_PANEL!$B$11<0,0,AH9-CONTROL_PANEL!$B$11)) -> 0 | AJ9: =IF(AK9<>1,"",IF(AG9<=0,0,MIN(AG9,MAX(0,CONTROL_PANEL!$B$13-AH9)))) -> 0 | AK9: 1 | AM9: 2016 | AN9: 2 | AO9: =IF(BD9<>1,"",DAY(DATE(AM9,AN9+1,))) -> 29 | AP9: =IF(BD8<>1,"",235+((AQ9/1000/2)^(1/3.02))) -> 261.4822 | AQ9: =IF(BD8<>1,"",IF(BA8>0,IF(BA8>CONTROL_PANEL!$B$11,CONTROL_PANEL!$B$11,BA8),0)) -> 39659872 | AR9: =IF(BD9<>1,"",0.6*(AP9-235)^2.02*10000) -> 4492814.5 | AS9: =IF(BD9<>1,"",DATA_INPUT!$I9) -> 0.78460202 | AT9: =IF(BD9<>1,"",AS9*CONTROL_PANEL!$B$5) -> 74458.732 | AU9: =IF(BD9<>1,"",DATA_INPUT!$C9) -> 72 | AV9: =IF(BD9<>1,"",(AU9*AR9)/1000) -> 323482.64 | AW9: =IF(BD9<>1,"",DATA_INPUT!$H9) -> 22.608353 | AX9: =IF(BD9<>1,"",((AW9*AR9)/1000)) -> 101575.14 | AY9: =IF(BD9<>1,"",AT9*CONTROL_PANEL!$B$14) -> 5212.1112 | AZ9: =IF(BD9<>1,"",DATA_INPUT!$M9) -> 0 | BA9: =IF(BD9<>1,"",(AQ9+AT9+AV9)-(AX9+AZ9+AY9)) -> 39951026 | BB9: =IF(BD9<>1,"",IF(BA9-CONTROL_PANEL!$B$11<0,0,BA9-CONTROL_PANEL!$B$11)) -> 0 | BC9: =IF(BD9<>1,"",IF(AZ9<=0,0,MIN(AZ9,MAX(0,CONTROL_PANEL!$B$13-BA9)))) -> 0 | BD9: 1 | BF9: 2016 | BG9: 2 | BH9: =IF(BW9<>1,"",DAY(DATE(BF9,BG9+1,))) -> 29 | BI9: =IF(BW8<>1,"",235+((BJ9/1000/2)^(1/3.02))) -> 261.4822 | BJ9: =IF(BW8<>1,"",IF(BT8>0,IF(BT8>CONTROL_PANEL!$B$11,CONTROL_PANEL!$B$11,BT8),0)) -> 39659872 | BK9: =IF(BW9<>1,"",0.6*(BI9-235)^2.02*10000) -> 4492814.5 | BL9: =IF(BW9<>1,"",DATA_INPUT!$I9) -> 0.78460202 | BM9: =IF(BW9<>1,"",BL9*CONTROL_PANEL!$B$5) -> 74458.732 | BN9: =IF(BW9<>1,"",DATA_INPUT!$C9) -> 72 | BO9: =IF(BW9<>1,"",(BN9*BK9)/1000) -> 323482.64 | BP9: =IF(BW9<>1,"",DATA_INPUT!$H9) -> 22.608353 | BQ9: =IF(BW9<>1,"",((BP9*BK9)/1000)) -> 101575.14 | BR9: =IF(BW9<>1,"",BM9*CONTROL_PANEL!$B$14) -> 5212.1112 | BS9: =IF(BW9<>1,"",DATA_INPUT!$N9) -> 0 | BT9: =IF(BW9<>1,"",(BJ9+BM9+BO9)-(BQ9+BS9+BR9)) -> 39951026 | BU9: =IF(BW9<>1,"",IF(BT9-CONTROL_PANEL!$B$11<0,0,BT9-CONTROL_PANEL!$B$11)) -> 0 | BV9: =IF(BW9<>1,"",IF(BS9<=0,0,MIN(BS9,MAX(0,CONTROL_PANEL!$B$13-BT9)))) -> 0 | BW9: 1 | BY9: 2016 | BZ9: 2 | CA9: =IF(CP9<>1,"",DAY(DATE(BY9,BZ9+1,))) -> 29 | CB9: =IF(CP8<>1,"",235+((CC9/1000/2)^(1/3.02))) -> 261.4822 | CC9: =IF(CP8<>1,"",IF(CM8>0,IF(CM8>CONTROL_PANEL!$B$11,CONTROL_PANEL!$B$11,CM8),0)) -> 39659872 | CD9: =IF(CP9<>1,"",0.6*(CB9-235)^2.02*10000) -> 4492814.5 | CE9: =IF(CP9<>1,"",DATA_INPUT!$I9) -> 0.78460202 | CF9: =IF(CP9<>1,"",CE9*CONTROL_PANEL!$B$5) -> 74458.732 | CG9: =IF(CP9<>1,"",DATA_INPUT!$C9) -> 72 | CH9: =IF(CP9<>1,"",(CG9*CD9)/1000) -> 323482.64 | CI9: =IF(CP9<>1,"",DATA_INPUT!$H9) -> 22.608353 | CJ9: =IF(CP9<>1,"",((CI9*CD9)/1000)) -> 101575.14 | CK9: =IF(CP9<>1,"",CF9*CONTROL_PANEL!$B$14) -> 5212.1112 | CL9: =IF(CP9<>1,"",DATA_INPUT!$O9) -> 0 | CM9: =IF(CP9<>1,"",(CC9+CF9+CH9)-(CJ9+CL9+CK9)) -> 39951026 | CN9: =IF(CP9<>1,"",IF(CM9-CONTROL_PANEL!$B$11<0,0,CM9-CONTROL_PANEL!$B$11)) -> 0 | CO9: =IF(CP9<>1,"",IF(CL9<=0,0,MIN(CL9,MAX(0,CONTROL_PANEL!$B$13-CM9)))) -> 0 | CP9: 1
A10: 2016 | B10: 3 | C10: =IF(R10<>1,"",DAY(DATE(A10,B10+1,))) -> 31 | D10: =IF(R9<>1,"",235+((E10/1000/2)^(1/3.02))) -> 261.54642 | E10: =IF(R9<>1,"",IF(O9>0,IF(O9>CONTROL_PANEL!$B$11,CONTROL_PANEL!$B$11,O9),0)) -> 39951026 | F10: =IF(R10<>1,"",0.6*(D10-235)^2.02*10000) -> 4514849.2 | G10: =IF(R10<>1,"",DATA_INPUT!I10) -> 5.8924163 | H10: =IF(R10<>1,"",G10*CONTROL_PANEL!$B$5) -> 559190.31 | I10: =IF(R10<>1,"",DATA_INPUT!C10) -> 29 | J10: =IF(R10<>1,"",(I10*F10)/1000) -> 130930.63 | K10: =IF(R10<>1,"",DATA_INPUT!H10) -> 38.783253 | L10: =IF(R10<>1,"",((K10*F10)/1000)) -> 175100.54 | M10: =IF(R10<>1,"",H10*CONTROL_PANEL!$B$14) -> 39143.322 | N10: =IF(R10<>1,"",DATA_INPUT!K10) -> 0 | O10: =IF(R10<>1,"",(E10+H10+J10)-(L10+N10+M10)) -> 40426903 | P10: =IF(R10<>1,"",IF(O10-CONTROL_PANEL!$B$11<0,0,O10-CONTROL_PANEL!$B$11)) -> 0 | Q10: =IF(R10<>1,"",IF(N10<=0,0,MIN(N10,MAX(0,CONTROL_PANEL!$B$13-O10)))) -> 0 | R10: 1 | T10: 2016 | U10: 3 | V10: =IF(AK10<>1,"",DAY(DATE(T10,U10+1,))) -> 31 | W10: =IF(AK9<>1,"",235+((X10/1000/2)^(1/3.02))) -> 261.54642 | X10: =IF(AK9<>1,"",IF(AH9>0,IF(AH9>CONTROL_PANEL!$B$11,CONTROL_PANEL!$B$11,AH9),0)) -> 39951026 | Y10: =IF(AK10<>1,"",0.6*(W10-235)^2.02*10000) -> 4514849.2 | Z10: =IF(AK10<>1,"",DATA_INPUT!I10) -> 5.8924163 | AA10: =IF(AK10<>1,"",Z10*CONTROL_PANEL!$B$5) -> 559190.31 | AB10: =IF(AK10<>1,"",DATA_INPUT!$C10) -> 29 | AC10: =IF(AK10<>1,"",(AB10*Y10)/1000) -> 130930.63 | AD10: =IF(AK10<>1,"",DATA_INPUT!$H10) -> 38.783253 | AE10: =IF(AK10<>1,"",((AD10*Y10)/1000)) -> 175100.54 | AF10: =IF(AK10<>1,"",AA10*CONTROL_PANEL!$B$14) -> 39143.322 | AG10: =IF(AK10<>1,"",DATA_INPUT!$L10) -> 0 | AH10: =IF(AK10<>1,"",(X10+AA10+AC10)-(AE10+AG10+AF10)) -> 40426903 | AI10: =IF(AK10<>1,"",IF(AH10-CONTROL_PANEL!$B$11<0,0,AH10-CONTROL_PANEL!$B$11)) -> 0 | AJ10: =IF(AK10<>1,"",IF(AG10<=0,0,MIN(AG10,MAX(0,CONTROL_PANEL!$B$13-AH10)))) -> 0 | AK10: 1 | AM10: 2016 | AN10: 3 | AO10: =IF(BD10<>1,"",DAY(DATE(AM10,AN10+1,))) -> 31 | AP10: =IF(BD9<>1,"",235+((AQ10/1000/2)^(1/3.02))) -> 261.54642 | AQ10: =IF(BD9<>1,"",IF(BA9>0,IF(BA9>CONTROL_PANEL!$B$11,CONTROL_PANEL!$B$11,BA9),0)) -> 39951026 | AR10: =IF(BD10<>1,"",0.6*(AP10-235)^2.02*10000) -> 4514849.2 | AS10: =IF(BD10<>1,"",DATA_INPUT!$I10) -> 5.8924163 | AT10: =IF(BD10<>1,"",AS10*CONTROL_PANEL!$B$5) -> 559190.31 | AU10: =IF(BD10<>1,"",DATA_INPUT!$C10) -> 29 | AV10: =IF(BD10<>1,"",(AU10*AR10)/1000) -> 130930.63 | AW10: =IF(BD10<>1,"",DATA_INPUT!$H10) -> 38.783253 | AX10: =IF(BD10<>1,"",((AW10*AR10)/1000)) -> 175100.54 | AY10: =IF(BD10<>1,"",AT10*CONTROL_PANEL!$B$14) -> 39143.322 | AZ10: =IF(BD10<>1,"",DATA_INPUT!$M10) -> 0 | BA10: =IF(BD10<>1,"",(AQ10+AT10+AV10)-(AX10+AZ10+AY10)) -> 40426903 | BB10: =IF(BD10<>1,"",IF(BA10-CONTROL_PANEL!$B$11<0,0,BA10-CONTROL_PANEL!$B$11)) -> 0 | BC10: =IF(BD10<>1,"",IF(AZ10<=0,0,MIN(AZ10,MAX(0,CONTROL_PANEL!$B$13-BA10)))) -> 0 | BD10: 1 | BF10: 2016 | BG10: 3 | BH10: =IF(BW10<>1,"",DAY(DATE(BF10,BG10+1,))) -> 31 | BI10: =IF(BW9<>1,"",235+((BJ10/1000/2)^(1/3.02))) -> 261.54642 | BJ10: =IF(BW9<>1,"",IF(BT9>0,IF(BT9>CONTROL_PANEL!$B$11,CONTROL_PANEL!$B$11,BT9),0)) -> 39951026 | BK10: =IF(BW10<>1,"",0.6*(BI10-235)^2.02*10000) -> 4514849.2 | BL10: =IF(BW10<>1,"",DATA_INPUT!$I10) -> 5.8924163 | BM10: =IF(BW10<>1,"",BL10*CONTROL_PANEL!$B$5) -> 559190.31 | BN10: =IF(BW10<>1,"",DATA_INPUT!$C10) -> 29 | BO10: =IF(BW10<>1,"",(BN10*BK10)/1000) -> 130930.63 | BP10: =IF(BW10<>1,"",DATA_INPUT!$H10) -> 38.783253 | BQ10: =IF(BW10<>1,"",((BP10*BK10)/1000)) -> 175100.54 | BR10: =IF(BW10<>1,"",BM10*CONTROL_PANEL!$B$14) -> 39143.322 | BS10: =IF(BW10<>1,"",DATA_INPUT!$N10) -> 0 | BT10: =IF(BW10<>1,"",(BJ10+BM10+BO10)-(BQ10+BS10+BR10)) -> 40426903 | BU10: =IF(BW10<>1,"",IF(BT10-CONTROL_PANEL!$B$11<0,0,BT10-CONTROL_PANEL!$B$11)) -> 0 | BV10: =IF(BW10<>1,"",IF(BS10<=0,0,MIN(BS10,MAX(0,CONTROL_PANEL!$B$13-BT10)))) -> 0 | BW10: 1 | BY10: 2016 | BZ10: 3 | CA10: =IF(CP10<>1,"",DAY(DATE(BY10,BZ10+1,))) -> 31 | CB10: =IF(CP9<>1,"",235+((CC10/1000/2)^(1/3.02))) -> 261.54642 | CC10: =IF(CP9<>1,"",IF(CM9>0,IF(CM9>CONTROL_PANEL!$B$11,CONTROL_PANEL!$B$11,CM9),0)) -> 39951026 | CD10: =IF(CP10<>1,"",0.6*(CB10-235)^2.02*10000) -> 4514849.2 | CE10: =IF(CP10<>1,"",DATA_INPUT!$I10) -> 5.8924163 | CF10: =IF(CP10<>1,"",CE10*CONTROL_PANEL!$B$5) -> 559190.31 | CG10: =IF(CP10<>1,"",DATA_INPUT!$C10) -> 29 | CH10: =IF(CP10<>1,"",(CG10*CD10)/1000) -> 130930.63 | CI10: =IF(CP10<>1,"",DATA_INPUT!$H10) -> 38.783253 | CJ10: =IF(CP10<>1,"",((CI10*CD10)/1000)) -> 175100.54 | CK10: =IF(CP10<>1,"",CF10*CONTROL_PANEL!$B$14) -> 39143.322 | CL10: =IF(CP10<>1,"",DATA_INPUT!$O10) -> 0 | CM10: =IF(CP10<>1,"",(CC10+CF10+CH10)-(CJ10+CL10+CK10)) -> 40426903 | CN10: =IF(CP10<>1,"",IF(CM10-CONTROL_PANEL!$B$11<0,0,CM10-CONTROL_PANEL!$B$11)) -> 0 | CO10: =IF(CP10<>1,"",IF(CL10<=0,0,MIN(CL10,MAX(0,CONTROL_PANEL!$B$13-CM10)))) -> 0 | CP10: 1
A11: 2016 | B11: 4 | C11: =IF(R11<>1,"",DAY(DATE(A11,B11+1,))) -> 30 | D11: =IF(R10<>1,"",235+((E11/1000/2)^(1/3.02))) -> 261.65071 | E11: =IF(R10<>1,"",IF(O10>0,IF(O10>CONTROL_PANEL!$B$11,CONTROL_PANEL!$B$11,O10),0)) -> 40426903 | F11: =IF(R11<>1,"",0.6*(D11-235)^2.02*10000) -> 4550749.8 | G11: =IF(R11<>1,"",DATA_INPUT!I11) -> 8.0845783 | H11: =IF(R11<>1,"",G11*CONTROL_PANEL!$B$5) -> 767226.48 | I11: =IF(R11<>1,"",DATA_INPUT!C11) -> 110 | J11: =IF(R11<>1,"",(I11*F11)/1000) -> 500582.48 | K11: =IF(R11<>1,"",DATA_INPUT!H11) -> 68.133038 | L11: =IF(R11<>1,"",((K11*F11)/1000)) -> 310056.41 | M11: =IF(R11<>1,"",H11*CONTROL_PANEL!$B$14) -> 53705.854 | N11: =IF(R11<>1,"",DATA_INPUT!K11) -> 25674.231 | O11: =IF(R11<>1,"",(E11+H11+J11)-(L11+N11+M11)) -> 41305276 | P11: =IF(R11<>1,"",IF(O11-CONTROL_PANEL!$B$11<0,0,O11-CONTROL_PANEL!$B$11)) -> 0 | Q11: =IF(R11<>1,"",IF(N11<=0,0,MIN(N11,MAX(0,CONTROL_PANEL!$B$13-O11)))) -> 0 | R11: 1 | T11: 2016 | U11: 4 | V11: =IF(AK11<>1,"",DAY(DATE(T11,U11+1,))) -> 30 | W11: =IF(AK10<>1,"",235+((X11/1000/2)^(1/3.02))) -> 261.65071 | X11: =IF(AK10<>1,"",IF(AH10>0,IF(AH10>CONTROL_PANEL!$B$11,CONTROL_PANEL!$B$11,AH10),0)) -> 40426903 | Y11: =IF(AK11<>1,"",0.6*(W11-235)^2.02*10000) -> 4550749.8 | Z11: =IF(AK11<>1,"",DATA_INPUT!I11) -> 8.0845783 | AA11: =IF(AK11<>1,"",Z11*CONTROL_PANEL!$B$5) -> 767226.48 | AB11: =IF(AK11<>1,"",DATA_INPUT!$C11) -> 110 | AC11: =IF(AK11<>1,"",(AB11*Y11)/1000) -> 500582.48 | AD11: =IF(AK11<>1,"",DATA_INPUT!$H11) -> 68.133038 | AE11: =IF(AK11<>1,"",((AD11*Y11)/1000)) -> 310056.41 | AF11: =IF(AK11<>1,"",AA11*CONTROL_PANEL!$B$14) -> 53705.854 | AG11: =IF(AK11<>1,"",DATA_INPUT!$L11) -> 32339.153 | AH11: =IF(AK11<>1,"",(X11+AA11+AC11)-(AE11+AG11+AF11)) -> 41298611 | AI11: =IF(AK11<>1,"",IF(AH11-CONTROL_PANEL!$B$11<0,0,AH11-CONTROL_PANEL!$B$11)) -> 0 | AJ11: =IF(AK11<>1,"",IF(AG11<=0,0,MIN(AG11,MAX(0,CONTROL_PANEL!$B$13-AH11)))) -> 0 | AK11: 1 | AM11: 2016 | AN11: 4 | AO11: =IF(BD11<>1,"",DAY(DATE(AM11,AN11+1,))) -> 30 | AP11: =IF(BD10<>1,"",235+((AQ11/1000/2)^(1/3.02))) -> 261.65071 | AQ11: =IF(BD10<>1,"",IF(BA10>0,IF(BA10>CONTROL_PANEL!$B$11,CONTROL_PANEL!$B$11,BA10),0)) -> 40426903 | AR11: =IF(BD11<>1,"",0.6*(AP11-235)^2.02*10000) -> 4550749.8 | AS11: =IF(BD11<>1,"",DATA_INPUT!$I11) -> 8.0845783 | AT11: =IF(BD11<>1,"",AS11*CONTROL_PANEL!$B$5) -> 767226.48 | AU11: =IF(BD11<>1,"",DATA_INPUT!$C11) -> 110 | AV11: =IF(BD11<>1,"",(AU11*AR11)/1000) -> 500582.48 | AW11: =IF(BD11<>1,"",DATA_INPUT!$H11) -> 68.133038 | AX11: =IF(BD11<>1,"",((AW11*AR11)/1000)) -> 310056.41 | AY11: =IF(BD11<>1,"",AT11*CONTROL_PANEL!$B$14) -> 53705.854 | AZ11: =IF(BD11<>1,"",DATA_INPUT!$M11) -> 21896.076 | BA11: =IF(BD11<>1,"",(AQ11+AT11+AV11)-(AX11+AZ11+AY11)) -> 41309054 | BB11: =IF(BD11<>1,"",IF(BA11-CONTROL_PANEL!$B$11<0,0,BA11-CONTROL_PANEL!$B$11)) -> 0 | BC11: =IF(BD11<>1,"",IF(AZ11<=0,0,MIN(AZ11,MAX(0,CONTROL_PANEL!$B$13-BA11)))) -> 0 | BD11: 1 | BF11: 2016 | BG11: 4 | BH11: =IF(BW11<>1,"",DAY(DATE(BF11,BG11+1,))) -> 30 | BI11: =IF(BW10<>1,"",235+((BJ11/1000/2)^(1/3.02))) -> 261.65071 | BJ11: =IF(BW10<>1,"",IF(BT10>0,IF(BT10>CONTROL_PANEL!$B$11,CONTROL_PANEL!$B$11,BT10),0)) -> 40426903 | BK11: =IF(BW11<>1,"",0.6*(BI11-235)^2.02*10000) -> 4550749.8 | BL11: =IF(BW11<>1,"",DATA_INPUT!$I11) -> 8.0845783 | BM11: =IF(BW11<>1,"",BL11*CONTROL_PANEL!$B$5) -> 767226.48 | BN11: =IF(BW11<>1,"",DATA_INPUT!$C11) -> 110 | BO11: =IF(BW11<>1,"",(BN11*BK11)/1000) -> 500582.48 | BP11: =IF(BW11<>1,"",DATA_INPUT!$H11) -> 68.133038 | BQ11: =IF(BW11<>1,"",((BP11*BK11)/1000)) -> 310056.41 | BR11: =IF(BW11<>1,"",BM11*CONTROL_PANEL!$B$14) -> 53705.854 | BS11: =IF(BW11<>1,"",DATA_INPUT!$N11) -> 13785.315 | BT11: =IF(BW11<>1,"",(BJ11+BM11+BO11)-(BQ11+BS11+BR11)) -> 41317165 | BU11: =IF(BW11<>1,"",IF(BT11-CONTROL_PANEL!$B$11<0,0,BT11-CONTROL_PANEL!$B$11)) -> 0 | BV11: =IF(BW11<>1,"",IF(BS11<=0,0,MIN(BS11,MAX(0,CONTROL_PANEL!$B$13-BT11)))) -> 0 | BW11: 1 | BY11: 2016 | BZ11: 4 | CA11: =IF(CP11<>1,"",DAY(DATE(BY11,BZ11+1,))) -> 30 | CB11: =IF(CP10<>1,"",235+((CC11/1000/2)^(1/3.02))) -> 261.65071 | CC11: =IF(CP10<>1,"",IF(CM10>0,IF(CM10>CONTROL_PANEL!$B$11,CONTROL_PANEL!$B$11,CM10),0)) -> 40426903 | CD11: =IF(CP11<>1,"",0.6*(CB11-235)^2.02*10000) -> 4550749.8 | CE11: =IF(CP11<>1,"",DATA_INPUT!$I11) -> 8.0845783 | CF11: =IF(CP11<>1,"",CE11*CONTROL_PANEL!$B$5) -> 767226.48 | CG11: =IF(CP11<>1,"",DATA_INPUT!$C11) -> 110 | CH11: =IF(CP11<>1,"",(CG11*CD11)/1000) -> 500582.48 | CI11: =IF(CP11<>1,"",DATA_INPUT!$H11) -> 68.133038 | CJ11: =IF(CP11<>1,"",((CI11*CD11)/1000)) -> 310056.41 | CK11: =IF(CP11<>1,"",CF11*CONTROL_PANEL!$B$14) -> 53705.854 | CL11: =IF(CP11<>1,"",DATA_INPUT!$O11) -> 15785.605 | CM11: =IF(CP11<>1,"",(CC11+CF11+CH11)-(CJ11+CL11+CK11)) -> 41315165 | CN11: =IF(CP11<>1,"",IF(CM11-CONTROL_PANEL!$B$11<0,0,CM11-CONTROL_PANEL!$B$11)) -> 0 | CO11: =IF(CP11<>1,"",IF(CL11<=0,0,MIN(CL11,MAX(0,CONTROL_PANEL!$B$13-CM11)))) -> 0 | CP11: 1
A12: 2016 | B12: 5 | C12: =IF(R12<>1,"",DAY(DATE(A12,B12+1,))) -> 31 | D12: =IF(R11<>1,"",235+((E12/1000/2)^(1/3.02))) -> 261.84107 | E12: =IF(R11<>1,"",IF(O11>0,IF(O11>CONTROL_PANEL!$B$11,CONTROL_PANEL!$B$11,O11),0)) -> 41305276 | F12: =IF(R12<>1,"",0.6*(D12-235)^2.02*10000) -> 4616649.9 | G12: =IF(R12<>1,"",DATA_INPUT!I12) -> 2.7629512 | H12: =IF(R12<>1,"",G12*CONTROL_PANEL!$B$5) -> 262204.07 | I12: =IF(R12<>1,"",DATA_INPUT!C12) -> 110 | J12: =IF(R12<>1,"",(I12*F12)/1000) -> 507831.48 | K12: =IF(R12<>1,"",DATA_INPUT!H12) -> 83.602588 | L12: =IF(R12<>1,"",((K12*F12)/1000)) -> 385963.87 | M12: =IF(R12<>1,"",H12*CONTROL_PANEL!$B$14) -> 18354.285 | N12: =IF(R12<>1,"",DATA_INPUT!K12) -> 90918.576 | O12: =IF(R12<>1,"",(E12+H12+J12)-(L12+N12+M12)) -> 41580075 | P12: =IF(R12<>1,"",IF(O12-CONTROL_PANEL!$B$11<0,0,O12-CONTROL_PANEL!$B$11)) -> 0 | Q12: =IF(R12<>1,"",IF(N12<=0,0,MIN(N12,MAX(0,CONTROL_PANEL!$B$13-O12)))) -> 0 | R12: 1 | T12: 2016 | U12: 5 | V12: =IF(AK12<>1,"",DAY(DATE(T12,U12+1,))) -> 31 | W12: =IF(AK11<>1,"",235+((X12/1000/2)^(1/3.02))) -> 261.83964 | X12: =IF(AK11<>1,"",IF(AH11>0,IF(AH11>CONTROL_PANEL!$B$11,CONTROL_PANEL!$B$11,AH11),0)) -> 41298611 | Y12: =IF(AK12<>1,"",0.6*(W12-235)^2.02*10000) -> 4616151.6 | Z12: =IF(AK12<>1,"",DATA_INPUT!I12) -> 2.7629512 | AA12: =IF(AK12<>1,"",Z12*CONTROL_PANEL!$B$5) -> 262204.07 | AB12: =IF(AK12<>1,"",DATA_INPUT!$C12) -> 110 | AC12: =IF(AK12<>1,"",(AB12*Y12)/1000) -> 507776.67 | AD12: =IF(AK12<>1,"",DATA_INPUT!$H12) -> 83.602588 | AE12: =IF(AK12<>1,"",((AD12*Y12)/1000)) -> 385922.22 | AF12: =IF(AK12<>1,"",AA12*CONTROL_PANEL!$B$14) -> 18354.285 | AG12: =IF(AK12<>1,"",DATA_INPUT!$L12) -> 115730.36 | AH12: =IF(AK12<>1,"",(X12+AA12+AC12)-(AE12+AG12+AF12)) -> 41548585 | AI12: =IF(AK12<>1,"",IF(AH12-CONTROL_PANEL!$B$11<0,0,AH12-CONTROL_PANEL!$B$11)) -> 0 | AJ12: =IF(AK12<>1,"",IF(AG12<=0,0,MIN(AG12,MAX(0,CONTROL_PANEL!$B$13-AH12)))) -> 0 | AK12: 1 | AM12: 2016 | AN12: 5 | AO12: =IF(BD12<>1,"",DAY(DATE(AM12,AN12+1,))) -> 31 | AP12: =IF(BD11<>1,"",235+((AQ12/1000/2)^(1/3.02))) -> 261.84188 | AQ12: =IF(BD11<>1,"",IF(BA11>0,IF(BA11>CONTROL_PANEL!$B$11,CONTROL_PANEL!$B$11,BA11),0)) -> 41309054 | AR12: =IF(BD12<>1,"",0.6*(AP12-235)^2.02*10000) -> 4616932.3 | AS12: =IF(BD12<>1,"",DATA_INPUT!$I12) -> 2.7629512 | AT12: =IF(BD12<>1,"",AS12*CONTROL_PANEL!$B$5) -> 262204.07 | AU12: =IF(BD12<>1,"",DATA_INPUT!$C12) -> 110 | AV12: =IF(BD12<>1,"",(AU12*AR12)/1000) -> 507862.55 | AW12: =IF(BD12<>1,"",DATA_INPUT!$H12) -> 83.602588 | AX12: =IF(BD12<>1,"",((AW12*AR12)/1000)) -> 385987.49 | AY12: =IF(BD12<>1,"",AT12*CONTROL_PANEL!$B$14) -> 18354.285 | AZ12: =IF(BD12<>1,"",DATA_INPUT!$M12) -> 66127.399 | BA12: =IF(BD12<>1,"",(AQ12+AT12+AV12)-(AX12+AZ12+AY12)) -> 41608652 | BB12: =IF(BD12<>1,"",IF(BA12-CONTROL_PANEL!$B$11<0,0,BA12-CONTROL_PANEL!$B$11)) -> 0 | BC12: =IF(BD12<>1,"",IF(AZ12<=0,0,MIN(AZ12,MAX(0,CONTROL_PANEL!$B$13-BA12)))) -> 0 | BD12: 1 | BF12: 2016 | BG12: 5 | BH12: =IF(BW12<>1,"",DAY(DATE(BF12,BG12+1,))) -> 31 | BI12: =IF(BW11<>1,"",235+((BJ12/1000/2)^(1/3.02))) -> 261.84363 | BJ12: =IF(BW11<>1,"",IF(BT11>0,IF(BT11>CONTROL_PANEL!$B$11,CONTROL_PANEL!$B$11,BT11),0)) -> 41317165 | BK12: =IF(BW12<>1,"",0.6*(BI12-235)^2.02*10000) -> 4617538.6 | BL12: =IF(BW12<>1,"",DATA_INPUT!$I12) -> 2.7629512 | BM12: =IF(BW12<>1,"",BL12*CONTROL_PANEL!$B$5) -> 262204.07 | BN12: =IF(BW12<>1,"",DATA_INPUT!$C12) -> 110 | BO12: =IF(BW12<>1,"",(BN12*BK12)/1000) -> 507929.25 | BP12: =IF(BW12<>1,"",DATA_INPUT!$H12) -> 83.602588 | BQ12: =IF(BW12<>1,"",((BP12*BK12)/1000)) -> 386038.18 | BR12: =IF(BW12<>1,"",BM12*CONTROL_PANEL!$B$14) -> 18354.285 | BS12: =IF(BW12<>1,"",DATA_INPUT!$N12) -> 27068.123 | BT12: =IF(BW12<>1,"",(BJ12+BM12+BO12)-(BQ12+BS12+BR12)) -> 41655838 | BU12: =IF(BW12<>1,"",IF(BT12-CONTROL_PANEL!$B$11<0,0,BT12-CONTROL_PANEL!$B$11)) -> 0 | BV12: =IF(BW12<>1,"",IF(BS12<=0,0,MIN(BS12,MAX(0,CONTROL_PANEL!$B$13-BT12)))) -> 0 | BW12: 1 | BY12: 2016 | BZ12: 5 | CA12: =IF(CP12<>1,"",DAY(DATE(BY12,BZ12+1,))) -> 31 | CB12: =IF(CP11<>1,"",235+((CC12/1000/2)^(1/3.02))) -> 261.8432 | CC12: =IF(CP11<>1,"",IF(CM11>0,IF(CM11>CONTROL_PANEL!$B$11,CONTROL_PANEL!$B$11,CM11),0)) -> 41315165 | CD12: =IF(CP12<>1,"",0.6*(CB12-235)^2.02*10000) -> 4617389.1 | CE12: =IF(CP12<>1,"",DATA_INPUT!$I12) -> 2.7629512 | CF12: =IF(CP12<>1,"",CE12*CONTROL_PANEL!$B$5) -> 262204.07 | CG12: =IF(CP12<>1,"",DATA_INPUT!$C12) -> 110 | CH12: =IF(CP12<>1,"",(CG12*CD12)/1000) -> 507912.8 | CI12: =IF(CP12<>1,"",DATA_INPUT!$H12) -> 83.602588 | CJ12: =IF(CP12<>1,"",((CI12*CD12)/1000)) -> 386025.68 | CK12: =IF(CP12<>1,"",CF12*CONTROL_PANEL!$B$14) -> 18354.285 | CL12: =IF(CP12<>1,"",DATA_INPUT!$O12) -> 30792.539 | CM12: =IF(CP12<>1,"",(CC12+CF12+CH12)-(CJ12+CL12+CK12)) -> 41650109 | CN12: =IF(CP12<>1,"",IF(CM12-CONTROL_PANEL!$B$11<0,0,CM12-CONTROL_PANEL!$B$11)) -> 0 | CO12: =IF(CP12<>1,"",IF(CL12<=0,0,MIN(CL12,MAX(0,CONTROL_PANEL!$B$13-CM12)))) -> 0 | CP12: 1
A13: 2016 | B13: 6 | C13: =IF(R13<>1,"",DAY(DATE(A13,B13+1,))) -> 30 | D13: =IF(R12<>1,"",235+((E13/1000/2)^(1/3.02))) -> 261.90007 | E13: =IF(R12<>1,"",IF(O12>0,IF(O12>CONTROL_PANEL!$B$11,CONTROL_PANEL!$B$11,O12),0)) -> 41580075 | F13: =IF(R13<>1,"",0.6*(D13-235)^2.02*10000) -> 4637171.1 | G13: =IF(R13<>1,"",DATA_INPUT!I13) -> 0.41207547 | H13: =IF(R13<>1,"",G13*CONTROL_PANEL!$B$5) -> 39105.962 | I13: =IF(R13<>1,"",DATA_INPUT!C13) -> 0.22064 | J13: =IF(R13<>1,"",(I13*F13)/1000) -> 1023.1454 | K13: =IF(R13<>1,"",DATA_INPUT!H13) -> 165.76647 | L13: =IF(R13<>1,"",((K13*F13)/1000)) -> 768687.47 | M13: =IF(R13<>1,"",H13*CONTROL_PANEL!$B$14) -> 2737.4173 | N13: =IF(R13<>1,"",DATA_INPUT!K13) -> 883210.26 | O13: =IF(R13<>1,"",(E13+H13+J13)-(L13+N13+M13)) -> 39965569 | P13: =IF(R13<>1,"",IF(O13-CONTROL_PANEL!$B$11<0,0,O13-CONTROL_PANEL!$B$11)) -> 0 | Q13: =IF(R13<>1,"",IF(N13<=0,0,MIN(N13,MAX(0,CONTROL_PANEL!$B$13-O13)))) -> 0 | R13: 1 | T13: 2016 | U13: 6 | V13: =IF(AK13<>1,"",DAY(DATE(T13,U13+1,))) -> 30 | W13: =IF(AK12<>1,"",235+((X13/1000/2)^(1/3.02))) -> 261.89332 | X13: =IF(AK12<>1,"",IF(AH12>0,IF(AH12>CONTROL_PANEL!$B$11,CONTROL_PANEL!$B$11,AH12),0)) -> 41548585 | Y13: =IF(AK13<>1,"",0.6*(W13-235)^2.02*10000) -> 4634821.8 | Z13: =IF(AK13<>1,"",DATA_INPUT!I13) -> 0.41207547 | AA13: =IF(AK13<>1,"",Z13*CONTROL_PANEL!$B$5) -> 39105.962 | AB13: =IF(AK13<>1,"",DATA_INPUT!$C13) -> 0.22064 | AC13: =IF(AK13<>1,"",(AB13*Y13)/1000) -> 1022.6271 | AD13: =IF(AK13<>1,"",DATA_INPUT!$H13) -> 165.76647 | AE13: =IF(AK13<>1,"",((AD13*Y13)/1000)) -> 768298.03 | AF13: =IF(AK13<>1,"",AA13*CONTROL_PANEL!$B$14) -> 2737.4173 | AG13: =IF(AK13<>1,"",DATA_INPUT!$L13) -> 1124425.4 | AH13: =IF(AK13<>1,"",(X13+AA13+AC13)-(AE13+AG13+AF13)) -> 39693253 | AI13: =IF(AK13<>1,"",IF(AH13-CONTROL_PANEL!$B$11<0,0,AH13-CONTROL_PANEL!$B$11)) -> 0 | AJ13: =IF(AK13<>1,"",IF(AG13<=0,0,MIN(AG13,MAX(0,CONTROL_PANEL!$B$13-AH13)))) -> 0 | AK13: 1 | AM13: 2016 | AN13: 6 | AO13: =IF(BD13<>1,"",DAY(DATE(AM13,AN13+1,))) -> 30 | AP13: =IF(BD12<>1,"",235+((AQ13/1000/2)^(1/3.02))) -> 261.90619 | AQ13: =IF(BD12<>1,"",IF(BA12>0,IF(BA12>CONTROL_PANEL!$B$11,CONTROL_PANEL!$B$11,BA12),0)) -> 41608652 | AR13: =IF(BD13<>1,"",0.6*(AP13-235)^2.02*10000) -> 4639302.5 | AS13: =IF(BD13<>1,"",DATA_INPUT!$I13) -> 0.41207547 | AT13: =IF(BD13<>1,"",AS13*CONTROL_PANEL!$B$5) -> 39105.962 | AU13: =IF(BD13<>1,"",DATA_INPUT!$C13) -> 0.22064 | AV13: =IF(BD13<>1,"",(AU13*AR13)/1000) -> 1023.6157 | AW13: =IF(BD13<>1,"",DATA_INPUT!$H13) -> 165.76647 | AX13: =IF(BD13<>1,"",((AW13*AR13)/1000)) -> 769040.79 | AY13: =IF(BD13<>1,"",AT13*CONTROL_PANEL!$B$14) -> 2737.4173 | AZ13: =IF(BD13<>1,"",DATA_INPUT!$M13) -> 909970.22 | BA13: =IF(BD13<>1,"",(AQ13+AT13+AV13)-(AX13+AZ13+AY13)) -> 39967033 | BB13: =IF(BD13<>1,"",IF(BA13-CONTROL_PANEL!$B$11<0,0,BA13-CONTROL_PANEL!$B$11)) -> 0 | BC13: =IF(BD13<>1,"",IF(AZ13<=0,0,MIN(AZ13,MAX(0,CONTROL_PANEL!$B$13-BA13)))) -> 0 | BD13: 1 | BF13: 2016 | BG13: 6 | BH13: =IF(BW13<>1,"",DAY(DATE(BF13,BG13+1,))) -> 30 | BI13: =IF(BW12<>1,"",235+((BJ13/1000/2)^(1/3.02))) -> 261.91629 | BJ13: =IF(BW12<>1,"",IF(BT12>0,IF(BT12>CONTROL_PANEL!$B$11,CONTROL_PANEL!$B$11,BT12),0)) -> 41655838 | BK13: =IF(BW13<>1,"",0.6*(BI13-235)^2.02*10000) -> 4642820.9 | BL13: =IF(BW13<>1,"",DATA_INPUT!$I13) -> 0.41207547 | BM13: =IF(BW13<>1,"",BL13*CONTROL_PANEL!$B$5) -> 39105.962 | BN13: =IF(BW13<>1,"",DATA_INPUT!$C13) -> 0.22064 | BO13: =IF(BW13<>1,"",(BN13*BK13)/1000) -> 1024.392 | BP13: =IF(BW13<>1,"",DATA_INPUT!$H13) -> 165.76647 | BQ13: =IF(BW13<>1,"",((BP13*BK13)/1000)) -> 769624.03 | BR13: =IF(BW13<>1,"",BM13*CONTROL_PANEL!$B$14) -> 2737.4173 | BS13: =IF(BW13<>1,"",DATA_INPUT!$N13) -> 759905.43 | BT13: =IF(BW13<>1,"",(BJ13+BM13+BO13)-(BQ13+BS13+BR13)) -> 40163701 | BU13: =IF(BW13<>1,"",IF(BT13-CONTROL_PANEL!$B$11<0,0,BT13-CONTROL_PANEL!$B$11)) -> 0 | BV13: =IF(BW13<>1,"",IF(BS13<=0,0,MIN(BS13,MAX(0,CONTROL_PANEL!$B$13-BT13)))) -> 0 | BW13: 1 | BY13: 2016 | BZ13: 6 | CA13: =IF(CP13<>1,"",DAY(DATE(BY13,BZ13+1,))) -> 30 | CB13: =IF(CP12<>1,"",235+((CC13/1000/2)^(1/3.02))) -> 261.91506 | CC13: =IF(CP12<>1,"",IF(CM12>0,IF(CM12>CONTROL_PANEL!$B$11,CONTROL_PANEL!$B$11,CM12),0)) -> 41650109 | CD13: =IF(CP13<>1,"",0.6*(CB13-235)^2.02*10000) -> 4642393.9 | CE13: =IF(CP13<>1,"",DATA_INPUT!$I13) -> 0.41207547 | CF13: =IF(CP13<>1,"",CE13*CONTROL_PANEL!$B$5) -> 39105.962 | CG13: =IF(CP13<>1,"",DATA_INPUT!$C13) -> 0.22064 | CH13: =IF(CP13<>1,"",(CG13*CD13)/1000) -> 1024.2978 | CI13: =IF(CP13<>1,"",DATA_INPUT!$H13) -> 165.76647 | CJ13: =IF(CP13<>1,"",((CI13*CD13)/1000)) -> 769553.23 | CK13: =IF(CP13<>1,"",CF13*CONTROL_PANEL!$B$14) -> 2737.4173 | CL13: =IF(CP13<>1,"",DATA_INPUT!$O13) -> 872339.75 | CM13: =IF(CP13<>1,"",(CC13+CF13+CH13)-(CJ13+CL13+CK13)) -> 40045609 | CN13: =IF(CP13<>1,"",IF(CM13-CONTROL_PANEL!$B$11<0,0,CM13-CONTROL_PANEL!$B$11)) -> 0 | CO13: =IF(CP13<>1,"",IF(CL13<=0,0,MIN(CL13,MAX(0,CONTROL_PANEL!$B$13-CM13)))) -> 0 | CP13: 1
