Workbook

Sheet README
A1: Integrated CIS Resilience Assessment Framework Tool
A3: Section | B3: Description
A4: Purpose | B4: Excel tool for the six-subsystem resilience framework for reservoir-fed pressurised collective irrigation systems (CIS).
A5: Initial use | B5: Designed for a 10-year present assessment, e.g. 2016–2025.
A6: Future use | B6: Can be extended to a 30-year projection horizon by changing the start and end year in CONTROL_YEARS.
A7: Scenario handling | B7: Scenario values are retained as supplementary uncertainty information; the main dashboard uses annual means for cross-subsystem comparison.
A8: Weights | B8: Equal weights are used by default. Editable weights are included for future multicriteria analysis.
A9: Language | B9: British English
A10: Colour code | B10: Yellow=input; grey=calculation; blue=output; purple=normalised scores.

Sheet CONTROL_YEARS
A1: Control panel and assessment years
A3: Field | B3: Value | C3: Unit/option | D3: Notes
A4: Case study name | B4: Minutos Collective Irrigation System | D4: Editable
A5: Assessment mode | B5: Present 10-year period | C5: Present/Future 30-year horizon | D5: Editable
A6: Start year | B6: 2016 | C6: year | D6: Editable
A7: End year | B7: 2025 | C7: year | D7: Editable
A8: Number of years | B8: =B7-B6+1 -> 10 | C8: years | D8: Calculated
A9: Use scenario mean in dashboard? | B9: Yes | C9: Yes/No | D9: Main dashboard uses annual means
A10: Use equal weights? | B10: Yes | C10: Yes/No | D10: Weights can be edited later
A13: Year | B13: Period type | C13: Horizon | D13: Notes
A14: =IF(ROW()-13<=$B$8,$B$6+ROW()-14,"") -> 2016 | B14: =IF(A14="","",$B$5) -> Present 10-year period | C14: =IF(A14="","",IF($B$8<=10,"Present period","Projection horizon")) -> Present period
A15: =IF(ROW()-13<=$B$8,$B$6+ROW()-14,"") -> 2017 | B15: =IF(A15="","",$B$5) -> Present 10-year period | C15: =IF(A15="","",IF($B$8<=10,"Present period","Projection horizon")) -> Present period
A16: =IF(ROW()-13<=$B$8,$B$6+ROW()-14,"") -> 2018 | B16: =IF(A16="","",$B$5) -> Present 10-year period | C16: =IF(A16="","",IF($B$8<=10,"Present period","Projection horizon")) -> Present period
A17: =IF(ROW()-13<=$B$8,$B$6+ROW()-14,"") -> 2019 | B17: =IF(A17="","",$B$5) -> Present 10-year period | C17: =IF(A17="","",IF($B$8<=10,"Present period","Projection horizon")) -> Present period
A18: =IF(ROW()-13<=$B$8,$B$6+ROW()-14,"") -> 2020 | B18: =IF(A18="","",$B$5) -> Present 10-year period | C18: =IF(A18="","",IF($B$8<=10,"Present period","Projection horizon")) -> Present period
A19: =IF(ROW()-13<=$B$8,$B$6+ROW()-14,"") -> 2021 | B19: =IF(A19="","",$B$5) -> Present 10-year period | C19: =IF(A19="","",IF($B$8<=10,"Present period","Projection horizon")) -> Present period
A20: =IF(ROW()-13<=$B$8,$B$6+ROW()-14,"") -> 2022 | B20: =IF(A20="","",$B$5) -> Present 10-year period | C20: =IF(A20="","",IF($B$8<=10,"Present period","Projection horizon")) -> Present period
A21: =IF(ROW()-13<=$B$8,$B$6+ROW()-14,"") -> 2023 | B21: =IF(A21="","",$B$5) -> Present 10-year period | C21: =IF(A21="","",IF($B$8<=10,"Present period","Projection horizon")) -> Present period
A22: =IF(ROW()-13<=$B$8,$B$6+ROW()-14,"") -> 2024 | B22: =IF(A22="","",$B$5) -> Present 10-year period | C22: =IF(A22="","",IF($B$8<=10,"Present period","Projection horizon")) -> Present period
A23: =IF(ROW()-13<=$B$8,$B$6+ROW()-14,"") -> 2025 | B23: =IF(A23="","",$B$5) -> Present 10-year period | C23: =IF(A23="","",IF($B$8<=10,"Present period","Projection horizon")) -> Present period
A24: =IF(ROW()-13<=$B$8,$B$6+ROW()-14,"") | B24: =IF(A24="","",$B$5) | C24: =IF(A24="","",IF($B$8<=10,"Present period","Projection horizon"))
A25: =IF(ROW()-13<=$B$8,$B$6+ROW()-14,"") | B25: =IF(A25="","",$B$5) | C25: =IF(A25="","",IF($B$8<=10,"Present period","Projection horizon"))
... A43: =IF(ROW()-13<=$B$8,$B$6+ROW()-14,"") | B43: =IF(A43="","",$B$5) | C43: =IF(A43="","",IF($B$8<=10,"Present period","Projection horizon"))

Sheet THRESHOLDS_WEIGHTS
A1: Thresholds and weights
A3: Subsystem | B3: Indicator code | C3: Indicator name | D3: Unit | E3: Orientation | F3: Class 1 Low | G3: Class 2 Moderate | H3: Class 3 Good | I3: Class 4 Excellent | J3: Weight | K3: Notes
A4: A | B4: A1 | C4: Time-based inflow reliability | D4: - | E4: Positive | F4: 0.4 | G4: 0.6 | H4: 0.8 | I4: 1 | J4: 0.16666667 | K4: Represent de failure frequency | L4: (Benavides-Muñoz, 2025; Wei et al., 2025).
A5: A | B5: A2 | C5: Volumetric inflow reliability | D5: - | E5: Positive | F5: 0.4 | G5: 0.6 | H5: 0.8 | I5: 1 | J5: 0.16666667 | K5: Represent the severity os the failure | L5: (Hashimoto et al., 1982; Hisdal et al., 2024).
A6: A | B6: A3 | C6: Mean drought duration | D6: months | E6: Negative | F6: 12 | G6: 6 | H6: 3 | I6: 0 | J6: 0.16666667 | K6: Represent how long is a failure duration | L6: Lema et al., 2025; Nalbantis and Tsakiris, 2009)
A7: A | B7: A4 | C7: Coefficient of variation | D7: - | E7: Negative | F7: 1.1 | G7: 0.9 | H7: 0.5 | I7: 0 | J7: 0.16666667 | K7: Interanual variability | L7: (Ariano and Ali, 2025; Botter et al., 2013; Kupzig et al., 2024).
A8: A | B8: A5 | C8: Buffering capacity | D8: - | E8: Negative | F8: 0.75 | G8: 1.5 | H8: 3 | I8: =MAX(INPUT_A_TO_C!F4:F33) -> 90.830935 | J8: 0.16666667 | K8: Capacity to regulate inflow | L8: (Granados et al., 2021; Ren et al., 2023).
A9: A | B9: A6 | C9: Carry-over dependence | D9: - | E9: Negative | F9: 1.5 | G9: 1.2 | H9: 1.05 | I9: 1 | J9: 0.16666667 | K9: Represent de dependence on multiseason inflow | L9: (Granados et al., 2021; Ren et al., 2023).
A10: B | B10: B1 | C10: Time-based supply reliability | D10: - | E10: Positive | F10: 0.5 | G10: 0.6 | H10: 0.8 | I10: 1 | J10: 0.2 | K10: represent de failure frequency | L10: hashimoto et al., 1982
A11: B | B11: B2 | C11: Volumetric supply reliability | D11: - | E11: Positive | F11: 0.5 | G11: 0.6 | H11: 0.8 | I11: 1 | J11: 0.2 | K11: Represent the severity os the failure
A12: B | B12: B3 | C12: Deficit severity | D12: - | E12: Positive | F12: 0.7 | G12: 0.75 | H12: 0.8 | I12: 1 | J12: 0.2 | K12: Represent the average failura volume in percentage
A13: B | B13: B4 | C13: Recovery after failure | D13: - | E13: Positive | F13: 0.25 | G13: 0.5 | H13: 0.75 | I13: 1 | J13: 0.2 | K13: reprents de capacity to return to normal conditon after a failure
A14: B | B14: B5 | C14: Spill–shortage coexistence | D14: - | E14: Negative | F14: 0.3 | G14: 0.1 | H14: 0.01 | I14: 0 | J14: 0.2 | K14: Represent extent of wich the service failure depende on reservoir capacity
A15: C | B15: C1 | C15: Hydrant pressure reliability | D15: - | E15: Positive | F15: 0.5 | G15: 0.75 | H15: 0.85 | I15: 1 | J15: 0.2 | K15: Represents the number o times that the hydrant failed carneiroo et al 2024 and prasad and Park 2004 | L15: % de falhas
A16: C | B16: C2 | C16: Network pressure reliability | D16: - | E16: Positive | F16: 0.5 | G16: 0.75 | H16: 0.85 | I16: 1 | J16: 0.2 | K16: Represents the exten of the netwok that is afected. carneiroo et al 2024 and prasad and Park 2004 | L16: % of failed hydrants
A17: C | B17: C3 | C17: Relative pressure deficit | D17: - | E17: Negative | F17: 1 | G17: 0.5 | H17: 0.3 | I17: 0.05 | J17: 0.2 | K17: RPD<-0.5 in some case can be reverse by increasinf Zo, but RPD<-1 can be a strcutural problem (Calejo et al., 2008) | L17: min relative deficit
A18: C | B18: C4 | C18: Critical hydrant deficit | D18: - | E18: Negative | F18: 1 | G18: 0.5 | H18: 0.3 | I18: 0.05 | J18: 0.2 | K18: RPD<-0.5 in some case can be reverse by increasinf Zo, but RPD<-1 can be a strcutural problem (Calejo et al., 2008) | L18: verificação dos treshold
A19: C | B19: C5 | C19: Maximum hydrant deficit | D19: - | E19: Negative | F19: 1 | G19: 0.5 | H19: 0.3 | I19: 0.05 | J19: 0.2 | K19: RPD<-0.5 in some case can be reverse by increasinf Zo, but RPD<-1 can be a strcutural problem (Calejo et al., 2008) | L19: verificação dos treshold
A20: D | B20: D1 | C20: Energy per irrigated area | D20: kWh ha⁻¹ | E20: Negative | F20: 2000 | G20: 1500 | H20: 1000 | I20: 500 | J20: 0.125 | K20: 2919.9 ± 502.3 kWh ha-1 by Cameira et al., 2024 (Portugal); 455 kWh ha-1 to 2000 kWh ha-1 by Rodríguez-Díaz et al. (2011);326 to 1,119 kWh ha-1 across systems in 2022 (van de Loo et al., 2025; energy consumption of more than 2000 kWh ha-1 is classified as as large energy consumers by IDAE (2008) lima et al 2019 - (from 1199 to 839 € ha−1) in 2015 and 16% (from 914 to 771 € ha−1) in 2016, when RDI is applied to all crops
A21: D | B21: D2 | C21: Energy per supplied volume | D21: kWh m⁻³ | E21: Negative | F21: 0.4 | G21: 0.3 | H21: 0.2 | I21: 0.1 | J21: 0.125 | K21: Rodríguez-Díaz et al. (2011) propose that CISs with a value greater than 0.4 kWh m-3 are considered large consumers, CISs with values between 0.4 and 0.3 kWh m-3 are considered average consumers and CISs with values below 0.3 kWh m-3 are small consumers. however recent work reported 0.14–0.75 kWh m-3 (van de Loo et al., 2025); carneiro et al 2024 ; 0.27- 0.43; 0.43-0.6; 0.6 ind | L21: verificação dos treshold
A22: D | B22: D3 | C22: Energy per abstracted volume | D22: kWh m⁻³ | E22: Negative | F22: 0.35 | G22: 0.25 | H22: 0.15 | I22: 0.1 | J22: 0.125 | K22: Rodríguez-Díaz et al. (2011) propose that CISs with a value greater than 0.4 kWh m-3 are considered large consumers, CISs with values between 0.4 and 0.3 kWh m-3 are considered average consumers and CISs with values below 0.3 kWh m-3 are small consumers. however recent work reported 0.14–0.75 kWh m-3 (van de Loo et al., 2025)
A23: D | B23: D4 | C23: Energy cost per irrigated area | D23: € ha⁻¹ | E23: Negative | F23: 200 | G23: 150 | H23: 100 | I23: 50 | J23: 0.125 | K23: Cameira reported 386.0 ± 81 € ha-1; Córcoles et al. (2012) about 118.5 € ha-1 and Lima et al. (2019) reported values between 56.3 and 59.0 € ha-1; zapata et al., 2023; The average difference is 134 € ha 1 yr 1, with a maximum of 187 and a minimum of 91 € ha 1 yr 1, again for 2005 and 2018;
A24: D | B24: D5 | C24: Energy cost per supplied volume | D24: € m⁻³ | E24: Negative | F24: 0.06 | G24: 0.04 | H24: 0.02 | I24: 0.01 | J24: 0.125 | K24: Energy cost per area is usually tariff- and country-specific. Cameira et al 2024 reported 0.052 ± 0.008 € m-3; Rodríguez-Díaz et al. (2011), report values between 0.01 and 0.08 € m-3 for 10 Spanish CISs, with an average value of 0.04 € m-3. Córcoles et al. (2012) reported 0.025 € m-3. Lima et al. (2019) reported ECostVo ranging from 0.0175 to 0.0185 € m-3. For Portugal, Chibeles (2007) gives the average value of 0.034 € ha-1 for four AFMA irrigation blocks.
A25: D | B25: D6 | C25: Energy cost per abstracted volume | D25: € m⁻³ | E25: Negative | F25: 0.06 | G25: 0.04 | H25: 0.02 | I25: 0.01 | J25: 0.125 | K25: Energy cost per area is usually tariff- and country-specific. Cameira et al 2024 reported 0.052 ± 0.008 € m-3; Rodríguez-Díaz et al. (2011), report values between 0.01 and 0.08 € m-3 for 10 Spanish CISs, with an average value of 0.04 € m-3. Córcoles et al. (2012) reported 0.025 € m-3. Lima et al. (2019) reported ECostVo ranging from 0.0175 to 0.0185 € m-3. For Portugal, Chibeles (2007) gives the average value of 0.034 € ha-1 for four AFMA irrigation blocks.
A26: D | B26: D7 | C26: Renewable energy contribution | D26: - | E26: Positive | F26: 0.05 | G26: 0.1 | H26: 0.2 | I26: 0.4 | J26: 0.125 | K26: Carneiro et al reported 10% good; 5-10% moderete; 5 pouco, European Green Deal aims to increase the share of energy derived from renewable sources, such as wind and solar, to 40 % by 2030 and reach climate neutrality by 2050
A27: D | B27: D8 | C27: Pump redundancy | D27: - | E27: Positive | F27: 0 | G27: 0.25 | H27: 0.5 | I27: 1 | J27: 0.125 | K27: Carneiro et al reported 75% good; 50-75% moderete; 50 pouco
A28: E | B28: E1 | C28: Gross irrigation requirement | D28: mm | E28: Negative | F28: 600 | G28: 500 | H28: 400 | I28: 300 | J28: 0.1 | K28: *
A29: E | B29: E2 | C29: Peak demand factor | D29: - | E29: Negative | F29: 0.45 | G29: 0.35 | H29: 0.25 | I29: 0.2 | J29: 0.1
A30: E | B30: E3 | C30: Peak demand staggering | D30: - | E30: Positive | F30: 0.25 | G30: 0.5 | H30: 0.75 | I30: 0.8 | J30: 0.1 | L30: verificação dos treshold
A31: E | B31: E4 | C31: Irrigation system factor | D31: - | E31: Negative | F31: 1.25 | G31: 1.05 | H31: 0.75 | I31: 0.5 | J31: 0.1
A32: E | B32: E5 | C32: On-farm technology and control | D32: - | E32: Positive | F32: 0.25 | G32: 0.5 | H32: 0.75 | I32: 1 | J32: 0.1
A33: E | B33: E6 | C33: Water deficit stress tolerance | D33: - | E33: Positive | F33: 0 | G33: 0.2 | H33: 0.25 | I33: 0.3 | J33: 0.1
A34: E | B34: E7 | C34: Share of permanent crops | D34: - | E34: Negative | F34: 0.6 | G34: 0.4 | H34: 0.3 | I34: 0.2 | J34: 0.1 | K34: * Alqueva tem 83 culturas permanents
A35: E | B35: E8 | C35: Soil water buffering capacity | D35: mm | E35: Positive | F35: 40 | G35: 60 | H35: 80 | I35: 100 | J35: 0.1
A36: E | B36: E9 | C36: Alternative local access to storage | D36: - | E36: Positive | F36: 0.25 | G36: 0.5 | H36: 0.75 | I36: 1 | J36: 0.1
A37: E | B37: E10 | C37: Chill requirement adequacy indicator | D37: - | E37: Positive | F37: 0.7 | G37: 0.85 | H37: 0.95 | I37: 1 | J37: 0.1
A38: F | B38: F1 | C38: Preparedness, alert thresholds and response rules | D38: - | E38: Positive | F38: 0.25 | G38: 0.5 | H38: 0.75 | I38: 1 | J38: 0.25
A39: F | B39: F2 | C39: Operational monitoring and control capacity | D39: - | E39: Positive | F39: 0.25 | G39: 0.5 | H39: 0.75 | I39: 1 | J39: 0.25
A40: F | B40: F3 | C40: Financial and infrastructure management capacity | D40: - | E40: Positive | F40: 0.25 | G40: 0.5 | H40: 0.75 | I40: 1 | J40: 0.25
A41: F | B41: F4 | C41: Participation, communication and compliance | D41: - | E41: Positive | F41: 0.25 | G41: 0.5 | H41: 0.75 | I41: 1 | J41: 0.25

Sheet CALC_NORMALISATION
A1: Calculation, normalisation and classes
A3: Subsystem | B3: Indicator code | C3: Indicator name | D3: Raw mean | E3: SD | F3: Min | G3: Max | H3: Unit | I3: Orientation | J3: Low | K3: Moderate | L3: Good | M3: Excellent | N3: Normalised score | O3: Class
A4: A | B4: A1 | C4: Time-based inflow reliability | D4: =IFERROR(AVERAGE(INPUT_A_TO_C!B$4:B$33),"") -> 0.725 | E4: =IFERROR(_xlfn.STDEV.S(INPUT_A_TO_C!B$4:B$33),"") -> 0.32406085 | F4: =IFERROR(MIN(INPUT_A_TO_C!B$4:B$33),"") -> 0.16666667 | G4: =IFERROR(MAX(INPUT_A_TO_C!B$4:B$33),"") -> 1 | H4: - | I4: Positive | J4: =THRESHOLDS_WEIGHTS!F4 -> 0.4 | K4: =THRESHOLDS_WEIGHTS!G4 -> 0.6 | L4: =THRESHOLDS_WEIGHTS!H4 -> 0.8 | M4: =THRESHOLDS_WEIGHTS!I4 -> 1 | N4: =IFERROR(IF($I4="Positive",IF($D4<$J4,0,IF($D4<$K4,0.25+0.25*($D4-$J4)/($K4-$J4),IF($D4<$L4,0.5+0.25*($D4-$K4)/($L4-$K4),IF($D4<$M4,0.75+0.25*($D4-$L4)/($M4-$L4),1)))),IF($D4>$J4,0,IF($D4>$K4,0.25+0.25*($J4-$D4)/($J4-$K4),IF($D4>$L4,0.5+0.25*($K4-$D4)/($K4-$L4),IF($D4>$M4,0.75+0.25*($L4-$D4)/($L4-$M4),1))))),"") -> 0.65625 | O4: =IF(N4="","",IF(N4<0.25,"Low",IF(N4<0.5,"Moderate",IF(N4<0.75,"Good","Excellent")))) -> Good
A5: A | B5: A2 | C5: Volumetric inflow reliability | D5: =IFERROR(AVERAGE(INPUT_A_TO_C!C$4:C$33),"") -> 0.81718292 | E5: =IFERROR(_xlfn.STDEV.S(INPUT_A_TO_C!C$4:C$33),"") -> 0.33254925 | F5: =IFERROR(MIN(INPUT_A_TO_C!C$4:C$33),"") -> 0.059809026 | G5: =IFERROR(MAX(INPUT_A_TO_C!C$4:C$33),"") -> 1 | H5: - | I5: Positive | J5: =THRESHOLDS_WEIGHTS!F5 -> 0.4 | K5: =THRESHOLDS_WEIGHTS!G5 -> 0.6 | L5: =THRESHOLDS_WEIGHTS!H5 -> 0.8 | M5: =THRESHOLDS_WEIGHTS!I5 -> 1 | N5: =IFERROR(IF($I5="Positive",IF($D5<$J5,0,IF($D5<$K5,0.25+0.25*($D5-$J5)/($K5-$J5),IF($D5<$L5,0.5+0.25*($D5-$K5)/($L5-$K5),IF($D5<$M5,0.75+0.25*($D5-$L5)/($M5-$L5),1)))),IF($D5>$J5,0,IF($D5>$K5,0.25+0.25*($J5-$D5)/($J5-$K5),IF($D5>$L5,0.5+0.25*($K5-$D5)/($K5-$L5),IF($D5>$M5,0.75+0.25*($L5-$D5)/($L5-$M5),1))))),"") -> 0.77147865 | O5: =IF(N5="","",IF(N5<0.25,"Low",IF(N5<0.5,"Moderate",IF(N5<0.75,"Good","Excellent")))) -> Excellent
A6: A | B6: A3 | C6: Mean drought duration | D6: =IFERROR(AVERAGE(INPUT_A_TO_C!D$4:D$33),"") -> 2.75 | E6: =IFERROR(_xlfn.STDEV.S(INPUT_A_TO_C!D$4:D$33),"") -> 3.3767999 | F6: =IFERROR(MIN(INPUT_A_TO_C!D$4:D$33),"") -> 0 | G6: =IFERROR(MAX(INPUT_A_TO_C!D$4:D$33),"") -> 9 | H6: months | I6: Negative | J6: =THRESHOLDS_WEIGHTS!F6 -> 12 | K6: =THRESHOLDS_WEIGHTS!G6 -> 6 | L6: =THRESHOLDS_WEIGHTS!H6 -> 3 | M6: =THRESHOLDS_WEIGHTS!I6 -> 0 | N6: =IFERROR(IF($I6="Positive",IF($D6<$J6,0,IF($D6<$K6,0.25+0.25*($D6-$J6)/($K6-$J6),IF($D6<$L6,0.5+0.25*($D6-$K6)/($L6-$K6),IF($D6<$M6,0.75+0.25*($D6-$L6)/($M6-$L6),1)))),IF($D6>$J6,0,IF($D6>$K6,0.25+0.25*($J6-$D6)/($J6-$K6),IF($D6>$L6,0.5+0.25*($K6-$D6)/($K6-$L6),IF($D6>$M6,0.75+0.25*($L6-$D6)/($L6-$M6),1))))),"") -> 0.77083333 | O6: =IF(N6="","",IF(N6<0.25,"Low",IF(N6<0.5,"Moderate",IF(N6<0.75,"Good","Excellent")))) -> Excellent
A7: A | B7: A4 | C7: Coefficient of variation | D7: =IFERROR(AVERAGE(INPUT_A_TO_C!E$4:E$33),"") -> 1.9622075 | E7: =IFERROR(_xlfn.STDEV.S(INPUT_A_TO_C!E$4:E$33),"") -> 0.45177266 | F7: =IFERROR(MIN(INPUT_A_TO_C!E$4:E$33),"") -> 1.1979349 | G7: =IFERROR(MAX(INPUT_A_TO_C!E$4:E$33),"") -> 2.4581429 | H7: - | I7: Negative | J7: =D7 -> 1.9622075 | K7: =THRESHOLDS_WEIGHTS!G7 -> 0.9 | L7: =THRESHOLDS_WEIGHTS!H7 -> 0.5 | M7: =THRESHOLDS_WEIGHTS!I7 -> 0 | N7: =IFERROR(IF($I7="Positive",IF($D7<$J7,0,IF($D7<$K7,0.25+0.25*($D7-$J7)/($K7-$J7),IF($D7<$L7,0.5+0.25*($D7-$K7)/($L7-$K7),IF($D7<$M7,0.75+0.25*($D7-$L7)/($M7-$L7),1)))),IF($D7>$J7,0,IF($D7>$K7,0.25+0.25*($J7-$D7)/($J7-$K7),IF($D7>$L7,0.5+0.25*($K7-$D7)/($K7-$L7),IF($D7>$M7,0.75+0.25*($L7-$D7)/($L7-$M7),1))))),"") -> 0.25 | O7: =IF(N7="","",IF(N7<0.25,"Low",IF(N7<0.5,"Moderate",IF(N7<0.75,"Good","Excellent")))) -> Moderate
A8: A | B8: A5 | C8: Buffering capacity | D8: =IFERROR(AVERAGE(INPUT_A_TO_C!F$4:F$33),"") -> 19.386571 | E8: =IFERROR(_xlfn.STDEV.S(INPUT_A_TO_C!F$4:F$33),"") -> 26.572204 | F8: =IFERROR(MIN(INPUT_A_TO_C!F$4:F$33),"") -> 2.410514 | G8: =IFERROR(MAX(INPUT_A_TO_C!F$4:F$33),"") -> 90.830935 | H8: - | I8: Positive | J8: =D8 -> 19.386571 | K8: =THRESHOLDS_WEIGHTS!G8 -> 1.5 | L8: =THRESHOLDS_WEIGHTS!H8 -> 3 | M8: =THRESHOLDS_WEIGHTS!I8 -> 90.830935 | N8: =IFERROR(IF($I8="Positive",IF($D8<$J8,0,IF($D8<$K8,0.25+0.25*($D8-$J8)/($K8-$J8),IF($D8<$L8,0.5+0.25*($D8-$K8)/($L8-$K8),IF($D8<$M8,0.75+0.25*($D8-$L8)/($M8-$L8),1)))),IF($D8>$J8,0,IF($D8>$K8,0.25+0.25*($J8-$D8)/($J8-$K8),IF($D8>$L8,0.5+0.25*($K8-$D8)/($K8-$L8),IF($D8>$M8,0.75+0.25*($L8-$D8)/($L8-$M8),1))))),"") -> 0.79664237 | O8: =IF(N8="","",IF(N8<0.25,"Low",IF(N8<0.5,"Moderate",IF(N8<0.75,"Good","Excellent")))) -> Excellent
A9: A | B9: A6 | C9: Carry-over dependence | D9: =IFERROR(AVERAGE(INPUT_A_TO_C!G$4:G$33),"") -> 5.0629469 | E9: =IFERROR(_xlfn.STDEV.S(INPUT_A_TO_C!G$4:G$33),"") -> 6.9395282 | F9: =IFERROR(MIN(INPUT_A_TO_C!G$4:G$33),"") -> 0.62952362 | G9: =IFERROR(MAX(INPUT_A_TO_C!G$4:G$33),"") -> 23.721173 | H9: - | I9: Negative | J9: =D9 -> 5.0629469 | K9: =THRESHOLDS_WEIGHTS!G9 -> 1.2 | L9: =THRESHOLDS_WEIGHTS!H9 -> 1.05 | M9: =THRESHOLDS_WEIGHTS!I9 -> 1 | N9: =IFERROR(IF($I9="Positive",IF($D9<$J9,0,IF($D9<$K9,0.25+0.25*($D9-$J9)/($K9-$J9),IF($D9<$L9,0.5+0.25*($D9-$K9)/($L9-$K9),IF($D9<$M9,0.75+0.25*($D9-$L9)/($M9-$L9),1)))),IF($D9>$J9,0,IF($D9>$K9,0.25+0.25*($J9-$D9)/($J9-$K9),IF($D9>$L9,0.5+0.25*($K9-$D9)/($K9-$L9),IF($D9>$M9,0.75+0.25*($L9-$D9)/($L9-$M9),1))))),"") -> 0.25 | O9: =IF(N9="","",IF(N9<0.25,"Low",IF(N9<0.5,"Moderate",IF(N9<0.75,"Good","Excellent")))) -> Moderate
A10: B | B10: B1 | C10: Time-based supply reliability | D10: =IFERROR(AVERAGE(INPUT_A_TO_C!L$4:L$33),"") -> 0.99375 | E10: =IFERROR(_xlfn.STDEV.S(INPUT_A_TO_C!L4:L13),"") | F10: =IFERROR(MIN(INPUT_A_TO_C!L$4:L$33),"") -> 0.99375 | G10: =IFERROR(MAX(INPUT_A_TO_C!L$4:L$33),"") -> 0.99375 | H10: - | I10: Positive | J10: =THRESHOLDS_WEIGHTS!F10 -> 0.5 | K10: =THRESHOLDS_WEIGHTS!G10 -> 0.6 | L10: =THRESHOLDS_WEIGHTS!H10 -> 0.8 | M10: =THRESHOLDS_WEIGHTS!I10 -> 1 | N10: =IFERROR(IF($I10="Positive",IF($D10<$J10,0,IF($D10<$K10,0.25+0.25*($D10-$J10)/($K10-$J10),IF($D10<$L10,0.5+0.25*($D10-$K10)/($L10-$K10),IF($D10<$M10,0.75+0.25*($D10-$L10)/($M10-$L10),1)))),IF($D10>$J10,0,IF($D10>$K10,0.25+0.25*($J10-$D10)/($J10-$K10),IF($D10>$L10,0.5+0.25*($K10-$D10)/($K10-$L10),IF($D10>$M10,0.75+0.25*($L10-$D10)/($L10-$M10),1))))),"") -> 0.9921875 | O10: =IF(N10="","",IF(N10<0.25,"Low",IF(N10<0.5,"Moderate",IF(N10<0.75,"Good","Excellent")))) -> Excellent
A11: B | B11: B2 | C11: Volumetric supply reliability | D11: =IFERROR(AVERAGE(INPUT_A_TO_C!M$4:M$33),"") -> 0.99375 | E11: =IFERROR(_xlfn.STDEV.S(INPUT_A_TO_C!M4:M33),"") | F11: =IFERROR(MIN(INPUT_A_TO_C!M$4:M$33),"") -> 0.99375 | G11: =IFERROR(MAX(INPUT_A_TO_C!M$4:M$33),"") -> 0.99375 | H11: - | I11: Positive | J11: =THRESHOLDS_WEIGHTS!F11 -> 0.5 | K11: =THRESHOLDS_WEIGHTS!G11 -> 0.6 | L11: =THRESHOLDS_WEIGHTS!H11 -> 0.8 | M11: =THRESHOLDS_WEIGHTS!I11 -> 1 | N11: =IFERROR(IF($I11="Positive",IF($D11<$J11,0,IF($D11<$K11,0.25+0.25*($D11-$J11)/($K11-$J11),IF($D11<$L11,0.5+0.25*($D11-$K11)/($L11-$K11),IF($D11<$M11,0.75+0.25*($D11-$L11)/($M11-$L11),1)))),IF($D11>$J11,0,IF($D11>$K11,0.25+0.25*($J11-$D11)/($J11-$K11),IF($D11>$L11,0.5+0.25*($K11-$D11)/($K11-$L11),IF($D11>$M11,0.75+0.25*($L11-$D11)/($L11-$M11),1))))),"") -> 0.9921875 | O11: =IF(N11="","",IF(N11<0.25,"Low",IF(N11<0.5,"Moderate",IF(N11<0.75,"Good","Excellent")))) -> Excellent
A12: B | B12: B3 | C12: Deficit severity | D12: =IFERROR(AVERAGE(INPUT_A_TO_C!N$4:N$33),"") -> 0.99375 | E12: =IFERROR(_xlfn.STDEV.S(INPUT_A_TO_C!O$4:O$33),"") | F12: =IFERROR(MIN(INPUT_A_TO_C!N$4:N$33),"") -> 0.99375 | G12: =IFERROR(MAX(INPUT_A_TO_C!N$4:N$33),"") -> 0.99375 | H12: - | I12: Positive | J12: =THRESHOLDS_WEIGHTS!F12 -> 0.7 | K12: =THRESHOLDS_WEIGHTS!G12 -> 0.75 | L12: =THRESHOLDS_WEIGHTS!H12 -> 0.8 | M12: =THRESHOLDS_WEIGHTS!I12 -> 1 | N12: =IFERROR(IF($I12="Positive",IF($D12<$J12,0,IF($D12<$K12,0.25+0.25*($D12-$J12)/($K12-$J12),IF($D12<$L12,0.5+0.25*($D12-$K12)/($L12-$K12),IF($D12<$M12,0.75+0.25*($D12-$L12)/($M12-$L12),1)))),IF($D12>$J12,0,IF($D12>$K12,0.25+0.25*($J12-$D12)/($J12-$K12),IF($D12>$L12,0.5+0.25*($K12-$D12)/($K12-$L12),IF($D12>$M12,0.75+0.25*($L12-$D12)/($L12-$M12),1))))),"") -> 0.9921875 | O12: =IF(N12="","",IF(N12<0.25,"Low",IF(N12<0.5,"Moderate",IF(N12<0.75,"Good","Excellent")))) -> Excellent
A13: B | B13: B4 | C13: Recovery after failure | D13: =IFERROR(AVERAGE(INPUT_A_TO_C!O$4:O$33),"") -> 0.99375 | E13: =IFERROR(_xlfn.STDEV.S(INPUT_A_TO_C!P$4:P$33),"") | F13: =IFERROR(MIN(INPUT_A_TO_C!O$4:O$33),"") -> 0.99375 | G13: =IFERROR(MAX(INPUT_A_TO_C!O$4:O$33),"") -> 0.99375 | H13: - | I13: Positive | J13: =THRESHOLDS_WEIGHTS!F13 -> 0.25 | K13: =THRESHOLDS_WEIGHTS!G13 -> 0.5 | L13: =THRESHOLDS_WEIGHTS!H13 -> 0.75 | M13: =THRESHOLDS_WEIGHTS!I13 -> 1 | N13: =IFERROR(IF($I13="Positive",IF($D13<$J13,0,IF($D13<$K13,0.25+0.25*($D13-$J13)/($K13-$J13),IF($D13<$L13,0.5+0.25*($D13-$K13)/($L13-$K13),IF($D13<$M13,0.75+0.25*($D13-$L13)/($M13-$L13),1)))),IF($D13>$J13,0,IF($D13>$K13,0.25+0.25*($J13-$D13)/($J13-$K13),IF($D13>$L13,0.5+0.25*($K13-$D13)/($K13-$L13),IF($D13>$M13,0.75+0.25*($L13-$D13)/($L13-$M13),1))))),"") -> 0.99375 | O13: =IF(N13="","",IF(N13<0.25,"Low",IF(N13<0.5,"Moderate",IF(N13<0.75,"Good","Excellent")))) -> Excellent
A14: B | B14: B5 | C14: Spill–shortage coexistence | D14: =IFERROR(AVERAGE(INPUT_A_TO_C!P$4:P$33),"") -> 0.99375 | E14: =IFERROR(_xlfn.STDEV.S(INPUT_A_TO_C!Q$4:Q$33),"") | F14: =IFERROR(MIN(INPUT_A_TO_C!P$4:P$33),"") -> 0.99375 | G14: =IFERROR(MAX(INPUT_A_TO_C!P$4:P$33),"") -> 0.99375 | H14: - | I14: Negative | J14: =THRESHOLDS_WEIGHTS!F14 -> 0.3 | K14: =THRESHOLDS_WEIGHTS!G14 -> 0.1 | L14: =THRESHOLDS_WEIGHTS!H14 -> 0.01 | M14: =THRESHOLDS_WEIGHTS!I14 -> 0 | N14: =IFERROR(IF($I14="Positive",IF($D14<$J14,0,IF($D14<$K14,0.25+0.25*($D14-$J14)/($K14-$J14),IF($D14<$L14,0.5+0.25*($D14-$K14)/($L14-$K14),IF($D14<$M14,0.75+0.25*($D14-$L14)/($M14-$L14),1)))),IF($D14>$J14,0,IF($D14>$K14,0.25+0.25*($J14-$D14)/($J14-$K14),IF($D14>$L14,0.5+0.25*($K14-$D14)/($K14-$L14),IF($D14>$M14,0.75+0.25*($L14-$D14)/($L14-$M14),1))))),"") -> 0 | O14: =IF(N14="","",IF(N14<0.25,"Low",IF(N14<0.5,"Moderate",IF(N14<0.75,"Good","Excellent")))) -> Low
A15: C | B15: C1 | C15: Hydrant pressure reliability | D15: =IFERROR(AVERAGE(INPUT_A_TO_C!T$4:T$33),"") -> 0.98197379 | E15: =IFERROR(_xlfn.STDEV.S(INPUT_A_TO_C!T$4:T$33),"") -> 0.0083551851 | F15: =IFERROR(MIN(INPUT_A_TO_C!T$4:T$33),"") -> 0.9749092 | G15: =IFERROR(MAX(INPUT_A_TO_C!T$4:T$33),"") -> 0.99202027 | H15: - | I15: Positive | J15: =THRESHOLDS_WEIGHTS!F15 -> 0.5 | K15: =THRESHOLDS_WEIGHTS!G15 -> 0.75 | L15: =THRESHOLDS_WEIGHTS!H15 -> 0.85 | M15: =THRESHOLDS_WEIGHTS!I15 -> 1 | N15: =IFERROR(IF($I15="Positive",IF($D15<$J15,0,IF($D15<$K15,0.25+0.25*($D15-$J15)/($K15-$J15),IF($D15<$L15,0.5+0.25*($D15-$K15)/($L15-$K15),IF($D15<$M15,0.75+0.25*($D15-$L15)/($M15-$L15),1)))),IF($D15>$J15,0,IF($D15>$K15,0.25+0.25*($J15-$D15)/($J15-$K15),IF($D15>$L15,0.5+0.25*($K15-$D15)/($K15-$L15),IF($D15>$M15,0.75+0.25*($L15-$D15)/($L15-$M15),1))))),"") -> 0.96995632 | O15: =IF(N15="","",IF(N15<0.25,"Low",IF(N15<0.5,"Moderate",IF(N15<0.75,"Good","Excellent")))) -> Excellent
A16: C | B16: C2 | C16: Network pressure reliability | D16: =IFERROR(AVERAGE(INPUT_A_TO_C!U$4:U$33),"") -> 0.94655854 | E16: =IFERROR(_xlfn.STDEV.S(INPUT_A_TO_C!U$4:U$33),"") -> 0.019083554 | F16: =IFERROR(MIN(INPUT_A_TO_C!U$4:U$33),"") -> 0.91666667 | G16: =IFERROR(MAX(INPUT_A_TO_C!U$4:U$33),"") -> 0.96202532 | H16: - | I16: Positive | J16: =THRESHOLDS_WEIGHTS!F16 -> 0.5 | K16: =THRESHOLDS_WEIGHTS!G16 -> 0.75 | L16: =THRESHOLDS_WEIGHTS!H16 -> 0.85 | M16: =THRESHOLDS_WEIGHTS!I16 -> 1 | N16: =IFERROR(IF($I16="Positive",IF($D16<$J16,0,IF($D16<$K16,0.25+0.25*($D16-$J16)/($K16-$J16),IF($D16<$L16,0.5+0.25*($D16-$K16)/($L16-$K16),IF($D16<$M16,0.75+0.25*($D16-$L16)/($M16-$L16),1)))),IF($D16>$J16,0,IF($D16>$K16,0.25+0.25*($J16-$D16)/($J16-$K16),IF($D16>$L16,0.5+0.25*($K16-$D16)/($K16-$L16),IF($D16>$M16,0.75+0.25*($L16-$D16)/($L16-$M16),1))))),"") -> 0.91093091 | O16: =IF(N16="","",IF(N16<0.25,"Low",IF(N16<0.5,"Moderate",IF(N16<0.75,"Good","Excellent")))) -> Excellent
A17: C | B17: C3 | C17: Relative pressure deficit | D17: =IFERROR(AVERAGE(INPUT_A_TO_C!V$4:V$33),"") -> 0.39790148 | E17: =IFERROR(_xlfn.STDEV.S(INPUT_A_TO_C!V$4:V$33),"") -> 0.29271272 | F17: =IFERROR(MIN(INPUT_A_TO_C!V$4:V$33),"") -> 0.055840733 | G17: =IFERROR(MAX(INPUT_A_TO_C!V$4:V$33),"") -> 0.64833247 | H17: - | I17: Negative | J17: =THRESHOLDS_WEIGHTS!F17 -> 1 | K17: =THRESHOLDS_WEIGHTS!G17 -> 0.5 | L17: =THRESHOLDS_WEIGHTS!H17 -> 0.3 | M17: =THRESHOLDS_WEIGHTS!I17 -> 0.05 | N17: =IFERROR(IF($I17="Positive",IF($D17<$J17,0,IF($D17<$K17,0.25+0.25*($D17-$J17)/($K17-$J17),IF($D17<$L17,0.5+0.25*($D17-$K17)/($L17-$K17),IF($D17<$M17,0.75+0.25*($D17-$L17)/($M17-$L17),1)))),IF($D17>$J17,0,IF($D17>$K17,0.25+0.25*($J17-$D17)/($J17-$K17),IF($D17>$L17,0.5+0.25*($K17-$D17)/($K17-$L17),IF($D17>$M17,0.75+0.25*($L17-$D17)/($L17-$M17),1))))),"") -> 0.62762315 | O17: =IF(N17="","",IF(N17<0.25,"Low",IF(N17<0.5,"Moderate",IF(N17<0.75,"Good","Excellent")))) -> Good
A18: C | B18: C4 | C18: Critical hydrant deficit | D18: =IFERROR(AVERAGE(INPUT_A_TO_C!W$4:W$33),"") -> 0.34425345 | E18: =IFERROR(_xlfn.STDEV.S(INPUT_A_TO_C!W$4:W$33),"") -> 0.20137343 | F18: =IFERROR(MIN(INPUT_A_TO_C!W$4:W$33),"") -> 0.10650384 | G18: =IFERROR(MAX(INPUT_A_TO_C!W$4:W$33),"") -> 0.50104234 | H18: - | I18: Negative | J18: =THRESHOLDS_WEIGHTS!F18 -> 1 | K18: =THRESHOLDS_WEIGHTS!G18 -> 0.5 | L18: =THRESHOLDS_WEIGHTS!H18 -> 0.3 | M18: =THRESHOLDS_WEIGHTS!I18 -> 0.05 | N18: =IFERROR(IF($I18="Positive",IF($D18<$J18,0,IF($D18<$K18,0.25+0.25*($D18-$J18)/($K18-$J18),IF($D18<$L18,0.5+0.25*($D18-$K18)/($L18-$K18),IF($D18<$M18,0.75+0.25*($D18-$L18)/($M18-$L18),1)))),IF($D18>$J18,0,IF($D18>$K18,0.25+0.25*($J18-$D18)/($J18-$K18),IF($D18>$L18,0.5+0.25*($K18-$D18)/($K18-$L18),IF($D18>$M18,0.75+0.25*($L18-$D18)/($L18-$M18),1))))),"") -> 0.69468319 | O18: =IF(N18="","",IF(N18<0.25,"Low",IF(N18<0.5,"Moderate",IF(N18<0.75,"Good","Excellent")))) -> Good
A19: C | B19: C5 | C19: Maximum hydrant deficit | D19: =IFERROR(AVERAGE(INPUT_A_TO_C!X$4:X$33),"") -> 0.43260759 | E19: =IFERROR(_xlfn.STDEV.S(INPUT_A_TO_C!X$4:X$33),"") -> 0.15740557 | F19: =IFERROR(MIN(INPUT_A_TO_C!X$4:X$33),"") -> 0.23593793 | G19: =IFERROR(MAX(INPUT_A_TO_C!X$4:X$33),"") -> 0.55690083 | H19: - | I19: Negative | J19: =THRESHOLDS_WEIGHTS!F19 -> 1 | K19: =THRESHOLDS_WEIGHTS!G19 -> 0.5 | L19: =THRESHOLDS_WEIGHTS!H19 -> 0.3 | M19: =THRESHOLDS_WEIGHTS!I19 -> 0.05 | N19: =IFERROR(IF($I19="Positive",IF($D19<$J19,0,IF($D19<$K19,0.25+0.25*($D19-$J19)/($K19-$J19),IF($D19<$L19,0.5+0.25*($D19-$K19)/($L19-$K19),IF($D19<$M19,0.75+0.25*($D19-$L19)/($M19-$L19),1)))),IF($D19>$J19,0,IF($D19>$K19,0.25+0.25*($J19-$D19)/($J19-$K19),IF($D19>$L19,0.5+0.25*($K19-$D19)/($K19-$L19),IF($D19>$M19,0.75+0.25*($L19-$D19)/($L19-$M19),1))))),"") -> 0.58424052 | O19: =IF(N19="","",IF(N19<0.25,"Low",IF(N19<0.5,"Moderate",IF(N19<0.75,"Good","Excellent")))) -> Good
A20: D | B20: D1 | C20: Energy per irrigated area | D20: =IFERROR(AVERAGE(INPUT_D_E!B$4:B$33),"") -> 833.41653 | E20: =IFERROR(_xlfn.STDEV.S(INPUT_D_E!B$4:B$33),"") -> 455.96295 | F20: =IFERROR(MIN(INPUT_D_E!B$4:B$33),"") -> 0 | G20: =IFERROR(MAX(INPUT_D_E!B$4:B$33),"") -> 1171.7135 | H20: kWh ha⁻¹ | I20: Negative | J20: =THRESHOLDS_WEIGHTS!F20 -> 2000 | K20: =THRESHOLDS_WEIGHTS!G20 -> 1500 | L20: =THRESHOLDS_WEIGHTS!H20 -> 1000 | M20: =THRESHOLDS_WEIGHTS!I20 -> 500 | N20: =IFERROR(IF($I20="Positive",IF($D20<$J20,0,IF($D20<$K20,0.25+0.25*($D20-$J20)/($K20-$J20),IF($D20<$L20,0.5+0.25*($D20-$K20)/($L20-$K20),IF($D20<$M20,0.75+0.25*($D20-$L20)/($M20-$L20),1)))),IF($D20>$J20,0,IF($D20>$K20,0.25+0.25*($J20-$D20)/($J20-$K20),IF($D20>$L20,0.5+0.25*($K20-$D20)/($K20-$L20),IF($D20>$M20,0.75+0.25*($L20-$D20)/($L20-$M20),1))))),"") -> 0.83329174 | O20: =IF(N20="","",IF(N20<0.25,"Low",IF(N20<0.5,"Moderate",IF(N20<0.75,"Good","Excellent")))) -> Excellent
A21: D | B21: D2 | C21: Energy per supplied volume | D21: =IFERROR(AVERAGE(INPUT_D_E!C$4:C$33),"") -> 0.1836846 | E21: =IFERROR(_xlfn.STDEV.S(INPUT_D_E!C$4:C$33),"") -> 0.099690083 | F21: =IFERROR(MIN(INPUT_D_E!C$4:C$33),"") -> 0 | G21: =IFERROR(MAX(INPUT_D_E!C$4:C$33),"") -> 0.25221274 | H21: kWh m⁻³ | I21: Negative | J21: =THRESHOLDS_WEIGHTS!F21 -> 0.4 | K21: =THRESHOLDS_WEIGHTS!G21 -> 0.3 | L21: =THRESHOLDS_WEIGHTS!H21 -> 0.2 | M21: =THRESHOLDS_WEIGHTS!I21 -> 0.1 | N21: =IFERROR(IF($I21="Positive",IF($D21<$J21,0,IF($D21<$K21,0.25+0.25*($D21-$J21)/($K21-$J21),IF($D21<$L21,0.5+0.25*($D21-$K21)/($L21-$K21),IF($D21<$M21,0.75+0.25*($D21-$L21)/($M21-$L21),1)))),IF($D21>$J21,0,IF($D21>$K21,0.25+0.25*($J21-$D21)/($J21-$K21),IF($D21>$L21,0.5+0.25*($K21-$D21)/($K21-$L21),IF($D21>$M21,0.75+0.25*($L21-$D21)/($L21-$M21),1))))),"") -> 0.79078849 | O21: =IF(N21="","",IF(N21<0.25,"Low",IF(N21<0.5,"Moderate",IF(N21<0.75,"Good","Excellent")))) -> Excellent
A22: D | B22: D3 | C22: Energy per abstracted volume | D22: =IFERROR(AVERAGE(INPUT_D_E!D$4:D$33),"") -> 0.17270026 | E22: =IFERROR(_xlfn.STDEV.S(INPUT_D_E!D$4:D$33),"") -> 0.093728616 | F22: =IFERROR(MIN(INPUT_D_E!D$4:D$33),"") -> 0 | G22: =IFERROR(MAX(INPUT_D_E!D$4:D$33),"") -> 0.23713042 | H22: kWh m⁻³ | I22: Negative | J22: =THRESHOLDS_WEIGHTS!F22 -> 0.35 | K22: =THRESHOLDS_WEIGHTS!G22 -> 0.25 | L22: =THRESHOLDS_WEIGHTS!H22 -> 0.15 | M22: =THRESHOLDS_WEIGHTS!I22 -> 0.1 | N22: =IFERROR(IF($I22="Positive",IF($D22<$J22,0,IF($D22<$K22,0.25+0.25*($D22-$J22)/($K22-$J22),IF($D22<$L22,0.5+0.25*($D22-$K22)/($L22-$K22),IF($D22<$M22,0.75+0.25*($D22-$L22)/($M22-$L22),1)))),IF($D22>$J22,0,IF($D22>$K22,0.25+0.25*($J22-$D22)/($J22-$K22),IF($D22>$L22,0.5+0.25*($K22-$D22)/($K22-$L22),IF($D22>$M22,0.75+0.25*($L22-$D22)/($L22-$M22),1))))),"") -> 0.69324934 | O22: =IF(N22="","",IF(N22<0.25,"Low",IF(N22<0.5,"Moderate",IF(N22<0.75,"Good","Excellent")))) -> Good
A23: D | B23: D4 | C23: Energy cost per irrigated area | D23: =IFERROR(AVERAGE(INPUT_D_E!E$4:E$33),"") -> 125.02781 | E23: =IFERROR(_xlfn.STDEV.S(INPUT_D_E!E$4:E$33),"") -> 22.268377 | F23: =IFERROR(MIN(INPUT_D_E!E$4:E$33),"") -> 77.248967 | G23: =IFERROR(MAX(INPUT_D_E!E$4:E$33),"") -> 151.33049 | H23: € ha⁻¹ | I23: Negative | J23: =THRESHOLDS_WEIGHTS!F23 -> 200 | K23: =THRESHOLDS_WEIGHTS!G23 -> 150 | L23: =THRESHOLDS_WEIGHTS!H23 -> 100 | M23: =THRESHOLDS_WEIGHTS!I23 -> 50 | N23: =IFERROR(IF($I23="Positive",IF($D23<$J23,0,IF($D23<$K23,0.25+0.25*($D23-$J23)/($K23-$J23),IF($D23<$L23,0.5+0.25*($D23-$K23)/($L23-$K23),IF($D23<$M23,0.75+0.25*($D23-$L23)/($M23-$L23),1)))),IF($D23>$J23,0,IF($D23>$K23,0.25+0.25*($J23-$D23)/($J23-$K23),IF($D23>$L23,0.5+0.25*($K23-$D23)/($K23-$L23),IF($D23>$M23,0.75+0.25*($L23-$D23)/($L23-$M23),1))))),"") -> 0.62486095 | O23: =IF(N23="","",IF(N23<0.25,"Low",IF(N23<0.5,"Moderate",IF(N23<0.75,"Good","Excellent")))) -> Good
A24: D | B24: D5 | C24: Energy cost per supplied volume | D24: =IFERROR(AVERAGE(INPUT_D_E!F$4:F$33),"") -> 0.02726971 | E24: =IFERROR(_xlfn.STDEV.S(INPUT_D_E!F$4:F$33),"") -> 0.0045445211 | F24: =IFERROR(MIN(INPUT_D_E!F$4:F$33),"") -> 0.017391186 | G24: =IFERROR(MAX(INPUT_D_E!F$4:F$33),"") -> 0.035042298 | H24: € m⁻³ | I24: Negative | J24: =THRESHOLDS_WEIGHTS!F24 -> 0.06 | K24: =THRESHOLDS_WEIGHTS!G24 -> 0.04 | L24: =THRESHOLDS_WEIGHTS!H24 -> 0.02 | M24: =THRESHOLDS_WEIGHTS!I24 -> 0.01 | N24: =IFERROR(IF($I24="Positive",IF($D24<$J24,0,IF($D24<$K24,0.25+0.25*($D24-$J24)/($K24-$J24),IF($D24<$L24,0.5+0.25*($D24-$K24)/($L24-$K24),IF($D24<$M24,0.75+0.25*($D24-$L24)/($M24-$L24),1)))),IF($D24>$J24,0,IF($D24>$K24,0.25+0.25*($J24-$D24)/($J24-$K24),IF($D24>$L24,0.5+0.25*($K24-$D24)/($K24-$L24),IF($D24>$M24,0.75+0.25*($L24-$D24)/($L24-$M24),1))))),"") -> 0.65912862 | O24: =IF(N24="","",IF(N24<0.25,"Low",IF(N24<0.5,"Moderate",IF(N24<0.75,"Good","Excellent")))) -> Good
A25: D | B25: D6 | C25: Energy cost per abstracted volume | D25: =IFERROR(AVERAGE(INPUT_D_E!G$4:G$33),"") -> 0.025638981 | E25: =IFERROR(_xlfn.STDEV.S(INPUT_D_E!G$4:G$33),"") -> 0.0042727588 | F25: =IFERROR(MIN(INPUT_D_E!G$4:G$33),"") -> 0.016351193 | G25: =IFERROR(MAX(INPUT_D_E!G$4:G$33),"") -> 0.032946769 | H25: € m⁻³ | I25: Negative | J25: =THRESHOLDS_WEIGHTS!F25 -> 0.06 | K25: =THRESHOLDS_WEIGHTS!G25 -> 0.04 | L25: =THRESHOLDS_WEIGHTS!H25 -> 0.02 | M25: =THRESHOLDS_WEIGHTS!I25 -> 0.01 | N25: =IFERROR(IF($I25="Positive",IF($D25<$J25,0,IF($D25<$K25,0.25+0.25*($D25-$J25)/($K25-$J25),IF($D25<$L25,0.5+0.25*($D25-$K25)/($L25-$K25),IF($D25<$M25,0.75+0.25*($D25-$L25)/($M25-$L25),1)))),IF($D25>$J25,0,IF($D25>$K25,0.25+0.25*($J25-$D25)/($J25-$K25),IF($D25>$L25,0.5+0.25*($K25-$D25)/($K25-$L25),IF($D25>$M25,0.75+0.25*($L25-$D25)/($L25-$M25),1))))),"") -> 0.67951273 | O25: =IF(N25="","",IF(N25<0.25,"Low",IF(N25<0.5,"Moderate",IF(N25<0.75,"Good","Excellent")))) -> Good
A26: D | B26: D7 | C26: Renewable energy contribution | D26: =[4]SD_SE_CALC_INDICATORS!AF13 -> 0.092583038 | E26: =IFERROR(_xlfn.STDEV.S(INPUT_D_E!H$4:H$33),"") -> 0.032733047 | F26: =IFERROR(MIN(INPUT_D_E!H$4:H$33),"") -> 0 | G26: =IFERROR(MAX(INPUT_D_E!H$4:H$33),"") -> 0.092583038 | H26: - | I26: Positive | J26: =THRESHOLDS_WEIGHTS!F26 -> 0.05 | K26: =THRESHOLDS_WEIGHTS!G26 -> 0.1 | L26: =THRESHOLDS_WEIGHTS!H26 -> 0.2 | M26: =THRESHOLDS_WEIGHTS!I26 -> 0.4 | N26: =IFERROR(IF($I26="Positive",IF($D26<$J26,0,IF($D26<$K26,0.25+0.25*($D26-$J26)/($K26-$J26),IF($D26<$L26,0.5+0.25*($D26-$K26)/($L26-$K26),IF($D26<$M26,0.75+0.25*($D26-$L26)/($M26-$L26),1)))),IF($D26>$J26,0,IF($D26>$K26,0.25+0.25*($J26-$D26)/($J26-$K26),IF($D26>$L26,0.5+0.25*($K26-$D26)/($K26-$L26),IF($D26>$M26,0.75+0.25*($L26-$D26)/($L26-$M26),1))))),"") -> 0.46291519 | O26: =IF(N26="","",IF(N26<0.25,"Low",IF(N26<0.5,"Moderate",IF(N26<0.75,"Good","Excellent")))) -> Moderate
A27: D | B27: D8 | C27: Pump redundancy | D27: =IFERROR(AVERAGE(INPUT_D_E!I$4:I$33),"") -> 0.80611898 | E27: =IFERROR(_xlfn.STDEV.S(INPUT_D_E!I$4:I$33),"") -> 0.12028454 | F27: =IFERROR(MIN(INPUT_D_E!I$4:I$33),"") -> 0.54761905 | G27: =IFERROR(MAX(INPUT_D_E!I$4:I$33),"") -> 0.94756554 | H27: - | I27: Positive | J27: =THRESHOLDS_WEIGHTS!F27 -> 0 | K27: =THRESHOLDS_WEIGHTS!G27 -> 0.25 | L27: =THRESHOLDS_WEIGHTS!H27 -> 0.5 | M27: =THRESHOLDS_WEIGHTS!I27 -> 1 | N27: =IFERROR(IF($I27="Positive",IF($D27<$J27,0,IF($D27<$K27,0.25+0.25*($D27-$J27)/($K27-$J27),IF($D27<$L27,0.5+0.25*($D27-$K27)/($L27-$K27),IF($D27<$M27,0.75+0.25*($D27-$L27)/($M27-$L27),1)))),IF($D27>$J27,0,IF($D27>$K27,0.25+0.25*($J27-$D27)/($J27-$K27),IF($D27>$L27,0.5+0.25*($K27-$D27)/($K27-$L27),IF($D27>$M27,0.75+0.25*($L27-$D27)/($L27-$M27),1))))),"") -> 0.90305949 | O27: =IF(N27="","",IF(N27<0.25,"Low",IF(N27<0.5,"Moderate",IF(N27<0.75,"Good","Excellent")))) -> Excellent
A28: E | B28: E1 | C28: Gross irrigation requirement | D28: =IFERROR(AVERAGE(INPUT_D_E!M$4:M$33),"") -> 452.76811 | E28: =IFERROR(_xlfn.STDEV.S(INPUT_D_E!M$4:M$33),"") -> 38.370383 | F28: =IFERROR(MIN(INPUT_D_E!M$4:M$33),"") -> 400.87365 | G28: =IFERROR(MAX(INPUT_D_E!M$4:M$33),"") -> 506.22936 | H28: mm | I28: Negative | J28: =THRESHOLDS_WEIGHTS!F28 -> 600 | K28: =THRESHOLDS_WEIGHTS!G28 -> 500 | L28: =THRESHOLDS_WEIGHTS!H28 -> 400 | M28: =THRESHOLDS_WEIGHTS!I28 -> 300 | N28: =IFERROR(IF($I28="Positive",IF($D28<$J28,0,IF($D28<$K28,0.25+0.25*($D28-$J28)/($K28-$J28),IF($D28<$L28,0.5+0.25*($D28-$K28)/($L28-$K28),IF($D28<$M28,0.75+0.25*($D28-$L28)/($M28-$L28),1)))),IF($D28>$J28,0,IF($D28>$K28,0.25+0.25*($J28-$D28)/($J28-$K28),IF($D28>$L28,0.5+0.25*($K28-$D28)/($K28-$L28),IF($D28>$M28,0.75+0.25*($L28-$D28)/($L28-$M28),1))))),"") -> 0.61807974 | O28: =IF(N28="","",IF(N28<0.25,"Low",IF(N28<0.5,"Moderate",IF(N28<0.75,"Good","Excellent")))) -> Good
A29: E | B29: E2 | C29: Peak demand factor | D29: =IFERROR(AVERAGE(INPUT_D_E!N$4:N$33),"") -> 0.34659797 | E29: =IFERROR(_xlfn.STDEV.S(INPUT_D_E!N$4:N$33),"") -> 0.019995666 | F29: =IFERROR(MIN(INPUT_D_E!N$4:N$33),"") -> 0.31597817 | G29: =IFERROR(MAX(INPUT_D_E!N$4:N$33),"") -> 0.38707723 | H29: - | I29: Negative | J29: =THRESHOLDS_WEIGHTS!F29 -> 0.45 | K29: =THRESHOLDS_WEIGHTS!G29 -> 0.35 | L29: =THRESHOLDS_WEIGHTS!H29 -> 0.25 | M29: =THRESHOLDS_WEIGHTS!I29 -> 0.2 | N29: =IFERROR(IF($I29="Positive",IF($D29<$J29,0,IF($D29<$K29,0.25+0.25*($D29-$J29)/($K29-$J29),IF($D29<$L29,0.5+0.25*($D29-$K29)/($L29-$K29),IF($D29<$M29,0.75+0.25*($D29-$L29)/($M29-$L29),1)))),IF($D29>$J29,0,IF($D29>$K29,0.25+0.25*($J29-$D29)/($J29-$K29),IF($D29>$L29,0.5+0.25*($K29-$D29)/($K29-$L29),IF($D29>$M29,0.75+0.25*($L29-$D29)/($L29-$M29),1))))),"") -> 0.50850507 | O29: =IF(N29="","",IF(N29<0.25,"Low",IF(N29<0.5,"Moderate",IF(N29<0.75,"Good","Excellent")))) -> Good
A30: E | B30: E3 | C30: Peak demand staggering | D30: =IFERROR(AVERAGE(INPUT_D_E!O$4:O$33),"") -> 0.76322927 | E30: =IFERROR(_xlfn.STDEV.S(INPUT_D_E!O$4:O$33),"") -> 0.038091936 | F30: =IFERROR(MIN(INPUT_D_E!O$4:O$33),"") -> 0.71248078 | G30: =IFERROR(MAX(INPUT_D_E!O$4:O$33),"") -> 0.81292855 | H30: - | I30: Positive | J30: =THRESHOLDS_WEIGHTS!F30 -> 0.25 | K30: =THRESHOLDS_WEIGHTS!G30 -> 0.5 | L30: =THRESHOLDS_WEIGHTS!H30 -> 0.75 | M30: =THRESHOLDS_WEIGHTS!I30 -> 0.8 | N30: =IFERROR(IF($I30="Positive",IF($D30<$J30,0,IF($D30<$K30,0.25+0.25*($D30-$J30)/($K30-$J30),IF($D30<$L30,0.5+0.25*($D30-$K30)/($L30-$K30),IF($D30<$M30,0.75+0.25*($D30-$L30)/($M30-$L30),1)))),IF($D30>$J30,0,IF($D30>$K30,0.25+0.25*($J30-$D30)/($J30-$K30),IF($D30>$L30,0.5+0.25*($K30-$D30)/($K30-$L30),IF($D30>$M30,0.75+0.25*($L30-$D30)/($L30-$M30),1))))),"") -> 0.81614637 | O30: =IF(N30="","",IF(N30<0.25,"Low",IF(N30<0.5,"Moderate",IF(N30<0.75,"Good","Excellent")))) -> Excellent
A31: E | B31: E4 | C31: Irrigation system factor | D31: =IFERROR(AVERAGE(INPUT_D_E!P$4:P$33),"") -> 1.007175 | E31: =IFERROR(_xlfn.STDEV.S(INPUT_D_E!P$4:P$33),"") -> 0.017447529 | F31: =IFERROR(MIN(INPUT_D_E!P$4:P$33),"") -> 0.98955181 | G31: =IFERROR(MAX(INPUT_D_E!P$4:P$33),"") -> 1.0469067 | H31: - | I31: Negative | J31: =THRESHOLDS_WEIGHTS!F31 -> 1.25 | K31: =THRESHOLDS_WEIGHTS!G31 -> 1.05 | L31: =THRESHOLDS_WEIGHTS!H31 -> 0.75 | M31: =THRESHOLDS_WEIGHTS!I31 -> 0.5 | N31: =IFERROR(IF($I31="Positive",IF($D31<$J31,0,IF($D31<$K31,0.25+0.25*($D31-$J31)/($K31-$J31),IF($D31<$L31,0.5+0.25*($D31-$K31)/($L31-$K31),IF($D31<$M31,0.75+0.25*($D31-$L31)/($M31-$L31),1)))),IF($D31>$J31,0,IF($D31>$K31,0.25+0.25*($J31-$D31)/($J31-$K31),IF($D31>$L31,0.5+0.25*($K31-$D31)/($K31-$L31),IF($D31>$M31,0.75+0.25*($L31-$D31)/($L31-$M31),1))))),"") -> 0.53568749 | O31: =IF(N31="","",IF(N31<0.25,"Low",IF(N31<0.5,"Moderate",IF(N31<0.75,"Good","Excellent")))) -> Good
A32: E | B32: E5 | C32: On-farm technology and control | D32: =IFERROR(AVERAGE(INPUT_D_E!Q$4:Q$33),"") -> 0.56628899 | E32: =IFERROR(_xlfn.STDEV.S(INPUT_D_E!Q$4:Q$33),"") -> 0.015757632 | F32: =IFERROR(MIN(INPUT_D_E!Q$4:Q$33),"") -> 0.55066358 | G32: =IFERROR(MAX(INPUT_D_E!Q$4:Q$33),"") -> 0.5914837 | H32: - | I32: Positive | J32: =THRESHOLDS_WEIGHTS!F32 -> 0.25 | K32: =THRESHOLDS_WEIGHTS!G32 -> 0.5 | L32: =THRESHOLDS_WEIGHTS!H32 -> 0.75 | M32: =THRESHOLDS_WEIGHTS!I32 -> 1 | N32: =IFERROR(IF($I32="Positive",IF($D32<$J32,0,IF($D32<$K32,0.25+0.25*($D32-$J32)/($K32-$J32),IF($D32<$L32,0.5+0.25*($D32-$K32)/($L32-$K32),IF($D32<$M32,0.75+0.25*($D32-$L32)/($M32-$L32),1)))),IF($D32>$J32,0,IF($D32>$K32,0.25+0.25*($J32-$D32)/($J32-$K32),IF($D32>$L32,0.5+0.25*($K32-$D32)/($K32-$L32),IF($D32>$M32,0.75+0.25*($L32-$D32)/($L32-$M32),1))))),"") -> 0.56628899 | O32: =IF(N32="","",IF(N32<0.25,"Low",IF(N32<0.5,"Moderate",IF(N32<0.75,"Good","Excellent")))) -> Good
A33: E | B33: E6 | C33: Water deficit stress tolerance | D33: =IFERROR(AVERAGE(INPUT_D_E!R$4:R$33),"") -> 0.54884269 | E33: =IFERROR(_xlfn.STDEV.S(INPUT_D_E!R$4:R$33),"") -> 0.0092998559 | F33: =IFERROR(MIN(INPUT_D_E!R$4:R$33),"") -> 0.5339345 | G33: =IFERROR(MAX(INPUT_D_E!R$4:R$33),"") -> 0.56121245 | H33: - | I33: Positive | J33: =THRESHOLDS_WEIGHTS!F33 -> 0 | K33: =THRESHOLDS_WEIGHTS!G33 -> 0.2 | L33: =THRESHOLDS_WEIGHTS!H33 -> 0.25 | M33: =THRESHOLDS_WEIGHTS!I33 -> 0.3 | N33: =IFERROR(IF($I33="Positive",IF($D33<$J33,0,IF($D33<$K33,0.25+0.25*($D33-$J33)/($K33-$J33),IF($D33<$L33,0.5+0.25*($D33-$K33)/($L33-$K33),IF($D33<$M33,0.75+0.25*($D33-$L33)/($M33-$L33),1)))),IF($D33>$J33,0,IF($D33>$K33,0.25+0.25*($J33-$D33)/($J33-$K33),IF($D33>$L33,0.5+0.25*($K33-$D33)/($K33-$L33),IF($D33>$M33,0.75+0.25*($L33-$D33)/($L33-$M33),1))))),"") -> 1 | O33: =IF(N33="","",IF(N33<0.25,"Low",IF(N33<0.5,"Moderate",IF(N33<0.75,"Good","Excellent")))) -> Excellent
A34: E | B34: E7 | C34: Share of permanent crops | D34: =IFERROR(AVERAGE(INPUT_D_E!S$4:S$33),"") -> 0.19744236 | E34: =IFERROR(_xlfn.STDEV.S(INPUT_D_E!S$4:S$33),"") -> 0.037360339 | F34: =IFERROR(MIN(INPUT_D_E!S$4:S$33),"") -> 0.12103906 | G34: =IFERROR(MAX(INPUT_D_E!S$4:S$33),"") -> 0.24275115 | H34: - | I34: Negative | J34: =THRESHOLDS_WEIGHTS!F34 -> 0.6 | K34: =THRESHOLDS_WEIGHTS!G34 -> 0.4 | L34: =THRESHOLDS_WEIGHTS!H34 -> 0.3 | M34: =THRESHOLDS_WEIGHTS!I34 -> 0.2 | N34: =IFERROR(IF($I34="Positive",IF($D34<$J34,0,IF($D34<$K34,0.25+0.25*($D34-$J34)/($K34-$J34),IF($D34<$L34,0.5+0.25*($D34-$K34)/($L34-$K34),IF($D34<$M34,0.75+0.25*($D34-$L34)/($M34-$L34),1)))),IF($D34>$J34,0,IF($D34>$K34,0.25+0.25*($J34-$D34)/($J34-$K34),IF($D34>$L34,0.5+0.25*($K34-$D34)/($K34-$L34),IF($D34>$M34,0.75+0.25*($L34-$D34)/($L34-$M34),1))))),"") -> 1 | O34: =IF(N34="","",IF(N34<0.25,"Low",IF(N34<0.5,"Moderate",IF(N34<0.75,"Good","Excellent")))) -> Excellent
A35: E | B35: E8 | C35: Soil water buffering capacity | D35: =IFERROR(AVERAGE(INPUT_D_E!T$4:T$33),"") -> 79.541354 | E35: =IFERROR(_xlfn.STDEV.S(INPUT_D_E!T$4:T$33),"") -> 2.5708539 | F35: =IFERROR(MIN(INPUT_D_E!T$4:T$33),"") -> 76.014548 | G35: =IFERROR(MAX(INPUT_D_E!T$4:T$33),"") -> 83.676408 | H35: mm | I35: Positive | J35: =THRESHOLDS_WEIGHTS!F35 -> 40 | K35: =THRESHOLDS_WEIGHTS!G35 -> 60 | L35: =THRESHOLDS_WEIGHTS!H35 -> 80 | M35: =THRESHOLDS_WEIGHTS!I35 -> 100 | N35: =IFERROR(IF($I35="Positive",IF($D35<$J35,0,IF($D35<$K35,0.25+0.25*($D35-$J35)/($K35-$J35),IF($D35<$L35,0.5+0.25*($D35-$K35)/($L35-$K35),IF($D35<$M35,0.75+0.25*($D35-$L35)/($M35-$L35),1)))),IF($D35>$J35,0,IF($D35>$K35,0.25+0.25*($J35-$D35)/($J35-$K35),IF($D35>$L35,0.5+0.25*($K35-$D35)/($K35-$L35),IF($D35>$M35,0.75+0.25*($L35-$D35)/($L35-$M35),1))))),"") -> 0.74426693 | O35: =IF(N35="","",IF(N35<0.25,"Low",IF(N35<0.5,"Moderate",IF(N35<0.75,"Good","Excellent")))) -> Good
A36: E | B36: E9 | C36: Alternative local access to storage | D36: =IFERROR(AVERAGE(INPUT_D_E!U$4:U$33),"") -> 0.41686881 | G36: =IFERROR(MAX(INPUT_D_E!U$4:U$33),"") -> 0.41686881 | H36: - | I36: Positive | J36: =THRESHOLDS_WEIGHTS!F36 -> 0.25 | K36: =THRESHOLDS_WEIGHTS!G36 -> 0.5 | L36: =THRESHOLDS_WEIGHTS!H36 -> 0.75 | M36: =THRESHOLDS_WEIGHTS!I36 -> 1 | N36: =IFERROR(IF($I36="Positive",IF($D36<$J36,0,IF($D36<$K36,0.25+0.25*($D36-$J36)/($K36-$J36),IF($D36<$L36,0.5+0.25*($D36-$K36)/($L36-$K36),IF($D36<$M36,0.75+0.25*($D36-$L36)/($M36-$L36),1)))),IF($D36>$J36,0,IF($D36>$K36,0.25+0.25*($J36-$D36)/($J36-$K36),IF($D36>$L36,0.5+0.25*($K36-$D36)/($K36-$L36),IF($D36>$M36,0.75+0.25*($L36-$D36)/($L36-$M36),1))))),"") -> 0.41686881 | O36: =IF(N36="","",IF(N36<0.25,"Low",IF(N36<0.5,"Moderate",IF(N36<0.75,"Good","Excellent")))) -> Moderate
A37: E | B37: E10 | C37: Chill requirement adequacy indicator | D37: =IFERROR(AVERAGE(INPUT_D_E!V$4:V$33),"") -> 0.96816475 | E37: =IFERROR(_xlfn.STDEV.S(INPUT_D_E!V$4:V$33),"") -> 0.037419715 | F37: =IFERROR(MIN(INPUT_D_E!V$4:V$33),"") -> 0.90774403 | G37: =IFERROR(MAX(INPUT_D_E!V$4:V$33),"") -> 1 | H37: - | I37: Positive | J37: =THRESHOLDS_WEIGHTS!F37 -> 0.7 | K37: =THRESHOLDS_WEIGHTS!G37 -> 0.85 | L37: =THRESHOLDS_WEIGHTS!H37 -> 0.95 | M37: =THRESHOLDS_WEIGHTS!I37 -> 1 | N37: =IFERROR(IF($I37="Positive",IF($D37<$J37,0,IF($D37<$K37,0.25+0.25*($D37-$J37)/($K37-$J37),IF($D37<$L37,0.5+0.25*($D37-$K37)/($L37-$K37),IF($D37<$M37,0.75+0.25*($D37-$L37)/($M37-$L37),1)))),IF($D37>$J37,0,IF($D37>$K37,0.25+0.25*($J37-$D37)/($J37-$K37),IF($D37>$L37,0.5+0.25*($K37-$D37)/($K37-$L37),IF($D37>$M37,0.75+0.25*($L37-$D37)/($L37-$M37),1))))),"") -> 0.84082376 | O37: =IF(N37="","",IF(N37<0.25,"Low",IF(N37<0.5,"Moderate",IF(N37<0.75,"Good","Excellent")))) -> Excellent
A38: F | B38: F1 | C38: Preparedness, alert thresholds and response rules | D38: =IFERROR(AVERAGEIFS(INPUT_F!$D:$D,INPUT_F!$A:$A,"PAR"),"") -> 0.8125 | H38: - | I38: Positive | J38: =THRESHOLDS_WEIGHTS!F38 -> 0.25 | K38: =THRESHOLDS_WEIGHTS!G38 -> 0.5 | L38: =THRESHOLDS_WEIGHTS!H38 -> 0.75 | M38: =THRESHOLDS_WEIGHTS!I38 -> 1 | N38: =IFERROR(IF($I38="Positive",IF($D38<$J38,0,IF($D38<$K38,0.25+0.25*($D38-$J38)/($K38-$J38),IF($D38<$L38,0.5+0.25*($D38-$K38)/($L38-$K38),IF($D38<$M38,0.75+0.25*($D38-$L38)/($M38-$L38),1)))),IF($D38>$J38,0,IF($D38>$K38,0.25+0.25*($J38-$D38)/($J38-$K38),IF($D38>$L38,0.5+0.25*($K38-$D38)/($K38-$L38),IF($D38>$M38,0.75+0.25*($L38-$D38)/($L38-$M38),1))))),"") -> 0.8125 | O38: =IF(N38="","",IF(N38<0.25,"Low",IF(N38<0.5,"Moderate",IF(N38<0.75,"Good","Excellent")))) -> Excellent
A39: F | B39: F2 | C39: Operational monitoring and control capacity | D39: =IFERROR(AVERAGEIFS(INPUT_F!$D:$D,INPUT_F!$A:$A,"OMC"),"") -> 0.625 | H39: - | I39: Positive | J39: =THRESHOLDS_WEIGHTS!F39 -> 0.25 | K39: =THRESHOLDS_WEIGHTS!G39 -> 0.5 | L39: =THRESHOLDS_WEIGHTS!H39 -> 0.75 | M39: =THRESHOLDS_WEIGHTS!I39 -> 1 | N39: =IFERROR(IF($I39="Positive",IF($D39<$J39,0,IF($D39<$K39,0.25+0.25*($D39-$J39)/($K39-$J39),IF($D39<$L39,0.5+0.25*($D39-$K39)/($L39-$K39),IF($D39<$M39,0.75+0.25*($D39-$L39)/($M39-$L39),1)))),IF($D39>$J39,0,IF($D39>$K39,0.25+0.25*($J39-$D39)/($J39-$K39),IF($D39>$L39,0.5+0.25*($K39-$D39)/($K39-$L39),IF($D39>$M39,0.75+0.25*($L39-$D39)/($L39-$M39),1))))),"") -> 0.625 | O39: =IF(N39="","",IF(N39<0.25,"Low",IF(N39<0.5,"Moderate",IF(N39<0.75,"Good","Excellent")))) -> Good
A40: F | B40: F3 | C40: Financial and infrastructure management capacity | D40: =IFERROR(AVERAGEIFS(INPUT_F!$D:$D,INPUT_F!$A:$A,"FIM"),"") -> 0.5 | H40: - | I40: Positive | J40: =THRESHOLDS_WEIGHTS!F40 -> 0.25 | K40: =THRESHOLDS_WEIGHTS!G40 -> 0.5 | L40: =THRESHOLDS_WEIGHTS!H40 -> 0.75 | M40: =THRESHOLDS_WEIGHTS!I40 -> 1 | N40: =IFERROR(IF($I40="Positive",IF($D40<$J40,0,IF($D40<$K40,0.25+0.25*($D40-$J40)/($K40-$J40),IF($D40<$L40,0.5+0.25*($D40-$K40)/($L40-$K40),IF($D40<$M40,0.75+0.25*($D40-$L40)/($M40-$L40),1)))),IF($D40>$J40,0,IF($D40>$K40,0.25+0.25*($J40-$D40)/($J40-$K40),IF($D40>$L40,0.5+0.25*($K40-$D40)/($K40-$L40),IF($D40>$M40,0.75+0.25*($L40-$D40)/($L40-$M40),1))))),"") -> 0.5 | O40: =IF(N40="","",IF(N40<0.25,"Low",IF(N40<0.5,"Moderate",IF(N40<0.75,"Good","Excellent")))) -> Good
A41: F | B41: F4 | C41: Participation, communication and compliance | D41: =IFERROR(AVERAGEIFS(INPUT_F!$D:$D,INPUT_F!$A:$A,"PCC"),"") -> 0.4375 | H41: - | I41: Positive | J41: =THRESHOLDS_WEIGHTS!F41 -> 0.25 | K41: =THRESHOLDS_WEIGHTS!G41 -> 0.5 | L41: =THRESHOLDS_WEIGHTS!H41 -> 0.75 | M41: =THRESHOLDS_WEIGHTS!I41 -> 1 | N41: =IFERROR(IF($I41="Positive",IF($D41<$J41,0,IF($D41<$K41,0.25+0.25*($D41-$J41)/($K41-$J41),IF($D41<$L41,0.5+0.25*($D41-$K41)/($L41-$K41),IF($D41<$M41,0.75+0.25*($D41-$L41)/($M41-$L41),1)))),IF($D41>$J41,0,IF($D41>$K41,0.25+0.25*($J41-$D41)/($J41-$K41),IF($D41>$L41,0.5+0.25*($K41-$D41)/($K41-$L41),IF($D41>$M41,0.75+0.25*($L41-$D41)/($L41-$M41),1))))),"") -> 0.4375 | O41: =IF(N41="","",IF(N41<0.25,"Low",IF(N41<0.5,"Moderate",IF(N41<0.75,"Good","Excellent")))) -> Moderate

Sheet DASHBOARD_EXPORTS
A1: Dashboard and export-ready summaries
A3: Overall CIS resilience score | B3: =J12 -> A | C3: Class | D3: =IFERROR(AVERAGE(C9:C14),"") -> 0.68972515
A4: Assessment period | B4: =CONTROL_YEARS!B6&"–"&CONTROL_YEARS!B7 -> 2016–2025 | C4: Years | D4: =CONTROL_YEARS!B8 -> 10
A5: Case study | B5: =CONTROL_YEARS!B4 -> Minutos Collective Irrigation System | C5: Scenario rule | D5: =CONTROL_YEARS!B9 -> Yes
A8: Subsystem | B8: Subsystem name | C8: Score | D8: Class | I8: Indicator | J8: Subsystem | K8: Score | L8: Class
A9: A | B9: Water-resource resilience | C9: =IFERROR(AVERAGE(K9:K14),"") -> 0.58253406 | D9: =IF(C9="","",IF(C9<0.33,"Low",IF(C9<0.67,"Moderate",IF(C9<0.9,"Good","Excellent")))) -> Moderate | I9: =CALC_NORMALISATION!B4 -> A1 | J9: =CALC_NORMALISATION!A4 -> A | K9: =CALC_NORMALISATION!N4 -> 0.65625 | L9: =CALC_NORMALISATION!O4 -> Good
A10: B | B10: Reservoir and service performance | C10: =IFERROR(AVERAGEIFS(CALC_NORMALISATION!$N:$N,CALC_NORMALISATION!$A:$A,A10),"") -> 0.7940625 | D10: =IF(C10="","",IF(C10<0.33,"Low",IF(C10<0.67,"Moderate",IF(C10<0.9,"Good","Excellent")))) -> Good | I10: =CALC_NORMALISATION!B5 -> A2 | J10: =CALC_NORMALISATION!A5 -> A | K10: =CALC_NORMALISATION!N5 -> 0.77147865 | L10: =CALC_NORMALISATION!O5 -> Excellent
A11: C | B11: Conveyance and distribution-network performance | C11: =IFERROR(AVERAGEIFS(CALC_NORMALISATION!$N:$N,CALC_NORMALISATION!$A:$A,A11),"") -> 0.75748682 | D11: =IF(C11="","",IF(C11<0.33,"Low",IF(C11<0.67,"Moderate",IF(C11<0.9,"Good","Excellent")))) -> Good | I11: =CALC_NORMALISATION!B6 -> A3 | J11: =CALC_NORMALISATION!A6 -> A | K11: =CALC_NORMALISATION!N6 -> 0.77083333 | L11: =CALC_NORMALISATION!O6 -> Excellent
A12: D | B12: Pumping and energy resilience | C12: =IFERROR(AVERAGEIFS(CALC_NORMALISATION!$N:$N,CALC_NORMALISATION!$A:$A,A12),"") -> 0.70585082 | D12: =IF(C12="","",IF(C12<0.33,"Low",IF(C12<0.67,"Moderate",IF(C12<0.9,"Good","Excellent")))) -> Good | I12: =CALC_NORMALISATION!B7 -> A4 | J12: =CALC_NORMALISATION!A7 -> A | K12: =CALC_NORMALISATION!N7 -> 0.25 | L12: =CALC_NORMALISATION!O7 -> Moderate
A13: E | B13: Farm-level adaptive capacity | C13: =IFERROR(AVERAGEIFS(CALC_NORMALISATION!$N:$N,CALC_NORMALISATION!$A:$A,A13),"") -> 0.70466672 | D13: =IF(C13="","",IF(C13<0.33,"Low",IF(C13<0.67,"Moderate",IF(C13<0.9,"Good","Excellent")))) -> Good | I13: =CALC_NORMALISATION!B8 -> A5 | J13: =CALC_NORMALISATION!A8 -> A | K13: =CALC_NORMALISATION!N8 -> 0.79664237 | L13: =CALC_NORMALISATION!O8 -> Excellent
A14: F | B14: CIS drought-management capacity | C14: =IFERROR(AVERAGEIFS(CALC_NORMALISATION!$N:$N,CALC_NORMALISATION!$A:$A,A14),"") -> 0.59375 | D14: =IF(C14="","",IF(C14<0.33,"Low",IF(C14<0.67,"Moderate",IF(C14<0.9,"Good","Excellent")))) -> Moderate | I14: =CALC_NORMALISATION!B9 -> A6 | J14: =CALC_NORMALISATION!A9 -> A | K14: =CALC_NORMALISATION!N9 -> 0.25 | L14: =CALC_NORMALISATION!O9 -> Moderate
C15: 0.33 | I15: =CALC_NORMALISATION!B10 -> B1 | J15: =CALC_NORMALISATION!A10 -> B | K15: =CALC_NORMALISATION!N10 -> 0.9921875 | L15: =CALC_NORMALISATION!O10 -> Excellent
I16: =CALC_NORMALISATION!B11 -> B2 | J16: =CALC_NORMALISATION!A11 -> B | K16: =CALC_NORMALISATION!N11 -> 0.9921875 | L16: =CALC_NORMALISATION!O11 -> Excellent
I17: =CALC_NORMALISATION!B12 -> B3 | J17: =CALC_NORMALISATION!A12 -> B | K17: =CALC_NORMALISATION!N12 -> 0.9921875 | L17: =CALC_NORMALISATION!O12 -> Excellent
I18: =CALC_NORMALISATION!B13 -> B4 | J18: =CALC_NORMALISATION!A13 -> B | K18: =CALC_NORMALISATION!N13 -> 0.99375 | L18: =CALC_NORMALISATION!O13 -> Excellent
I19: =CALC_NORMALISATION!B14 -> B5 | J19: =CALC_NORMALISATION!A14 -> B | K19: =CALC_NORMALISATION!N14 -> 0 | L19: =CALC_NORMALISATION!O14 -> Low
I20: =CALC_NORMALISATION!B15 -> C1 | J20: =CALC_NORMALISATION!A15 -> C | K20: =CALC_NORMALISATION!N15 -> 0.96995632 | L20: =CALC_NORMALISATION!O15 -> Excellent
I21: =CALC_NORMALISATION!B16 -> C2 | J21: =CALC_NORMALISATION!A16 -> C | K21: =CALC_NORMALISATION!N16 -> 0.91093091 | L21: =CALC_NORMALISATION!O16 -> Excellent
I22: =CALC_NORMALISATION!B17 -> C3 | J22: =CALC_NORMALISATION!A17 -> C | K22: =CALC_NORMALISATION!N17 -> 0.62762315 | L22: =CALC_NORMALISATION!O17 -> Good
I23: =CALC_NORMALISATION!B18 -> C4 | J23: =CALC_NORMALISATION!A18 -> C | K23: =CALC_NORMALISATION!N18 -> 0.69468319 | L23: =CALC_NORMALISATION!O18 -> Good
I24: =CALC_NORMALISATION!B19 -> C5 | J24: =CALC_NORMALISATION!A19 -> C | K24: =CALC_NORMALISATION!N19 -> 0.58424052 | L24: =CALC_NORMALISATION!O19 -> Good
I25: =CALC_NORMALISATION!B20 -> D1 | J25: =CALC_NORMALISATION!A20 -> D | K25: =CALC_NORMALISATION!N20 -> 0.83329174 | L25: =CALC_NORMALISATION!O20 -> Excellent
I26: =CALC_NORMALISATION!B21 -> D2 | J26: =CALC_NORMALISATION!A21 -> D | K26: =CALC_NORMALISATION!N21 -> 0.79078849 | L26: =CALC_NORMALISATION!O21 -> Excellent
I27: =CALC_NORMALISATION!B22 -> D3 | J27: =CALC_NORMALISATION!A22 -> D | K27: =CALC_NORMALISATION!N22 -> 0.69324934 | L27: =CALC_NORMALISATION!O22 -> Good
... I46: =CALC_NORMALISATION!B41 -> F4 | J46: =CALC_NORMALISATION!A41 -> F | K46: =CALC_NORMALISATION!N41 -> 0.4375 | L46: =CALC_NORMALISATION!O41 -> Moderate

Sheet INPUT_A_TO_C
A1: Inputs A–C: annual indicators
A3: Year | B3: A1 Rt | C3: A2 Rv | D3: A3 L | E3: A4 Cv | F3: A5 BC | G3: A6 CD | H3: Notes | J3: Period | K3: Scenario | L3: B1 RtB | M3: B2 RvB | N3: B3 VB | O3: B4 RecB | P3: B5 SSCB | Q3: Notes | S3: Year | T3: C1 Hydrant reliability | U3: C2 Network reliability | V3: C3 RPD | W3: C4 Critical deficit | X3: C5 Max deficit | Y3: Notes
A4: =CONTROL_YEARS!A14 -> 2016 | B4: =[1]SA_calcu_indicators!G4 -> 1 | C4: =[1]SA_calcu_indicators!H4 -> 1 | D4: =[1]SA_calcu_indicators!I4 -> 0 | E4: =[1]SA_calcu_indicators!J4 -> 1.5612659 | F4: =[1]SA_calcu_indicators!K4 -> 25.869852 | G4: =[1]SA_calcu_indicators!L4 -> 6.7561039 | J4: =CONTROL_YEARS!B5 -> Present 10-year period | L4: =[2]B_EXPORT_TABLE!$B$9 -> 0.99375 | M4: =[2]B_EXPORT_TABLE!$B$9 -> 0.99375 | N4: =[2]B_EXPORT_TABLE!$B$9 -> 0.99375 | O4: =[2]B_EXPORT_TABLE!$B$9 -> 0.99375 | P4: =[2]B_EXPORT_TABLE!$B$9 -> 0.99375 | S4: =CONTROL_YEARS!A14 -> 2016 | T4: =[3]C_FINAL_TOOL!B9 -> 0.97626513 | U4: =[3]C_FINAL_TOOL!C9 -> 0.94936709 | V4: =[3]C_FINAL_TOOL!D9 -> 0.60129413 | W4: =[3]C_FINAL_TOOL!E9 -> 0.49990097 | X4: =[3]C_FINAL_TOOL!F9 -> 0.55037189
A5: =CONTROL_YEARS!A15 -> 2017 | B5: =[1]SA_calcu_indicators!G5 -> 0.75 | C5: =[1]SA_calcu_indicators!H5 -> 0.96357805 | D5: =[1]SA_calcu_indicators!I5 -> 1 | E5: =[1]SA_calcu_indicators!J5 -> 2.3320146 | F5: =[1]SA_calcu_indicators!K5 -> 90.830935 | G5: =[1]SA_calcu_indicators!L5 -> 23.721173 | S5: =CONTROL_YEARS!A15 -> 2017 | T5: =[3]C_FINAL_TOOL!B10 -> 0.97501816 | U5: =[3]C_FINAL_TOOL!C10 -> 0.96202532 | V5: =[3]C_FINAL_TOOL!D10 -> 0.64833247 | W5: =[3]C_FINAL_TOOL!E10 -> 0.50104234 | X5: =[3]C_FINAL_TOOL!F10 -> 0.55458604
A6: =CONTROL_YEARS!A16 -> 2018 | B6: =[1]SA_calcu_indicators!G6 -> 0.83333333 | C6: =[1]SA_calcu_indicators!H6 -> 0.93986504 | D6: =[1]SA_calcu_indicators!I6 -> 4 | E6: =[1]SA_calcu_indicators!J6 -> 2.2886757 | F6: =[1]SA_calcu_indicators!K6 -> 4.8587336 | G6: =[1]SA_calcu_indicators!L6 -> 1.2688943 | S6: =CONTROL_YEARS!A16 -> 2018 | T6: =[3]C_FINAL_TOOL!B11 -> 0.9759322 | U6: =[3]C_FINAL_TOOL!C11 -> 0.96202532 | V6: =[3]C_FINAL_TOOL!D11 -> 0.61001838 | W6: =[3]C_FINAL_TOOL!E11 -> 0.49936024 | X6: =[3]C_FINAL_TOOL!F11 -> 0.55690083
A7: =CONTROL_YEARS!A17 -> 2019 | B7: =[1]SA_calcu_indicators!G7 -> 0.25 | C7: =[1]SA_calcu_indicators!H7 -> 0.059809026 | D7: =[1]SA_calcu_indicators!I7 -> 9 | E7: =[1]SA_calcu_indicators!J7 -> 2.3680953 | F7: =[1]SA_calcu_indicators!K7 -> 27.329636 | G7: =[1]SA_calcu_indicators!L7 -> 7.1373372 | S7: =CONTROL_YEARS!A17 -> 2019 | T7: =[3]C_FINAL_TOOL!B12 -> 0.9749092 | U7: =[3]C_FINAL_TOOL!C12 -> 0.94936709 | V7: =[3]C_FINAL_TOOL!D12 -> 0.63987618 | W7: =[3]C_FINAL_TOOL!E12 -> 0.50076627 | X7: =[3]C_FINAL_TOOL!F12 -> 0.554328
A8: =CONTROL_YEARS!A18 -> 2020 | B8: =[1]SA_calcu_indicators!G8 -> 0.91666667 | C8: =[1]SA_calcu_indicators!H8 -> 0.98303478 | D8: =[1]SA_calcu_indicators!I8 -> 1 | E8: =[1]SA_calcu_indicators!J8 -> 1.527372 | F8: =[1]SA_calcu_indicators!K8 -> 12.700056 | G8: =[1]SA_calcu_indicators!L8 -> 3.316714 | S8: =CONTROL_YEARS!A18 -> 2020 | T8: =[3]C_FINAL_TOOL!B13 -> 0.97582324 | U8: =[3]C_FINAL_TOOL!C13 -> 0.96202532 | V8: =[3]C_FINAL_TOOL!D13 -> 0.61031492 | W8: =[3]C_FINAL_TOOL!E13 -> 0.49944204 | X8: =[3]C_FINAL_TOOL!F13 -> 0.55392089
A9: =CONTROL_YEARS!A19 -> 2021 | B9: =[1]SA_calcu_indicators!G9 -> 0.91666667 | C9: =[1]SA_calcu_indicators!H9 -> 0.99999759 | D9: =[1]SA_calcu_indicators!I9 -> 0 | E9: =[1]SA_calcu_indicators!J9 -> 1.854971 | F9: =[1]SA_calcu_indicators!K9 -> 5.2828921 | G9: =[1]SA_calcu_indicators!L9 -> 1.3796665 | S9: =CONTROL_YEARS!A19 -> 2021 | T9: =[3]C_FINAL_TOOL!B14 -> 0.97512107 | U9: =[3]C_FINAL_TOOL!C14 -> 0.96202532 | V9: =[3]C_FINAL_TOOL!D14 -> 0.63629196 | W9: =[3]C_FINAL_TOOL!E14 -> 0.50087193 | X9: =[3]C_FINAL_TOOL!F14 -> 0.55567438
A10: =CONTROL_YEARS!A20 -> 2022 | B10: =[1]SA_calcu_indicators!G10 -> 0.16666667 | C10: =[1]SA_calcu_indicators!H10 -> 0.87776459 | D10: =[1]SA_calcu_indicators!I10 -> 5.5 | E10: =[1]SA_calcu_indicators!J10 -> 2.3569793 | F10: =[1]SA_calcu_indicators!K10 -> 10.672448 | G10: =[1]SA_calcu_indicators!L10 -> 2.787189 | S10: =CONTROL_YEARS!A20 -> 2022 | T10: =[3]C_FINAL_TOOL!B15 -> 0.99161486 | U10: =[3]C_FINAL_TOOL!C15 -> 0.92708333 | V10: =[3]C_FINAL_TOOL!D15 -> 0.058028261 | W10: =[3]C_FINAL_TOOL!E15 -> 0.10650384 | X10: =[3]C_FINAL_TOOL!F15 -> 0.27403071
A11: =CONTROL_YEARS!A21 -> 2023 | B11: =[1]SA_calcu_indicators!G11 -> 0.41666667 | C11: =[1]SA_calcu_indicators!H11 -> 0.34778017 | D11: =[1]SA_calcu_indicators!I11 -> 7 | E11: =[1]SA_calcu_indicators!J11 -> 2.4581429 | F11: =[1]SA_calcu_indicators!K11 -> 9.9082909 | G11: =[1]SA_calcu_indicators!L11 -> 2.5876237 | S11: =CONTROL_YEARS!A21 -> 2023 | T11: =[3]C_FINAL_TOOL!B16 -> 0.99130405 | U11: =[3]C_FINAL_TOOL!C16 -> 0.91666667 | V11: =[3]C_FINAL_TOOL!D16 -> 0.061643262 | W11: =[3]C_FINAL_TOOL!E16 -> 0.10963378 | X11: =[3]C_FINAL_TOOL!F16 -> 0.23593793
A12: =CONTROL_YEARS!A22 -> 2024 | B12: =[1]SA_calcu_indicators!G12 -> 1 | C12: =[1]SA_calcu_indicators!H12 -> 1 | D12: =[1]SA_calcu_indicators!I12 -> 0 | E12: =[1]SA_calcu_indicators!J12 -> 1.1979349 | F12: =[1]SA_calcu_indicators!K12 -> 4.0023524 | G12: =[1]SA_calcu_indicators!L12 -> 1.045244 | S12: =CONTROL_YEARS!A22 -> 2024 | T12: =[3]C_FINAL_TOOL!B17 -> 0.99172973 | U12: =[3]C_FINAL_TOOL!C17 -> 0.95833333 | V12: =[3]C_FINAL_TOOL!D17 -> 0.05737454 | W12: =[3]C_FINAL_TOOL!E17 -> 0.11192855 | X12: =[3]C_FINAL_TOOL!F17 -> 0.24219634
