Workbook

Sheet 00_README
A1: CIS Integrated Resilience Framework — V3 Public Tool
A3: Field | B3: Description
A4: Version | B4: v3-public
A5: Assessment period | B5: 2016–2025
A6: Purpose | B6: Autonomous public workbook integrating Subsystems A–F, with visible formulas for normalisation, aggregation, GIR-ensemble uncertainty, pre/post-expansion comparison and methodological sensitivity.
A7: Primary weighting | B7: Dimension-balanced within each subsystem; equal weights among the six subsystem indices.
A8: Comparator weighting | B8: Equal-indicator weighting within each subsystem.
A9: GIR ensemble | B9: Four complete variants: ISW50_EffLow, ISW50_EffHigh, ISW90_EffLow and ISW90_EffHigh. The arithmetic mean and min–max range are reported separately.
A10: Expansion comparison | B10: Pre-expansion: 2016–2020; transition year: 2021; post-expansion: 2022–2025.
A11: Sensitivity | B11: Threshold anchors are shifted simultaneously by ±20%. Lenient and stricter cases respect indicator orientation.
A12: Leave-one-out | B12: Both leave-one-indicator-out and leave-one-subsystem-out robustness checks are included.
A13: Stress and adaptation scenarios | B13: Not included. Those prospective scenario families belong to Paper 6 and are methodologically separate from this historical diagnostic tool.
A14: External links | B14: None. Source values are embedded from the six public subsystem workbooks.
... A16: Important interpretation | B16: Pre/post contrasts are descriptive and should not be interpreted as causal effects of the 2021 expansion.

Sheet 01_CONTROL
A1: Control panel
A3: Parameter | B3: Value | C3: Use | D3: Editable
A4: Assessment start | B4: 2016 | C4: Historical assessment | D4: Yes
A5: Pre-expansion start | B5: 2016 | C5: Pre/post comparison | D5: Yes
A6: Pre-expansion end | B6: 2020 | C6: Pre/post comparison | D6: Yes
A7: Transition year | B7: 2021 | C7: Excluded from pre/post means | D7: Yes
A8: Post-expansion start | B8: 2022 | C8: Pre/post comparison | D8: Yes
A9: Post-expansion end | B9: 2025 | C9: Pre/post comparison | D9: Yes
A10: Threshold sensitivity | B10: 0.2 | C10: Lenient/stricter anchor shift | D10: Yes
A11: Selected weighting | B11: Dimension-balanced | C11: Preferred dashboard result | D11: Yes
A12: Class boundaries | B12: 0.25 / 0.50 / 0.75 | C12: Low / Moderate / Good / Excellent | D12: No
A13: Subsystem weights | B13: Equal, 1/6 | C13: Overall CIS index | D13: No
A14: Stress/adaptation module | B14: Excluded | C14: Paper 6 | D14: No

Sheet 02_SOURCE_REGISTER
A1: Embedded source register
A3: Subsystem | B3: Public workbook | C3: Primary public output | D3: Imported content | E3: External links | F3: Version | G3: Formula visibility | H3: Status | I3: Notes
A4: A | B4: RI_SA_water_availability_tool_v1_1_public.xlsx | C4: EXPORT_CIS | D4: Period and annual values | E4: None | F4: v1.1-public | G4: Source formulas retained in subsystem workbook | H4: Imported | I4: Hydrological boundary condition.
A5: B | B5: RI_SB_reservoir_service_tool_v1_public.xlsx | C5: B_CALC_PERIOD / B_CALC_ANNUAL | D5: Four variants and annual values | E5: None | F5: v1.1-public | G5: Correct B3/B4/B5 columns used | H5: Imported | I5: Complete GIR scenario chains.
A6: C | B6: RI_SC_conveyance_distribution_tool_v1_1_public.xlsx | C6: C_INPUT_PREPROCESSED / C_FINAL_TOOL | D6: Four variants and annual values | E6: None | F6: v1.1-public | G6: C3 follows public C_FINAL_TOOL scaling (K×100) | H6: Imported | I6: C5 uses Pmin=40 m.
A7: D | B7: RI_SD_energy_performance_tool_v1_1_public.xlsx | C7: 02_EXPORT_CIS | D7: Assessment and annual values | E7: None | F7: v1.1-public | G7: D1–D3 use 2018–2025; D7 is 2025 snapshot | H7: Imported | I7: Missing years remain blank.
A8: E | B8: RI_SE_on_farm_performance_tool_v1_1_public.xlsx | C8: 02_EXPORT_CIS / 03_ENSEMBLE | D8: Assessment, annual and variant values | E8: None | F8: v1.1-public | G8: E1/E2 four variants; E4 efficiency variants | H8: Imported | I8: E3 remains ensemble-central.
A9: F | B9: RI_SF_drought_management_tool_v1_1_public.xlsx | C9: 02_EXPORT_CIS | D9: Assessment-period scores | E9: None | F9: v1.1-public | G9: Formula-driven F1–F4 | H9: Imported | I9: No annual reconstruction.

Sheet 03_CATALOG
A1: Indicator catalog and operational dimensions
A3: Subsystem | B3: Code | C3: Indicator | D3: Unit | E3: Orientation | F3: Indicator type | G3: Operational dimension | H3: Operational role | I3: Failure mechanism | J3: Decision supported | K3: Temporal basis | L3: Ensemble dependency | M3: Coverage | N3: Aggregation status | O3: Active | P3: Equal weight | Q3: Dimension weight | R3: Notes
A4: A | B4: A1 | C4: Time-based inflow reliability | D4: – | E4: Positive | F4: Performance | G4: Inflow adequacy | H4: Frequency with which monthly inflow meets the seasonal minimum threshold | I4: Frequent low-inflow months | J4: Drought alert and seasonal storage planning | K4: Period; annual diagnostic | L4: No | M4: 2016–2025 monthly inflow | N4: Active — retained | O4: Yes | P4: 0.16666667 | Q4: 0.125
A5: A | B5: A2 | C5: Volumetric inflow reliability | D5: – | E5: Positive | F5: Performance | G5: Inflow adequacy | H5: Cumulative inflow deficit severity relative to seasonal thresholds | I5: Large cumulative inflow deficits | J5: Allocation and carry-over planning | K5: Period; annual diagnostic | L5: No | M5: 2016–2025 monthly inflow | N5: Active — retained | O5: Yes | P5: 0.16666667 | Q5: 0.125
A6: A | B6: A3 | C6: Mean drought duration | D6: months | E6: Negative | F6: Stress | G6: Drought persistence | H6: Persistence of consecutive below-threshold inflow months | I6: Prolonged hydrological drought | J6: Multi-season restriction and recovery planning | K6: Period; annual diagnostic | L6: No | M6: 2016–2025 monthly inflow | N6: Active — retained | O6: Yes | P6: 0.16666667 | Q6: 0.25
A7: A | B7: A4 | C7: Coefficient of variation of annual inflow | D7: – | E7: Negative | F7: Exposure | G7: Interannual variability | H7: Year-to-year instability of annual inflow | I7: Unpredictable replenishment and sequencing risk | J7: Carry-over and allocation safety margins | K7: Period only | L7: No | M7: 2016–2025 annual inflow | N7: Active — retained | O7: Yes | P7: 0.16666667 | Q7: 0.25
A8: A | B8: A5 | C8: Buffering capacity | D8: – | E8: Positive | F8: Structural proxy | G8: Storage context and dependence | H8: Theoretical regulation potential relative to mean annual inflow | I8: Insufficient storage relative to inflow regime | J8: Long-term storage planning | K8: Period only | L8: No | M8: Net capacity and period mean inflow | N8: Active — retained | O8: Yes | P8: 0.16666667 | Q8: 0.125 | R8: Share a dimension; A5 is structural potential and A6 is dependence/stress.
A9: A | B9: A6 | C9: Carry-over dependence | D9: – | E9: Negative | F9: Stress | G9: Storage context and dependence | H9: Increase in dependence on multi-year storage relative to baseline inflow | I9: Service reliant on accumulated storage under declining inflow | J9: Carry-over safeguards and drought rules | K9: Period only | L9: No | M9: Baseline and period mean inflow | N9: Active — retained | O9: Yes | P9: 0.16666667 | Q9: 0.125 | R9: Share a dimension; A5 is structural potential and A6 is dependence/stress.
A10: B | B10: B1 | C10: Time-based supply reliability | D10: – | E10: Positive | F10: Performance | G10: Supply adequacy | H10: Frequency of months in which source demand is fully supplied | I10: Repeated service-failure months | J10: Reservoir operating rules and allocation | K10: Period and annual | L10: Yes | M10: 2016–2025; four GIR variants | N10: Active — retained | O10: Yes | P10: 0.2 | Q10: 0.125
A11: B | B11: B2 | C11: Volumetric supply reliability | D11: – | E11: Positive | F11: Performance | G11: Supply adequacy | H11: Share of source demand effectively supplied | I11: Large cumulative service deficit | J11: Supply targets and deficit allocation | K11: Period and annual | L11: Yes | M11: 2016–2025; four GIR variants | N11: Active — retained | O11: Yes | P11: 0.2 | Q11: 0.125
A12: B | B12: B3 | C12: Mean supply performance during failure | D12: – | E12: Positive | F12: Performance | G12: Failure severity | H12: Mean proportion of demand supplied during failure months | I12: Severe partial supply during failure | J12: Rationing intensity and priority rules | K12: Period and annual | L12: Yes | M12: 2016–2025; four GIR variants | N12: Active — retained | O12: Yes | P12: 0.2 | Q12: 0.25
A13: B | B13: B4 | C13: Recovery after failure | D13: – | E13: Positive | F13: Performance | G13: Recovery | H13: Probability of returning to satisfactory service after failure | I13: Persistent service failure | J13: Recovery rules and reserve margins | K13: Period and annual | L13: Yes | M13: 2016–2025; four GIR variants | N13: Active — retained | O13: Yes | P13: 0.2 | Q13: 0.25
A14: B | B14: B5 | C14: Spill–shortage coexistence frequency | D14: – | E14: Negative | F14: Performance | G14: Operational coherence | H14: Frequency of years with both spill and irrigation shortage | I14: Storage/operation mismatch | J14: Rule-curve and timing adjustments | K14: Period and annual | L14: Yes | M14: 2016–2025; four GIR variants | N14: Active — retained | O14: Yes | P14: 0.2 | Q14: 0.25
A15: C | B15: C1 | C15: Hydrant pressure reliability | D15: – | E15: Positive | F15: Performance | G15: Pressure reliability | H15: Overall reliability across open hydrant–simulation records (current workbook implementation) | I15: Frequent pressure failure at operating hydrants | J15: Network operation and rehabilitation | K15: Annual and period | L15: Yes | M15: 2016–2025; four GIR variants | N15: Active — retained | O15: Yes | P15: 0.2 | Q15: 0.25 | R15: Equation/label/unit harmonisation required before publication.
A16: C | B16: C2 | C16: Network pressure reliability | D16: – | E16: Positive | F16: Performance | G16: Pressure reliability | H16: Share of hydrants remaining outside the critical failed set | I16: Spatial concentration of hydraulic failure | J16: Sector prioritisation and network upgrades | K16: Annual and period | L16: Yes | M16: 2016–2025; four GIR variants | N16: Active — retained | O16: Yes | P16: 0.2 | Q16: 0.25 | R16: Equation/label/unit harmonisation required before publication.
A17: C | B17: C3 | C17: Relative pressure deficit | D17: % Pmin | E17: Negative | F17: Performance | G17: Pressure-deficit severity | H17: Mean relative pressure-deficit severity during hydraulic failure | I17: Widespread pressure shortfall | J17: Pressure setpoints and peak-demand control | K17: Annual and period | L17: Yes | M17: 2016–2025; four GIR variants | N17: Active — retained | O17: Yes | P17: 0.2 | Q17: 0.16666667 | R17: Equation/label/unit harmonisation required before publication.
A18: C | B18: C4 | C18: Critical hydrant deficit (P80) | D18: – | E18: Negative | F18: Performance | G18: Pressure-deficit severity | H18: Upper-tail relative pressure deficit at critical hydrants | I18: Persistent severe deficit at vulnerable hydrants | J18: Targeted pipe/hydrant rehabilitation | K18: Annual and period | L18: Yes | M18: 2016–2025; four GIR variants | N18: Active — retained | O18: Yes | P18: 0.2 | Q18: 0.16666667 | R18: Equation/label/unit harmonisation required before publication.
A19: C | B19: C5 | C19: Maximum hydrant deficit | D19: – | E19: Negative | F19: Performance | G19: Pressure-deficit severity | H19: Maximum simulated relative pressure deficit | I19: Extreme local hydraulic failure | J19: Critical-node protection | K19: Annual and period | L19: Yes | M19: 2016–2025; four GIR variants | N19: Active — retained | O19: Yes | P19: 0.2 | Q19: 0.16666667 | R19: Equation/label/unit harmonisation required before publication.
A20: D | B20: D1 | C20: Energy per irrigated area | D20: kWh ha⁻¹ | E20: Negative | F20: Performance | G20: Energy intensity | H20: Energy intensity relative to effectively irrigated area | I20: High energy burden per service area | J20: Pump operation and efficiency investment | K20: Annual; incomplete | L20: No | M20: 2018–2025 | N20: Active — retained | O20: Yes | P20: 0.125 | Q20: 0.083333333
A21: D | B21: D2 | C21: Energy per supplied volume | D21: kWh m⁻³ | E21: Negative | F21: Performance | G21: Energy intensity | H21: Energy intensity per volume delivered at hydrants | I21: High energy use per unit service | J21: Pumping efficiency and leakage control | K21: Annual; incomplete | L21: No | M21: 2018–2025 | N21: Active — retained | O21: Yes | P21: 0.125 | Q21: 0.083333333
A22: D | B22: D3 | C22: Energy per abstracted volume | D22: kWh m⁻³ | E22: Negative | F22: Performance | G22: Energy intensity | H22: Energy intensity per abstracted/source volume | I22: High source-side pumping intensity | J22: Pumping station optimisation | K22: Annual; incomplete | L22: No | M22: 2018–2025 | N22: Active — retained | O22: Yes | P22: 0.125 | Q22: 0.083333333 | R22: High redundancy flag; retained and tested as diagnostic-only alternative.
A23: D | B23: D4 | C23: Energy cost per irrigated area | D23: € ha⁻¹ | E23: Negative | F23: Exposure | G23: Financial exposure | H23: Energy-cost exposure per irrigated area | I23: High operating cost per service area | J23: Tariffs, budgets and investments | K23: Annual | L23: No | M23: 2016–2025 | N23: Active — retained | O23: Yes | P23: 0.125 | Q23: 0.083333333
A24: D | B24: D5 | C24: Energy cost per supplied volume | D24: € m⁻³ | E24: Negative | F24: Exposure | G24: Financial exposure | H24: Energy-cost exposure per delivered volume | I24: High financial burden per unit service | J24: Energy procurement and tariff design | K24: Annual | L24: No | M24: 2016–2025 | N24: Active — retained | O24: Yes | P24: 0.125 | Q24: 0.083333333
A25: D | B25: D6 | C25: Energy cost per abstracted volume | D25: € m⁻³ | E25: Negative | F25: Exposure | G25: Financial exposure | H25: Energy-cost exposure per source withdrawal | I25: High source-side financial burden | J25: Pumping and procurement strategy | K25: Annual | L25: No | M25: 2016–2025 | N25: Active — retained | O25: Yes | P25: 0.125 | Q25: 0.083333333 | R25: High redundancy flag; retained and tested as diagnostic-only alternative.
A26: D | B26: D7 | C26: Renewable energy contribution | D26: – | E26: Positive | F26: Adaptive capacity | G26: Decarbonisation | H26: Share of pumping energy covered by renewables | I26: Dependence on grid energy and price volatility | J26: Renewable-energy investment | K26: Current snapshot | L26: No | M26: 2025 only | N26: Active — retained | O26: Yes | P26: 0.125 | Q26: 0.25
A27: D | B27: D8 | C27: Pump redundancy | D27: – | E27: Positive | F27: Adaptive capacity | G27: Functional redundancy | H27: Spare pumping capacity relative to peak requirement | I27: No backup under pump failure or peak demand | J27: Pump reserve and contingency planning | K27: Annual | L27: No | M27: 2016–2025 | N27: Active — retained | O27: Yes | P27: 0.125 | Q27: 0.25
A28: E | B28: E1 | C28: Gross irrigation requirement | D28: mm | E28: Negative | F28: Stress | G28: Demand magnitude and concentration | H28: Seasonal gross irrigation demand imposed by crop/technology configuration | I28: High seasonal water demand | J28: Crop pattern and efficiency measures | K28: Annual and period | L28: Yes | M28: 2016–2025; four GIR variants | N28: Active — retained | O28: Yes | P28: 0.1 | Q28: 0.083333333
A29: E | B29: E2 | C29: Peak demand factor | D29: – | E29: Negative | F29: Stress | G29: Demand magnitude and concentration | H29: Share of seasonal demand concentrated in peak month | I29: High short-term pressure on source/network/energy | J29: Peak management and operating schedules | K29: Annual and period | L29: Yes | M29: 2016–2025; four GIR variants | N29: Active — retained | O29: Yes | P29: 0.1 | Q29: 0.083333333
A30: E | B30: E3 | C30: Peak demand staggering | D30: – | E30: Positive | F30: Adaptive capacity | G30: Demand magnitude and concentration | H30: Reduction in coincident peak due to temporal spreading among crops | I30: Synchronous crop-demand peaks | J30: Crop calendars and demand scheduling | K30: Annual and period | L30: Yes | M30: 2016–2025; four GIR variants | N30: Active — retained | O30: Yes | P30: 0.1 | Q30: 0.083333333
A31: E | B31: E4 | C31: Irrigation system factor | D31: – | E31: Negative | F31: Stress | G31: Irrigation technology and control | H31: Demand amplification associated with application efficiency and wetted fraction | I31: Technology-induced gross-demand amplification | J31: Technology performance improvement | K31: Annual and period | L31: Partly | M31: 2016–2025; low/high efficiency | N31: Active — retained | O31: Yes | P31: 0.1 | Q31: 0.125
A32: E | B32: E5 | C32: On-farm technology and control | D32: – | E32: Positive | F32: Adaptive capacity | G32: Irrigation technology and control | H32: Monitoring, scheduling, automation and variable-rate control | I32: Limited ability to adjust irrigation under stress | J32: Farm-control upgrades | K32: Annual and period | L32: No | M32: 2016–2025 | N32: Active — retained | O32: Yes | P32: 0.1 | Q32: 0.125
A33: E | B33: E6 | C33: Water-deficit and salinity tolerance | D33: – | E33: Positive | F33: Adaptive capacity | G33: Crop flexibility and exposure | H33: Crop-pattern capacity to tolerate moderate abiotic stress | I33: Yield sensitivity under deficit/salinity | J33: Crop diversification and deficit irrigation | K33: Annual and period | L33: No | M33: 2016–2025 | N33: Active — retained | O33: Yes | P33: 0.1 | Q33: 0.083333333
A34: E | B34: E7 | C34: Share of permanent crops | D34: – | E34: Negative | F34: Exposure | G34: Crop flexibility and exposure | H34: Long-term irrigation commitment and reduced allocation flexibility | I34: Rigid drought demand and asset-loss risk | J34: Allocation priorities and expansion control | K34: Annual and period | L34: No | M34: 2016–2025 | N34: Active — retained | O34: Yes | P34: 0.1 | Q34: 0.083333333
A35: E | B35: E8 | C35: Soil-water buffering capacity | D35: mm | E35: Positive | F35: Structural capacity | G35: Local buffering | H35: Plant-available soil-water storage in the effective root zone | I35: Rapid onset of irrigation demand and low interruption buffer | J35: Soil/crop management | K35: Annual and period | L35: No | M35: 2016–2025 | N35: Active — retained | O35: Yes | P35: 0.1 | Q35: 0.125
A36: E | B36: E9 | C36: Alternative local access to storage | D36: – | E36: Positive | F36: Structural proxy | G36: Local buffering | H36: Potential proximity-based access to local ponds/tanks | I36: No local buffer during short supply interruptions | J36: Local storage inventory and connection verification | K36: Current structural snapshot | L36: No | M36: Current mapping | N36: Active — retained | O36: Yes | P36: 0.1 | Q36: 0.125
A37: E | B37: E10 | C37: Chill requirement adequacy indicator | D37: – | E37: Positive | F37: Exposure | G37: Crop flexibility and exposure | H37: Adequacy of accumulated winter chill for chill-dependent crops | I37: Phenological/yield risk under warm winters | J37: Crop/variety adaptation | K37: Annual and period | L37: No | M37: 2016–2025 | N37: Active — retained | O37: Yes | P37: 0.1 | Q37: 0.083333333
... A41: F | B41: F4 | C41: Participation, communication and compliance | D41: – | E41: Positive | F41: Institutional capacity | G41: Participation and compliance | H41: Farmer involvement, communication, enforcement and conflict resolution | I41: Low compliance and ineffective rationing | J41: Communication and governance procedures | K41: Current assessment | L41: No | M41: Current evidence | N41: Active — retained | O41: Yes | P41: 0.25 | Q41: 0.25

Sheet 04_THRESHOLDS_WEIGHTS
A1: Thresholds and formula-driven weights
A3: Subsystem | B3: Code | C3: Indicator | D3: Unit | E3: Orientation | F3: Dimension | G3: T1 | H3: T2 | I3: T3 | J3: T4 saturation | K3: Equal-indicator weight | L3: Dimension-balanced weight | M3: Active | N3: Threshold note
A4: A | B4: A1 | C4: Time-based inflow reliability | D4: – | E4: Positive | F4: Inflow adequacy | G4: 0.4 | H4: 0.6 | I4: 0.8 | J4: 1 | K4: =1/COUNTIF($A$4:$A$41,A4) -> 0.16666667 | L4: =1/4/COUNTIFS($A$4:$A$41,A4,$F$4:$F$41,F4) -> 0.125 | M4: Yes
A5: A | B5: A2 | C5: Volumetric inflow reliability | D5: – | E5: Positive | F5: Inflow adequacy | G5: 0.4 | H5: 0.6 | I5: 0.8 | J5: 1 | K5: =1/COUNTIF($A$4:$A$41,A5) -> 0.16666667 | L5: =1/4/COUNTIFS($A$4:$A$41,A5,$F$4:$F$41,F5) -> 0.125 | M5: Yes
A6: A | B6: A3 | C6: Mean drought duration | D6: months | E6: Negative | F6: Drought persistence | G6: 12 | H6: 6 | I6: 3 | J6: 0 | K6: =1/COUNTIF($A$4:$A$41,A6) -> 0.16666667 | L6: =1/4/COUNTIFS($A$4:$A$41,A6,$F$4:$F$41,F6) -> 0.25 | M6: Yes
A7: A | B7: A4 | C7: Coefficient of variation of annual inflow | D7: – | E7: Negative | F7: Interannual variability | G7: 1.1 | H7: 0.9 | I7: 0.5 | J7: 0 | K7: =1/COUNTIF($A$4:$A$41,A7) -> 0.16666667 | L7: =1/4/COUNTIFS($A$4:$A$41,A7,$F$4:$F$41,F7) -> 0.25 | M7: Yes
A8: A | B8: A5 | C8: Buffering capacity | D8: – | E8: Positive | F8: Storage context and dependence | G8: 0.75 | H8: 1.5 | I8: 3 | J8: 90.830935 | K8: =1/COUNTIF($A$4:$A$41,A8) -> 0.16666667 | L8: =1/4/COUNTIFS($A$4:$A$41,A8,$F$4:$F$41,F8) -> 0.125 | M8: Yes | N8: T4=90.8309 is a fixed technical saturation anchor, not the Excellent class boundary.
A9: A | B9: A6 | C9: Carry-over dependence | D9: – | E9: Negative | F9: Storage context and dependence | G9: 2 | H9: 1.5 | I9: 1.05 | J9: 1 | K9: =1/COUNTIF($A$4:$A$41,A9) -> 0.16666667 | L9: =1/4/COUNTIFS($A$4:$A$41,A9,$F$4:$F$41,F9) -> 0.125 | M9: Yes | N9: User-approved correction: Good 1.05<x≤1.50; Excellent x≤1.05.
A10: B | B10: B1 | C10: Time-based supply reliability | D10: – | E10: Positive | F10: Supply adequacy | G10: 0.5 | H10: 0.6 | I10: 0.8 | J10: 1 | K10: =1/COUNTIF($A$4:$A$41,A10) -> 0.2 | L10: =1/4/COUNTIFS($A$4:$A$41,A10,$F$4:$F$41,F10) -> 0.125 | M10: Yes
A11: B | B11: B2 | C11: Volumetric supply reliability | D11: – | E11: Positive | F11: Supply adequacy | G11: 0.5 | H11: 0.6 | I11: 0.8 | J11: 1 | K11: =1/COUNTIF($A$4:$A$41,A11) -> 0.2 | L11: =1/4/COUNTIFS($A$4:$A$41,A11,$F$4:$F$41,F11) -> 0.125 | M11: Yes
A12: B | B12: B3 | C12: Mean supply performance during failure | D12: – | E12: Positive | F12: Failure severity | G12: 0.7 | H12: 0.75 | I12: 0.8 | J12: 1 | K12: =1/COUNTIF($A$4:$A$41,A12) -> 0.2 | L12: =1/4/COUNTIFS($A$4:$A$41,A12,$F$4:$F$41,F12) -> 0.25 | M12: Yes
A13: B | B13: B4 | C13: Recovery after failure | D13: – | E13: Positive | F13: Recovery | G13: 0.25 | H13: 0.5 | I13: 0.75 | J13: 1 | K13: =1/COUNTIF($A$4:$A$41,A13) -> 0.2 | L13: =1/4/COUNTIFS($A$4:$A$41,A13,$F$4:$F$41,F13) -> 0.25 | M13: Yes
A14: B | B14: B5 | C14: Spill–shortage coexistence frequency | D14: – | E14: Negative | F14: Operational coherence | G14: 0.3 | H14: 0.1 | I14: 0.01 | J14: 0 | K14: =1/COUNTIF($A$4:$A$41,A14) -> 0.2 | L14: =1/4/COUNTIFS($A$4:$A$41,A14,$F$4:$F$41,F14) -> 0.25 | M14: Yes
A15: C | B15: C1 | C15: Hydrant pressure reliability | D15: – | E15: Positive | F15: Pressure reliability | G15: 0.5 | H15: 0.75 | I15: 0.85 | J15: 1 | K15: =1/COUNTIF($A$4:$A$41,A15) -> 0.2 | L15: =1/2/COUNTIFS($A$4:$A$41,A15,$F$4:$F$41,F15) -> 0.25 | M15: Yes
A16: C | B16: C2 | C16: Network pressure reliability | D16: – | E16: Positive | F16: Pressure reliability | G16: 0.5 | H16: 0.75 | I16: 0.85 | J16: 1 | K16: =1/COUNTIF($A$4:$A$41,A16) -> 0.2 | L16: =1/2/COUNTIFS($A$4:$A$41,A16,$F$4:$F$41,F16) -> 0.25 | M16: Yes
A17: C | B17: C3 | C17: Relative pressure deficit | D17: % Pmin | E17: Negative | F17: Pressure-deficit severity | G17: 1 | H17: 0.5 | I17: 0.3 | J17: 0.05 | K17: =1/COUNTIF($A$4:$A$41,A17) -> 0.2 | L17: =1/2/COUNTIFS($A$4:$A$41,A17,$F$4:$F$41,F17) -> 0.16666667 | M17: Yes | N17: Current v2 preserves % of Pmin implementation; harmonise manuscript equation/unit.
A18: C | B18: C4 | C18: Critical hydrant deficit (P80) | D18: – | E18: Negative | F18: Pressure-deficit severity | G18: 1 | H18: 0.5 | I18: 0.3 | J18: 0.05 | K18: =1/COUNTIF($A$4:$A$41,A18) -> 0.2 | L18: =1/2/COUNTIFS($A$4:$A$41,A18,$F$4:$F$41,F18) -> 0.16666667 | M18: Yes
A19: C | B19: C5 | C19: Maximum hydrant deficit | D19: – | E19: Negative | F19: Pressure-deficit severity | G19: 1 | H19: 0.5 | I19: 0.3 | J19: 0.05 | K19: =1/COUNTIF($A$4:$A$41,A19) -> 0.2 | L19: =1/2/COUNTIFS($A$4:$A$41,A19,$F$4:$F$41,F19) -> 0.16666667 | M19: Yes
A20: D | B20: D1 | C20: Energy per irrigated area | D20: kWh ha⁻¹ | E20: Negative | F20: Energy intensity | G20: 2000 | H20: 1500 | I20: 1000 | J20: 500 | K20: =1/COUNTIF($A$4:$A$41,A20) -> 0.125 | L20: =1/4/COUNTIFS($A$4:$A$41,A20,$F$4:$F$41,F20) -> 0.083333333 | M20: Yes
A21: D | B21: D2 | C21: Energy per supplied volume | D21: kWh m⁻³ | E21: Negative | F21: Energy intensity | G21: 0.4 | H21: 0.3 | I21: 0.2 | J21: 0.1 | K21: =1/COUNTIF($A$4:$A$41,A21) -> 0.125 | L21: =1/4/COUNTIFS($A$4:$A$41,A21,$F$4:$F$41,F21) -> 0.083333333 | M21: Yes
A22: D | B22: D3 | C22: Energy per abstracted volume | D22: kWh m⁻³ | E22: Negative | F22: Energy intensity | G22: 0.35 | H22: 0.25 | I22: 0.15 | J22: 0.1 | K22: =1/COUNTIF($A$4:$A$41,A22) -> 0.125 | L22: =1/4/COUNTIFS($A$4:$A$41,A22,$F$4:$F$41,F22) -> 0.083333333 | M22: Yes
A23: D | B23: D4 | C23: Energy cost per irrigated area | D23: € ha⁻¹ | E23: Negative | F23: Financial exposure | G23: 200 | H23: 150 | I23: 100 | J23: 50 | K23: =1/COUNTIF($A$4:$A$41,A23) -> 0.125 | L23: =1/4/COUNTIFS($A$4:$A$41,A23,$F$4:$F$41,F23) -> 0.083333333 | M23: Yes
A24: D | B24: D5 | C24: Energy cost per supplied volume | D24: € m⁻³ | E24: Negative | F24: Financial exposure | G24: 0.06 | H24: 0.04 | I24: 0.02 | J24: 0.01 | K24: =1/COUNTIF($A$4:$A$41,A24) -> 0.125 | L24: =1/4/COUNTIFS($A$4:$A$41,A24,$F$4:$F$41,F24) -> 0.083333333 | M24: Yes
A25: D | B25: D6 | C25: Energy cost per abstracted volume | D25: € m⁻³ | E25: Negative | F25: Financial exposure | G25: 0.06 | H25: 0.04 | I25: 0.02 | J25: 0.01 | K25: =1/COUNTIF($A$4:$A$41,A25) -> 0.125 | L25: =1/4/COUNTIFS($A$4:$A$41,A25,$F$4:$F$41,F25) -> 0.083333333 | M25: Yes
A26: D | B26: D7 | C26: Renewable energy contribution | D26: – | E26: Positive | F26: Decarbonisation | G26: 0.05 | H26: 0.1 | I26: 0.2 | J26: 0.4 | K26: =1/COUNTIF($A$4:$A$41,A26) -> 0.125 | L26: =1/4/COUNTIFS($A$4:$A$41,A26,$F$4:$F$41,F26) -> 0.25 | M26: Yes
A27: D | B27: D8 | C27: Pump redundancy | D27: – | E27: Positive | F27: Functional redundancy | G27: 0 | H27: 0.25 | I27: 0.5 | J27: 1 | K27: =1/COUNTIF($A$4:$A$41,A27) -> 0.125 | L27: =1/4/COUNTIFS($A$4:$A$41,A27,$F$4:$F$41,F27) -> 0.25 | M27: Yes
A28: E | B28: E1 | C28: Gross irrigation requirement | D28: mm | E28: Negative | F28: Demand magnitude and concentration | G28: 600 | H28: 500 | I28: 400 | J28: 300 | K28: =1/COUNTIF($A$4:$A$41,A28) -> 0.1 | L28: =1/4/COUNTIFS($A$4:$A$41,A28,$F$4:$F$41,F28) -> 0.083333333 | M28: Yes
A29: E | B29: E2 | C29: Peak demand factor | D29: – | E29: Negative | F29: Demand magnitude and concentration | G29: 0.45 | H29: 0.35 | I29: 0.25 | J29: 0.2 | K29: =1/COUNTIF($A$4:$A$41,A29) -> 0.1 | L29: =1/4/COUNTIFS($A$4:$A$41,A29,$F$4:$F$41,F29) -> 0.083333333 | M29: Yes
A30: E | B30: E3 | C30: Peak demand staggering | D30: – | E30: Positive | F30: Demand magnitude and concentration | G30: 0.25 | H30: 0.5 | I30: 0.75 | J30: 0.8 | K30: =1/COUNTIF($A$4:$A$41,A30) -> 0.1 | L30: =1/4/COUNTIFS($A$4:$A$41,A30,$F$4:$F$41,F30) -> 0.083333333 | M30: Yes
A31: E | B31: E4 | C31: Irrigation system factor | D31: – | E31: Negative | F31: Irrigation technology and control | G31: 1.25 | H31: 1.05 | I31: 0.75 | J31: 0.5 | K31: =1/COUNTIF($A$4:$A$41,A31) -> 0.1 | L31: =1/4/COUNTIFS($A$4:$A$41,A31,$F$4:$F$41,F31) -> 0.125 | M31: Yes
... A41: F | B41: F4 | C41: Participation, communication and compliance | D41: – | E41: Positive | F41: Participation and compliance | G41: 0.25 | H41: 0.5 | I41: 0.75 | J41: 1 | K41: =1/COUNTIF($A$4:$A$41,A41) -> 0.25 | L41: =1/4/COUNTIFS($A$4:$A$41,A41,$F$4:$F$41,F41) -> 0.25 | M41: Yes

Sheet 05_IMPORT_BASELINE
A1: Embedded assessment-period inputs from public subsystem workbooks
A3: Subsystem | B3: Code | C3: Indicator | D3: Raw value | E3: Unit | F3: Temporal basis | G3: Source workbook | H3: Source sheet | I3: Source cell/range | J3: Derivation | K3: Import status
A4: A | B4: A1 | C4: Time-based inflow reliability | D4: 0.725 | E4: – | F4: Period; annual diagnostic | G4: RI_SA_water_availability_tool_v1_1_public(1).xlsx | H4: EXPORT_CIS | I4: C16 | J4: Period-level value linked internally to SA_calcu_indicators. | K4: EMBEDDED
A5: A | B5: A2 | C5: Volumetric inflow reliability | D5: 0.81718292 | E5: – | F5: Period; annual diagnostic | G5: RI_SA_water_availability_tool_v1_1_public(1).xlsx | H5: EXPORT_CIS | I5: C17 | J5: Period-level value linked internally to SA_calcu_indicators. | K5: EMBEDDED
A6: A | B6: A3 | C6: Mean drought duration | D6: 4.5 | E6: months | F6: Period; annual diagnostic | G6: RI_SA_water_availability_tool_v1_1_public(1).xlsx | H6: EXPORT_CIS | I6: C18 | J6: Period-level value linked internally to SA_calcu_indicators. | K6: EMBEDDED
A7: A | B7: A4 | C7: Coefficient of variation of annual inflow | D7: 0.87666572 | E7: – | F7: Period only | G7: RI_SA_water_availability_tool_v1_1_public(1).xlsx | H7: EXPORT_CIS | I7: C19 | J7: Period-level value linked internally to SA_calcu_indicators. | K7: EMBEDDED
A8: A | B8: A5 | C8: Buffering capacity | D8: 7.0450966 | E8: – | F8: Period only | G8: RI_SA_water_availability_tool_v1_1_public(1).xlsx | H8: EXPORT_CIS | I8: C20 | J8: Period-level value linked internally to SA_calcu_indicators. | K8: EMBEDDED
A9: A | B9: A6 | C9: Carry-over dependence | D9: 1.8398792 | E9: – | F9: Period only | G9: RI_SA_water_availability_tool_v1_1_public(1).xlsx | H9: EXPORT_CIS | I9: C21 | J9: Period-level value linked internally to SA_calcu_indicators. | K9: EMBEDDED
A10: B | B10: B1 | C10: Time-based supply reliability | D10: 0.99375 | E10: – | F10: Period and annual | G10: RI_SB_reservoir_service_tool_v1_public.xlsx | H10: B_CALC_PERIOD | I10: H4:M8 | J10: Arithmetic mean of four complete GIR variants; B1 uses corrected B_CALC_PERIOD column. | K10: EMBEDDED
A11: B | B11: B2 | C11: Volumetric supply reliability | D11: 0.99046393 | E11: – | F11: Period and annual | G11: RI_SB_reservoir_service_tool_v1_public.xlsx | H11: B_CALC_PERIOD | I11: H4:M8 | J11: Arithmetic mean of four complete GIR variants; B2 uses corrected B_CALC_PERIOD column. | K11: EMBEDDED
A12: B | B12: B3 | C12: Mean supply performance during failure | D12: 0.77155359 | E12: – | F12: Period and annual | G12: RI_SB_reservoir_service_tool_v1_public.xlsx | H12: B_CALC_PERIOD | I12: H4:M8 | J12: Arithmetic mean of four complete GIR variants; B3 uses corrected B_CALC_PERIOD column. | K12: EMBEDDED
A13: B | B13: B4 | C13: Recovery after failure | D13: 0.83333333 | E13: – | F13: Period and annual | G13: RI_SB_reservoir_service_tool_v1_public.xlsx | H13: B_CALC_PERIOD | I13: H4:M8 | J13: Arithmetic mean of four complete GIR variants; B4 uses corrected B_CALC_PERIOD column. | K13: EMBEDDED
A14: B | B14: B5 | C14: Spill–shortage coexistence frequency | D14: 0 | E14: – | F14: Period and annual | G14: RI_SB_reservoir_service_tool_v1_public.xlsx | H14: B_CALC_PERIOD | I14: H4:M8 | J14: Arithmetic mean of four complete GIR variants; B5 uses corrected B_CALC_PERIOD column. | K14: EMBEDDED
A15: C | B15: C1 | C15: Hydrant pressure reliability | D15: 0.98197379 | E15: – | F15: Annual and period | G15: RI_SC_conveyance_distribution_tool_v1_1_public.xlsx | H15: C_INPUT_PREPROCESSED | I15: H5:N44 | J15: Scenario-period mean matching C_FINAL_TOOL; C3 uses K×100 and C5 uses maximum deficit/Pmin (40 m). | K15: EMBEDDED
... A41: F | B41: F4 | C41: Participation, communication and compliance | D41: 0.4375 | E41: – | F41: Current assessment | G41: RI_SF_drought_management_tool_v1_1_public(1).xlsx | H41: 02_EXPORT_CIS | I41: H7 | J41: Assessment-period evidence | K41: EMBEDDED

Sheet 06_IMPORT_ANNUAL
A1: Embedded annual central series
A3: Subsystem | B3: Code | C3: Year | D3: Raw value | E3: Central-series rule | F3: Source workbook | G3: Source sheet | H3: Source cell/range | I3: Coverage/derivation
A4: A | B4: A1 | C4: 2016 | D4: 1 | E4: Central | F4: RI_SA_water_availability_tool_v1_1_public(1).xlsx | G4: EXPORT_CIS | H4: G28
A5: A | B5: A1 | C5: 2017 | D5: 0.75 | E5: Central | F5: RI_SA_water_availability_tool_v1_1_public(1).xlsx | G5: EXPORT_CIS | H5: G29
A6: A | B6: A1 | C6: 2018 | D6: 0.83333333 | E6: Central | F6: RI_SA_water_availability_tool_v1_1_public(1).xlsx | G6: EXPORT_CIS | H6: G30
A7: A | B7: A1 | C7: 2019 | D7: 0.25 | E7: Central | F7: RI_SA_water_availability_tool_v1_1_public(1).xlsx | G7: EXPORT_CIS | H7: G31
A8: A | B8: A1 | C8: 2020 | D8: 0.91666667 | E8: Central | F8: RI_SA_water_availability_tool_v1_1_public(1).xlsx | G8: EXPORT_CIS | H8: G32
A9: A | B9: A1 | C9: 2021 | D9: 0.91666667 | E9: Central | F9: RI_SA_water_availability_tool_v1_1_public(1).xlsx | G9: EXPORT_CIS | H9: G33
A10: A | B10: A1 | C10: 2022 | D10: 0.16666667 | E10: Central | F10: RI_SA_water_availability_tool_v1_1_public(1).xlsx | G10: EXPORT_CIS | H10: G34
A11: A | B11: A1 | C11: 2023 | D11: 0.41666667 | E11: Central | F11: RI_SA_water_availability_tool_v1_1_public(1).xlsx | G11: EXPORT_CIS | H11: G35
A12: A | B12: A1 | C12: 2024 | D12: 1 | E12: Central | F12: RI_SA_water_availability_tool_v1_1_public(1).xlsx | G12: EXPORT_CIS | H12: G36
A13: A | B13: A1 | C13: 2025 | D13: 1 | E13: Central | F13: RI_SA_water_availability_tool_v1_1_public(1).xlsx | G13: EXPORT_CIS | H13: G37
A14: A | B14: A2 | C14: 2016 | D14: 1 | E14: Central | F14: RI_SA_water_availability_tool_v1_1_public(1).xlsx | G14: EXPORT_CIS | H14: H28
A15: A | B15: A2 | C15: 2017 | D15: 0.96357805 | E15: Central | F15: RI_SA_water_availability_tool_v1_1_public(1).xlsx | G15: EXPORT_CIS | H15: H29
... A63: A | B63: A6 | C63: 2025 | D63: 0.62952362 | E63: Central | F63: RI_SA_water_availability_tool_v1_1_public(1).xlsx | G63: EXPORT_CIS | H63: L37
A64: B | B64: B1 | C64: 2016 | D64: 1 | E64: Ensemble_mean | F64: RI_SB_reservoir_service_tool_v1_public.xlsx | G64: B_CALC_ANNUAL | H64: I:N | I64: Mean of the four complete GIR-variant annual indicators.
A65: B | B65: B1 | C65: 2017 | D65: 1 | E65: Ensemble_mean | F65: RI_SB_reservoir_service_tool_v1_public.xlsx | G65: B_CALC_ANNUAL | H65: I:N | I65: Mean of the four complete GIR-variant annual indicators.
A66: B | B66: B1 | C66: 2018 | D66: 1 | E66: Ensemble_mean | F66: RI_SB_reservoir_service_tool_v1_public.xlsx | G66: B_CALC_ANNUAL | H66: I:N | I66: Mean of the four complete GIR-variant annual indicators.
A67: B | B67: B1 | C67: 2019 | D67: 1 | E67: Ensemble_mean | F67: RI_SB_reservoir_service_tool_v1_public.xlsx | G67: B_CALC_ANNUAL | H67: I:N | I67: Mean of the four complete GIR-variant annual indicators.
A68: B | B68: B1 | C68: 2020 | D68: 1 | E68: Ensemble_mean | F68: RI_SB_reservoir_service_tool_v1_public.xlsx | G68: B_CALC_ANNUAL | H68: I:N | I68: Mean of the four complete GIR-variant annual indicators.
A69: B | B69: B1 | C69: 2021 | D69: 1 | E69: Ensemble_mean | F69: RI_SB_reservoir_service_tool_v1_public.xlsx | G69: B_CALC_ANNUAL | H69: I:N | I69: Mean of the four complete GIR-variant annual indicators.
A70: B | B70: B1 | C70: 2022 | D70: 1 | E70: Ensemble_mean | F70: RI_SB_reservoir_service_tool_v1_public.xlsx | G70: B_CALC_ANNUAL | H70: I:N | I70: Mean of the four complete GIR-variant annual indicators.
A71: B | B71: B1 | C71: 2023 | D71: 0.9375 | E71: Ensemble_mean | F71: RI_SB_reservoir_service_tool_v1_public.xlsx | G71: B_CALC_ANNUAL | H71: I:N | I71: Mean of the four complete GIR-variant annual indicators.
A72: B | B72: B1 | C72: 2024 | D72: 1 | E72: Ensemble_mean | F72: RI_SB_reservoir_service_tool_v1_public.xlsx | G72: B_CALC_ANNUAL | H72: I:N | I72: Mean of the four complete GIR-variant annual indicators.
A73: B | B73: B1 | C73: 2025 | D73: 1 | E73: Ensemble_mean | F73: RI_SB_reservoir_service_tool_v1_public.xlsx | G73: B_CALC_ANNUAL | H73: I:N | I73: Mean of the four complete GIR-variant annual indicators.
A74: B | B74: B2 | C74: 2016 | D74: 1 | E74: Ensemble_mean | F74: RI_SB_reservoir_service_tool_v1_public.xlsx | G74: B_CALC_ANNUAL | H74: I:N | I74: Mean of the four complete GIR-variant annual indicators.
A75: B | B75: B2 | C75: 2017 | D75: 1 | E75: Ensemble_mean | F75: RI_SB_reservoir_service_tool_v1_public.xlsx | G75: B_CALC_ANNUAL | H75: I:N | I75: Mean of the four complete GIR-variant annual indicators.
... A328: E | B328: E9 | C328: 2025 | D328: 0.41686881 | E328: Not_applicable | F328: RI_SE_on_farm_performance_tool_v1_1_public(1).xlsx | G328: 02_EXPORT_CIS | H328: H112 | I328: Annual

Sheet 07_IMPORT_ENSEMBLE
A1: Embedded four-variant GIR ensemble
A3: Subsystem | B3: Code | C3: Indicator | D3: Ensemble dependency | E3: ISW50_EffLow | F3: ISW50_EffHigh | G3: ISW90_EffLow | H3: ISW90_EffHigh | I3: Ensemble mean | J3: Minimum | K3: Maximum | L3: Source/derivation
A4: A | B4: A1 | C4: Time-based inflow reliability | D4: No | E4: 0.725 | F4: 0.725 | G4: 0.725 | H4: 0.725 | I4: =AVERAGE(E4:H4) -> 0.725 | J4: =MIN(E4:H4) -> 0.725 | K4: =MAX(E4:H4) -> 0.725 | L4: Period-level value linked internally to SA_calcu_indicators.
A5: A | B5: A2 | C5: Volumetric inflow reliability | D5: No | E5: 0.81718292 | F5: 0.81718292 | G5: 0.81718292 | H5: 0.81718292 | I5: =AVERAGE(E5:H5) -> 0.81718292 | J5: =MIN(E5:H5) -> 0.81718292 | K5: =MAX(E5:H5) -> 0.81718292 | L5: Period-level value linked internally to SA_calcu_indicators.
A6: A | B6: A3 | C6: Mean drought duration | D6: No | E6: 4.5 | F6: 4.5 | G6: 4.5 | H6: 4.5 | I6: =AVERAGE(E6:H6) -> 4.5 | J6: =MIN(E6:H6) -> 4.5 | K6: =MAX(E6:H6) -> 4.5 | L6: Period-level value linked internally to SA_calcu_indicators.
A7: A | B7: A4 | C7: Coefficient of variation of annual inflow | D7: No | E7: 0.87666572 | F7: 0.87666572 | G7: 0.87666572 | H7: 0.87666572 | I7: =AVERAGE(E7:H7) -> 0.87666572 | J7: =MIN(E7:H7) -> 0.87666572 | K7: =MAX(E7:H7) -> 0.87666572 | L7: Period-level value linked internally to SA_calcu_indicators.
A8: A | B8: A5 | C8: Buffering capacity | D8: No | E8: 7.0450966 | F8: 7.0450966 | G8: 7.0450966 | H8: 7.0450966 | I8: =AVERAGE(E8:H8) -> 7.0450966 | J8: =MIN(E8:H8) -> 7.0450966 | K8: =MAX(E8:H8) -> 7.0450966 | L8: Period-level value linked internally to SA_calcu_indicators.
A9: A | B9: A6 | C9: Carry-over dependence | D9: No | E9: 1.8398792 | F9: 1.8398792 | G9: 1.8398792 | H9: 1.8398792 | I9: =AVERAGE(E9:H9) -> 1.8398792 | J9: =MIN(E9:H9) -> 1.8398792 | K9: =MAX(E9:H9) -> 1.8398792 | L9: Period-level value linked internally to SA_calcu_indicators.
A10: B | B10: B1 | C10: Time-based supply reliability | D10: Yes | E10: 0.975 | F10: 1 | G10: 1 | H10: 1 | I10: =AVERAGE(E10:H10) -> 0.99375 | J10: =MIN(E10:H10) -> 0.975 | K10: =MAX(E10:H10) -> 1 | L10: Arithmetic mean of four complete GIR variants; B1 uses corrected B_CALC_PERIOD column.
A11: B | B11: B2 | C11: Volumetric supply reliability | D11: Yes | E11: 0.96185573 | F11: 1 | G11: 1 | H11: 1 | I11: =AVERAGE(E11:H11) -> 0.99046393 | J11: =MIN(E11:H11) -> 0.96185573 | K11: =MAX(E11:H11) -> 1 | L11: Arithmetic mean of four complete GIR variants; B2 uses corrected B_CALC_PERIOD column.
A12: B | B12: B3 | C12: Mean supply performance during failure | D12: Yes | E12: 0.086214364 | F12: 1 | G12: 1 | H12: 1 | I12: =AVERAGE(E12:H12) -> 0.77155359 | J12: =MIN(E12:H12) -> 0.086214364 | K12: =MAX(E12:H12) -> 1 | L12: Arithmetic mean of four complete GIR variants; B3 uses corrected B_CALC_PERIOD column.
A13: B | B13: B4 | C13: Recovery after failure | D13: Yes | E13: 0.33333333 | F13: 1 | G13: 1 | H13: 1 | I13: =AVERAGE(E13:H13) -> 0.83333333 | J13: =MIN(E13:H13) -> 0.33333333 | K13: =MAX(E13:H13) -> 1 | L13: Arithmetic mean of four complete GIR variants; B4 uses corrected B_CALC_PERIOD column.
A14: B | B14: B5 | C14: Spill–shortage coexistence frequency | D14: Yes | E14: 0 | F14: 0 | G14: 0 | H14: 0 | I14: =AVERAGE(E14:H14) -> 0 | J14: =MIN(E14:H14) -> 0 | K14: =MAX(E14:H14) -> 0 | L14: Arithmetic mean of four complete GIR variants; B5 uses corrected B_CALC_PERIOD column.
A15: C | B15: C1 | C15: Hydrant pressure reliability | D15: Yes | E15: 0.98159819 | F15: 0.98222542 | G15: 0.9820672 | H15: 0.98200435 | I15: =AVERAGE(E15:H15) -> 0.98197379 | J15: =MIN(E15:H15) -> 0.98159819 | K15: =MAX(E15:H15) -> 0.98222542 | L15: Scenario-period mean matching C_FINAL_TOOL; C3 uses K×100 and C5 uses maximum deficit/Pmin (40 m).
... A41: F | B41: F4 | C41: Participation, communication and compliance | D41: No | E41: 0.4375 | F41: 0.4375 | G41: 0.4375 | H41: 0.4375 | I41: =AVERAGE(E41:H41) -> 0.4375 | J41: =MIN(E41:H41) -> 0.4375 | K41: =MAX(E41:H41) -> 0.4375 | L41: Assessment-period evidence

Sheet 08_NORMALISATION
A1: Baseline normalisation and contributions
A3: Subsystem | B3: Code | C3: Indicator | D3: Type | E3: Dimension | F3: Orientation | G3: Raw value | H3: T1 | I3: T2 | J3: T3 | K3: T4 | L3: Normalised | M3: Class | N3: Equal wt | O3: Dimension wt | P3: Equal contribution | Q3: Dimension contribution
A4: A | B4: A1 | C4: Time-based inflow reliability | D4: Performance | E4: Inflow adequacy | F4: Positive | G4: ='05_IMPORT_BASELINE'!D4 -> 0.725 | H4: ='04_THRESHOLDS_WEIGHTS'!G4 -> 0.4 | I4: ='04_THRESHOLDS_WEIGHTS'!H4 -> 0.6 | J4: ='04_THRESHOLDS_WEIGHTS'!I4 -> 0.8 | K4: ='04_THRESHOLDS_WEIGHTS'!J4 -> 1 | L4: =IF(NOT(ISNUMBER(G4)),"",IF(F4="Positive",IF(G4<H4,0,IF(G4<I4,0.25+0.25*(G4-H4)/(I4-H4),IF(G4<J4,0.5+0.25*(G4-I4)/(J4-I4),IF(G4<K4,0.75+0.25*(G4-J4)/(K4-J4),1)))),IF(G4>H4,0,IF(G4>I4,0.25+0.25*(H4-G4)/(H4-I4),IF(G4>J4,0.5+0.25*(I4-G4)/(I4-J4),IF(G4>K4,0.75+0.25*(J4-G4)/(J4-K4),1)))))) -> 0.65625 | M4: =IF(NOT(ISNUMBER(L4)),"",IF(L4<0.25,"Low",IF(L4<0.5,"Moderate",IF(L4<0.75,"Good","Excellent")))) -> Good | N4: ='04_THRESHOLDS_WEIGHTS'!K4 -> 0.16666667 | O4: ='04_THRESHOLDS_WEIGHTS'!L4 -> 0.125 | P4: =L4*N4 -> 0.109375 | Q4: =L4*O4 -> 0.08203125
A5: A | B5: A2 | C5: Volumetric inflow reliability | D5: Performance | E5: Inflow adequacy | F5: Positive | G5: ='05_IMPORT_BASELINE'!D5 -> 0.81718292 | H5: ='04_THRESHOLDS_WEIGHTS'!G5 -> 0.4 | I5: ='04_THRESHOLDS_WEIGHTS'!H5 -> 0.6 | J5: ='04_THRESHOLDS_WEIGHTS'!I5 -> 0.8 | K5: ='04_THRESHOLDS_WEIGHTS'!J5 -> 1 | L5: =IF(NOT(ISNUMBER(G5)),"",IF(F5="Positive",IF(G5<H5,0,IF(G5<I5,0.25+0.25*(G5-H5)/(I5-H5),IF(G5<J5,0.5+0.25*(G5-I5)/(J5-I5),IF(G5<K5,0.75+0.25*(G5-J5)/(K5-J5),1)))),IF(G5>H5,0,IF(G5>I5,0.25+0.25*(H5-G5)/(H5-I5),IF(G5>J5,0.5+0.25*(I5-G5)/(I5-J5),IF(G5>K5,0.75+0.25*(J5-G5)/(J5-K5),1)))))) -> 0.77147865 | M5: =IF(NOT(ISNUMBER(L5)),"",IF(L5<0.25,"Low",IF(L5<0.5,"Moderate",IF(L5<0.75,"Good","Excellent")))) -> Excellent | N5: ='04_THRESHOLDS_WEIGHTS'!K5 -> 0.16666667 | O5: ='04_THRESHOLDS_WEIGHTS'!L5 -> 0.125 | P5: =L5*N5 -> 0.12857978 | Q5: =L5*O5 -> 0.096434832
A6: A | B6: A3 | C6: Mean drought duration | D6: Stress | E6: Drought persistence | F6: Negative | G6: ='05_IMPORT_BASELINE'!D6 -> 4.5 | H6: ='04_THRESHOLDS_WEIGHTS'!G6 -> 12 | I6: ='04_THRESHOLDS_WEIGHTS'!H6 -> 6 | J6: ='04_THRESHOLDS_WEIGHTS'!I6 -> 3 | K6: ='04_THRESHOLDS_WEIGHTS'!J6 -> 0 | L6: =IF(NOT(ISNUMBER(G6)),"",IF(F6="Positive",IF(G6<H6,0,IF(G6<I6,0.25+0.25*(G6-H6)/(I6-H6),IF(G6<J6,0.5+0.25*(G6-I6)/(J6-I6),IF(G6<K6,0.75+0.25*(G6-J6)/(K6-J6),1)))),IF(G6>H6,0,IF(G6>I6,0.25+0.25*(H6-G6)/(H6-I6),IF(G6>J6,0.5+0.25*(I6-G6)/(I6-J6),IF(G6>K6,0.75+0.25*(J6-G6)/(J6-K6),1)))))) -> 0.625 | M6: =IF(NOT(ISNUMBER(L6)),"",IF(L6<0.25,"Low",IF(L6<0.5,"Moderate",IF(L6<0.75,"Good","Excellent")))) -> Good | N6: ='04_THRESHOLDS_WEIGHTS'!K6 -> 0.16666667 | O6: ='04_THRESHOLDS_WEIGHTS'!L6 -> 0.25 | P6: =L6*N6 -> 0.10416667 | Q6: =L6*O6 -> 0.15625
A7: A | B7: A4 | C7: Coefficient of variation of annual inflow | D7: Exposure | E7: Interannual variability | F7: Negative | G7: ='05_IMPORT_BASELINE'!D7 -> 0.87666572 | H7: ='04_THRESHOLDS_WEIGHTS'!G7 -> 1.1 | I7: ='04_THRESHOLDS_WEIGHTS'!H7 -> 0.9 | J7: ='04_THRESHOLDS_WEIGHTS'!I7 -> 0.5 | K7: ='04_THRESHOLDS_WEIGHTS'!J7 -> 0 | L7: =IF(NOT(ISNUMBER(G7)),"",IF(F7="Positive",IF(G7<H7,0,IF(G7<I7,0.25+0.25*(G7-H7)/(I7-H7),IF(G7<J7,0.5+0.25*(G7-I7)/(J7-I7),IF(G7<K7,0.75+0.25*(G7-J7)/(K7-J7),1)))),IF(G7>H7,0,IF(G7>I7,0.25+0.25*(H7-G7)/(H7-I7),IF(G7>J7,0.5+0.25*(I7-G7)/(I7-J7),IF(G7>K7,0.75+0.25*(J7-G7)/(J7-K7),1)))))) -> 0.51458393 | M7: =IF(NOT(ISNUMBER(L7)),"",IF(L7<0.25,"Low",IF(L7<0.5,"Moderate",IF(L7<0.75,"Good","Excellent")))) -> Good | N7: ='04_THRESHOLDS_WEIGHTS'!K7 -> 0.16666667 | O7: ='04_THRESHOLDS_WEIGHTS'!L7 -> 0.25 | P7: =L7*N7 -> 0.085763988 | Q7: =L7*O7 -> 0.12864598
A8: A | B8: A5 | C8: Buffering capacity | D8: Structural proxy | E8: Storage context and dependence | F8: Positive | G8: ='05_IMPORT_BASELINE'!D8 -> 7.0450966 | H8: ='04_THRESHOLDS_WEIGHTS'!G8 -> 0.75 | I8: ='04_THRESHOLDS_WEIGHTS'!H8 -> 1.5 | J8: ='04_THRESHOLDS_WEIGHTS'!I8 -> 3 | K8: ='04_THRESHOLDS_WEIGHTS'!J8 -> 90.830935 | L8: =IF(NOT(ISNUMBER(G8)),"",IF(F8="Positive",IF(G8<H8,0,IF(G8<I8,0.25+0.25*(G8-H8)/(I8-H8),IF(G8<J8,0.5+0.25*(G8-I8)/(J8-I8),IF(G8<K8,0.75+0.25*(G8-J8)/(K8-J8),1)))),IF(G8>H8,0,IF(G8>I8,0.25+0.25*(H8-G8)/(H8-I8),IF(G8>J8,0.5+0.25*(I8-G8)/(I8-J8),IF(G8>K8,0.75+0.25*(J8-G8)/(J8-K8),1)))))) -> 0.76151387 | M8: =IF(NOT(ISNUMBER(L8)),"",IF(L8<0.25,"Low",IF(L8<0.5,"Moderate",IF(L8<0.75,"Good","Excellent")))) -> Excellent | N8: ='04_THRESHOLDS_WEIGHTS'!K8 -> 0.16666667 | O8: ='04_THRESHOLDS_WEIGHTS'!L8 -> 0.125 | P8: =L8*N8 -> 0.12691898 | Q8: =L8*O8 -> 0.095189234
A9: A | B9: A6 | C9: Carry-over dependence | D9: Stress | E9: Storage context and dependence | F9: Negative | G9: ='05_IMPORT_BASELINE'!D9 -> 1.8398792 | H9: ='04_THRESHOLDS_WEIGHTS'!G9 -> 2 | I9: ='04_THRESHOLDS_WEIGHTS'!H9 -> 1.5 | J9: ='04_THRESHOLDS_WEIGHTS'!I9 -> 1.05 | K9: ='04_THRESHOLDS_WEIGHTS'!J9 -> 1 | L9: =IF(NOT(ISNUMBER(G9)),"",IF(F9="Positive",IF(G9<H9,0,IF(G9<I9,0.25+0.25*(G9-H9)/(I9-H9),IF(G9<J9,0.5+0.25*(G9-I9)/(J9-I9),IF(G9<K9,0.75+0.25*(G9-J9)/(K9-J9),1)))),IF(G9>H9,0,IF(G9>I9,0.25+0.25*(H9-G9)/(H9-I9),IF(G9>J9,0.5+0.25*(I9-G9)/(I9-J9),IF(G9>K9,0.75+0.25*(J9-G9)/(J9-K9),1)))))) -> 0.33006038 | M9: =IF(NOT(ISNUMBER(L9)),"",IF(L9<0.25,"Low",IF(L9<0.5,"Moderate",IF(L9<0.75,"Good","Excellent")))) -> Moderate | N9: ='04_THRESHOLDS_WEIGHTS'!K9 -> 0.16666667 | O9: ='04_THRESHOLDS_WEIGHTS'!L9 -> 0.125 | P9: =L9*N9 -> 0.055010063 | Q9: =L9*O9 -> 0.041257547
A10: B | B10: B1 | C10: Time-based supply reliability | D10: Performance | E10: Supply adequacy | F10: Positive | G10: ='05_IMPORT_BASELINE'!D10 -> 0.99375 | H10: ='04_THRESHOLDS_WEIGHTS'!G10 -> 0.5 | I10: ='04_THRESHOLDS_WEIGHTS'!H10 -> 0.6 | J10: ='04_THRESHOLDS_WEIGHTS'!I10 -> 0.8 | K10: ='04_THRESHOLDS_WEIGHTS'!J10 -> 1 | L10: =IF(NOT(ISNUMBER(G10)),"",IF(F10="Positive",IF(G10<H10,0,IF(G10<I10,0.25+0.25*(G10-H10)/(I10-H10),IF(G10<J10,0.5+0.25*(G10-I10)/(J10-I10),IF(G10<K10,0.75+0.25*(G10-J10)/(K10-J10),1)))),IF(G10>H10,0,IF(G10>I10,0.25+0.25*(H10-G10)/(H10-I10),IF(G10>J10,0.5+0.25*(I10-G10)/(I10-J10),IF(G10>K10,0.75+0.25*(J10-G10)/(J10-K10),1)))))) -> 0.9921875 | M10: =IF(NOT(ISNUMBER(L10)),"",IF(L10<0.25,"Low",IF(L10<0.5,"Moderate",IF(L10<0.75,"Good","Excellent")))) -> Excellent | N10: ='04_THRESHOLDS_WEIGHTS'!K10 -> 0.2 | O10: ='04_THRESHOLDS_WEIGHTS'!L10 -> 0.125 | P10: =L10*N10 -> 0.1984375 | Q10: =L10*O10 -> 0.12402344
A11: B | B11: B2 | C11: Volumetric supply reliability | D11: Performance | E11: Supply adequacy | F11: Positive | G11: ='05_IMPORT_BASELINE'!D11 -> 0.99046393 | H11: ='04_THRESHOLDS_WEIGHTS'!G11 -> 0.5 | I11: ='04_THRESHOLDS_WEIGHTS'!H11 -> 0.6 | J11: ='04_THRESHOLDS_WEIGHTS'!I11 -> 0.8 | K11: ='04_THRESHOLDS_WEIGHTS'!J11 -> 1 | L11: =IF(NOT(ISNUMBER(G11)),"",IF(F11="Positive",IF(G11<H11,0,IF(G11<I11,0.25+0.25*(G11-H11)/(I11-H11),IF(G11<J11,0.5+0.25*(G11-I11)/(J11-I11),IF(G11<K11,0.75+0.25*(G11-J11)/(K11-J11),1)))),IF(G11>H11,0,IF(G11>I11,0.25+0.25*(H11-G11)/(H11-I11),IF(G11>J11,0.5+0.25*(I11-G11)/(I11-J11),IF(G11>K11,0.75+0.25*(J11-G11)/(J11-K11),1)))))) -> 0.98807992 | M11: =IF(NOT(ISNUMBER(L11)),"",IF(L11<0.25,"Low",IF(L11<0.5,"Moderate",IF(L11<0.75,"Good","Excellent")))) -> Excellent | N11: ='04_THRESHOLDS_WEIGHTS'!K11 -> 0.2 | O11: ='04_THRESHOLDS_WEIGHTS'!L11 -> 0.125 | P11: =L11*N11 -> 0.19761598 | Q11: =L11*O11 -> 0.12350999
A12: B | B12: B3 | C12: Mean supply performance during failure | D12: Performance | E12: Failure severity | F12: Positive | G12: ='05_IMPORT_BASELINE'!D12 -> 0.77155359 | H12: ='04_THRESHOLDS_WEIGHTS'!G12 -> 0.7 | I12: ='04_THRESHOLDS_WEIGHTS'!H12 -> 0.75 | J12: ='04_THRESHOLDS_WEIGHTS'!I12 -> 0.8 | K12: ='04_THRESHOLDS_WEIGHTS'!J12 -> 1 | L12: =IF(NOT(ISNUMBER(G12)),"",IF(F12="Positive",IF(G12<H12,0,IF(G12<I12,0.25+0.25*(G12-H12)/(I12-H12),IF(G12<J12,0.5+0.25*(G12-I12)/(J12-I12),IF(G12<K12,0.75+0.25*(G12-J12)/(K12-J12),1)))),IF(G12>H12,0,IF(G12>I12,0.25+0.25*(H12-G12)/(H12-I12),IF(G12>J12,0.5+0.25*(I12-G12)/(I12-J12),IF(G12>K12,0.75+0.25*(J12-G12)/(J12-K12),1)))))) -> 0.60776795 | M12: =IF(NOT(ISNUMBER(L12)),"",IF(L12<0.25,"Low",IF(L12<0.5,"Moderate",IF(L12<0.75,"Good","Excellent")))) -> Good | N12: ='04_THRESHOLDS_WEIGHTS'!K12 -> 0.2 | O12: ='04_THRESHOLDS_WEIGHTS'!L12 -> 0.25 | P12: =L12*N12 -> 0.12155359 | Q12: =L12*O12 -> 0.15194199
A13: B | B13: B4 | C13: Recovery after failure | D13: Performance | E13: Recovery | F13: Positive | G13: ='05_IMPORT_BASELINE'!D13 -> 0.83333333 | H13: ='04_THRESHOLDS_WEIGHTS'!G13 -> 0.25 | I13: ='04_THRESHOLDS_WEIGHTS'!H13 -> 0.5 | J13: ='04_THRESHOLDS_WEIGHTS'!I13 -> 0.75 | K13: ='04_THRESHOLDS_WEIGHTS'!J13 -> 1 | L13: =IF(NOT(ISNUMBER(G13)),"",IF(F13="Positive",IF(G13<H13,0,IF(G13<I13,0.25+0.25*(G13-H13)/(I13-H13),IF(G13<J13,0.5+0.25*(G13-I13)/(J13-I13),IF(G13<K13,0.75+0.25*(G13-J13)/(K13-J13),1)))),IF(G13>H13,0,IF(G13>I13,0.25+0.25*(H13-G13)/(H13-I13),IF(G13>J13,0.5+0.25*(I13-G13)/(I13-J13),IF(G13>K13,0.75+0.25*(J13-G13)/(J13-K13),1)))))) -> 0.83333333 | M13: =IF(NOT(ISNUMBER(L13)),"",IF(L13<0.25,"Low",IF(L13<0.5,"Moderate",IF(L13<0.75,"Good","Excellent")))) -> Excellent | N13: ='04_THRESHOLDS_WEIGHTS'!K13 -> 0.2 | O13: ='04_THRESHOLDS_WEIGHTS'!L13 -> 0.25 | P13: =L13*N13 -> 0.16666667 | Q13: =L13*O13 -> 0.20833333
A14: B | B14: B5 | C14: Spill–shortage coexistence frequency | D14: Performance | E14: Operational coherence | F14: Negative | G14: ='05_IMPORT_BASELINE'!D14 -> 0 | H14: ='04_THRESHOLDS_WEIGHTS'!G14 -> 0.3 | I14: ='04_THRESHOLDS_WEIGHTS'!H14 -> 0.1 | J14: ='04_THRESHOLDS_WEIGHTS'!I14 -> 0.01 | K14: ='04_THRESHOLDS_WEIGHTS'!J14 -> 0 | L14: =IF(NOT(ISNUMBER(G14)),"",IF(F14="Positive",IF(G14<H14,0,IF(G14<I14,0.25+0.25*(G14-H14)/(I14-H14),IF(G14<J14,0.5+0.25*(G14-I14)/(J14-I14),IF(G14<K14,0.75+0.25*(G14-J14)/(K14-J14),1)))),IF(G14>H14,0,IF(G14>I14,0.25+0.25*(H14-G14)/(H14-I14),IF(G14>J14,0.5+0.25*(I14-G14)/(I14-J14),IF(G14>K14,0.75+0.25*(J14-G14)/(J14-K14),1)))))) -> 1 | M14: =IF(NOT(ISNUMBER(L14)),"",IF(L14<0.25,"Low",IF(L14<0.5,"Moderate",IF(L14<0.75,"Good","Excellent")))) -> Excellent | N14: ='04_THRESHOLDS_WEIGHTS'!K14 -> 0.2 | O14: ='04_THRESHOLDS_WEIGHTS'!L14 -> 0.25 | P14: =L14*N14 -> 0.2 | Q14: =L14*O14 -> 0.25
A15: C | B15: C1 | C15: Hydrant pressure reliability | D15: Performance | E15: Pressure reliability | F15: Positive | G15: ='05_IMPORT_BASELINE'!D15 -> 0.98197379 | H15: ='04_THRESHOLDS_WEIGHTS'!G15 -> 0.5 | I15: ='04_THRESHOLDS_WEIGHTS'!H15 -> 0.75 | J15: ='04_THRESHOLDS_WEIGHTS'!I15 -> 0.85 | K15: ='04_THRESHOLDS_WEIGHTS'!J15 -> 1 | L15: =IF(NOT(ISNUMBER(G15)),"",IF(F15="Positive",IF(G15<H15,0,IF(G15<I15,0.25+0.25*(G15-H15)/(I15-H15),IF(G15<J15,0.5+0.25*(G15-I15)/(J15-I15),IF(G15<K15,0.75+0.25*(G15-J15)/(K15-J15),1)))),IF(G15>H15,0,IF(G15>I15,0.25+0.25*(H15-G15)/(H15-I15),IF(G15>J15,0.5+0.25*(I15-G15)/(I15-J15),IF(G15>K15,0.75+0.25*(J15-G15)/(J15-K15),1)))))) -> 0.96995632 | M15: =IF(NOT(ISNUMBER(L15)),"",IF(L15<0.25,"Low",IF(L15<0.5,"Moderate",IF(L15<0.75,"Good","Excellent")))) -> Excellent | N15: ='04_THRESHOLDS_WEIGHTS'!K15 -> 0.2 | O15: ='04_THRESHOLDS_WEIGHTS'!L15 -> 0.25 | P15: =L15*N15 -> 0.19399126 | Q15: =L15*O15 -> 0.24248908
... A41: F | B41: F4 | C41: Participation, communication and compliance | D41: Institutional capacity | E41: Participation and compliance | F41: Positive | G41: ='05_IMPORT_BASELINE'!D41 -> 0.4375 | H41: ='04_THRESHOLDS_WEIGHTS'!G41 -> 0.25 | I41: ='04_THRESHOLDS_WEIGHTS'!H41 -> 0.5 | J41: ='04_THRESHOLDS_WEIGHTS'!I41 -> 0.75 | K41: ='04_THRESHOLDS_WEIGHTS'!J41 -> 1 | L41: =IF(NOT(ISNUMBER(G41)),"",IF(F41="Positive",IF(G41<H41,0,IF(G41<I41,0.25+0.25*(G41-H41)/(I41-H41),IF(G41<J41,0.5+0.25*(G41-I41)/(J41-I41),IF(G41<K41,0.75+0.25*(G41-J41)/(K41-J41),1)))),IF(G41>H41,0,IF(G41>I41,0.25+0.25*(H41-G41)/(H41-I41),IF(G41>J41,0.5+0.25*(I41-G41)/(I41-J41),IF(G41>K41,0.75+0.25*(J41-G41)/(J41-K41),1)))))) -> 0.4375 | M41: =IF(NOT(ISNUMBER(L41)),"",IF(L41<0.25,"Low",IF(L41<0.5,"Moderate",IF(L41<0.75,"Good","Excellent")))) -> Moderate | N41: ='04_THRESHOLDS_WEIGHTS'!K41 -> 0.25 | O41: ='04_THRESHOLDS_WEIGHTS'!L41 -> 0.25 | P41: =L41*N41 -> 0.109375 | Q41: =L41*O41 -> 0.109375

Sheet 09_BASELINE_RESULTS
A1: Baseline subsystem and CIS resilience
A3: Subsystem | B3: Equal-indicator score | C3: Dimension-balanced score | D3: Equal class | E3: Dimension class | F3: Difference | G3: Interpretation
A4: A | B4: =SUMIFS('08_NORMALISATION'!$P$4:$P$41,'08_NORMALISATION'!$A$4:$A$41,A4) -> 0.60981447 | C4: =SUMIFS('08_NORMALISATION'!$Q$4:$Q$41,'08_NORMALISATION'!$A$4:$A$41,A4) -> 0.59980884 | D4: =IF(NOT(ISNUMBER(B4)),"",IF(B4<0.25,"Low",IF(B4<0.5,"Moderate",IF(B4<0.75,"Good","Excellent")))) -> Good | E4: =IF(NOT(ISNUMBER(C4)),"",IF(C4<0.25,"Low",IF(C4<0.5,"Moderate",IF(C4<0.75,"Good","Excellent")))) -> Good | F4: =C4-B4 -> -0.010005627 | G4: Preferred result is dimension-balanced.
A5: B | B5: =SUMIFS('08_NORMALISATION'!$P$4:$P$41,'08_NORMALISATION'!$A$4:$A$41,A5) -> 0.88427374 | C5: =SUMIFS('08_NORMALISATION'!$Q$4:$Q$41,'08_NORMALISATION'!$A$4:$A$41,A5) -> 0.85780875 | D5: =IF(NOT(ISNUMBER(B5)),"",IF(B5<0.25,"Low",IF(B5<0.5,"Moderate",IF(B5<0.75,"Good","Excellent")))) -> Excellent | E5: =IF(NOT(ISNUMBER(C5)),"",IF(C5<0.25,"Low",IF(C5<0.5,"Moderate",IF(C5<0.75,"Good","Excellent")))) -> Excellent | F5: =C5-B5 -> -0.026464992 | G5: Preferred result is dimension-balanced.
A6: C | B6: =SUMIFS('08_NORMALISATION'!$P$4:$P$41,'08_NORMALISATION'!$A$4:$A$41,A6) -> 0.76150514 | C6: =SUMIFS('08_NORMALISATION'!$Q$4:$Q$41,'08_NORMALISATION'!$A$4:$A$41,A6) -> 0.79300253 | D6: =IF(NOT(ISNUMBER(B6)),"",IF(B6<0.25,"Low",IF(B6<0.5,"Moderate",IF(B6<0.75,"Good","Excellent")))) -> Excellent | E6: =IF(NOT(ISNUMBER(C6)),"",IF(C6<0.25,"Low",IF(C6<0.5,"Moderate",IF(C6<0.75,"Good","Excellent")))) -> Excellent | F6: =C6-B6 -> 0.031497382 | G6: Preferred result is dimension-balanced.
A7: D | B7: =SUMIFS('08_NORMALISATION'!$P$4:$P$41,'08_NORMALISATION'!$A$4:$A$41,A7) -> 0.66498612 | C7: =SUMIFS('08_NORMALISATION'!$Q$4:$Q$41,'08_NORMALISATION'!$A$4:$A$41,A7) -> 0.67098653 | D7: =IF(NOT(ISNUMBER(B7)),"",IF(B7<0.25,"Low",IF(B7<0.5,"Moderate",IF(B7<0.75,"Good","Excellent")))) -> Good | E7: =IF(NOT(ISNUMBER(C7)),"",IF(C7<0.25,"Low",IF(C7<0.5,"Moderate",IF(C7<0.75,"Good","Excellent")))) -> Good | F7: =C7-B7 -> 0.0060004069 | G7: Preferred result is dimension-balanced.
A8: E | B8: =SUMIFS('08_NORMALISATION'!$P$4:$P$41,'08_NORMALISATION'!$A$4:$A$41,A8) -> 0.6079908 | C8: =SUMIFS('08_NORMALISATION'!$Q$4:$Q$41,'08_NORMALISATION'!$A$4:$A$41,A8) -> 0.59489976 | D8: =IF(NOT(ISNUMBER(B8)),"",IF(B8<0.25,"Low",IF(B8<0.5,"Moderate",IF(B8<0.75,"Good","Excellent")))) -> Good | E8: =IF(NOT(ISNUMBER(C8)),"",IF(C8<0.25,"Low",IF(C8<0.5,"Moderate",IF(C8<0.75,"Good","Excellent")))) -> Good | F8: =C8-B8 -> -0.013091037 | G8: Preferred result is dimension-balanced.
A9: F | B9: =SUMIFS('08_NORMALISATION'!$P$4:$P$41,'08_NORMALISATION'!$A$4:$A$41,A9) -> 0.59375 | C9: =SUMIFS('08_NORMALISATION'!$Q$4:$Q$41,'08_NORMALISATION'!$A$4:$A$41,A9) -> 0.59375 | D9: =IF(NOT(ISNUMBER(B9)),"",IF(B9<0.25,"Low",IF(B9<0.5,"Moderate",IF(B9<0.75,"Good","Excellent")))) -> Good | E9: =IF(NOT(ISNUMBER(C9)),"",IF(C9<0.25,"Low",IF(C9<0.5,"Moderate",IF(C9<0.75,"Good","Excellent")))) -> Good | F9: =C9-B9 -> 0 | G9: Preferred result is dimension-balanced.
A12: CIS result | B12: Equal-indicator overall | C12: Dimension-balanced overall | D12: Equal class | E12: Dimension class | F12: Selected score | G12: Selected weighting
A13: 2016–2025 | B13: =AVERAGE(B4:B9) -> 0.68705338 | C13: =AVERAGE(C4:C9) -> 0.68504273 | D13: =IF(NOT(ISNUMBER(B13)),"",IF(B13<0.25,"Low",IF(B13<0.5,"Moderate",IF(B13<0.75,"Good","Excellent")))) -> Good | E13: =IF(NOT(ISNUMBER(C13)),"",IF(C13<0.25,"Low",IF(C13<0.5,"Moderate",IF(C13<0.75,"Good","Excellent")))) -> Good | F13: =IF('01_CONTROL'!B11="Equal indicators",B13,C13) -> 0.68504273 | G13: ='01_CONTROL'!B11 -> Dimension-balanced
A16: Interpretation item | B16: Result | C16: Meaning
A17: Overall class | B17: =E13 -> Good | C17: Class based on the selected overall score.
A18: Weakest subsystem | B18: =INDEX(A4:A9,MATCH(MIN(C4:C9),C4:C9,0)) -> F | C18: Lowest dimension-balanced subsystem score.
A19: Strongest subsystem | B19: =INDEX(A4:A9,MATCH(MAX(C4:C9),C4:C9,0)) -> B | C19: Highest dimension-balanced subsystem score.
A20: Lowest indicator score | B20: =INDEX('08_NORMALISATION'!B4:B41,MATCH(MIN('08_NORMALISATION'!L4:L41),'08_NORMALISATION'!L4:L41,0)) -> E3 | C20: Most limiting normalised indicator.
A21: Highest indicator score | B21: =INDEX('08_NORMALISATION'!B4:B41,MATCH(MAX('08_NORMALISATION'!L4:L41),'08_NORMALISATION'!L4:L41,0)) -> B5 | C21: Highest normalised indicator.
A22: Important caution | B22: The overall index is a diagnostic synthesis and must be interpreted with the subsystem profile.

Sheet 10_ENSEMBLE_ANALYSIS
A1: Four complete GIR variants — normalisation and aggregation
A3: Subsystem | B3: Code | C3: Indicator | D3: Dimension | E3: Orientation | F3: T1 | G3: T2 | H3: T3 | I3: T4 | J3: ISW50_EffLow raw | K3: ISW50_EffLow norm | L3: ISW50_EffHigh raw | M3: ISW50_EffHigh norm | N3: ISW90_EffLow raw | O3: ISW90_EffLow norm | P3: ISW90_EffHigh raw | Q3: ISW90_EffHigh norm | R3: Raw mean | S3: Norm of raw mean | T3: Raw minimum | U3: Raw maximum
A4: A | B4: A1 | C4: Time-based inflow reliability | D4: Inflow adequacy | E4: Positive | F4: ='04_THRESHOLDS_WEIGHTS'!G4 -> 0.4 | G4: ='04_THRESHOLDS_WEIGHTS'!H4 -> 0.6 | H4: ='04_THRESHOLDS_WEIGHTS'!I4 -> 0.8 | I4: ='04_THRESHOLDS_WEIGHTS'!J4 -> 1 | J4: ='07_IMPORT_ENSEMBLE'!E4 -> 0.725 | K4: =IF(NOT(ISNUMBER(J4)),"",IF(E4="Positive",IF(J4<F4,0,IF(J4<G4,0.25+0.25*(J4-F4)/(G4-F4),IF(J4<H4,0.5+0.25*(J4-G4)/(H4-G4),IF(J4<I4,0.75+0.25*(J4-H4)/(I4-H4),1)))),IF(J4>F4,0,IF(J4>G4,0.25+0.25*(F4-J4)/(F4-G4),IF(J4>H4,0.5+0.25*(G4-J4)/(G4-H4),IF(J4>I4,0.75+0.25*(H4-J4)/(H4-I4),1)))))) -> 0.65625 | L4: ='07_IMPORT_ENSEMBLE'!F4 -> 0.725 | M4: =IF(NOT(ISNUMBER(L4)),"",IF(E4="Positive",IF(L4<F4,0,IF(L4<G4,0.25+0.25*(L4-F4)/(G4-F4),IF(L4<H4,0.5+0.25*(L4-G4)/(H4-G4),IF(L4<I4,0.75+0.25*(L4-H4)/(I4-H4),1)))),IF(L4>F4,0,IF(L4>G4,0.25+0.25*(F4-L4)/(F4-G4),IF(L4>H4,0.5+0.25*(G4-L4)/(G4-H4),IF(L4>I4,0.75+0.25*(H4-L4)/(H4-I4),1)))))) -> 0.65625 | N4: ='07_IMPORT_ENSEMBLE'!G4 -> 0.725 | O4: =IF(NOT(ISNUMBER(N4)),"",IF(E4="Positive",IF(N4<F4,0,IF(N4<G4,0.25+0.25*(N4-F4)/(G4-F4),IF(N4<H4,0.5+0.25*(N4-G4)/(H4-G4),IF(N4<I4,0.75+0.25*(N4-H4)/(I4-H4),1)))),IF(N4>F4,0,IF(N4>G4,0.25+0.25*(F4-N4)/(F4-G4),IF(N4>H4,0.5+0.25*(G4-N4)/(G4-H4),IF(N4>I4,0.75+0.25*(H4-N4)/(H4-I4),1)))))) -> 0.65625 | P4: ='07_IMPORT_ENSEMBLE'!H4 -> 0.725 | Q4: =IF(NOT(ISNUMBER(P4)),"",IF(E4="Positive",IF(P4<F4,0,IF(P4<G4,0.25+0.25*(P4-F4)/(G4-F4),IF(P4<H4,0.5+0.25*(P4-G4)/(H4-G4),IF(P4<I4,0.75+0.25*(P4-H4)/(I4-H4),1)))),IF(P4>F4,0,IF(P4>G4,0.25+0.25*(F4-P4)/(F4-G4),IF(P4>H4,0.5+0.25*(G4-P4)/(G4-H4),IF(P4>I4,0.75+0.25*(H4-P4)/(H4-I4),1)))))) -> 0.65625 | R4: =AVERAGE(J4,L4,N4,P4) -> 0.725 | S4: =IF(NOT(ISNUMBER(R4)),"",IF(E4="Positive",IF(R4<F4,0,IF(R4<G4,0.25+0.25*(R4-F4)/(G4-F4),IF(R4<H4,0.5+0.25*(R4-G4)/(H4-G4),IF(R4<I4,0.75+0.25*(R4-H4)/(I4-H4),1)))),IF(R4>F4,0,IF(R4>G4,0.25+0.25*(F4-R4)/(F4-G4),IF(R4>H4,0.5+0.25*(G4-R4)/(G4-H4),IF(R4>I4,0.75+0.25*(H4-R4)/(H4-I4),1)))))) -> 0.65625 | T4: =MIN(J4,L4,N4,P4) -> 0.725 | U4: =MAX(J4,L4,N4,P4) -> 0.725
