Workbook

Sheet 00_README
A1: CIS integrated resilience framework tool v2
A3: Version | B3: v2 — standalone audit build
A4: Purpose | B4: Calculate and audit baseline, annual, four-member GIR ensemble, pre/post-expansion, correlation/redundancy and sensitivity results without external workbook links.
A5: Indicator policy | B5: All 38 indicators are retained by default. High correlation does not automatically remove an indicator. Operational-dimension weighting and diagnostic-only sensitivity are used before any exclusion.
A6: Baseline period | B6: 2016–2025
A7: Pre/post definition | B7: Pre: 2016–2020; Transition: 2021; Post: 2022–2025.
A8: Ensemble definition | B8: Four members only: ISW50_EffHigh, ISW50_EffLow, ISW90_EffHigh, ISW90_EffLow. Mean/min/max are summaries.
A9: Range terminology | B9: Annual min–max = interannual variability. Ensemble min–max = demand-scenario uncertainty. Pre–post difference = structural/temporal contrast. Sensitivity = methodological robustness.
A10: Default aggregation candidate | B10: Dimension-balanced within each subsystem, equal weights among subsystems. Equal-indicator aggregation remains available for comparison.
A11: Important limitation | B11: Pre/post differences are not causal estimates of expansion because climate, crop pattern and operations also differ.
A12: Subsystem F | B12: Current evidence assessment only; excluded from pre/post A–E comparison.
A13: Data provenance | B13: Embedded values were extracted from the uploaded Subsystems A–F workbooks and checked against the manuscript and supplementary material.

Sheet 01_CONTROL
A1: Control panel
A3: Parameter | B3: Value | C3: Use | D3: Editable?
A4: Assessment start | B4: 2016 | C4: Annual/baseline scope | D4: Yes
A5: Assessment end | B5: 2025 | C5: Annual/baseline scope | D5: Yes
A6: Pre period start | B6: 2016 | C6: Pre/post comparison | D6: Yes
A7: Pre period end | B7: 2020 | C7: Pre/post comparison | D7: Yes
A8: Transition year | B8: 2021 | C8: Excluded from pre/post | D8: Yes
A9: Post period start | B9: 2022 | C9: Pre/post comparison | D9: Yes
A10: Post period end | B10: 2025 | C10: Pre/post comparison | D10: Yes
A11: Selected weighting profile | B11: Dimension-balanced | C11: Baseline dashboard | D11: Yes
A12: Indicator retention policy | B12: Retain by default | C12: Methodological rule | D12: No
A13: Class thresholds (normalised) | B13: 0.25 / 0.50 / 0.75 | C13: Low / Moderate / Good / Excellent | D13: No

Sheet 02_CATALOG
A1: Indicator catalog and operational rationale
A3: Subsystem | B3: Code | C3: Indicator name | D3: Unit | E3: Orientation | F3: Indicator type | G3: Operational dimension | H3: Operational role | I3: Failure mechanism | J3: Decision supported | K3: Temporal basis | L3: Ensemble dependency | M3: Coverage | N3: Aggregation status | O3: Active | P3: Equal weight | Q3: Dimension weight | R3: Notes
A4: A | B4: A1 | C4: Time-based inflow reliability | D4: – | E4: Positive | F4: Performance | G4: Inflow adequacy | H4: Frequency with which monthly inflow meets the seasonal minimum threshold | I4: Frequent low-inflow months | J4: Drought alert and seasonal storage planning | K4: Period; annual diagnostic | L4: No | M4: 2016–2025 monthly inflow | N4: Active — retained | O4: Yes | P4: 0.16666667 | Q4: 0.125
A5: A | B5: A2 | C5: Volumetric inflow reliability | D5: – | E5: Positive | F5: Performance | G5: Inflow adequacy | H5: Cumulative inflow deficit severity relative to seasonal thresholds | I5: Large cumulative inflow deficits | J5: Allocation and carry-over planning | K5: Period; annual diagnostic | L5: No | M5: 2016–2025 monthly inflow | N5: Active — retained | O5: Yes | P5: 0.16666667 | Q5: 0.125
A6: A | B6: A3 | C6: Mean drought duration | D6: months | E6: Negative | F6: Stress | G6: Drought persistence | H6: Persistence of consecutive below-threshold inflow months | I6: Prolonged hydrological drought | J6: Multi-season restriction and recovery planning | K6: Period; annual diagnostic | L6: No | M6: 2016–2025 monthly inflow | N6: Active — retained | O6: Yes | P6: 0.16666667 | Q6: 0.25
A7: A | B7: A4 | C7: Coefficient of variation of annual inflow | D7: – | E7: Negative | F7: Exposure | G7: Interannual variability | H7: Year-to-year instability of annual inflow | I7: Unpredictable replenishment and sequencing risk | J7: Carry-over and allocation safety margins | K7: Period only | L7: No | M7: 2016–2025 annual inflow | N7: Active — retained | O7: Yes | P7: 0.16666667 | Q7: 0.25
A8: A | B8: A5 | C8: Buffering capacity | D8: – | E8: Positive | F8: Structural proxy | G8: Storage context and dependence | H8: Theoretical regulation potential relative to mean annual inflow | I8: Insufficient storage relative to inflow regime | J8: Long-term storage planning | K8: Period only | L8: No | M8: Net capacity and period mean inflow | N8: Active — retained | O8: Yes | P8: 0.16666667 | Q8: 0.125 | R8: Share a dimension; A5 is structural potential and A6 is dependence/stress.
A9: A | B9: A6 | C9: Carry-over dependence | D9: – | E9: Negative | F9: Stress | G9: Storage context and dependence | H9: Increase in dependence on multi-year storage relative to baseline inflow | I9: Service reliant on accumulated storage under declining inflow | J9: Carry-over safeguards and drought rules | K9: Period only | L9: No | M9: Baseline and period mean inflow | N9: Active — retained | O9: Yes | P9: 0.16666667 | Q9: 0.125 | R9: Share a dimension; A5 is structural potential and A6 is dependence/stress.
A10: B | B10: B1 | C10: Time-based supply reliability | D10: – | E10: Positive | F10: Performance | G10: Supply adequacy | H10: Frequency of months in which source demand is fully supplied | I10: Repeated service-failure months | J10: Reservoir operating rules and allocation | K10: Period and annual | L10: Yes | M10: 2016–2025; four GIR variants | N10: Active — retained | O10: Yes | P10: 0.2 | Q10: 0.125
A11: B | B11: B2 | C11: Volumetric supply reliability | D11: – | E11: Positive | F11: Performance | G11: Supply adequacy | H11: Share of source demand effectively supplied | I11: Large cumulative service deficit | J11: Supply targets and deficit allocation | K11: Period and annual | L11: Yes | M11: 2016–2025; four GIR variants | N11: Active — retained | O11: Yes | P11: 0.2 | Q11: 0.125
A12: B | B12: B3 | C12: Mean supply performance during failure | D12: – | E12: Positive | F12: Performance | G12: Failure severity | H12: Mean proportion of demand supplied during failure months | I12: Severe partial supply during failure | J12: Rationing intensity and priority rules | K12: Period and annual | L12: Yes | M12: 2016–2025; four GIR variants | N12: Active — retained | O12: Yes | P12: 0.2 | Q12: 0.25
A13: B | B13: B4 | C13: Recovery after failure | D13: – | E13: Positive | F13: Performance | G13: Recovery | H13: Probability of returning to satisfactory service after failure | I13: Persistent service failure | J13: Recovery rules and reserve margins | K13: Period and annual | L13: Yes | M13: 2016–2025; four GIR variants | N13: Active — retained | O13: Yes | P13: 0.2 | Q13: 0.25
A14: B | B14: B5 | C14: Spill–shortage coexistence frequency | D14: – | E14: Negative | F14: Performance | G14: Operational coherence | H14: Frequency of years with both spill and irrigation shortage | I14: Storage/operation mismatch | J14: Rule-curve and timing adjustments | K14: Period and annual | L14: Yes | M14: 2016–2025; four GIR variants | N14: Active — retained | O14: Yes | P14: 0.2 | Q14: 0.25
A15: C | B15: C1 | C15: Hydrant pressure reliability | D15: – | E15: Positive | F15: Performance | G15: Pressure reliability | H15: Overall reliability across open hydrant–simulation records (current workbook implementation) | I15: Frequent pressure failure at operating hydrants | J15: Network operation and rehabilitation | K15: Annual and period | L15: Yes | M15: 2016–2025; four GIR variants | N15: Active — retained | O15: Yes | P15: 0.2 | Q15: 0.25 | R15: Equation/label/unit harmonisation required before publication.
A16: C | B16: C2 | C16: Network pressure reliability | D16: – | E16: Positive | F16: Performance | G16: Pressure reliability | H16: Share of hydrants remaining outside the critical failed set | I16: Spatial concentration of hydraulic failure | J16: Sector prioritisation and network upgrades | K16: Annual and period | L16: Yes | M16: 2016–2025; four GIR variants | N16: Active — retained | O16: Yes | P16: 0.2 | Q16: 0.25 | R16: Equation/label/unit harmonisation required before publication.
A17: C | B17: C3 | C17: Relative pressure deficit | D17: % Pmin | E17: Negative | F17: Performance | G17: Pressure-deficit severity | H17: Mean relative pressure-deficit severity during hydraulic failure | I17: Widespread pressure shortfall | J17: Pressure setpoints and peak-demand control | K17: Annual and period | L17: Yes | M17: 2016–2025; four GIR variants | N17: Active — retained | O17: Yes | P17: 0.2 | Q17: 0.16666667 | R17: Equation/label/unit harmonisation required before publication.
A18: C | B18: C4 | C18: Critical hydrant deficit (P80) | D18: – | E18: Negative | F18: Performance | G18: Pressure-deficit severity | H18: Upper-tail relative pressure deficit at critical hydrants | I18: Persistent severe deficit at vulnerable hydrants | J18: Targeted pipe/hydrant rehabilitation | K18: Annual and period | L18: Yes | M18: 2016–2025; four GIR variants | N18: Active — retained | O18: Yes | P18: 0.2 | Q18: 0.16666667 | R18: Equation/label/unit harmonisation required before publication.
A19: C | B19: C5 | C19: Maximum hydrant deficit | D19: – | E19: Negative | F19: Performance | G19: Pressure-deficit severity | H19: Maximum simulated relative pressure deficit | I19: Extreme local hydraulic failure | J19: Critical-node protection | K19: Annual and period | L19: Yes | M19: 2016–2025; four GIR variants | N19: Active — retained | O19: Yes | P19: 0.2 | Q19: 0.16666667 | R19: Equation/label/unit harmonisation required before publication.
A20: D | B20: D1 | C20: Energy per irrigated area | D20: kWh ha⁻¹ | E20: Negative | F20: Performance | G20: Energy intensity | H20: Energy intensity relative to effectively irrigated area | I20: High energy burden per service area | J20: Pump operation and efficiency investment | K20: Annual; incomplete | L20: No | M20: 2018–2025 | N20: Active — retained | O20: Yes | P20: 0.125 | Q20: 0.083333333
A21: D | B21: D2 | C21: Energy per supplied volume | D21: kWh m⁻³ | E21: Negative | F21: Performance | G21: Energy intensity | H21: Energy intensity per volume delivered at hydrants | I21: High energy use per unit service | J21: Pumping efficiency and leakage control | K21: Annual; incomplete | L21: No | M21: 2018–2025 | N21: Active — retained | O21: Yes | P21: 0.125 | Q21: 0.083333333
A22: D | B22: D3 | C22: Energy per abstracted volume | D22: kWh m⁻³ | E22: Negative | F22: Performance | G22: Energy intensity | H22: Energy intensity per abstracted/source volume | I22: High source-side pumping intensity | J22: Pumping station optimisation | K22: Annual; incomplete | L22: No | M22: 2018–2025 | N22: Active — retained | O22: Yes | P22: 0.125 | Q22: 0.083333333 | R22: High redundancy flag; retained and tested as diagnostic-only alternative.
A23: D | B23: D4 | C23: Energy cost per irrigated area | D23: € ha⁻¹ | E23: Negative | F23: Exposure | G23: Financial exposure | H23: Energy-cost exposure per irrigated area | I23: High operating cost per service area | J23: Tariffs, budgets and investments | K23: Annual | L23: No | M23: 2016–2025 | N23: Active — retained | O23: Yes | P23: 0.125 | Q23: 0.083333333
A24: D | B24: D5 | C24: Energy cost per supplied volume | D24: € m⁻³ | E24: Negative | F24: Exposure | G24: Financial exposure | H24: Energy-cost exposure per delivered volume | I24: High financial burden per unit service | J24: Energy procurement and tariff design | K24: Annual | L24: No | M24: 2016–2025 | N24: Active — retained | O24: Yes | P24: 0.125 | Q24: 0.083333333
A25: D | B25: D6 | C25: Energy cost per abstracted volume | D25: € m⁻³ | E25: Negative | F25: Exposure | G25: Financial exposure | H25: Energy-cost exposure per source withdrawal | I25: High source-side financial burden | J25: Pumping and procurement strategy | K25: Annual | L25: No | M25: 2016–2025 | N25: Active — retained | O25: Yes | P25: 0.125 | Q25: 0.083333333 | R25: High redundancy flag; retained and tested as diagnostic-only alternative.
A26: D | B26: D7 | C26: Renewable energy contribution | D26: – | E26: Positive | F26: Adaptive capacity | G26: Decarbonisation | H26: Share of pumping energy covered by renewables | I26: Dependence on grid energy and price volatility | J26: Renewable-energy investment | K26: Current snapshot | L26: No | M26: 2025 only | N26: Active — retained | O26: Yes | P26: 0.125 | Q26: 0.25
A27: D | B27: D8 | C27: Pump redundancy | D27: – | E27: Positive | F27: Adaptive capacity | G27: Functional redundancy | H27: Spare pumping capacity relative to peak requirement | I27: No backup under pump failure or peak demand | J27: Pump reserve and contingency planning | K27: Annual | L27: No | M27: 2016–2025 | N27: Active — retained | O27: Yes | P27: 0.125 | Q27: 0.25
A28: E | B28: E1 | C28: Gross irrigation requirement | D28: mm | E28: Negative | F28: Stress | G28: Demand magnitude and concentration | H28: Seasonal gross irrigation demand imposed by crop/technology configuration | I28: High seasonal water demand | J28: Crop pattern and efficiency measures | K28: Annual and period | L28: Yes | M28: 2016–2025; four GIR variants | N28: Active — retained | O28: Yes | P28: 0.1 | Q28: 0.083333333
A29: E | B29: E2 | C29: Peak demand factor | D29: – | E29: Negative | F29: Stress | G29: Demand magnitude and concentration | H29: Share of seasonal demand concentrated in peak month | I29: High short-term pressure on source/network/energy | J29: Peak management and operating schedules | K29: Annual and period | L29: Yes | M29: 2016–2025; four GIR variants | N29: Active — retained | O29: Yes | P29: 0.1 | Q29: 0.083333333
A30: E | B30: E3 | C30: Peak demand staggering | D30: – | E30: Positive | F30: Adaptive capacity | G30: Demand magnitude and concentration | H30: Reduction in coincident peak due to temporal spreading among crops | I30: Synchronous crop-demand peaks | J30: Crop calendars and demand scheduling | K30: Annual and period | L30: Yes | M30: 2016–2025; four GIR variants | N30: Active — retained | O30: Yes | P30: 0.1 | Q30: 0.083333333
A31: E | B31: E4 | C31: Irrigation system factor | D31: – | E31: Negative | F31: Stress | G31: Irrigation technology and control | H31: Demand amplification associated with application efficiency and wetted fraction | I31: Technology-induced gross-demand amplification | J31: Technology performance improvement | K31: Annual and period | L31: Partly | M31: 2016–2025; low/high efficiency | N31: Active — retained | O31: Yes | P31: 0.1 | Q31: 0.125
A32: E | B32: E5 | C32: On-farm technology and control | D32: – | E32: Positive | F32: Adaptive capacity | G32: Irrigation technology and control | H32: Monitoring, scheduling, automation and variable-rate control | I32: Limited ability to adjust irrigation under stress | J32: Farm-control upgrades | K32: Annual and period | L32: No | M32: 2016–2025 | N32: Active — retained | O32: Yes | P32: 0.1 | Q32: 0.125
A33: E | B33: E6 | C33: Water-deficit and salinity tolerance | D33: – | E33: Positive | F33: Adaptive capacity | G33: Crop flexibility and exposure | H33: Crop-pattern capacity to tolerate moderate abiotic stress | I33: Yield sensitivity under deficit/salinity | J33: Crop diversification and deficit irrigation | K33: Annual and period | L33: No | M33: 2016–2025 | N33: Active — retained | O33: Yes | P33: 0.1 | Q33: 0.083333333
A34: E | B34: E7 | C34: Share of permanent crops | D34: – | E34: Negative | F34: Exposure | G34: Crop flexibility and exposure | H34: Long-term irrigation commitment and reduced allocation flexibility | I34: Rigid drought demand and asset-loss risk | J34: Allocation priorities and expansion control | K34: Annual and period | L34: No | M34: 2016–2025 | N34: Active — retained | O34: Yes | P34: 0.1 | Q34: 0.083333333
A35: E | B35: E8 | C35: Soil-water buffering capacity | D35: mm | E35: Positive | F35: Structural capacity | G35: Local buffering | H35: Plant-available soil-water storage in the effective root zone | I35: Rapid onset of irrigation demand and low interruption buffer | J35: Soil/crop management | K35: Annual and period | L35: No | M35: 2016–2025 | N35: Active — retained | O35: Yes | P35: 0.1 | Q35: 0.125
A36: E | B36: E9 | C36: Alternative local access to storage | D36: – | E36: Positive | F36: Structural proxy | G36: Local buffering | H36: Potential proximity-based access to local ponds/tanks | I36: No local buffer during short supply interruptions | J36: Local storage inventory and connection verification | K36: Current structural snapshot | L36: No | M36: Current mapping | N36: Active — retained | O36: Yes | P36: 0.1 | Q36: 0.125
A37: E | B37: E10 | C37: Chill requirement adequacy indicator | D37: – | E37: Positive | F37: Exposure | G37: Crop flexibility and exposure | H37: Adequacy of accumulated winter chill for chill-dependent crops | I37: Phenological/yield risk under warm winters | J37: Crop/variety adaptation | K37: Annual and period | L37: No | M37: 2016–2025 | N37: Active — retained | O37: Yes | P37: 0.1 | Q37: 0.083333333
... A41: F | B41: F4 | C41: Participation, communication and compliance | D41: – | E41: Positive | F41: Institutional capacity | G41: Participation and compliance | H41: Farmer involvement, communication, enforcement and conflict resolution | I41: Low compliance and ineffective rationing | J41: Communication and governance procedures | K41: Current assessment | L41: No | M41: Current evidence | N41: Active — retained | O41: Yes | P41: 0.25 | Q41: 0.25

Sheet 03_THRESHOLDS
A1: Corrected resilience thresholds and boundary rules
A3: Subsystem | B3: Code | C3: Indicator | D3: Unit | E3: Orientation | F3: T1 | G3: T2 | H3: T3 | I3: T4 saturation | J3: Class 1 Low | K3: Class 2 Moderate | L3: Class 3 Good | M3: Class 4 Excellent | N3: Threshold note
A4: A | B4: A1 | C4: Time-based inflow reliability | D4: – | E4: Positive | F4: 0.4 | G4: 0.6 | H4: 0.8 | I4: 1 | J4: x < 0.4 | K4: 0.4 ≤ x < 0.6 | L4: 0.6 ≤ x < 0.8 | M4: x ≥ 0.8
A5: A | B5: A2 | C5: Volumetric inflow reliability | D5: – | E5: Positive | F5: 0.4 | G5: 0.6 | H5: 0.8 | I5: 1 | J5: x < 0.4 | K5: 0.4 ≤ x < 0.6 | L5: 0.6 ≤ x < 0.8 | M5: x ≥ 0.8
A6: A | B6: A3 | C6: Mean drought duration | D6: months | E6: Negative | F6: 12 | G6: 6 | H6: 3 | I6: 0 | J6: x > 12 | K6: 6 < x ≤ 12 | L6: 3 < x ≤ 6 | M6: x ≤ 3
A7: A | B7: A4 | C7: Coefficient of variation of annual inflow | D7: – | E7: Negative | F7: 1.1 | G7: 0.9 | H7: 0.5 | I7: 0 | J7: x > 1.1 | K7: 0.9 < x ≤ 1.1 | L7: 0.5 < x ≤ 0.9 | M7: x ≤ 0.5
A8: A | B8: A5 | C8: Buffering capacity | D8: – | E8: Positive | F8: 0.75 | G8: 1.5 | H8: 3 | I8: 90.830935 | J8: x < 0.75 | K8: 0.75 ≤ x < 1.5 | L8: 1.5 ≤ x ≤ 3 | M8: x > 3 | N8: T4=90.8309 is a fixed technical saturation anchor, not the Excellent class boundary.
A9: A | B9: A6 | C9: Carry-over dependence | D9: – | E9: Negative | F9: 2 | G9: 1.5 | H9: 1.05 | I9: 1 | J9: x > 2 | K9: 1.5 < x ≤ 2 | L9: 1.05 < x ≤ 1.5 | M9: x ≤ 1.05 | N9: User-approved correction: Good 1.05<x≤1.50; Excellent x≤1.05.
A10: B | B10: B1 | C10: Time-based supply reliability | D10: – | E10: Positive | F10: 0.5 | G10: 0.6 | H10: 0.8 | I10: 1 | J10: x < 0.5 | K10: 0.5 ≤ x < 0.6 | L10: 0.6 ≤ x < 0.8 | M10: x ≥ 0.8
A11: B | B11: B2 | C11: Volumetric supply reliability | D11: – | E11: Positive | F11: 0.5 | G11: 0.6 | H11: 0.8 | I11: 1 | J11: x < 0.5 | K11: 0.5 ≤ x < 0.6 | L11: 0.6 ≤ x < 0.8 | M11: x ≥ 0.8
A12: B | B12: B3 | C12: Mean supply performance during failure | D12: – | E12: Positive | F12: 0.7 | G12: 0.75 | H12: 0.8 | I12: 1 | J12: x < 0.7 | K12: 0.7 ≤ x < 0.75 | L12: 0.75 ≤ x < 0.8 | M12: x ≥ 0.8
A13: B | B13: B4 | C13: Recovery after failure | D13: – | E13: Positive | F13: 0.25 | G13: 0.5 | H13: 0.75 | I13: 1 | J13: x < 0.25 | K13: 0.25 ≤ x < 0.5 | L13: 0.5 ≤ x < 0.75 | M13: x ≥ 0.75
A14: B | B14: B5 | C14: Spill–shortage coexistence frequency | D14: – | E14: Negative | F14: 0.3 | G14: 0.1 | H14: 0.01 | I14: 0 | J14: x > 0.3 | K14: 0.1 < x ≤ 0.3 | L14: 0.01 < x ≤ 0.1 | M14: x ≤ 0.01
A15: C | B15: C1 | C15: Hydrant pressure reliability | D15: – | E15: Positive | F15: 0.5 | G15: 0.75 | H15: 0.85 | I15: 1 | J15: x < 0.5 | K15: 0.5 ≤ x < 0.75 | L15: 0.75 ≤ x < 0.85 | M15: x ≥ 0.85
A16: C | B16: C2 | C16: Network pressure reliability | D16: – | E16: Positive | F16: 0.5 | G16: 0.75 | H16: 0.85 | I16: 1 | J16: x < 0.5 | K16: 0.5 ≤ x < 0.75 | L16: 0.75 ≤ x < 0.85 | M16: x ≥ 0.85
A17: C | B17: C3 | C17: Relative pressure deficit | D17: % Pmin | E17: Negative | F17: 1 | G17: 0.5 | H17: 0.3 | I17: 0.05 | J17: x > 1 | K17: 0.5 < x ≤ 1 | L17: 0.3 < x ≤ 0.5 | M17: x ≤ 0.3 | N17: Current v2 preserves % of Pmin implementation; harmonise manuscript equation/unit.
A18: C | B18: C4 | C18: Critical hydrant deficit (P80) | D18: – | E18: Negative | F18: 1 | G18: 0.5 | H18: 0.3 | I18: 0.05 | J18: x > 1 | K18: 0.5 < x ≤ 1 | L18: 0.3 < x ≤ 0.5 | M18: x ≤ 0.3
A19: C | B19: C5 | C19: Maximum hydrant deficit | D19: – | E19: Negative | F19: 1 | G19: 0.5 | H19: 0.3 | I19: 0.05 | J19: x > 1 | K19: 0.5 < x ≤ 1 | L19: 0.3 < x ≤ 0.5 | M19: x ≤ 0.3
A20: D | B20: D1 | C20: Energy per irrigated area | D20: kWh ha⁻¹ | E20: Negative | F20: 2000 | G20: 1500 | H20: 1000 | I20: 500 | J20: x > 2000 | K20: 1500 < x ≤ 2000 | L20: 1000 < x ≤ 1500 | M20: x ≤ 1000
A21: D | B21: D2 | C21: Energy per supplied volume | D21: kWh m⁻³ | E21: Negative | F21: 0.4 | G21: 0.3 | H21: 0.2 | I21: 0.1 | J21: x > 0.4 | K21: 0.3 < x ≤ 0.4 | L21: 0.2 < x ≤ 0.3 | M21: x ≤ 0.2
A22: D | B22: D3 | C22: Energy per abstracted volume | D22: kWh m⁻³ | E22: Negative | F22: 0.35 | G22: 0.25 | H22: 0.15 | I22: 0.1 | J22: x > 0.35 | K22: 0.25 < x ≤ 0.35 | L22: 0.15 < x ≤ 0.25 | M22: x ≤ 0.15
A23: D | B23: D4 | C23: Energy cost per irrigated area | D23: € ha⁻¹ | E23: Negative | F23: 200 | G23: 150 | H23: 100 | I23: 50 | J23: x > 200 | K23: 150 < x ≤ 200 | L23: 100 < x ≤ 150 | M23: x ≤ 100
A24: D | B24: D5 | C24: Energy cost per supplied volume | D24: € m⁻³ | E24: Negative | F24: 0.06 | G24: 0.04 | H24: 0.02 | I24: 0.01 | J24: x > 0.06 | K24: 0.04 < x ≤ 0.06 | L24: 0.02 < x ≤ 0.04 | M24: x ≤ 0.02
A25: D | B25: D6 | C25: Energy cost per abstracted volume | D25: € m⁻³ | E25: Negative | F25: 0.06 | G25: 0.04 | H25: 0.02 | I25: 0.01 | J25: x > 0.06 | K25: 0.04 < x ≤ 0.06 | L25: 0.02 < x ≤ 0.04 | M25: x ≤ 0.02
A26: D | B26: D7 | C26: Renewable energy contribution | D26: – | E26: Positive | F26: 0.05 | G26: 0.1 | H26: 0.2 | I26: 0.4 | J26: x < 0.05 | K26: 0.05 ≤ x < 0.1 | L26: 0.1 ≤ x < 0.2 | M26: x ≥ 0.2
A27: D | B27: D8 | C27: Pump redundancy | D27: – | E27: Positive | F27: 0 | G27: 0.25 | H27: 0.5 | I27: 1 | J27: x < 0 | K27: 0 ≤ x < 0.25 | L27: 0.25 ≤ x < 0.5 | M27: x ≥ 0.5
A28: E | B28: E1 | C28: Gross irrigation requirement | D28: mm | E28: Negative | F28: 600 | G28: 500 | H28: 400 | I28: 300 | J28: x > 600 | K28: 500 < x ≤ 600 | L28: 400 < x ≤ 500 | M28: x ≤ 400
A29: E | B29: E2 | C29: Peak demand factor | D29: – | E29: Negative | F29: 0.45 | G29: 0.35 | H29: 0.25 | I29: 0.2 | J29: x > 0.45 | K29: 0.35 < x ≤ 0.45 | L29: 0.25 < x ≤ 0.35 | M29: x ≤ 0.25
... A41: F | B41: F4 | C41: Participation, communication and compliance | D41: – | E41: Positive | F41: 0.25 | G41: 0.5 | H41: 0.75 | I41: 1 | J41: x < 0.25 | K41: 0.25 ≤ x < 0.5 | L41: 0.5 ≤ x < 0.75 | M41: x ≥ 0.75

Sheet 04_ANNUAL_DATA
A1: Embedded annual indicator values
A3: Year | B3: Period group | C3: Subsystem | D3: Indicator | E3: Raw value | F3: Annual availability | G3: Source treatment | H3: Notes
A4: 2016 | B4: Pre | C4: A | D4: A1 | E4: 1 | F4: Available
A5: 2016 | B5: Pre | C5: A | D5: A2 | E5: 1 | F5: Available
A6: 2016 | B6: Pre | C6: A | D6: A3 | E6: 0 | F6: Available
A7: 2016 | B7: Pre | C7: A | D7: A4 | F7: Not annual / missing | G7: Period-level definition; annual diagnostic excluded.
A8: 2016 | B8: Pre | C8: A | D8: A5 | F8: Not annual / missing | G8: Period-level definition; annual diagnostic excluded.
A9: 2016 | B9: Pre | C9: A | D9: A6 | F9: Not annual / missing | G9: Period-level definition; annual diagnostic excluded.
A10: 2016 | B10: Pre | C10: B | D10: B1 | E10: 1 | F10: Available
A11: 2016 | B11: Pre | C11: B | D11: B2 | E11: 1 | F11: Available
A12: 2016 | B12: Pre | C12: B | D12: B3 | E12: 1 | F12: Available
A13: 2016 | B13: Pre | C13: B | D13: B4 | E13: 1 | F13: Available
A14: 2016 | B14: Pre | C14: B | D14: B5 | E14: 0 | F14: Available
A15: 2016 | B15: Pre | C15: C | D15: C1 | E15: 0.97626513 | F15: Available
A16: 2016 | B16: Pre | C16: C | D16: C2 | E16: 0.94936709 | F16: Available
A17: 2016 | B17: Pre | C17: C | D17: C3 | E17: 0.60129413 | F17: Available
A18: 2016 | B18: Pre | C18: C | D18: C4 | E18: 0.49990097 | F18: Available
A19: 2016 | B19: Pre | C19: C | D19: C5 | E19: 0.55037189 | F19: Available
A20: 2016 | B20: Pre | C20: D | D20: D1 | F20: Not annual / missing | G20: Missing energy data; blank, not zero.
A21: 2016 | B21: Pre | C21: D | D21: D2 | F21: Not annual / missing | G21: Missing energy data; blank, not zero.
A22: 2016 | B22: Pre | C22: D | D22: D3 | F22: Not annual / missing | G22: Missing energy data; blank, not zero.
A23: 2016 | B23: Pre | C23: D | D23: D4 | E23: 107.93797 | F23: Available
A24: 2016 | B24: Pre | C24: D | D24: D5 | E24: 0.025065525 | F24: Available
A25: 2016 | B25: Pre | C25: D | D25: D6 | E25: 0.023566606 | F25: Available
A26: 2016 | B26: Pre | C26: D | D26: D7 | F26: Not annual / missing | G26: PV contribution unavailable before 2025.
A27: 2016 | B27: Pre | C27: D | D27: D8 | E27: 0.8813314 | F27: Available
A28: 2016 | B28: Pre | C28: E | D28: E1 | E28: 406.89192 | F28: Available
A29: 2016 | B29: Pre | C29: E | D29: E2 | E29: 0.35340835 | F29: Available
A30: 2016 | B30: Pre | C30: E | D30: E3 | E30: 0.81292855 | F30: Available
A31: 2016 | B31: Pre | C31: E | D31: E4 | E31: 0.9998195 | F31: Available
A32: 2016 | B32: Pre | C32: E | D32: E5 | E32: 0.55455787 | F32: Available
A33: 2016 | B33: Pre | C33: E | D33: E6 | E33: 0.56121245 | F33: Available
A34: 2016 | B34: Pre | C34: E | D34: E7 | E34: 0.18425818 | F34: Available
A35: 2016 | B35: Pre | C35: E | D35: E8 | E35: 77.802488 | F35: Available
A36: 2016 | B36: Pre | C36: E | D36: E9 | E36: 0.41686881 | F36: Available | G36: Current structural value; annual change not inferred.
A37: 2016 | B37: Pre | C37: E | D37: E10 | E37: 0.90774403 | F37: Available
A38: 2016 | B38: Pre | C38: F | D38: F1 | F38: Not annual / missing | G38: Current evidence assessment only.
A39: 2016 | B39: Pre | C39: F | D39: F2 | F39: Not annual / missing | G39: Current evidence assessment only.
A40: 2016 | B40: Pre | C40: F | D40: F3 | F40: Not annual / missing | G40: Current evidence assessment only.
A41: 2016 | B41: Pre | C41: F | D41: F4 | F41: Not annual / missing | G41: Current evidence assessment only.
...

Sheet 05_ENSEMBLE
A1: Four-member GIR ensemble — period results | J1: Variant-level integrated results
A2: Rule | B2: The ensemble has four members. Mean/min/max are summaries and are not counted as additional members.
J3: Variant | K3: Equal A | L3: Equal B | M3: Equal C | N3: Equal D | O3: Equal E | P3: Equal F | Q3: Equal overall | R3: Dim overall
A4: Variant | B4: Subsystem | C4: Indicator | D4: Raw value | E4: Normalised value | F4: Indicator type | G4: Operational dimension | H4: Comment | J4: ISW50_EffHigh | K4: 0.60981447 | L4: 1 | M4: 0.76314556 | N4: 0.66498612 | O4: 0.68875176 | P4: 0.59375 | Q4: 0.72007465 | R4: 0.72169522
A5: ISW50_EffHigh | B5: B | C5: B1 | D5: 1 | E5: 1 | F5: Performance | G5: Supply adequacy | H5: Complete variant retained; no cross-variant mixing. | J5: ISW50_EffLow | K5: 0.60981447 | L5: 0.6508806 | M5: 0.75539745 | N5: 0.66498612 | O5: 0.70973657 | P5: 0.59375 | Q5: 0.6640942 | R5: 0.65116968
A6: ISW50_EffHigh | B6: B | C6: B2 | D6: 1 | E6: 1 | F6: Performance | G6: Supply adequacy | H6: Complete variant retained; no cross-variant mixing. | J6: ISW90_EffHigh | K6: 0.60981447 | L6: 1 | M6: 0.76387995 | N6: 0.66498612 | O6: 0.70226985 | P6: 0.59375 | Q6: 0.72245006 | R6: 0.72374196
A7: ISW50_EffHigh | B7: B | C7: B3 | D7: 1 | E7: 1 | F7: Performance | G7: Failure severity | H7: Complete variant retained; no cross-variant mixing. | J7: ISW90_EffLow | K7: 0.60981447 | L7: 1 | M7: 0.76359761 | N7: 0.66498612 | O7: 0.72569417 | P7: 0.59375 | Q7: 0.72630706 | R7: 0.72581751
A8: ISW50_EffHigh | B8: B | C8: B4 | D8: 1 | E8: 1 | F8: Performance | G8: Recovery | H8: Complete variant retained; no cross-variant mixing.
A9: ISW50_EffHigh | B9: B | C9: B5 | D9: 0 | E9: 1 | F9: Performance | G9: Operational coherence | H9: Complete variant retained; no cross-variant mixing. | J9: Summary | K9: Min | L9: Mean | M9: Max
A10: ISW50_EffHigh | B10: C | C10: C1 | D10: 0.98222542 | E10: 0.97037571 | F10: Performance | G10: Pressure reliability | H10: Complete variant retained; no cross-variant mixing. | J10: Equal overall | K10: 0.6640942 | L10: 0.70823149 | M10: 0.72630706
A11: ISW50_EffHigh | B11: C | C11: C2 | D11: 0.95719937 | E11: 0.92866561 | F11: Performance | G11: Pressure reliability | H11: Complete variant retained; no cross-variant mixing. | J11: Dimension overall | K11: 0.65116968 | L11: 0.70560609 | M11: 0.72581751
A12: ISW50_EffHigh | B12: C | C12: C3 | D12: 0.39084251 | E12: 0.63644687 | F12: Performance | G12: Pressure-deficit severity | H12: Complete variant retained; no cross-variant mixing.
A13: ISW50_EffHigh | B13: C | C13: C4 | D13: 0.34259933 | E13: 0.69675083 | F13: Performance | G13: Pressure-deficit severity | H13: Complete variant retained; no cross-variant mixing.
A14: ISW50_EffHigh | B14: C | C14: C5 | D14: 0.43320896 | E14: 0.5834888 | F14: Performance | G14: Pressure-deficit severity | H14: Complete variant retained; no cross-variant mixing.
A15: ISW50_EffHigh | B15: E | C15: E1 | D15: 510.25104 | E15: 0.47437239 | F15: Stress | G15: Demand magnitude and concentration | H15: Complete variant retained; no cross-variant mixing.
A16: ISW50_EffHigh | B16: E | C16: E2 | D16: 0.33755008 | E16: 0.53112481 | F16: Stress | G16: Demand magnitude and concentration | H16: Complete variant retained; no cross-variant mixing.
A17: ISW50_EffHigh | B17: E | C17: E3 | D17: 0.70220232 | E17: 0.70220232 | F17: Adaptive capacity | G17: Demand magnitude and concentration | H17: Complete variant retained; no cross-variant mixing.
A18: ISW50_EffHigh | B18: E | C18: E4 | D18: 0.9161165 | E18: 0.61156959 | F18: Stress | G18: Irrigation technology and control | H18: Complete variant retained; no cross-variant mixing.
A19: ISW50_EffHigh | B19: E | C19: E5 | D19: 0.56628899 | E19: 0.56628899 | F19: Adaptive capacity | G19: Irrigation technology and control | H19: Complete variant retained; no cross-variant mixing.
A20: ISW50_EffHigh | B20: E | C20: E6 | D20: 0.54884269 | E20: 1 | F20: Adaptive capacity | G20: Crop flexibility and exposure | H20: Complete variant retained; no cross-variant mixing.
A21: ISW50_EffHigh | B21: E | C21: E7 | D21: 0.19744236 | E21: 1 | F21: Exposure | G21: Crop flexibility and exposure | H21: Complete variant retained; no cross-variant mixing.
A22: ISW50_EffHigh | B22: E | C22: E8 | D22: 79.541354 | E22: 0.74426693 | F22: Structural capacity | G22: Local buffering | H22: Complete variant retained; no cross-variant mixing.
A23: ISW50_EffHigh | B23: E | C23: E9 | D23: 0.41686881 | E23: 0.41686881 | F23: Structural proxy | G23: Local buffering | H23: Complete variant retained; no cross-variant mixing.
... A84: ISW90_EffLow | B84: E | C84: E10 | D84: 0.96816475 | E84: 0.84082376 | F84: Exposure | G84: Crop flexibility and exposure | H84: Complete variant retained; no cross-variant mixing.

Sheet 06_BASELINE_RESULTS
A1: Baseline 2016–2025 — corrected normalisation and aggregation
A3: Subsystem | B3: Code | C3: Indicator | D3: Type | E3: Dimension | F3: Orientation | G3: Raw value | H3: T1 | I3: T2 | J3: T3 | K3: T4 | L3: Normalised | M3: Class | N3: Equal wt | O3: Dimension wt | P3: Active | Q3: Selected contribution
A4: A | B4: A1 | C4: Time-based inflow reliability | D4: Performance | E4: Inflow adequacy | F4: Positive | G4: 0.725 | H4: 0.4 | I4: 0.6 | J4: 0.8 | K4: 1 | L4: =IF(F4="Positive",IF(G4<H4,0,IF(G4<I4,0.25+0.25*(G4-H4)/(I4-H4),IF(G4<J4,0.5+0.25*(G4-I4)/(J4-I4),IF(G4<K4,0.75+0.25*(G4-J4)/(K4-J4),1)))),IF(G4>H4,0,IF(G4>I4,0.25+0.25*(H4-G4)/(H4-I4),IF(G4>J4,0.5+0.25*(I4-G4)/(I4-J4),IF(G4>K4,0.75+0.25*(J4-G4)/(J4-K4),1))))) -> 0.65625 | M4: =IF(L4<0.25,"Low",IF(L4<0.5,"Moderate",IF(L4<0.75,"Good","Excellent"))) -> Good | N4: 0.16666667 | O4: 0.125 | P4: Yes | Q4: =IF(P4<>"Yes",0,L4*IF('01_CONTROL'!$B$11="Equal indicators",N4,O4)) -> 0.08203125
A5: A | B5: A2 | C5: Volumetric inflow reliability | D5: Performance | E5: Inflow adequacy | F5: Positive | G5: 0.81718292 | H5: 0.4 | I5: 0.6 | J5: 0.8 | K5: 1 | L5: =IF(F5="Positive",IF(G5<H5,0,IF(G5<I5,0.25+0.25*(G5-H5)/(I5-H5),IF(G5<J5,0.5+0.25*(G5-I5)/(J5-I5),IF(G5<K5,0.75+0.25*(G5-J5)/(K5-J5),1)))),IF(G5>H5,0,IF(G5>I5,0.25+0.25*(H5-G5)/(H5-I5),IF(G5>J5,0.5+0.25*(I5-G5)/(I5-J5),IF(G5>K5,0.75+0.25*(J5-G5)/(J5-K5),1))))) -> 0.77147865 | M5: =IF(L5<0.25,"Low",IF(L5<0.5,"Moderate",IF(L5<0.75,"Good","Excellent"))) -> Excellent | N5: 0.16666667 | O5: 0.125 | P5: Yes | Q5: =IF(P5<>"Yes",0,L5*IF('01_CONTROL'!$B$11="Equal indicators",N5,O5)) -> 0.096434832
A6: A | B6: A3 | C6: Mean drought duration | D6: Stress | E6: Drought persistence | F6: Negative | G6: 4.5 | H6: 12 | I6: 6 | J6: 3 | K6: 0 | L6: =IF(F6="Positive",IF(G6<H6,0,IF(G6<I6,0.25+0.25*(G6-H6)/(I6-H6),IF(G6<J6,0.5+0.25*(G6-I6)/(J6-I6),IF(G6<K6,0.75+0.25*(G6-J6)/(K6-J6),1)))),IF(G6>H6,0,IF(G6>I6,0.25+0.25*(H6-G6)/(H6-I6),IF(G6>J6,0.5+0.25*(I6-G6)/(I6-J6),IF(G6>K6,0.75+0.25*(J6-G6)/(J6-K6),1))))) -> 0.625 | M6: =IF(L6<0.25,"Low",IF(L6<0.5,"Moderate",IF(L6<0.75,"Good","Excellent"))) -> Good | N6: 0.16666667 | O6: 0.25 | P6: Yes | Q6: =IF(P6<>"Yes",0,L6*IF('01_CONTROL'!$B$11="Equal indicators",N6,O6)) -> 0.15625
A7: A | B7: A4 | C7: Coefficient of variation of annual inflow | D7: Exposure | E7: Interannual variability | F7: Negative | G7: 0.87666572 | H7: 1.1 | I7: 0.9 | J7: 0.5 | K7: 0 | L7: =IF(F7="Positive",IF(G7<H7,0,IF(G7<I7,0.25+0.25*(G7-H7)/(I7-H7),IF(G7<J7,0.5+0.25*(G7-I7)/(J7-I7),IF(G7<K7,0.75+0.25*(G7-J7)/(K7-J7),1)))),IF(G7>H7,0,IF(G7>I7,0.25+0.25*(H7-G7)/(H7-I7),IF(G7>J7,0.5+0.25*(I7-G7)/(I7-J7),IF(G7>K7,0.75+0.25*(J7-G7)/(J7-K7),1))))) -> 0.51458393 | M7: =IF(L7<0.25,"Low",IF(L7<0.5,"Moderate",IF(L7<0.75,"Good","Excellent"))) -> Good | N7: 0.16666667 | O7: 0.25 | P7: Yes | Q7: =IF(P7<>"Yes",0,L7*IF('01_CONTROL'!$B$11="Equal indicators",N7,O7)) -> 0.12864598
A8: A | B8: A5 | C8: Buffering capacity | D8: Structural proxy | E8: Storage context and dependence | F8: Positive | G8: 7.0450966 | H8: 0.75 | I8: 1.5 | J8: 3 | K8: 90.830935 | L8: =IF(F8="Positive",IF(G8<H8,0,IF(G8<I8,0.25+0.25*(G8-H8)/(I8-H8),IF(G8<J8,0.5+0.25*(G8-I8)/(J8-I8),IF(G8<K8,0.75+0.25*(G8-J8)/(K8-J8),1)))),IF(G8>H8,0,IF(G8>I8,0.25+0.25*(H8-G8)/(H8-I8),IF(G8>J8,0.5+0.25*(I8-G8)/(I8-J8),IF(G8>K8,0.75+0.25*(J8-G8)/(J8-K8),1))))) -> 0.76151387 | M8: =IF(L8<0.25,"Low",IF(L8<0.5,"Moderate",IF(L8<0.75,"Good","Excellent"))) -> Excellent | N8: 0.16666667 | O8: 0.125 | P8: Yes | Q8: =IF(P8<>"Yes",0,L8*IF('01_CONTROL'!$B$11="Equal indicators",N8,O8)) -> 0.095189234
A9: A | B9: A6 | C9: Carry-over dependence | D9: Stress | E9: Storage context and dependence | F9: Negative | G9: 1.8398792 | H9: 2 | I9: 1.5 | J9: 1.05 | K9: 1 | L9: =IF(F9="Positive",IF(G9<H9,0,IF(G9<I9,0.25+0.25*(G9-H9)/(I9-H9),IF(G9<J9,0.5+0.25*(G9-I9)/(J9-I9),IF(G9<K9,0.75+0.25*(G9-J9)/(K9-J9),1)))),IF(G9>H9,0,IF(G9>I9,0.25+0.25*(H9-G9)/(H9-I9),IF(G9>J9,0.5+0.25*(I9-G9)/(I9-J9),IF(G9>K9,0.75+0.25*(J9-G9)/(J9-K9),1))))) -> 0.33006038 | M9: =IF(L9<0.25,"Low",IF(L9<0.5,"Moderate",IF(L9<0.75,"Good","Excellent"))) -> Moderate | N9: 0.16666667 | O9: 0.125 | P9: Yes | Q9: =IF(P9<>"Yes",0,L9*IF('01_CONTROL'!$B$11="Equal indicators",N9,O9)) -> 0.041257547
A10: B | B10: B1 | C10: Time-based supply reliability | D10: Performance | E10: Supply adequacy | F10: Positive | G10: 0.99375 | H10: 0.5 | I10: 0.6 | J10: 0.8 | K10: 1 | L10: =IF(F10="Positive",IF(G10<H10,0,IF(G10<I10,0.25+0.25*(G10-H10)/(I10-H10),IF(G10<J10,0.5+0.25*(G10-I10)/(J10-I10),IF(G10<K10,0.75+0.25*(G10-J10)/(K10-J10),1)))),IF(G10>H10,0,IF(G10>I10,0.25+0.25*(H10-G10)/(H10-I10),IF(G10>J10,0.5+0.25*(I10-G10)/(I10-J10),IF(G10>K10,0.75+0.25*(J10-G10)/(J10-K10),1))))) -> 0.9921875 | M10: =IF(L10<0.25,"Low",IF(L10<0.5,"Moderate",IF(L10<0.75,"Good","Excellent"))) -> Excellent | N10: 0.2 | O10: 0.125 | P10: Yes | Q10: =IF(P10<>"Yes",0,L10*IF('01_CONTROL'!$B$11="Equal indicators",N10,O10)) -> 0.12402344
A11: B | B11: B2 | C11: Volumetric supply reliability | D11: Performance | E11: Supply adequacy | F11: Positive | G11: 0.99046393 | H11: 0.5 | I11: 0.6 | J11: 0.8 | K11: 1 | L11: =IF(F11="Positive",IF(G11<H11,0,IF(G11<I11,0.25+0.25*(G11-H11)/(I11-H11),IF(G11<J11,0.5+0.25*(G11-I11)/(J11-I11),IF(G11<K11,0.75+0.25*(G11-J11)/(K11-J11),1)))),IF(G11>H11,0,IF(G11>I11,0.25+0.25*(H11-G11)/(H11-I11),IF(G11>J11,0.5+0.25*(I11-G11)/(I11-J11),IF(G11>K11,0.75+0.25*(J11-G11)/(J11-K11),1))))) -> 0.98807992 | M11: =IF(L11<0.25,"Low",IF(L11<0.5,"Moderate",IF(L11<0.75,"Good","Excellent"))) -> Excellent | N11: 0.2 | O11: 0.125 | P11: Yes | Q11: =IF(P11<>"Yes",0,L11*IF('01_CONTROL'!$B$11="Equal indicators",N11,O11)) -> 0.12350999
A12: B | B12: B3 | C12: Mean supply performance during failure | D12: Performance | E12: Failure severity | F12: Positive | G12: 0.77155359 | H12: 0.7 | I12: 0.75 | J12: 0.8 | K12: 1 | L12: =IF(F12="Positive",IF(G12<H12,0,IF(G12<I12,0.25+0.25*(G12-H12)/(I12-H12),IF(G12<J12,0.5+0.25*(G12-I12)/(J12-I12),IF(G12<K12,0.75+0.25*(G12-J12)/(K12-J12),1)))),IF(G12>H12,0,IF(G12>I12,0.25+0.25*(H12-G12)/(H12-I12),IF(G12>J12,0.5+0.25*(I12-G12)/(I12-J12),IF(G12>K12,0.75+0.25*(J12-G12)/(J12-K12),1))))) -> 0.60776795 | M12: =IF(L12<0.25,"Low",IF(L12<0.5,"Moderate",IF(L12<0.75,"Good","Excellent"))) -> Good | N12: 0.2 | O12: 0.25 | P12: Yes | Q12: =IF(P12<>"Yes",0,L12*IF('01_CONTROL'!$B$11="Equal indicators",N12,O12)) -> 0.15194199
A13: B | B13: B4 | C13: Recovery after failure | D13: Performance | E13: Recovery | F13: Positive | G13: 0.83333333 | H13: 0.25 | I13: 0.5 | J13: 0.75 | K13: 1 | L13: =IF(F13="Positive",IF(G13<H13,0,IF(G13<I13,0.25+0.25*(G13-H13)/(I13-H13),IF(G13<J13,0.5+0.25*(G13-I13)/(J13-I13),IF(G13<K13,0.75+0.25*(G13-J13)/(K13-J13),1)))),IF(G13>H13,0,IF(G13>I13,0.25+0.25*(H13-G13)/(H13-I13),IF(G13>J13,0.5+0.25*(I13-G13)/(I13-J13),IF(G13>K13,0.75+0.25*(J13-G13)/(J13-K13),1))))) -> 0.83333333 | M13: =IF(L13<0.25,"Low",IF(L13<0.5,"Moderate",IF(L13<0.75,"Good","Excellent"))) -> Excellent | N13: 0.2 | O13: 0.25 | P13: Yes | Q13: =IF(P13<>"Yes",0,L13*IF('01_CONTROL'!$B$11="Equal indicators",N13,O13)) -> 0.20833333
A14: B | B14: B5 | C14: Spill–shortage coexistence frequency | D14: Performance | E14: Operational coherence | F14: Negative | G14: 0 | H14: 0.3 | I14: 0.1 | J14: 0.01 | K14: 0 | L14: =IF(F14="Positive",IF(G14<H14,0,IF(G14<I14,0.25+0.25*(G14-H14)/(I14-H14),IF(G14<J14,0.5+0.25*(G14-I14)/(J14-I14),IF(G14<K14,0.75+0.25*(G14-J14)/(K14-J14),1)))),IF(G14>H14,0,IF(G14>I14,0.25+0.25*(H14-G14)/(H14-I14),IF(G14>J14,0.5+0.25*(I14-G14)/(I14-J14),IF(G14>K14,0.75+0.25*(J14-G14)/(J14-K14),1))))) -> 1 | M14: =IF(L14<0.25,"Low",IF(L14<0.5,"Moderate",IF(L14<0.75,"Good","Excellent"))) -> Excellent | N14: 0.2 | O14: 0.25 | P14: Yes | Q14: =IF(P14<>"Yes",0,L14*IF('01_CONTROL'!$B$11="Equal indicators",N14,O14)) -> 0.25
A15: C | B15: C1 | C15: Network pressure reliability | D15: Performance | E15: Pressure reliability | F15: Positive | G15: 0.98197379 | H15: 0.5 | I15: 0.75 | J15: 0.85 | K15: 1 | L15: =IF(F15="Positive",IF(G15<H15,0,IF(G15<I15,0.25+0.25*(G15-H15)/(I15-H15),IF(G15<J15,0.5+0.25*(G15-I15)/(J15-I15),IF(G15<K15,0.75+0.25*(G15-J15)/(K15-J15),1)))),IF(G15>H15,0,IF(G15>I15,0.25+0.25*(H15-G15)/(H15-I15),IF(G15>J15,0.5+0.25*(I15-G15)/(I15-J15),IF(G15>K15,0.75+0.25*(J15-G15)/(J15-K15),1))))) -> 0.96995632 | M15: =IF(L15<0.25,"Low",IF(L15<0.5,"Moderate",IF(L15<0.75,"Good","Excellent"))) -> Excellent | N15: 0.2 | O15: 0.25 | P15: Yes | Q15: =IF(P15<>"Yes",0,L15*IF('01_CONTROL'!$B$11="Equal indicators",N15,O15)) -> 0.24248908
... A41: F | B41: F4 | C41: Participation, communication and compliance | D41: Institutional capacity | E41: Participation and compliance | F41: Positive | G41: 0.4375 | H41: 0.25 | I41: 0.5 | J41: 0.75 | K41: 1 | L41: =IF(F41="Positive",IF(G41<H41,0,IF(G41<I41,0.25+0.25*(G41-H41)/(I41-H41),IF(G41<J41,0.5+0.25*(G41-I41)/(J41-I41),IF(G41<K41,0.75+0.25*(G41-J41)/(K41-J41),1)))),IF(G41>H41,0,IF(G41>I41,0.25+0.25*(H41-G41)/(H41-I41),IF(G41>J41,0.5+0.25*(I41-G41)/(I41-J41),IF(G41>K41,0.75+0.25*(J41-G41)/(J41-K41),1))))) -> 0.4375 | M41: =IF(L41<0.25,"Low",IF(L41<0.5,"Moderate",IF(L41<0.75,"Good","Excellent"))) -> Moderate | N41: 0.25 | O41: 0.25 | P41: Yes | Q41: =IF(P41<>"Yes",0,L41*IF('01_CONTROL'!$B$11="Equal indicators",N41,O41)) -> 0.109375
A44: Subsystem and CIS scores
A45: Subsystem | B45: Equal indicators | C45: Dimension-balanced | D45: Selected score | E45: Class | F45: Manuscript comparison
A46: A | B46: =SUMPRODUCT((A$4:A$41=A46)*(P$4:P$41="Yes")*L$4:L$41)/COUNTIFS(A$4:A$41,A46,P$4:P$41,"Yes") -> 0.60981447 | C46: =SUMPRODUCT((A$4:A$41=A46)*(P$4:P$41="Yes")*L$4:L$41*O$4:O$41)/SUMPRODUCT((A$4:A$41=A46)*(P$4:P$41="Yes")*O$4:O$41) -> 0.59980884 | D46: =IF('01_CONTROL'!$B$11="Equal indicators",B46,C46) -> 0.59980884 | E46: =IF(D46<0.25,"Low",IF(D46<0.5,"Moderate",IF(D46<0.75,"Good","Excellent"))) -> Good | F46: Manuscript 0.63
A47: B | B47: =SUMPRODUCT((A$4:A$41=A47)*(P$4:P$41="Yes")*L$4:L$41)/COUNTIFS(A$4:A$41,A47,P$4:P$41,"Yes") -> 0.88427374 | C47: =SUMPRODUCT((A$4:A$41=A47)*(P$4:P$41="Yes")*L$4:L$41*O$4:O$41)/SUMPRODUCT((A$4:A$41=A47)*(P$4:P$41="Yes")*O$4:O$41) -> 0.85780875 | D47: =IF('01_CONTROL'!$B$11="Equal indicators",B47,C47) -> 0.85780875 | E47: =IF(D47<0.25,"Low",IF(D47<0.5,"Moderate",IF(D47<0.75,"Good","Excellent"))) -> Excellent | F47: Manuscript 0.90
A48: C | B48: =SUMPRODUCT((A$4:A$41=A48)*(P$4:P$41="Yes")*L$4:L$41)/COUNTIFS(A$4:A$41,A48,P$4:P$41,"Yes") -> 0.75748682 | C48: =SUMPRODUCT((A$4:A$41=A48)*(P$4:P$41="Yes")*L$4:L$41*O$4:O$41)/SUMPRODUCT((A$4:A$41=A48)*(P$4:P$41="Yes")*O$4:O$41) -> 0.78797962 | D48: =IF('01_CONTROL'!$B$11="Equal indicators",B48,C48) -> 0.78797962 | E48: =IF(D48<0.25,"Low",IF(D48<0.5,"Moderate",IF(D48<0.75,"Good","Excellent"))) -> Excellent | F48: Manuscript 0.76
A49: D | B49: =SUMPRODUCT((A$4:A$41=A49)*(P$4:P$41="Yes")*L$4:L$41)/COUNTIFS(A$4:A$41,A49,P$4:P$41,"Yes") -> 0.66498612 | C49: =SUMPRODUCT((A$4:A$41=A49)*(P$4:P$41="Yes")*L$4:L$41*O$4:O$41)/SUMPRODUCT((A$4:A$41=A49)*(P$4:P$41="Yes")*O$4:O$41) -> 0.67098653 | D49: =IF('01_CONTROL'!$B$11="Equal indicators",B49,C49) -> 0.67098653 | E49: =IF(D49<0.25,"Low",IF(D49<0.5,"Moderate",IF(D49<0.75,"Good","Excellent"))) -> Good | F49: Manuscript 0.71
A50: E | B50: =SUMPRODUCT((A$4:A$41=A50)*(P$4:P$41="Yes")*L$4:L$41)/COUNTIFS(A$4:A$41,A50,P$4:P$41,"Yes") -> 0.70466672 | C50: =SUMPRODUCT((A$4:A$41=A50)*(P$4:P$41="Yes")*L$4:L$41*O$4:O$41)/SUMPRODUCT((A$4:A$41=A50)*(P$4:P$41="Yes")*O$4:O$41) -> 0.6815186 | D50: =IF('01_CONTROL'!$B$11="Equal indicators",B50,C50) -> 0.6815186 | E50: =IF(D50<0.25,"Low",IF(D50<0.5,"Moderate",IF(D50<0.75,"Good","Excellent"))) -> Good | F50: Manuscript 0.70
A51: F | B51: =SUMPRODUCT((A$4:A$41=A51)*(P$4:P$41="Yes")*L$4:L$41)/COUNTIFS(A$4:A$41,A51,P$4:P$41,"Yes") -> 0.59375 | C51: =SUMPRODUCT((A$4:A$41=A51)*(P$4:P$41="Yes")*L$4:L$41*O$4:O$41)/SUMPRODUCT((A$4:A$41=A51)*(P$4:P$41="Yes")*O$4:O$41) -> 0.59375 | D51: =IF('01_CONTROL'!$B$11="Equal indicators",B51,C51) -> 0.59375 | E51: =IF(D51<0.25,"Low",IF(D51<0.5,"Moderate",IF(D51<0.75,"Good","Excellent"))) -> Good | F51: Manuscript 0.59
A52: Overall CIS | B52: =AVERAGE(B46:B51) -> 0.70249631 | C52: =AVERAGE(C46:C51) -> 0.69864206 | D52: =IF('01_CONTROL'!$B$11="Equal indicators",B52,C52) -> 0.69864206 | E52: =IF(D52<0.25,"Low",IF(D52<0.5,"Moderate",IF(D52<0.75,"Good","Excellent"))) -> Good | F52: Manuscript 0.72

Sheet 07_ANNUAL_SUMMARY
A1: Annual indicator summary — interannual variability only
A2: Definition | B2: Min–max on this sheet is the range among annual values. It is not the four-member ensemble range.
A4: Subsystem | B4: Indicator | C4: n years | D4: Mean | E4: SD | F4: Annual min | G4: Annual max | H4: Coverage | I4: Interpretation | J4: Use in aggregation | K4: QC
A5: A | B5: A1 | C5: 10 | D5: 0.725 | E5: 0.32406085 | F5: 0.16666667 | G5: 1 | H5: 2016–2025 monthly inflow | I5: Describe interannual variability only; do not label as ensemble uncertainty. | J5: Annual variability | K5: OK
A6: A | B6: A2 | C6: 10 | D6: 0.81718292 | E6: 0.33254925 | F6: 0.059809026 | G6: 1 | H6: 2016–2025 monthly inflow | I6: Describe interannual variability only; do not label as ensemble uncertainty. | J6: Annual variability | K6: OK
A7: A | B7: A3 | C7: 10 | D7: 2.75 | E7: 3.3767999 | F7: 0 | G7: 9 | H7: 2016–2025 monthly inflow | I7: Describe interannual variability only; do not label as ensemble uncertainty. | J7: Annual variability | K7: OK
A8: A | B8: A4 | C8: 0 | H8: 2016–2025 annual inflow | I8: Describe interannual variability only; do not label as ensemble uncertainty. | J8: Period-only; annual diagnostic excluded | K8: Not annual
A9: A | B9: A5 | C9: 0 | H9: Net capacity and period mean inflow | I9: Describe interannual variability only; do not label as ensemble uncertainty. | J9: Period-only; annual diagnostic excluded | K9: Not annual
A10: A | B10: A6 | C10: 0 | H10: Baseline and period mean inflow | I10: Describe interannual variability only; do not label as ensemble uncertainty. | J10: Period-only; annual diagnostic excluded | K10: Not annual
A11: B | B11: B1 | C11: 10 | D11: 0.99375 | E11: 0.019764235 | F11: 0.9375 | G11: 1 | H11: 2016–2025; four GIR variants | I11: Describe interannual variability only; do not label as ensemble uncertainty. | J11: Annual variability | K11: OK
A12: B | B12: B2 | C12: 10 | D12: 0.99248271 | E12: 0.023771758 | F12: 0.9248271 | G12: 1 | H12: 2016–2025; four GIR variants | I12: Describe interannual variability only; do not label as ensemble uncertainty. | J12: Annual variability | K12: OK
A13: B | B13: B3 | C13: 10 | D13: 0.97715536 | E13: 0.072241098 | F13: 0.77155359 | G13: 1 | H13: 2016–2025; four GIR variants | I13: Describe interannual variability only; do not label as ensemble uncertainty. | J13: Annual variability | K13: OK
A14: B | B14: B4 | C14: 10 | D14: 0.98333333 | E14: 0.052704628 | F14: 0.83333333 | G14: 1 | H14: 2016–2025; four GIR variants | I14: Describe interannual variability only; do not label as ensemble uncertainty. | J14: Annual variability | K14: OK
A15: B | B15: B5 | C15: 10 | D15: 0 | E15: 0 | F15: 0 | G15: 0 | H15: 2016–2025; four GIR variants | I15: Describe interannual variability only; do not label as ensemble uncertainty. | J15: Annual variability | K15: OK
A16: C | B16: C1 | C16: 10 | D16: 0.98197379 | E16: 0.0083551851 | F16: 0.9749092 | G16: 0.99202027 | H16: 2016–2025; four GIR variants | I16: Describe interannual variability only; do not label as ensemble uncertainty. | J16: Annual variability | K16: OK
A17: C | B17: C2 | C17: 10 | D17: 0.94655854 | E17: 0.019083554 | F17: 0.91666667 | G17: 0.96202532 | H17: 2016–2025; four GIR variants | I17: Describe interannual variability only; do not label as ensemble uncertainty. | J17: Annual variability | K17: OK
A18: C | B18: C3 | C18: 10 | D18: 0.39790148 | E18: 0.29271272 | F18: 0.055840733 | G18: 0.64833247 | H18: 2016–2025; four GIR variants | I18: Describe interannual variability only; do not label as ensemble uncertainty. | J18: Annual variability | K18: OK
A19: C | B19: C4 | C19: 10 | D19: 0.34425345 | E19: 0.20137343 | F19: 0.10650384 | G19: 0.50104234 | H19: 2016–2025; four GIR variants | I19: Describe interannual variability only; do not label as ensemble uncertainty. | J19: Annual variability | K19: OK
A20: C | B20: C5 | C20: 10 | D20: 0.43260759 | E20: 0.15740557 | F20: 0.23593793 | G20: 0.55690083 | H20: 2016–2025; four GIR variants | I20: Describe interannual variability only; do not label as ensemble uncertainty. | J20: Annual variability | K20: OK
A21: D | B21: D1 | C21: 8 | D21: 1041.7707 | E21: 138.69914 | F21: 767.97303 | G21: 1171.7135 | H21: 2018–2025 | I21: Describe interannual variability only; do not label as ensemble uncertainty. | J21: Annual variability | K21: OK
A22: D | B22: D2 | C22: 8 | D22: 0.22960575 | E22: 0.02697335 | F22: 0.1655449 | G22: 0.25221274 | H22: 2018–2025 | I22: Describe interannual variability only; do not label as ensemble uncertainty. | J22: Annual variability | K22: OK
... A26: D | B26: D6 | C26: 10 | D26: 0.025638981 | E26: 0.0042727588 | F26: 0.016351193 | G26: 0.032946769 | H26: 2016–2025 | I26: Describe interannual variability only; do not label as ensemble uncertainty. | J26: Annual variability | K26: OK
A27: D | B27: D7 | C27: 1 | D27: 0.092583038 | F27: 0.092583038 | G27: 0.092583038 | H27: 2025 only | I27: Describe interannual variability only; do not label as ensemble uncertainty. | J27: 2025 snapshot | K27: Not annual
A28: D | B28: D8 | C28: 10 | D28: 0.80611898 | E28: 0.12028454 | F28: 0.54761905 | G28: 0.94756554 | H28: 2016–2025 | I28: Describe interannual variability only; do not label as ensemble uncertainty. | J28: Annual variability | K28: OK
A29: E | B29: E1 | C29: 10 | D29: 452.76811 | E29: 38.370383 | F29: 400.87365 | G29: 506.22936 | H29: 2016–2025; four GIR variants | I29: Describe interannual variability only; do not label as ensemble uncertainty. | J29: Annual variability | K29: OK
A30: E | B30: E2 | C30: 10 | D30: 0.34659797 | E30: 0.019995666 | F30: 0.31597817 | G30: 0.38707723 | H30: 2016–2025; four GIR variants | I30: Describe interannual variability only; do not label as ensemble uncertainty. | J30: Annual variability | K30: OK
A31: E | B31: E3 | C31: 10 | D31: 0.76322927 | E31: 0.038091936 | F31: 0.71248078 | G31: 0.81292855 | H31: 2016–2025; four GIR variants | I31: Describe interannual variability only; do not label as ensemble uncertainty. | J31: Annual variability | K31: OK
A32: E | B32: E4 | C32: 10 | D32: 1.007175 | E32: 0.017447529 | F32: 0.98955181 | G32: 1.0469067 | H32: 2016–2025; low/high efficiency | I32: Describe interannual variability only; do not label as ensemble uncertainty. | J32: Annual variability | K32: OK
A33: E | B33: E5 | C33: 10 | D33: 0.56628899 | E33: 0.015757632 | F33: 0.55066358 | G33: 0.5914837 | H33: 2016–2025 | I33: Describe interannual variability only; do not label as ensemble uncertainty. | J33: Annual variability | K33: OK
A34: E | B34: E6 | C34: 10 | D34: 0.54884269 | E34: 0.0092998559 | F34: 0.5339345 | G34: 0.56121245 | H34: 2016–2025 | I34: Describe interannual variability only; do not label as ensemble uncertainty. | J34: Annual variability | K34: OK
A35: E | B35: E7 | C35: 10 | D35: 0.19744236 | E35: 0.037360339 | F35: 0.12103906 | G35: 0.24275115 | H35: 2016–2025 | I35: Describe interannual variability only; do not label as ensemble uncertainty. | J35: Annual variability | K35: OK
A36: E | B36: E8 | C36: 10 | D36: 79.541354 | E36: 2.5708539 | F36: 76.014548 | G36: 83.676408 | H36: 2016–2025 | I36: Describe interannual variability only; do not label as ensemble uncertainty. | J36: Annual variability | K36: OK
A37: E | B37: E9 | C37: 10 | D37: 0.41686881 | E37: 0 | F37: 0.41686881 | G37: 0.41686881 | H37: Current mapping | I37: Describe interannual variability only; do not label as ensemble uncertainty. | J37: Structural snapshot | K37: OK
A38: E | B38: E10 | C38: 10 | D38: 0.96816475 | E38: 0.037419715 | F38: 0.90774403 | G38: 1 | H38: 2016–2025 | I38: Describe interannual variability only; do not label as ensemble uncertainty. | J38: Annual variability | K38: OK
A39: F | B39: F1 | C39: 0 | H39: Current evidence | I39: Describe interannual variability only; do not label as ensemble uncertainty. | J39: Annual variability | K39: Not annual
A40: F | B40: F2 | C40: 0 | H40: Current evidence | I40: Describe interannual variability only; do not label as ensemble uncertainty. | J40: Annual variability | K40: Not annual
A41: F | B41: F3 | C41: 0 | H41: Current evidence | I41: Describe interannual variability only; do not label as ensemble uncertainty. | J41: Annual variability | K41: Not annual
A42: F | B42: F4 | C42: 0 | H42: Current evidence | I42: Describe interannual variability only; do not label as ensemble uncertainty. | J42: Annual variability | K42: Not annual

Sheet 08_PRE_POST
A1: Pre- versus post-expansion comparison
A2: Caution | B2: Main periods: 2016–2020 versus 2022–2025; 2021 is transition. Differences are descriptive, not causal expansion effects.
A4: Subsystem | B4: Indicator | C4: Pre raw | D4: Post raw | E4: Difference | F4: Relative change % | G4: Pre norm | H4: Post norm | I4: Norm change | J4: Pre class | K4: Post class | L4: Use | M4: Interpretation
A5: A | B5: A1 | C5: 0.75 | D5: 0.64583333 | E5: -0.10416667 | F5: -13.888889 | G5: 0.6875 | H5: 0.55729167 | I5: -0.13020833 | J5: Good | K5: Good | L5: A–E comparable indicator | M5: Interpret jointly with climate and crop/technology changes; do not infer causality from period contrast.
A6: A | B6: A2 | C6: 0.78925738 | D6: 0.80638619 | E6: 0.017128811 | F6: 2.170244 | G6: 0.73657172 | H6: 0.75798274 | I6: 0.021411013 | J6: Good | K6: Excellent | L6: A–E comparable indicator | M6: Interpret jointly with climate and crop/technology changes; do not infer causality from period contrast.
A7: A | B7: A3 | C7: 3 | D7: 4.25 | E7: 1.25 | F7: 41.666667 | G7: 0.75 | H7: 0.64583333 | I7: -0.10416667 | J7: Excellent | K7: Good | L7: A–E comparable indicator | M7: Interpret jointly with climate and crop/technology changes; do not infer causality from period contrast.
A8: A | B8: A4 | C8: 1.0447731 | D8: 0.70532816 | E8: -0.33944497 | F8: -32.489826 | G8: 0.31903359 | H8: 0.6216699 | I8: 0.30263631 | J8: Moderate | K8: Good | L8: A–E comparable indicator | M8: Interpret jointly with climate and crop/technology changes; do not infer causality from period contrast.
A9: A | B9: A5 | C9: 13.48401 | D9: 4.6548047 | E9: -8.8292056 | F9: -65.479078 | G9: 0.77984145 | H9: 0.7547102 | I9: -0.025131252 | J9: Excellent | K9: Excellent | L9: A–E comparable indicator | M9: Interpret jointly with climate and crop/technology changes; do not infer causality from period contrast.
A10: A | B10: A6 | C10: 3.5214493 | D10: 1.2156368 | E10: -2.3058125 | F10: -65.479078 | G10: 0 | H10: 0.65797956 | I10: 0.65797956 | J10: Low | K10: Good | L10: A–E comparable indicator | M10: Interpret jointly with climate and crop/technology changes; do not infer causality from period contrast.
A11: B | B11: B1 | C11: 1 | D11: 0.984375 | E11: -0.015625 | F11: -1.5625 | G11: 1 | H11: 0.98046875 | I11: -0.01953125 | J11: Excellent | K11: Excellent | L11: A–E comparable indicator | M11: Interpret jointly with climate and crop/technology changes; do not infer causality from period contrast.
A12: B | B12: B2 | C12: 1 | D12: 0.98120678 | E12: -0.018793225 | F12: -1.8793225 | G12: 1 | H12: 0.97650847 | I12: -0.023491531 | J12: Excellent | K12: Excellent | L12: A–E comparable indicator | M12: Interpret jointly with climate and crop/technology changes; do not infer causality from period contrast.
A13: B | B13: B3 | C13: 1 | D13: 0.9428884 | E13: -0.057111602 | F13: -5.7111602 | G13: 1 | H13: 0.9286105 | I13: -0.071389503 | J13: Excellent | K13: Excellent | L13: A–E comparable indicator | M13: Interpret jointly with climate and crop/technology changes; do not infer causality from period contrast.
A14: B | B14: B4 | C14: 1 | D14: 0.95833333 | E14: -0.041666667 | F14: -4.1666667 | G14: 1 | H14: 0.95833333 | I14: -0.041666667 | J14: Excellent | K14: Excellent | L14: A–E comparable indicator | M14: Interpret jointly with climate and crop/technology changes; do not infer causality from period contrast.
A15: B | B15: B5 | C15: 0 | D15: 0 | E15: 0 | G15: 1 | H15: 1 | I15: 0 | J15: Excellent | K15: Excellent | L15: A–E comparable indicator | M15: Interpret jointly with climate and crop/technology changes; do not infer causality from period contrast.
A16: C | B16: C1 | C16: 0.97558959 | D16: 0.99166723 | E16: 0.016077641 | F16: 1.6479923 | G16: 0.95931598 | H16: 0.98611205 | I16: 0.026796069 | J16: Excellent | K16: Excellent | L16: A–E comparable indicator | M16: Interpret jointly with climate and crop/technology changes; do not infer causality from period contrast.
A17: C | B17: C2 | C17: 0.95696203 | D17: 0.9296875 | E17: -0.027274525 | F17: -2.8501157 | G17: 0.92827004 | H17: 0.8828125 | I17: -0.045457542 | J17: Excellent | K17: Excellent | L17: A–E comparable indicator | M17: Interpret jointly with climate and crop/technology changes; do not infer causality from period contrast.
A18: C | B18: C3 | C18: 0.62196722 | D18: 0.058221699 | E18: -0.56374552 | F18: -90.639105 | G18: 0.43901639 | H18: 0.9917783 | I18: 0.55276191 | J18: Moderate | K18: Excellent | L18: A–E comparable indicator | M18: Interpret jointly with climate and crop/technology changes; do not infer causality from period contrast.
A19: C | B19: C4 | C19: 0.50010237 | D19: 0.11028767 | E19: -0.3898147 | F19: -77.94698 | G19: 0.49994881 | H19: 0.93971233 | I19: 0.43976351 | J19: Moderate | K19: Excellent | L19: A–E comparable indicator | M19: Interpret jointly with climate and crop/technology changes; do not infer causality from period contrast.
A20: C | B20: C5 | C20: 0.55402153 | D20: 0.25007346 | E20: -0.30394806 | F20: -54.86214 | G20: 0.47298924 | H20: 0.79992654 | I20: 0.3269373 | J20: Moderate | K20: Excellent | L20: A–E comparable indicator | M20: Interpret jointly with climate and crop/technology changes; do not infer causality from period contrast.
A21: D | B21: D1 | C21: 1098.8671 | D21: 989.20026 | E21: -109.66685 | F21: -9.9799917 | G21: 0.70056645 | H21: 0.75539987 | I21: 0.054833423 | J21: Good | K21: Excellent | L21: A–E comparable indicator | M21: Interpret jointly with climate and crop/technology changes; do not infer causality from period contrast.
A22: D | B22: D2 | C22: 0.24387706 | D22: 0.21628273 | E22: -0.027594332 | F22: -11.314853 | G22: 0.64030734 | H22: 0.70929317 | I22: 0.06898583 | J22: Good | K22: Good | L22: A–E comparable indicator | M22: Interpret jointly with climate and crop/technology changes; do not infer causality from period contrast.
A23: D | B23: D3 | C23: 0.22929322 | D23: 0.20334902 | E23: -0.025944191 | F23: -11.314853 | G23: 0.55176696 | H23: 0.61662744 | I23: 0.064860478 | J23: Good | K23: Good | L23: A–E comparable indicator | M23: Interpret jointly with climate and crop/technology changes; do not infer causality from period contrast.
A24: D | B24: D4 | C24: 127.48737 | D24: 121.56545 | E24: -5.9219166 | F24: -4.6451008 | G24: 0.61256317 | H24: 0.64217275 | I24: 0.029609583 | J24: Good | K24: Good | L24: A–E comparable indicator | M24: Interpret jointly with climate and crop/technology changes; do not infer causality from period contrast.
A25: D | B25: D5 | C25: 0.027643028 | D25: 0.026590803 | E25: -0.0010522251 | F25: -3.8064753 | G25: 0.65446214 | H25: 0.66761496 | I25: 0.013152813 | J25: Good | K25: Good | L25: A–E comparable indicator | M25: Interpret jointly with climate and crop/technology changes; do not infer causality from period contrast.
A26: D | B26: D6 | C26: 0.025989975 | D26: 0.025000673 | E26: -0.00098930199 | F26: -3.8064753 | G26: 0.67512531 | H26: 0.68749158 | I26: 0.012366275 | J26: Good | K26: Good | L26: A–E comparable indicator | M26: Interpret jointly with climate and crop/technology changes; do not infer causality from period contrast.
